{
  "version": 8,
  "blockIdVersion": 11,
  "anchorX": 1,
  "anchorY": 5,
  "anchorZ": 1,
  "blocks": [
    {
      "x": -22,
      "y": 10,
      "z": 0,
      "name": "Wood_Drywood_Planks"
    },
    {
      "x": -22,
      "y": 11,
      "z": 0,
      "name": "Wood_Drywood_Decorative"
    },
    {
      "x": -22,
      "y": 12,
      "z": 0,
      "name": "*Wood_Drywood_Fence_State_Definitions_Corner",
      "rotation": 1
    },
    {
      "x": -22,
      "y": 10,
      "z": 1,
      "name": "Wood_Drywood_Planks"
    },
    {
      "x": -22,
      "y": 11,
      "z": 1,
      "name": "Wood_Drywood_Decorative"
    },
    {
      "x": -22,
      "y": 12,
      "z": 1,
      "name": "Wood_Drywood_Fence",
      "rotation": 3
    },
    {
      "x": -22,
      "y": 10,
      "z": 2,
      "name": "Wood_Drywood_Planks"
    },
    {
      "x": -22,
      "y": 11,
      "z": 2,
      "name": "Wood_Drywood_Decorative"
    },
    {
      "x": -22,
      "y": 12,
      "z": 2,
      "name": "*Wood_Drywood_Fence_State_Definitions_Corner",
      "rotation": 2
    },
    {
      "x": -21,
      "y": 10,
      "z": -1,
      "name": "Wood_Drywood_Planks"
    },
    {
      "x": -21,
      "y": 11,
      "z": -1,
      "name": "Wood_Drywood_Decorative"
    },
    {
      "x": -21,
      "y": 12,
      "z": -1,
      "name": "*Wood_Drywood_Fence_State_Definitions_Corner",
      "rotation": 1
    },
    {
      "x": -21,
      "y": 9,
      "z": 0,
      "name": "Wood_Drywood_Planks"
    },
    {
      "x": -21,
      "y": 11,
      "z": 0,
      "name": "Wood_Drywood_Planks"
    },
    {
      "x": -21,
      "y": 12,
      "z": 0,
      "name": "*Wood_Drywood_Fence_State_Definitions_Corner",
      "rotation": 3
    },
    {
      "x": -21,
      "y": 8,
      "z": 1,
      "name": "Wood_Drywood_Planks"
    },
    {
      "x": -21,
      "y": 9,
      "z": 1,
      "name": "Wood_Drywood_Planks"
    },
    {
      "x": -21,
      "y": 11,
      "z": 1,
      "name": "Wood_Drywood_Planks"
    },
    {
      "x": -21,
      "y": 9,
      "z": 2,
      "name": "Wood_Drywood_Planks"
    },
    {
      "x": -21,
      "y": 11,
      "z": 2,
      "name": "Wood_Drywood_Planks"
    },
    {
      "x": -21,
      "y": 12,
      "z": 2,
      "name": "*Wood_Drywood_Fence_State_Definitions_Corner"
    },
    {
      "x": -21,
      "y": 10,
      "z": 3,
      "name": "Wood_Drywood_Planks"
    },
    {
      "x": -21,
      "y": 11,
      "z": 3,
      "name": "Wood_Drywood_Decorative"
    },
    {
      "x": -21,
      "y": 12,
      "z": 3,
      "name": "*Wood_Drywood_Fence_State_Definitions_Corner",
      "rotation": 2
    },
    {
      "x": -20,
      "y": 9,
      "z": -2,
      "name": "Wood_Drywood_Planks"
    },
    {
      "x": -20,
      "y": 10,
      "z": -2,
      "name": "Wood_Drywood_Planks"
    },
    {
      "x": -20,
      "y": 11,
      "z": -2,
      "name": "Wood_Drywood_Decorative"
    },
    {
      "x": -20,
      "y": 12,
      "z": -2,
      "name": "*Wood_Drywood_Fence_State_Definitions_Corner",
      "rotation": 1
    },
    {
      "x": -20,
      "y": 8,
      "z": -1,
      "name": "Wood_Drywood_Planks"
    },
    {
      "x": -20,
      "y": 9,
      "z": -1,
      "name": "Wood_Drywood_Planks"
    },
    {
      "x": -20,
      "y": 11,
      "z": -1,
      "name": "Wood_Drywood_Planks"
    },
    {
      "x": -20,
      "y": 12,
      "z": -1,
      "name": "*Wood_Drywood_Fence_State_Definitions_Corner",
      "rotation": 3
    },
    {
      "x": -20,
      "y": 7,
      "z": 0,
      "name": "Wood_Drywood_Planks"
    },
    {
      "x": -20,
      "y": 8,
      "z": 0,
      "name": "Wood_Drywood_Planks"
    },
    {
      "x": -20,
      "y": 11,
      "z": 0,
      "name": "Wood_Drywood_Planks"
    },
    {
      "x": -20,
      "y": 7,
      "z": 1,
      "name": "Wood_Drywood_Planks"
    },
    {
      "x": -20,
      "y": 11,
      "z": 1,
      "name": "Wood_Drywood_Planks"
    },
    {
      "x": -20,
      "y": 7,
      "z": 2,
      "name": "Wood_Drywood_Planks"
    },
    {
      "x": -20,
      "y": 8,
      "z": 2,
      "name": "Wood_Drywood_Planks"
    },
    {
      "x": -20,
      "y": 11,
      "z": 2,
      "name": "Wood_Drywood_Planks"
    },
    {
      "x": -20,
      "y": 8,
      "z": 3,
      "name": "Wood_Drywood_Planks"
    },
    {
      "x": -20,
      "y": 9,
      "z": 3,
      "name": "Wood_Drywood_Planks"
    },
    {
      "x": -20,
      "y": 11,
      "z": 3,
      "name": "Wood_Drywood_Planks"
    },
    {
      "x": -20,
      "y": 12,
      "z": 3,
      "name": "*Wood_Drywood_Fence_State_Definitions_Corner"
    },
    {
      "x": -20,
      "y": 9,
      "z": 4,
      "name": "Wood_Drywood_Planks"
    },
    {
      "x": -20,
      "y": 10,
      "z": 4,
      "name": "Wood_Drywood_Planks"
    },
    {
      "x": -20,
      "y": 11,
      "z": 4,
      "name": "Wood_Drywood_Decorative"
    },
    {
      "x": -20,
      "y": 12,
      "z": 4,
      "name": "*Wood_Drywood_Fence_State_Definitions_Corner",
      "rotation": 2
    },
    {
      "x": -19,
      "y": 9,
      "z": -2,
      "name": "Wood_Drywood_Planks"
    },
    {
      "x": -19,
      "y": 10,
      "z": -2,
      "name": "Wood_Drywood_Planks"
    },
    {
      "x": -19,
      "y": 11,
      "z": -2,
      "name": "Wood_Drywood_Decorative"
    },
    {
      "x": -19,
      "y": 12,
      "z": -2,
      "name": "Wood_Drywood_Fence",
      "rotation": 2
    },
    {
      "x": -19,
      "y": 7,
      "z": -1,
      "name": "Wood_Drywood_Planks"
    },
    {
      "x": -19,
      "y": 8,
      "z": -1,
      "name": "Wood_Drywood_Planks"
    },
    {
      "x": -19,
      "y": 11,
      "z": -1,
      "name": "Wood_Drywood_Planks"
    },
    {
      "x": -19,
      "y": 6,
      "z": 0,
      "name": "Wood_Drywood_Planks"
    },
    {
      "x": -19,
      "y": 7,
      "z": 0,
      "name": "Wood_Drywood_Planks"
    },
    {
      "x": -19,
      "y": 11,
      "z": 0,
      "name": "Wood_Drywood_Planks"
    },
    {
      "x": -19,
      "y": 6,
      "z": 1,
      "name": "Wood_Drywood_Planks"
    },
    {
      "x": -19,
      "y": 7,
      "z": 1,
      "name": "Wood_Drywood_Planks"
    },
    {
      "x": -19,
      "y": 11,
      "z": 1,
      "name": "Wood_Drywood_Planks"
    },
    {
      "x": -19,
      "y": 6,
      "z": 2,
      "name": "Wood_Drywood_Planks"
    },
    {
      "x": -19,
      "y": 7,
      "z": 2,
      "name": "Wood_Drywood_Planks"
    },
    {
      "x": -19,
      "y": 11,
      "z": 2,
      "name": "Wood_Drywood_Planks"
    },
    {
      "x": -19,
      "y": 7,
      "z": 3,
      "name": "Wood_Drywood_Planks"
    },
    {
      "x": -19,
      "y": 8,
      "z": 3,
      "name": "Wood_Drywood_Planks"
    },
    {
      "x": -19,
      "y": 11,
      "z": 3,
      "name": "Wood_Drywood_Planks"
    },
    {
      "x": -19,
      "y": 9,
      "z": 4,
      "name": "Wood_Drywood_Planks"
    },
    {
      "x": -19,
      "y": 10,
      "z": 4,
      "name": "Wood_Drywood_Planks"
    },
    {
      "x": -19,
      "y": 11,
      "z": 4,
      "name": "Wood_Drywood_Decorative"
    },
    {
      "x": -19,
      "y": 12,
      "z": 4,
      "name": "Wood_Drywood_Fence"
    },
    {
      "x": -18,
      "y": 9,
      "z": -3,
      "name": "Wood_Drywood_Planks"
    },
    {
      "x": -18,
      "y": 10,
      "z": -3,
      "name": "Wood_Drywood_Planks"
    },
    {
      "x": -18,
      "y": 11,
      "z": -3,
      "name": "Wood_Drywood_Decorative"
    },
    {
      "x": -18,
      "y": 12,
      "z": -3,
      "name": "*Wood_Drywood_Fence_State_Definitions_Corner",
      "rotation": 1
    },
    {
      "x": -18,
      "y": 8,
      "z": -2,
      "name": "Wood_Drywood_Planks"
    },
    {
      "x": -18,
      "y": 11,
      "z": -2,
      "name": "Wood_Drywood_Planks"
    },
    {
      "x": -18,
      "y": 12,
      "z": -2,
      "name": "*Wood_Drywood_Fence_State_Definitions_Corner",
      "rotation": 3
    },
    {
      "x": -18,
      "y": 7,
      "z": -1,
      "name": "Wood_Drywood_Planks"
    },
    {
      "x": -18,
      "y": 11,
      "z": -1,
      "name": "Wood_Drywood_Planks"
    },
    {
      "x": -18,
      "y": 5,
      "z": 0,
      "name": "Wood_Drywood_Planks"
    },
    {
      "x": -18,
      "y": 6,
      "z": 0,
      "name": "Wood_Drywood_Planks"
    },
    {
      "x": -18,
      "y": 7,
      "z": 0,
      "name": "Wood_Drywood_Planks"
    },
    {
      "x": -18,
      "y": 11,
      "z": 0,
      "name": "Wood_Drywood_Planks"
    },
    {
      "x": -18,
      "y": 4,
      "z": 1,
      "name": "Wood_Drywood_Planks"
    },
    {
      "x": -18,
      "y": 5,
      "z": 1,
      "name": "Wood_Drywood_Planks"
    },
    {
      "x": -18,
      "y": 6,
      "z": 1,
      "name": "Wood_Drywood_Planks"
    },
    {
      "x": -18,
      "y": 7,
      "z": 1,
      "name": "Wood_Drywood_Planks"
    },
    {
      "x": -18,
      "y": 11,
      "z": 1,
      "name": "Wood_Drywood_Planks"
    },
    {
      "x": -18,
      "y": 5,
      "z": 2,
      "name": "Wood_Drywood_Planks"
    },
    {
      "x": -18,
      "y": 6,
      "z": 2,
      "name": "Wood_Drywood_Planks"
    },
    {
      "x": -18,
      "y": 7,
      "z": 2,
      "name": "Wood_Drywood_Planks"
    },
    {
      "x": -18,
      "y": 11,
      "z": 2,
      "name": "Wood_Drywood_Planks"
    },
    {
      "x": -18,
      "y": 7,
      "z": 3,
      "name": "Wood_Drywood_Planks"
    },
    {
      "x": -18,
      "y": 11,
      "z": 3,
      "name": "Wood_Drywood_Planks"
    },
    {
      "x": -18,
      "y": 8,
      "z": 4,
      "name": "Wood_Drywood_Planks"
    },
    {
      "x": -18,
      "y": 11,
      "z": 4,
      "name": "Wood_Drywood_Planks"
    },
    {
      "x": -18,
      "y": 12,
      "z": 4,
      "name": "*Wood_Drywood_Fence_State_Definitions_Corner"
    },
    {
      "x": -18,
      "y": 9,
      "z": 5,
      "name": "Wood_Drywood_Planks"
    },
    {
      "x": -18,
      "y": 10,
      "z": 5,
      "name": "Wood_Drywood_Planks"
    },
    {
      "x": -18,
      "y": 11,
      "z": 5,
      "name": "Wood_Drywood_Decorative"
    },
    {
      "x": -18,
      "y": 12,
      "z": 5,
      "name": "*Wood_Drywood_Fence_State_Definitions_Corner",
      "rotation": 2
    },
    {
      "x": -17,
      "y": 9,
      "z": -3,
      "name": "Wood_Drywood_Planks"
    },
    {
      "x": -17,
      "y": 10,
      "z": -3,
      "name": "Wood_Drywood_Planks"
    },
    {
      "x": -17,
      "y": 11,
      "z": -3,
      "name": "Wood_Drywood_Decorative"
    },
    {
      "x": -17,
      "y": 12,
      "z": -3,
      "name": "Wood_Drywood_Fence",
      "rotation": 2
    },
    {
      "x": -17,
      "y": 8,
      "z": -2,
      "name": "Wood_Drywood_Planks"
    },
    {
      "x": -17,
      "y": 11,
      "z": -2,
      "name": "Wood_Drywood_Planks"
    },
    {
      "x": -17,
      "y": 6,
      "z": -1,
      "name": "Wood_Drywood_Planks"
    },
    {
      "x": -17,
      "y": 7,
      "z": -1,
      "name": "Wood_Drywood_Planks"
    },
    {
      "x": -17,
      "y": 11,
      "z": -1,
      "name": "Wood_Drywood_Planks"
    },
    {
      "x": -17,
      "y": 4,
      "z": 0,
      "name": "Wood_Drywood_Planks"
    },
    {
      "x": -17,
      "y": 5,
      "z": 0,
      "name": "Wood_Drywood_Planks"
    },
    {
      "x": -17,
      "y": 6,
      "z": 0,
      "name": "Wood_Drywood_Planks"
    },
    {
      "x": -17,
      "y": 7,
      "z": 0,
      "name": "Wood_Drywood_Planks"
    },
    {
      "x": -17,
      "y": 11,
      "z": 0,
      "name": "Wood_Drywood_Planks"
    },
    {
      "x": -17,
      "y": 3,
      "z": 1,
      "name": "Wood_Drywood_Planks"
    },
    {
      "x": -17,
      "y": 4,
      "z": 1,
      "name": "Wood_Drywood_Planks"
    },
    {
      "x": -17,
      "y": 7,
      "z": 1,
      "name": "Wood_Drywood_Planks"
    },
    {
      "x": -17,
      "y": 11,
      "z": 1,
      "name": "Wood_Drywood_Planks"
    },
    {
      "x": -17,
      "y": 4,
      "z": 2,
      "name": "Wood_Drywood_Planks"
    },
    {
      "x": -17,
      "y": 5,
      "z": 2,
      "name": "Wood_Drywood_Planks"
    },
    {
      "x": -17,
      "y": 6,
      "z": 2,
      "name": "Wood_Drywood_Planks"
    },
    {
      "x": -17,
      "y": 7,
      "z": 2,
      "name": "Wood_Drywood_Planks"
    },
    {
      "x": -17,
      "y": 11,
      "z": 2,
      "name": "Wood_Drywood_Planks"
    },
    {
      "x": -17,
      "y": 6,
      "z": 3,
      "name": "Wood_Drywood_Planks"
    },
    {
      "x": -17,
      "y": 7,
      "z": 3,
      "name": "Wood_Drywood_Planks"
    },
    {
      "x": -17,
      "y": 11,
      "z": 3,
      "name": "Wood_Drywood_Planks"
    },
    {
      "x": -17,
      "y": 8,
      "z": 4,
      "name": "Wood_Drywood_Planks"
    },
    {
      "x": -17,
      "y": 11,
      "z": 4,
      "name": "Wood_Drywood_Planks"
    },
    {
      "x": -17,
      "y": 9,
      "z": 5,
      "name": "Wood_Drywood_Planks"
    },
    {
      "x": -17,
      "y": 10,
      "z": 5,
      "name": "Wood_Drywood_Planks"
    },
    {
      "x": -17,
      "y": 11,
      "z": 5,
      "name": "Wood_Drywood_Decorative"
    },
    {
      "x": -17,
      "y": 12,
      "z": 5,
      "name": "Wood_Drywood_Fence"
    },
    {
      "x": -16,
      "y": 9,
      "z": -4,
      "name": "Wood_Drywood_Planks"
    },
    {
      "x": -16,
      "y": 10,
      "z": -4,
      "name": "Wood_Drywood_Planks"
    },
    {
      "x": -16,
      "y": 11,
      "z": -4,
      "name": "Wood_Drywood_Decorative"
    },
    {
      "x": -16,
      "y": 12,
      "z": -4,
      "name": "*Wood_Drywood_Fence_State_Definitions_Corner",
      "rotation": 1
    },
    {
      "x": -16,
      "y": 8,
      "z": -3,
      "name": "Wood_Drywood_Planks"
    },
    {
      "x": -16,
      "y": 11,
      "z": -3,
      "name": "Wood_Drywood_Planks"
    },
    {
      "x": -16,
      "y": 12,
      "z": -3,
      "name": "*Wood_Drywood_Fence_State_Definitions_Corner",
      "rotation": 3
    },
    {
      "x": -16,
      "y": 7,
      "z": -2,
      "name": "Wood_Drywood_Planks"
    },
    {
      "x": -16,
      "y": 8,
      "z": -2,
      "name": "Wood_Drywood_Planks"
    },
    {
      "x": -16,
      "y": 11,
      "z": -2,
      "name": "Wood_Drywood_Planks"
    },
    {
      "x": -16,
      "y": 5,
      "z": -1,
      "name": "Wood_Drywood_Planks"
    },
    {
      "x": -16,
      "y": 6,
      "z": -1,
      "name": "Wood_Drywood_Planks"
    },
    {
      "x": -16,
      "y": 7,
      "z": -1,
      "name": "Wood_Drywood_Planks"
    },
    {
      "x": -16,
      "y": 11,
      "z": -1,
      "name": "Wood_Drywood_Planks"
    },
    {
      "x": -16,
      "y": 4,
      "z": 0,
      "name": "Wood_Drywood_Planks"
    },
    {
      "x": -16,
      "y": 7,
      "z": 0,
      "name": "Wood_Drywood_Planks"
    },
    {
      "x": -16,
      "y": 11,
      "z": 0,
      "name": "Wood_Drywood_Planks"
    },
    {
      "x": -16,
      "y": 3,
      "z": 1,
      "name": "Wood_Drywood_Planks"
    },
    {
      "x": -16,
      "y": 4,
      "z": 1,
      "name": "Wood_Drywood_Planks"
    },
    {
      "x": -16,
      "y": 7,
      "z": 1,
      "name": "Wood_Drywood_Planks"
    },
    {
      "x": -16,
      "y": 11,
      "z": 1,
      "name": "Wood_Drywood_Planks"
    },
    {
      "x": -16,
      "y": 4,
      "z": 2,
      "name": "Wood_Drywood_Planks"
    },
    {
      "x": -16,
      "y": 7,
      "z": 2,
      "name": "Wood_Drywood_Planks"
    },
    {
      "x": -16,
      "y": 11,
      "z": 2,
      "name": "Wood_Drywood_Planks"
    },
    {
      "x": -16,
      "y": 5,
      "z": 3,
      "name": "Wood_Drywood_Planks"
    },
    {
      "x": -16,
      "y": 6,
      "z": 3,
      "name": "Wood_Drywood_Planks"
    },
    {
      "x": -16,
      "y": 7,
      "z": 3,
      "name": "Wood_Drywood_Planks"
    },
    {
      "x": -16,
      "y": 11,
      "z": 3,
      "name": "Wood_Drywood_Planks"
    },
    {
      "x": -16,
      "y": 7,
      "z": 4,
      "name": "Wood_Drywood_Planks"
    },
    {
      "x": -16,
      "y": 8,
      "z": 4,
      "name": "Wood_Drywood_Planks"
    },
    {
      "x": -16,
      "y": 11,
      "z": 4,
      "name": "Wood_Drywood_Planks"
    },
    {
      "x": -16,
      "y": 8,
      "z": 5,
      "name": "Wood_Drywood_Planks"
    },
    {
      "x": -16,
      "y": 11,
      "z": 5,
      "name": "Wood_Drywood_Planks"
    },
    {
      "x": -16,
      "y": 12,
      "z": 5,
      "name": "*Wood_Drywood_Fence_State_Definitions_Corner"
    },
    {
      "x": -16,
      "y": 9,
      "z": 6,
      "name": "Wood_Drywood_Planks"
    },
    {
      "x": -16,
      "y": 10,
      "z": 6,
      "name": "Wood_Drywood_Planks"
    },
    {
      "x": -16,
      "y": 11,
      "z": 6,
      "name": "Wood_Drywood_Decorative"
    },
    {
      "x": -16,
      "y": 12,
      "z": 6,
      "name": "*Wood_Drywood_Fence_State_Definitions_Corner",
      "rotation": 2
    },
    {
      "x": -15,
      "y": 9,
      "z": -4,
      "name": "Wood_Drywood_Planks"
    },
    {
      "x": -15,
      "y": 10,
      "z": -4,
      "name": "Wood_Drywood_Planks"
    },
    {
      "x": -15,
      "y": 11,
      "z": -4,
      "name": "Wood_Drywood_Decorative"
    },
    {
      "x": -15,
      "y": 12,
      "z": -4,
      "name": "Wood_Drywood_Fence",
      "rotation": 2
    },
    {
      "x": -15,
      "y": 8,
      "z": -3,
      "name": "Wood_Drywood_Planks"
    },
    {
      "x": -15,
      "y": 11,
      "z": -3,
      "name": "Wood_Drywood_Planks"
    },
    {
      "x": -15,
      "y": 6,
      "z": -2,
      "name": "Wood_Drywood_Planks"
    },
    {
      "x": -15,
      "y": 7,
      "z": -2,
      "name": "Wood_Drywood_Planks"
    },
    {
      "x": -15,
      "y": 11,
      "z": -2,
      "name": "Wood_Drywood_Planks"
    },
    {
      "x": -15,
      "y": 5,
      "z": -1,
      "name": "Wood_Drywood_Planks"
    },
    {
      "x": -15,
      "y": 6,
      "z": -1,
      "name": "Wood_Drywood_Planks"
    },
    {
      "x": -15,
      "y": 7,
      "z": -1,
      "name": "Wood_Drywood_Planks"
    },
    {
      "x": -15,
      "y": 11,
      "z": -1,
      "name": "Wood_Drywood_Planks"
    },
    {
      "x": -15,
      "y": 4,
      "z": 0,
      "name": "Wood_Drywood_Planks"
    },
    {
      "x": -15,
      "y": 7,
      "z": 0,
      "name": "Wood_Drywood_Planks"
    },
    {
      "x": -15,
      "y": 11,
      "z": 0,
      "name": "Wood_Drywood_Planks"
    },
    {
      "x": -15,
      "y": 3,
      "z": 1,
      "name": "Wood_Drywood_Planks"
    },
    {
      "x": -15,
      "y": 7,
      "z": 1,
      "name": "Wood_Drywood_Planks"
    },
    {
      "x": -15,
      "y": 11,
      "z": 1,
      "name": "Wood_Drywood_Planks"
    },
    {
      "x": -15,
      "y": 4,
      "z": 2,
      "name": "Wood_Drywood_Planks"
    },
    {
      "x": -15,
      "y": 7,
      "z": 2,
      "name": "Wood_Drywood_Planks"
    },
    {
      "x": -15,
      "y": 11,
      "z": 2,
      "name": "Wood_Drywood_Planks"
    },
    {
      "x": -15,
      "y": 5,
      "z": 3,
      "name": "Wood_Drywood_Planks"
    },
    {
      "x": -15,
      "y": 6,
      "z": 3,
      "name": "Wood_Drywood_Planks"
    },
    {
      "x": -15,
      "y": 7,
      "z": 3,
      "name": "Wood_Drywood_Planks"
    },
    {
      "x": -15,
      "y": 11,
      "z": 3,
      "name": "Wood_Drywood_Planks"
    },
    {
      "x": -15,
      "y": 6,
      "z": 4,
      "name": "Wood_Drywood_Planks"
    },
    {
      "x": -15,
      "y": 7,
      "z": 4,
      "name": "Wood_Drywood_Planks"
    },
    {
      "x": -15,
      "y": 11,
      "z": 4,
      "name": "Wood_Drywood_Planks"
    },
    {
      "x": -15,
      "y": 8,
      "z": 5,
      "name": "Wood_Drywood_Planks"
    },
    {
      "x": -15,
      "y": 11,
      "z": 5,
      "name": "Wood_Drywood_Planks"
    },
    {
      "x": -15,
      "y": 9,
      "z": 6,
      "name": "Wood_Drywood_Planks"
    },
    {
      "x": -15,
      "y": 10,
      "z": 6,
      "name": "Wood_Drywood_Planks"
    },
    {
      "x": -15,
      "y": 11,
      "z": 6,
      "name": "Wood_Drywood_Decorative"
    },
    {
      "x": -15,
      "y": 12,
      "z": 6,
      "name": "Wood_Drywood_Fence"
    },
    {
      "x": -14,
      "y": 9,
      "z": -5,
      "name": "Wood_Drywood_Planks"
    },
    {
      "x": -14,
      "y": 10,
      "z": -5,
      "name": "Wood_Drywood_Planks"
    },
    {
      "x": -14,
      "y": 11,
      "z": -5,
      "name": "Wood_Drywood_Decorative"
    },
    {
      "x": -14,
      "y": 12,
      "z": -5,
      "name": "*Wood_Drywood_Fence_State_Definitions_Corner",
      "rotation": 1
    },
    {
      "x": -14,
      "y": 8,
      "z": -4,
      "name": "Wood_Drywood_Planks"
    },
    {
      "x": -14,
      "y": 11,
      "z": -4,
      "name": "Wood_Drywood_Planks"
    },
    {
      "x": -14,
      "y": 12,
      "z": -4,
      "name": "*Wood_Drywood_Fence_State_Definitions_Corner",
      "rotation": 3
    },
    {
      "x": -14,
      "y": 7,
      "z": -3,
      "name": "Wood_Drywood_Planks"
    },
    {
      "x": -14,
      "y": 8,
      "z": -3,
      "name": "Wood_Drywood_Planks"
    },
    {
      "x": -14,
      "y": 11,
      "z": -3,
      "name": "Wood_Drywood_Planks"
    },
    {
      "x": -14,
      "y": 5,
      "z": -2,
      "name": "Wood_Drywood_Planks"
    },
    {
      "x": -14,
      "y": 6,
      "z": -2,
      "name": "Wood_Drywood_Planks"
    },
    {
      "x": -14,
      "y": 7,
      "z": -2,
      "name": "Wood_Drywood_Planks"
    },
    {
      "x": -14,
      "y": 11,
      "z": -2,
      "name": "Wood_Drywood_Planks"
    },
    {
      "x": -14,
      "y": 4,
      "z": -1,
      "name": "Wood_Drywood_Planks"
    },
    {
      "x": -14,
      "y": 7,
      "z": -1,
      "name": "Wood_Drywood_Planks"
    },
    {
      "x": -14,
      "y": 11,
      "z": -1,
      "name": "Wood_Drywood_Planks"
    },
    {
      "x": -14,
      "y": 3,
      "z": 0,
      "name": "Wood_Drywood_Planks"
    },
    {
      "x": -14,
      "y": 4,
      "z": 0,
      "name": "Wood_Drywood_Planks"
    },
    {
      "x": -14,
      "y": 7,
      "z": 0,
      "name": "Wood_Drywood_Planks"
    },
    {
      "x": -14,
      "y": 11,
      "z": 0,
      "name": "Wood_Drywood_Planks"
    },
    {
      "x": -14,
      "y": 3,
      "z": 1,
      "name": "Wood_Drywood_Planks"
    },
    {
      "x": -14,
      "y": 7,
      "z": 1,
      "name": "Wood_Drywood_Planks"
    },
    {
      "x": -14,
      "y": 11,
      "z": 1,
      "name": "Wood_Drywood_Planks"
    },
    {
      "x": -14,
      "y": 3,
      "z": 2,
      "name": "Wood_Drywood_Planks"
    },
    {
      "x": -14,
      "y": 4,
      "z": 2,
      "name": "Wood_Drywood_Planks"
    },
    {
      "x": -14,
      "y": 7,
      "z": 2,
      "name": "Wood_Drywood_Planks"
    },
    {
      "x": -14,
      "y": 11,
      "z": 2,
      "name": "Wood_Drywood_Planks"
    },
    {
      "x": -14,
      "y": 4,
      "z": 3,
      "name": "Wood_Drywood_Planks"
    },
    {
      "x": -14,
      "y": 7,
      "z": 3,
      "name": "Wood_Drywood_Planks"
    },
    {
      "x": -14,
      "y": 11,
      "z": 3,
      "name": "Wood_Drywood_Planks"
    },
    {
      "x": -14,
      "y": 5,
      "z": 4,
      "name": "Wood_Drywood_Planks"
    },
    {
      "x": -14,
      "y": 6,
      "z": 4,
      "name": "Wood_Drywood_Planks"
    },
    {
      "x": -14,
      "y": 7,
      "z": 4,
      "name": "Wood_Drywood_Planks"
    },
    {
      "x": -14,
      "y": 11,
      "z": 4,
      "name": "Wood_Drywood_Planks"
    },
    {
      "x": -14,
      "y": 7,
      "z": 5,
      "name": "Wood_Drywood_Planks"
    },
    {
      "x": -14,
      "y": 8,
      "z": 5,
      "name": "Wood_Drywood_Planks"
    },
    {
      "x": -14,
      "y": 11,
      "z": 5,
      "name": "Wood_Drywood_Planks"
    },
    {
      "x": -14,
      "y": 8,
      "z": 6,
      "name": "Wood_Drywood_Planks"
    },
    {
      "x": -14,
      "y": 11,
      "z": 6,
      "name": "Wood_Drywood_Planks"
    },
    {
      "x": -14,
      "y": 12,
      "z": 6,
      "name": "*Wood_Drywood_Fence_State_Definitions_Corner"
    },
    {
      "x": -14,
      "y": 9,
      "z": 7,
      "name": "Wood_Drywood_Planks"
    },
    {
      "x": -14,
      "y": 10,
      "z": 7,
      "name": "Wood_Drywood_Planks"
    },
    {
      "x": -14,
      "y": 11,
      "z": 7,
      "name": "Wood_Drywood_Decorative"
    },
    {
      "x": -14,
      "y": 12,
      "z": 7,
      "name": "*Wood_Drywood_Fence_State_Definitions_Corner",
      "rotation": 2
    },
    {
      "x": -13,
      "y": 9,
      "z": -5,
      "name": "Wood_Drywood_Planks"
    },
    {
      "x": -13,
      "y": 10,
      "z": -5,
      "name": "Wood_Drywood_Planks"
    },
    {
      "x": -13,
      "y": 11,
      "z": -5,
      "name": "Wood_Drywood_Decorative"
    },
    {
      "x": -13,
      "y": 12,
      "z": -5,
      "name": "Wood_Drywood_Fence",
      "rotation": 2
    },
    {
      "x": -13,
      "y": 8,
      "z": -4,
      "name": "Wood_Drywood_Planks"
    },
    {
      "x": -13,
      "y": 11,
      "z": -4,
      "name": "Wood_Drywood_Planks"
    },
    {
      "x": -13,
      "y": 6,
      "z": -3,
      "name": "Wood_Drywood_Planks"
    },
    {
      "x": -13,
      "y": 7,
      "z": -3,
      "name": "Wood_Drywood_Planks"
    },
    {
      "x": -13,
      "y": 11,
      "z": -3,
      "name": "Wood_Drywood_Planks"
    },
    {
      "x": -13,
      "y": 5,
      "z": -2,
      "name": "Wood_Drywood_Planks"
    },
    {
      "x": -13,
      "y": 6,
      "z": -2,
      "name": "Wood_Drywood_Planks"
    },
    {
      "x": -13,
      "y": 7,
      "z": -2,
      "name": "Wood_Drywood_Planks"
    },
    {
      "x": -13,
      "y": 11,
      "z": -2,
      "name": "Wood_Drywood_Planks"
    },
    {
      "x": -13,
      "y": 4,
      "z": -1,
      "name": "Wood_Drywood_Planks"
    },
    {
      "x": -13,
      "y": 7,
      "z": -1,
      "name": "Wood_Drywood_Planks"
    },
    {
      "x": -13,
      "y": 11,
      "z": -1,
      "name": "Wood_Drywood_Planks"
    },
    {
      "x": -13,
      "y": 3,
      "z": 0,
      "name": "Wood_Drywood_Planks"
    },
    {
      "x": -13,
      "y": 7,
      "z": 0,
      "name": "Wood_Drywood_Planks"
    },
    {
      "x": -13,
      "y": 11,
      "z": 0,
      "name": "Wood_Drywood_Planks"
    },
    {
      "x": -13,
      "y": 3,
      "z": 1,
      "name": "Wood_Drywood_Planks"
    },
    {
      "x": -13,
      "y": 7,
      "z": 1,
      "name": "Wood_Drywood_Planks"
    },
    {
      "x": -13,
      "y": 11,
      "z": 1,
      "name": "Wood_Drywood_Planks"
    },
    {
      "x": -13,
      "y": 3,
      "z": 2,
      "name": "Wood_Drywood_Planks"
    },
    {
      "x": -13,
      "y": 7,
      "z": 2,
      "name": "Wood_Drywood_Planks"
    },
    {
      "x": -13,
      "y": 11,
      "z": 2,
      "name": "Wood_Drywood_Planks"
    },
    {
      "x": -13,
      "y": 4,
      "z": 3,
      "name": "Wood_Drywood_Planks"
    },
    {
      "x": -13,
      "y": 7,
      "z": 3,
      "name": "Wood_Drywood_Planks"
    },
    {
      "x": -13,
      "y": 11,
      "z": 3,
      "name": "Wood_Drywood_Planks"
    },
    {
      "x": -13,
      "y": 5,
      "z": 4,
      "name": "Wood_Drywood_Planks"
    },
    {
      "x": -13,
      "y": 6,
      "z": 4,
      "name": "Wood_Drywood_Planks"
    },
    {
      "x": -13,
      "y": 7,
      "z": 4,
      "name": "Wood_Drywood_Planks"
    },
    {
      "x": -13,
      "y": 11,
      "z": 4,
      "name": "Wood_Drywood_Planks"
    },
    {
      "x": -13,
      "y": 6,
      "z": 5,
      "name": "Wood_Drywood_Planks"
    },
    {
      "x": -13,
      "y": 7,
      "z": 5,
      "name": "Wood_Drywood_Planks"
    },
    {
      "x": -13,
      "y": 11,
      "z": 5,
      "name": "Wood_Drywood_Planks"
    },
    {
      "x": -13,
      "y": 8,
      "z": 6,
      "name": "Wood_Drywood_Planks"
    },
    {
      "x": -13,
      "y": 11,
      "z": 6,
      "name": "Wood_Drywood_Planks"
    },
    {
      "x": -13,
      "y": 9,
      "z": 7,
      "name": "Wood_Drywood_Planks"
    },
    {
      "x": -13,
      "y": 10,
      "z": 7,
      "name": "Wood_Drywood_Planks"
    },
    {
      "x": -13,
      "y": 11,
      "z": 7,
      "name": "Wood_Drywood_Decorative"
    },
    {
      "x": -13,
      "y": 12,
      "z": 7,
      "name": "Wood_Drywood_Fence"
    },
    {
      "x": -12,
      "y": 9,
      "z": -5,
      "name": "Wood_Drywood_Planks"
    },
    {
      "x": -12,
      "y": 10,
      "z": -5,
      "name": "Wood_Drywood_Planks"
    },
    {
      "x": -12,
      "y": 11,
      "z": -5,
      "name": "Wood_Drywood_Decorative"
    },
    {
      "x": -12,
      "y": 12,
      "z": -5,
      "name": "Wood_Drywood_Fence",
      "rotation": 2
    },
    {
      "x": -12,
      "y": 8,
      "z": -4,
      "name": "Wood_Drywood_Planks"
    },
    {
      "x": -12,
      "y": 11,
      "z": -4,
      "name": "Wood_Drywood_Planks"
    },
    {
      "x": -12,
      "y": 5,
      "z": -3,
      "name": "Wood_Drywood_Planks"
    },
    {
      "x": -12,
      "y": 6,
      "z": -3,
      "name": "Wood_Drywood_Planks"
    },
    {
      "x": -12,
      "y": 7,
      "z": -3,
      "name": "Wood_Drywood_Planks"
    },
    {
      "x": -12,
      "y": 11,
      "z": -3,
      "name": "Wood_Drywood_Planks"
    },
    {
      "x": -12,
      "y": 4,
      "z": -2,
      "name": "Wood_Drywood_Planks"
    },
    {
      "x": -12,
      "y": 7,
      "z": -2,
      "name": "Wood_Drywood_Planks"
    },
    {
      "x": -12,
      "y": 11,
      "z": -2,
      "name": "Wood_Drywood_Planks"
    },
    {
      "x": -12,
      "y": 3,
      "z": -1,
      "name": "Wood_Drywood_Planks"
    },
    {
      "x": -12,
      "y": 4,
      "z": -1,
      "name": "Wood_Drywood_Planks"
    },
    {
      "x": -12,
      "y": 7,
      "z": -1,
      "name": "Wood_Drywood_Planks"
    },
    {
      "x": -12,
      "y": 11,
      "z": -1,
      "name": "Wood_Drywood_Planks"
    },
    {
      "x": -12,
      "y": 3,
      "z": 0,
      "name": "Wood_Drywood_Planks"
    },
    {
      "x": -12,
      "y": 7,
      "z": 0,
      "name": "Wood_Drywood_Planks"
    },
    {
      "x": -12,
      "y": 11,
      "z": 0,
      "name": "Wood_Drywood_Planks"
    },
    {
      "x": -12,
      "y": 3,
      "z": 1,
      "name": "Wood_Drywood_Planks"
    },
    {
      "x": -12,
      "y": 7,
      "z": 1,
      "name": "Wood_Drywood_Planks"
    },
    {
      "x": -12,
      "y": 11,
      "z": 1,
      "name": "Wood_Drywood_Planks"
    },
    {
      "x": -12,
      "y": 3,
      "z": 2,
      "name": "Wood_Drywood_Planks"
    },
    {
      "x": -12,
      "y": 7,
      "z": 2,
      "name": "Wood_Drywood_Planks"
    },
    {
      "x": -12,
      "y": 11,
      "z": 2,
      "name": "Wood_Drywood_Planks"
    },
    {
      "x": -12,
      "y": 3,
      "z": 3,
      "name": "Wood_Drywood_Planks"
    },
    {
      "x": -12,
      "y": 4,
      "z": 3,
      "name": "Wood_Drywood_Planks"
    },
    {
      "x": -12,
      "y": 7,
      "z": 3,
      "name": "Wood_Drywood_Planks"
    },
    {
      "x": -12,
      "y": 11,
      "z": 3,
      "name": "Wood_Drywood_Planks"
    },
    {
      "x": -12,
      "y": 4,
      "z": 4,
      "name": "Wood_Drywood_Planks"
    },
    {
      "x": -12,
      "y": 7,
      "z": 4,
      "name": "Wood_Drywood_Planks"
    },
    {
      "x": -12,
      "y": 11,
      "z": 4,
      "name": "Wood_Drywood_Planks"
    },
    {
      "x": -12,
      "y": 5,
      "z": 5,
      "name": "Wood_Drywood_Planks"
    },
    {
      "x": -12,
      "y": 6,
      "z": 5,
      "name": "Wood_Drywood_Planks"
    },
    {
      "x": -12,
      "y": 7,
      "z": 5,
      "name": "Wood_Drywood_Planks"
    },
    {
      "x": -12,
      "y": 11,
      "z": 5,
      "name": "Wood_Drywood_Planks"
    },
    {
      "x": -12,
      "y": 8,
      "z": 6,
      "name": "Wood_Drywood_Planks"
    },
    {
      "x": -12,
      "y": 11,
      "z": 6,
      "name": "Wood_Drywood_Planks"
    },
    {
      "x": -12,
      "y": 9,
      "z": 7,
      "name": "Wood_Drywood_Planks"
    },
    {
      "x": -12,
      "y": 10,
      "z": 7,
      "name": "Wood_Drywood_Planks"
    },
    {
      "x": -12,
      "y": 11,
      "z": 7,
      "name": "Wood_Drywood_Decorative"
    },
    {
      "x": -12,
      "y": 12,
      "z": 7,
      "name": "Wood_Drywood_Fence"
    },
    {
      "x": -11,
      "y": 9,
      "z": -5,
      "name": "Wood_Drywood_Planks"
    },
    {
      "x": -11,
      "y": 10,
      "z": -5,
      "name": "Wood_Drywood_Planks"
    },
    {
      "x": -11,
      "y": 11,
      "z": -5,
      "name": "Wood_Drywood_Decorative"
    },
    {
      "x": -11,
      "y": 12,
      "z": -5,
      "name": "Wood_Drywood_Fence",
      "rotation": 2
    },
    {
      "x": -11,
      "y": 8,
      "z": -4,
      "name": "Wood_Drywood_Planks"
    },
    {
      "x": -11,
      "y": 11,
      "z": -4,
      "name": "Wood_Drywood_Planks"
    },
    {
      "x": -11,
      "y": 17,
      "z": -4,
      "name": "Wood_Dry_Trunk_Half",
      "rotation": 6
    },
    {
      "x": -11,
      "y": 5,
      "z": -3,
      "name": "Wood_Drywood_Planks"
    },
    {
      "x": -11,
      "y": 6,
      "z": -3,
      "name": "Wood_Drywood_Planks"
    },
    {
      "x": -11,
      "y": 7,
      "z": -3,
      "name": "Wood_Drywood_Planks"
    },
    {
      "x": -11,
      "y": 11,
      "z": -3,
      "name": "Wood_Drywood_Planks"
    },
    {
      "x": -11,
      "y": 15,
      "z": -3,
      "name": "Cloth_Roof_Hide_Flap",
      "support": 15,
      "rotation": 3
    },
    {
      "x": -11,
      "y": 16,
      "z": -3,
      "name": "Cloth_Roof_Hide_Vertical",
      "rotation": 3
    },
    {
      "x": -11,
      "y": 17,
      "z": -3,
      "name": "Wood_Dry_Trunk",
      "rotation": 4
    },
    {
      "x": -11,
      "y": 4,
      "z": -2,
      "name": "Wood_Drywood_Planks"
    },
    {
      "x": -11,
      "y": 7,
      "z": -2,
      "name": "Wood_Drywood_Planks"
    },
    {
      "x": -11,
      "y": 11,
      "z": -2,
      "name": "Wood_Drywood_Planks"
    },
    {
      "x": -11,
      "y": 16,
      "z": -2,
      "name": "Cloth_Roof_Hide_Flap",
      "rotation": 3
    },
    {
      "x": -11,
      "y": 17,
      "z": -2,
      "name": "Wood_Dry_Trunk",
      "rotation": 4
    },
    {
      "x": -11,
      "y": 3,
      "z": -1,
      "name": "Wood_Drywood_Planks"
    },
    {
      "x": -11,
      "y": 7,
      "z": -1,
      "name": "Wood_Drywood_Planks"
    },
    {
      "x": -11,
      "y": 11,
      "z": -1,
      "name": "Wood_Drywood_Planks"
    },
    {
      "x": -11,
      "y": 16,
      "z": -1,
      "name": "Cloth_Roof_Hide_Flap",
      "rotation": 3
    },
    {
      "x": -11,
      "y": 17,
      "z": -1,
      "name": "Wood_Dry_Trunk_Half",
      "rotation": 4
    },
    {
      "x": -11,
      "y": 3,
      "z": 0,
      "name": "Wood_Drywood_Planks"
    },
    {
      "x": -11,
      "y": 7,
      "z": 0,
      "name": "Wood_Drywood_Planks"
    },
    {
      "x": -11,
      "y": 11,
      "z": 0,
      "name": "Wood_Drywood_Planks"
    },
    {
      "x": -11,
      "y": 2,
      "z": 1,
      "name": "Wood_Drywood_Planks"
    },
    {
      "x": -11,
      "y": 3,
      "z": 1,
      "name": "Wood_Drywood_Planks"
    },
    {
      "x": -11,
      "y": 7,
      "z": 1,
      "name": "Wood_Drywood_Planks"
    },
    {
      "x": -11,
      "y": 11,
      "z": 1,
      "name": "Wood_Drywood_Planks"
    },
    {
      "x": -11,
      "y": 3,
      "z": 2,
      "name": "Wood_Drywood_Planks"
    },
    {
      "x": -11,
      "y": 7,
      "z": 2,
      "name": "Wood_Drywood_Planks"
    },
    {
      "x": -11,
      "y": 11,
      "z": 2,
      "name": "Wood_Drywood_Planks"
    },
    {
      "x": -11,
      "y": 3,
      "z": 3,
      "name": "Wood_Drywood_Planks"
    },
    {
      "x": -11,
      "y": 7,
      "z": 3,
      "name": "Wood_Drywood_Planks"
    },
    {
      "x": -11,
      "y": 11,
      "z": 3,
      "name": "Wood_Drywood_Planks"
    },
    {
      "x": -11,
      "y": 4,
      "z": 4,
      "name": "Wood_Drywood_Planks"
    },
    {
      "x": -11,
      "y": 7,
      "z": 4,
      "name": "Wood_Drywood_Planks"
    },
    {
      "x": -11,
      "y": 11,
      "z": 4,
      "name": "Wood_Drywood_Planks"
    },
    {
      "x": -11,
      "y": 5,
      "z": 5,
      "name": "Wood_Drywood_Planks"
    },
    {
      "x": -11,
      "y": 6,
      "z": 5,
      "name": "Wood_Drywood_Planks"
    },
    {
      "x": -11,
      "y": 7,
      "z": 5,
      "name": "Wood_Drywood_Planks"
    },
    {
      "x": -11,
      "y": 11,
      "z": 5,
      "name": "Wood_Drywood_Planks"
    },
    {
      "x": -11,
      "y": 8,
      "z": 6,
      "name": "Wood_Drywood_Planks"
    },
    {
      "x": -11,
      "y": 11,
      "z": 6,
      "name": "Wood_Drywood_Planks"
    },
    {
      "x": -11,
      "y": 9,
      "z": 7,
      "name": "Wood_Drywood_Planks"
    },
    {
      "x": -11,
      "y": 10,
      "z": 7,
      "name": "Wood_Drywood_Planks"
    },
    {
      "x": -11,
      "y": 11,
      "z": 7,
      "name": "Wood_Drywood_Decorative"
    },
    {
      "x": -11,
      "y": 12,
      "z": 7,
      "name": "Wood_Drywood_Fence"
    },
    {
      "x": -10,
      "y": 9,
      "z": -6,
      "name": "Wood_Drywood_Planks"
    },
    {
      "x": -10,
      "y": 10,
      "z": -6,
      "name": "Wood_Drywood_Planks"
    },
    {
      "x": -10,
      "y": 11,
      "z": -6,
      "name": "Wood_Drywood_Decorative"
    },
    {
      "x": -10,
      "y": 12,
      "z": -6,
      "name": "*Wood_Drywood_Fence_State_Definitions_Corner",
      "rotation": 1
    },
    {
      "x": -10,
      "y": 8,
      "z": -5,
      "name": "Wood_Drywood_Planks"
    },
    {
      "x": -10,
      "y": 11,
      "z": -5,
      "name": "Wood_Drywood_Planks"
    },
    {
      "x": -10,
      "y": 12,
      "z": -5,
      "name": "*Wood_Drywood_Fence_State_Definitions_Corner",
      "rotation": 3
    },
    {
      "x": -10,
      "y": 7,
      "z": -4,
      "name": "Wood_Drywood_Planks"
    },
    {
      "x": -10,
      "y": 8,
      "z": -4,
      "name": "Wood_Drywood_Planks"
    },
    {
      "x": -10,
      "y": 11,
      "z": -4,
      "name": "Wood_Drywood_Planks"
    },
    {
      "x": -10,
      "y": 5,
      "z": -3,
      "name": "Wood_Drywood_Planks"
    },
    {
      "x": -10,
      "y": 6,
      "z": -3,
      "name": "Wood_Drywood_Planks"
    },
    {
      "x": -10,
      "y": 7,
      "z": -3,
      "name": "Wood_Drywood_Planks"
    },
    {
      "x": -10,
      "y": 11,
      "z": -3,
      "name": "Wood_Drywood_Planks"
    },
    {
      "x": -10,
      "y": 4,
      "z": -2,
      "name": "Wood_Drywood_Planks"
    },
    {
      "x": -10,
      "y": 7,
      "z": -2,
      "name": "Wood_Drywood_Planks"
    },
    {
      "x": -10,
      "y": 11,
      "z": -2,
      "name": "Wood_Drywood_Planks"
    },
    {
      "x": -10,
      "y": 18,
      "z": -2,
      "name": "Wood_Dry_Trunk_Half",
      "rotation": 6
    },
    {
      "x": -10,
      "y": 3,
      "z": -1,
      "name": "Wood_Drywood_Planks"
    },
    {
      "x": -10,
      "y": 7,
      "z": -1,
      "name": "Wood_Drywood_Planks"
    },
    {
      "x": -10,
      "y": 11,
      "z": -1,
      "name": "Wood_Drywood_Planks"
    },
    {
      "x": -10,
      "y": 16,
      "z": -1,
      "name": "Cloth_Roof_Hide_Flap",
      "support": 15,
      "rotation": 1
    },
    {
      "x": -10,
      "y": 17,
      "z": -1,
      "name": "Cloth_Roof_Hide_Vertical",
      "rotation": 1
    },
    {
      "x": -10,
      "y": 18,
      "z": -1,
      "name": "Wood_Dry_Trunk",
      "rotation": 4
    },
    {
      "x": -10,
      "y": 3,
      "z": 0,
      "name": "Wood_Drywood_Planks"
    },
    {
      "x": -10,
      "y": 7,
      "z": 0,
      "name": "Wood_Drywood_Planks"
    },
    {
      "x": -10,
      "y": 11,
      "z": 0,
      "name": "Wood_Drywood_Planks"
    },
    {
      "x": -10,
      "y": 17,
      "z": 0,
      "name": "Cloth_Roof_Hide_Flap",
      "rotation": 1
    },
    {
      "x": -10,
      "y": 18,
      "z": 0,
      "name": "Wood_Dry_Trunk",
      "rotation": 4
    },
    {
      "x": -10,
      "y": 2,
      "z": 1,
      "name": "Wood_Drywood_Planks"
    },
    {
      "x": -10,
      "y": 3,
      "z": 1,
      "name": "Wood_Drywood_Planks"
    },
    {
      "x": -10,
      "y": 7,
      "z": 1,
      "name": "Wood_Drywood_Planks"
    },
    {
      "x": -10,
      "y": 11,
      "z": 1,
      "name": "Wood_Drywood_Planks"
    },
    {
      "x": -10,
      "y": 12,
      "z": 1,
      "name": "Wood_Dry_Trunk_Half",
      "rotation": 7
    },
    {
      "x": -10,
      "y": 16,
      "z": 1,
      "name": "Cloth_Roof_Hide_Flap",
      "support": 15,
      "rotation": 1
    },
    {
      "x": -10,
      "y": 17,
      "z": 1,
      "name": "Cloth_Roof_Hide_Vertical",
      "rotation": 1
    },
    {
      "x": -10,
      "y": 18,
      "z": 1,
      "name": "Wood_Dry_Trunk",
      "rotation": 4
    },
    {
      "x": -10,
      "y": 3,
      "z": 2,
      "name": "Wood_Drywood_Planks"
    },
    {
      "x": -10,
      "y": 7,
      "z": 2,
      "name": "Wood_Drywood_Planks"
    },
    {
      "x": -10,
      "y": 11,
      "z": 2,
      "name": "Wood_Drywood_Planks"
    },
    {
      "x": -10,
      "y": 18,
      "z": 2,
      "name": "Wood_Dry_Trunk",
      "rotation": 4
    },
    {
      "x": -10,
      "y": 3,
      "z": 3,
      "name": "Wood_Drywood_Planks"
    },
    {
      "x": -10,
      "y": 7,
      "z": 3,
      "name": "Wood_Drywood_Planks"
    },
    {
      "x": -10,
      "y": 11,
      "z": 3,
      "name": "Wood_Drywood_Planks"
    },
    {
      "x": -10,
      "y": 17,
      "z": 3,
      "name": "Cloth_Roof_Hide_Flap",
      "rotation": 1
    },
    {
      "x": -10,
      "y": 18,
      "z": 3,
      "name": "Wood_Dry_Trunk",
      "rotation": 4
    },
    {
      "x": -10,
      "y": 4,
      "z": 4,
      "name": "Wood_Drywood_Planks"
    },
    {
      "x": -10,
      "y": 7,
      "z": 4,
      "name": "Wood_Drywood_Planks"
    },
    {
      "x": -10,
      "y": 11,
      "z": 4,
      "name": "Wood_Drywood_Planks"
    },
    {
      "x": -10,
      "y": 17,
      "z": 4,
      "name": "Cloth_Roof_Hide_Flap",
      "rotation": 3
    },
    {
      "x": -10,
      "y": 18,
      "z": 4,
      "name": "Wood_Dry_Trunk_Half",
      "rotation": 4
    },
    {
      "x": -10,
      "y": 5,
      "z": 5,
      "name": "Wood_Drywood_Planks"
    },
    {
      "x": -10,
      "y": 6,
      "z": 5,
      "name": "Wood_Drywood_Planks"
    },
    {
      "x": -10,
      "y": 7,
      "z": 5,
      "name": "Wood_Drywood_Planks"
    },
    {
      "x": -10,
      "y": 11,
      "z": 5,
      "name": "Wood_Drywood_Planks"
    },
    {
      "x": -10,
      "y": 7,
      "z": 6,
      "name": "Wood_Drywood_Planks"
    },
    {
      "x": -10,
      "y": 8,
      "z": 6,
      "name": "Wood_Drywood_Planks"
    },
    {
      "x": -10,
      "y": 11,
      "z": 6,
      "name": "Wood_Drywood_Planks"
    },
    {
      "x": -10,
      "y": 8,
      "z": 7,
      "name": "Wood_Drywood_Planks"
    },
    {
      "x": -10,
      "y": 11,
      "z": 7,
      "name": "Wood_Drywood_Planks"
    },
    {
      "x": -10,
      "y": 12,
      "z": 7,
      "name": "*Wood_Drywood_Fence_State_Definitions_Corner"
    },
    {
      "x": -10,
      "y": 9,
      "z": 8,
      "name": "Wood_Drywood_Planks"
    },
    {
      "x": -10,
      "y": 10,
      "z": 8,
      "name": "Wood_Drywood_Planks"
    },
    {
      "x": -10,
      "y": 11,
      "z": 8,
      "name": "Wood_Drywood_Decorative"
    },
    {
      "x": -10,
      "y": 12,
      "z": 8,
      "name": "*Wood_Drywood_Fence_State_Definitions_Corner",
      "rotation": 2
    },
    {
      "x": -9,
      "y": 9,
      "z": -6,
      "name": "Wood_Drywood_Planks"
    },
    {
      "x": -9,
      "y": 10,
      "z": -6,
      "name": "Wood_Drywood_Planks"
    },
    {
      "x": -9,
      "y": 11,
      "z": -6,
      "name": "Wood_Drywood_Decorative"
    },
    {
      "x": -9,
      "y": 12,
      "z": -6,
      "name": "Wood_Drywood_Fence",
      "rotation": 2
    },
    {
      "x": -9,
      "y": 8,
      "z": -5,
      "name": "Wood_Drywood_Planks"
    },
    {
      "x": -9,
      "y": 11,
      "z": -5,
      "name": "Wood_Drywood_Planks"
    },
    {
      "x": -9,
      "y": 6,
      "z": -4,
      "name": "Wood_Drywood_Planks"
    },
    {
      "x": -9,
      "y": 7,
      "z": -4,
      "name": "Wood_Drywood_Planks"
    },
    {
      "x": -9,
      "y": 11,
      "z": -4,
      "name": "Wood_Drywood_Planks"
    },
    {
      "x": -9,
      "y": 4,
      "z": -3,
      "name": "Wood_Drywood_Planks"
    },
    {
      "x": -9,
      "y": 5,
      "z": -3,
      "name": "Wood_Drywood_Planks"
    },
    {
      "x": -9,
      "y": 6,
      "z": -3,
      "name": "Wood_Drywood_Planks"
    },
    {
      "x": -9,
      "y": 7,
      "z": -3,
      "name": "Wood_Drywood_Planks"
    },
    {
      "x": -9,
      "y": 11,
      "z": -3,
      "name": "Wood_Drywood_Planks"
    },
    {
      "x": -9,
      "y": 3,
      "z": -2,
      "name": "Wood_Drywood_Planks"
    },
    {
      "x": -9,
      "y": 4,
      "z": -2,
      "name": "Wood_Drywood_Planks"
    },
    {
      "x": -9,
      "y": 5,
      "z": -2,
      "name": "Wood_Drywood_Planks"
    },
    {
      "x": -9,
      "y": 6,
      "z": -2,
      "name": "Wood_Drywood_Planks"
    },
    {
      "x": -9,
      "y": 7,
      "z": -2,
      "name": "Wood_Drywood_Planks"
    },
    {
      "x": -9,
      "y": 11,
      "z": -2,
      "name": "Wood_Drywood_Planks"
    },
    {
      "x": -9,
      "y": 3,
      "z": -1,
      "name": "Wood_Drywood_Planks"
    },
    {
      "x": -9,
      "y": 7,
      "z": -1,
      "name": "Wood_Drywood_Planks"
    },
    {
      "x": -9,
      "y": 11,
      "z": -1,
      "name": "Wood_Drywood_Planks"
    },
    {
      "x": -9,
      "y": 3,
      "z": 0,
      "name": "Wood_Drywood_Planks"
    },
    {
      "x": -9,
      "y": 7,
      "z": 0,
      "name": "Wood_Drywood_Planks"
    },
    {
      "x": -9,
      "y": 11,
      "z": 0,
      "name": "Wood_Drywood_Planks"
    },
    {
      "x": -9,
      "y": 12,
      "z": 0,
      "name": "Wood_Dry_Trunk_Half",
      "rotation": 6
    },
    {
      "x": -9,
      "y": 13,
      "z": 0,
      "name": "Furniture_Desert_Sign",
      "rotation": 3
    },
    {
      "x": -9,
      "y": 18,
      "z": 0,
      "name": "Wood_Dry_Trunk_Half",
      "rotation": 6
    },
    {
      "x": -9,
      "y": 2,
      "z": 1,
      "name": "Wood_Drywood_Planks"
    },
    {
      "x": -9,
      "y": 3,
      "z": 1,
      "name": "Wood_Drywood_Planks"
    },
    {
      "x": -9,
      "y": 7,
      "z": 1,
      "name": "Wood_Drywood_Planks"
    },
    {
      "x": -9,
      "y": 11,
      "z": 1,
      "name": "Wood_Drywood_Planks",
      "support": 15
    },
    {
      "x": -9,
      "y": 12,
      "z": 1,
      "name": "Wood_Dry_Trunk",
      "support": 15
    },
    {
      "x": -9,
      "y": 13,
      "z": 1,
      "name": "Wood_Dry_Trunk",
      "support": 15
    },
    {
      "x": -9,
      "y": 14,
      "z": 1,
      "name": "Wood_Dry_Trunk",
      "support": 15
    },
    {
      "x": -9,
      "y": 15,
      "z": 1,
      "name": "Wood_Dry_Trunk",
      "support": 15
    },
    {
      "x": -9,
      "y": 16,
      "z": 1,
      "name": "Wood_Dry_Trunk",
      "support": 15
    },
    {
      "x": -9,
      "y": 17,
      "z": 1,
      "name": "Wood_Dry_Trunk",
      "support": 15
    },
    {
      "x": -9,
      "y": 18,
      "z": 1,
      "name": "Wood_Dry_Trunk",
      "support": 15
    },
    {
      "x": -9,
      "y": 19,
      "z": 1,
      "name": "Wood_Dry_Trunk",
      "support": 15
    },
    {
      "x": -9,
      "y": 20,
      "z": 1,
      "name": "Wood_Dry_Trunk"
    },
    {
      "x": -9,
      "y": 21,
      "z": 1,
      "name": "Wood_Dry_Trunk"
    },
    {
      "x": -9,
      "y": 22,
      "z": 1,
      "name": "Wood_Dry_Trunk_Half"
    },
    {
      "x": -9,
      "y": 3,
      "z": 2,
      "name": "Wood_Drywood_Planks"
    },
    {
      "x": -9,
      "y": 7,
      "z": 2,
      "name": "Wood_Drywood_Planks"
    },
    {
      "x": -9,
      "y": 11,
      "z": 2,
      "name": "Wood_Drywood_Planks"
    },
    {
      "x": -9,
      "y": 12,
      "z": 2,
      "name": "Wood_Dry_Trunk_Half",
      "rotation": 4
    },
    {
      "x": -9,
      "y": 13,
      "z": 2,
      "name": "Furniture_Desert_Sign",
      "rotation": 3
    },
    {
      "x": -9,
      "y": 18,
      "z": 2,
      "name": "Wood_Dry_Trunk_Half",
      "rotation": 4
    },
    {
      "x": -9,
      "y": 3,
      "z": 3,
      "name": "Wood_Drywood_Planks"
    },
    {
      "x": -9,
      "y": 7,
      "z": 3,
      "name": "Wood_Drywood_Planks"
    },
    {
      "x": -9,
      "y": 11,
      "z": 3,
      "name": "Wood_Drywood_Planks"
    },
    {
      "x": -9,
      "y": 19,
      "z": 3,
      "name": "Wood_Dry_Trunk_Half",
      "rotation": 6
    },
    {
      "x": -9,
      "y": 3,
      "z": 4,
      "name": "Wood_Drywood_Planks"
    },
    {
      "x": -9,
      "y": 4,
      "z": 4,
      "name": "Wood_Drywood_Planks"
    },
    {
      "x": -9,
      "y": 5,
      "z": 4,
      "name": "Wood_Drywood_Planks"
    },
    {
      "x": -9,
      "y": 6,
      "z": 4,
      "name": "Wood_Drywood_Planks"
    },
    {
      "x": -9,
      "y": 7,
      "z": 4,
      "name": "Wood_Drywood_Planks"
    },
    {
      "x": -9,
      "y": 11,
      "z": 4,
      "name": "Wood_Drywood_Planks"
    },
    {
      "x": -9,
      "y": 16,
      "z": 4,
      "name": "Cloth_Roof_Hide_Flap",
      "rotation": 1
    },
    {
      "x": -9,
      "y": 17,
      "z": 4,
      "name": "Cloth_Roof_Hide_Vertical",
      "support": 15,
      "rotation": 1
    },
    {
      "x": -9,
      "y": 18,
      "z": 4,
      "name": "Cloth_Roof_Hide_Vertical",
      "rotation": 1
    },
    {
      "x": -9,
      "y": 19,
      "z": 4,
      "name": "Wood_Dry_Trunk",
      "rotation": 4
    },
    {
      "x": -9,
      "y": 4,
      "z": 5,
      "name": "Wood_Drywood_Planks"
    },
    {
      "x": -9,
      "y": 5,
      "z": 5,
      "name": "Wood_Drywood_Planks"
    },
    {
      "x": -9,
      "y": 6,
      "z": 5,
      "name": "Wood_Drywood_Planks"
    },
    {
      "x": -9,
      "y": 7,
      "z": 5,
      "name": "Wood_Drywood_Planks"
    },
    {
      "x": -9,
      "y": 11,
      "z": 5,
      "name": "Wood_Drywood_Planks"
    },
    {
      "x": -9,
      "y": 18,
      "z": 5,
      "name": "Cloth_Roof_Hide_Flap",
      "rotation": 1
    },
    {
      "x": -9,
      "y": 19,
      "z": 5,
      "name": "Wood_Dry_Trunk",
      "rotation": 4
    },
    {
      "x": -9,
      "y": 6,
      "z": 6,
      "name": "Wood_Drywood_Planks"
    },
    {
      "x": -9,
      "y": 7,
      "z": 6,
      "name": "Wood_Drywood_Planks"
    },
    {
      "x": -9,
      "y": 11,
      "z": 6,
      "name": "Wood_Drywood_Planks"
    },
    {
      "x": -9,
      "y": 19,
      "z": 6,
      "name": "Wood_Dry_Trunk_Half",
      "rotation": 4
    },
    {
      "x": -9,
      "y": 8,
      "z": 7,
      "name": "Wood_Drywood_Planks"
    },
    {
      "x": -9,
      "y": 11,
      "z": 7,
      "name": "Wood_Drywood_Planks"
    },
    {
      "x": -9,
      "y": 9,
      "z": 8,
      "name": "Wood_Drywood_Planks"
    },
    {
      "x": -9,
      "y": 10,
      "z": 8,
      "name": "Wood_Drywood_Planks"
    },
    {
      "x": -9,
      "y": 11,
      "z": 8,
      "name": "Wood_Drywood_Decorative"
    },
    {
      "x": -9,
      "y": 12,
      "z": 8,
      "name": "Wood_Drywood_Fence"
    },
    {
      "x": -8,
      "y": 9,
      "z": -6,
      "name": "Wood_Drywood_Planks"
    },
    {
      "x": -8,
      "y": 10,
      "z": -6,
      "name": "Wood_Drywood_Planks"
    },
    {
      "x": -8,
      "y": 11,
      "z": -6,
      "name": "Wood_Drywood_Decorative"
    },
    {
      "x": -8,
      "y": 12,
      "z": -6,
      "name": "Wood_Drywood_Fence",
      "rotation": 2
    },
    {
      "x": -8,
      "y": 8,
      "z": -5,
      "name": "Wood_Drywood_Planks"
    },
    {
      "x": -8,
      "y": 11,
      "z": -5,
      "name": "Wood_Drywood_Planks"
    },
    {
      "x": -8,
      "y": 5,
      "z": -4,
      "name": "Wood_Drywood_Planks"
    },
    {
      "x": -8,
      "y": 6,
      "z": -4,
      "name": "Wood_Drywood_Planks"
    },
    {
      "x": -8,
      "y": 7,
      "z": -4,
      "name": "Wood_Drywood_Planks"
    },
    {
      "x": -8,
      "y": 11,
      "z": -4,
      "name": "Wood_Drywood_Planks"
    },
    {
      "x": -8,
      "y": 4,
      "z": -3,
      "name": "Wood_Drywood_Planks"
    },
    {
      "x": -8,
      "y": 5,
      "z": -3,
      "name": "Wood_Drywood_Planks"
    },
    {
      "x": -8,
      "y": 6,
      "z": -3,
      "name": "Wood_Drywood_Planks"
    },
    {
      "x": -8,
      "y": 7,
      "z": -3,
      "name": "Wood_Drywood_Stairs",
      "rotation": 1
    },
    {
      "x": -8,
      "y": 11,
      "z": -3,
      "name": "Wood_Drywood_Planks"
    },
    {
      "x": -8,
      "y": 3,
      "z": -2,
      "name": "Wood_Drywood_Planks"
    },
    {
      "x": -8,
      "y": 4,
      "z": -2,
      "name": "Wood_Drywood_Planks"
    },
    {
      "x": -8,
      "y": 5,
      "z": -2,
      "name": "Wood_Drywood_Planks"
    },
    {
      "x": -8,
      "y": 6,
      "z": -2,
      "name": "Wood_Drywood_Planks"
    },
    {
      "x": -8,
      "y": 7,
      "z": -2,
      "name": "Wood_Drywood_Stairs",
      "rotation": 1
    },
    {
      "x": -8,
      "y": 11,
      "z": -2,
      "name": "Wood_Drywood_Planks"
    },
    {
      "x": -8,
      "y": 3,
      "z": -1,
      "name": "Wood_Drywood_Planks"
    },
    {
      "x": -8,
      "y": 7,
      "z": -1,
      "name": "Wood_Drywood_Planks"
    },
    {
      "x": -8,
      "y": 11,
      "z": -1,
      "name": "Wood_Drywood_Planks"
    },
    {
      "x": -8,
      "y": 2,
      "z": 0,
      "name": "Wood_Drywood_Planks"
    },
    {
      "x": -8,
      "y": 3,
      "z": 0,
      "name": "Wood_Drywood_Planks"
    },
    {
      "x": -8,
      "y": 7,
      "z": 0,
      "name": "Wood_Drywood_Planks"
    },
    {
      "x": -8,
      "y": 11,
      "z": 0,
      "name": "Wood_Drywood_Planks"
    },
    {
      "x": -8,
      "y": 2,
      "z": 1,
      "name": "Wood_Drywood_Planks"
    },
    {
      "x": -8,
      "y": 3,
      "z": 1,
      "name": "Wood_Drywood_Planks"
    },
    {
      "x": -8,
      "y": 7,
      "z": 1,
      "name": "Wood_Drywood_Planks"
    },
    {
      "x": -8,
      "y": 11,
      "z": 1,
      "name": "Wood_Drywood_Planks"
    },
    {
      "x": -8,
      "y": 12,
      "z": 1,
      "name": "Wood_Dry_Trunk_Half",
      "rotation": 5
    },
    {
      "x": -8,
      "y": 18,
      "z": 1,
      "name": "Wood_Dry_Trunk_Half",
      "rotation": 5
    },
    {
      "x": -8,
      "y": 2,
      "z": 2,
      "name": "Wood_Drywood_Planks"
    },
    {
      "x": -8,
      "y": 3,
      "z": 2,
      "name": "Wood_Drywood_Planks"
    },
    {
      "x": -8,
      "y": 7,
      "z": 2,
      "name": "Wood_Drywood_Planks"
    },
    {
      "x": -8,
      "y": 11,
      "z": 2,
      "name": "Wood_Drywood_Planks"
    },
    {
      "x": -8,
      "y": 3,
      "z": 3,
      "name": "Wood_Drywood_Planks"
    },
    {
      "x": -8,
      "y": 7,
      "z": 3,
      "name": "Wood_Drywood_Planks"
    },
    {
      "x": -8,
      "y": 11,
      "z": 3,
      "name": "Wood_Drywood_Planks"
    },
    {
      "x": -8,
      "y": 3,
      "z": 4,
      "name": "Wood_Drywood_Planks"
    },
    {
      "x": -8,
      "y": 4,
      "z": 4,
      "name": "Wood_Drywood_Planks"
    },
    {
      "x": -8,
      "y": 5,
      "z": 4,
      "name": "Wood_Drywood_Planks"
    },
    {
      "x": -8,
      "y": 6,
      "z": 4,
      "name": "Wood_Drywood_Planks"
    },
    {
      "x": -8,
      "y": 7,
      "z": 4,
      "name": "Wood_Drywood_Stairs",
      "rotation": 1
    },
    {
      "x": -8,
      "y": 11,
      "z": 4,
      "name": "Wood_Drywood_Planks"
    },
    {
      "x": -8,
      "y": 4,
      "z": 5,
      "name": "Wood_Drywood_Planks"
    },
    {
      "x": -8,
      "y": 5,
      "z": 5,
      "name": "Wood_Drywood_Planks"
    },
    {
      "x": -8,
      "y": 6,
      "z": 5,
      "name": "Wood_Drywood_Planks"
    },
    {
      "x": -8,
      "y": 7,
      "z": 5,
      "name": "Wood_Drywood_Stairs",
      "rotation": 1
    },
    {
      "x": -8,
      "y": 11,
      "z": 5,
      "name": "Wood_Drywood_Planks"
    },
    {
      "x": -8,
      "y": 5,
      "z": 6,
      "name": "Wood_Drywood_Planks"
    },
    {
      "x": -8,
      "y": 6,
      "z": 6,
      "name": "Wood_Drywood_Planks"
    },
    {
      "x": -8,
      "y": 7,
      "z": 6,
      "name": "Wood_Drywood_Planks"
    },
    {
      "x": -8,
      "y": 11,
      "z": 6,
      "name": "Wood_Drywood_Planks"
    },
    {
      "x": -8,
      "y": 8,
      "z": 7,
      "name": "Wood_Drywood_Planks"
    },
    {
      "x": -8,
      "y": 11,
      "z": 7,
      "name": "Wood_Drywood_Planks"
    },
    {
      "x": -8,
      "y": 9,
      "z": 8,
      "name": "Wood_Drywood_Planks"
    },
    {
      "x": -8,
      "y": 10,
      "z": 8,
      "name": "Wood_Drywood_Planks"
    },
    {
      "x": -8,
      "y": 11,
      "z": 8,
      "name": "Wood_Drywood_Decorative"
    },
    {
      "x": -8,
      "y": 12,
      "z": 8,
      "name": "Wood_Drywood_Fence"
    },
    {
      "x": -7,
      "y": 9,
      "z": -6,
      "name": "Wood_Drywood_Planks"
    },
    {
      "x": -7,
      "y": 10,
      "z": -6,
      "name": "Wood_Drywood_Planks"
    },
    {
      "x": -7,
      "y": 11,
      "z": -6,
      "name": "Wood_Drywood_Decorative"
    },
    {
      "x": -7,
      "y": 12,
      "z": -6,
      "name": "Wood_Drywood_Fence",
      "rotation": 2
    },
    {
      "x": -7,
      "y": 8,
      "z": -5,
      "name": "Wood_Drywood_Planks"
    },
    {
      "x": -7,
      "y": 11,
      "z": -5,
      "name": "Wood_Drywood_Planks"
    },
    {
      "x": -7,
      "y": 5,
      "z": -4,
      "name": "Wood_Drywood_Planks"
    },
    {
      "x": -7,
      "y": 6,
      "z": -4,
      "name": "Wood_Drywood_Planks"
    },
    {
      "x": -7,
      "y": 7,
      "z": -4,
      "name": "Wood_Drywood_Planks"
    },
    {
      "x": -7,
      "y": 11,
      "z": -4,
      "name": "Wood_Drywood_Planks"
    },
    {
      "x": -7,
      "y": 4,
      "z": -3,
      "name": "Wood_Drywood_Planks"
    },
    {
      "x": -7,
      "y": 5,
      "z": -3,
      "name": "Wood_Drywood_Planks"
    },
    {
      "x": -7,
      "y": 6,
      "z": -3,
      "name": "Wood_Drywood_Stairs",
      "rotation": 1
    },
    {
      "x": -7,
      "y": 11,
      "z": -3,
      "name": "Wood_Drywood_Planks"
    },
    {
      "x": -7,
      "y": 3,
      "z": -2,
      "name": "Wood_Drywood_Planks"
    },
    {
      "x": -7,
      "y": 4,
      "z": -2,
      "name": "Wood_Drywood_Planks"
    },
    {
      "x": -7,
      "y": 5,
      "z": -2,
      "name": "Wood_Drywood_Planks"
    },
    {
      "x": -7,
      "y": 6,
      "z": -2,
      "name": "Wood_Drywood_Stairs",
      "rotation": 1
    },
    {
      "x": -7,
      "y": 11,
      "z": -2,
      "name": "Wood_Drywood_Planks"
    },
    {
      "x": -7,
      "y": 3,
      "z": -1,
      "name": "Wood_Drywood_Planks"
    },
    {
      "x": -7,
      "y": 7,
      "z": -1,
      "name": "Wood_Drywood_Planks"
    },
    {
      "x": -7,
      "y": 11,
      "z": -1,
      "name": "Wood_Drywood_Planks"
    },
    {
      "x": -7,
      "y": 2,
      "z": 0,
      "name": "Wood_Drywood_Planks"
    },
    {
      "x": -7,
      "y": 3,
      "z": 0,
      "name": "Wood_Drywood_Planks"
    },
    {
      "x": -7,
      "y": 7,
      "z": 0,
      "name": "Wood_Drywood_Planks"
    },
    {
      "x": -7,
      "y": 11,
      "z": 0,
      "name": "Wood_Drywood_Planks"
    },
    {
      "x": -7,
      "y": 2,
      "z": 1,
      "name": "Wood_Drywood_Planks"
    },
    {
      "x": -7,
      "y": 3,
      "z": 1,
      "name": "Wood_Drywood_Planks"
    },
    {
      "x": -7,
      "y": 7,
      "z": 1,
      "name": "Wood_Drywood_Planks"
    },
    {
      "x": -7,
      "y": 11,
      "z": 1,
      "name": "Wood_Drywood_Planks"
    },
    {
      "x": -7,
      "y": 2,
      "z": 2,
      "name": "Wood_Drywood_Planks"
    },
    {
      "x": -7,
      "y": 3,
      "z": 2,
      "name": "Wood_Drywood_Planks"
    },
    {
      "x": -7,
      "y": 7,
      "z": 2,
      "name": "Wood_Drywood_Planks"
    },
    {
      "x": -7,
      "y": 11,
      "z": 2,
      "name": "Wood_Drywood_Planks"
    },
    {
      "x": -7,
      "y": 3,
      "z": 3,
      "name": "Wood_Drywood_Planks"
    },
    {
      "x": -7,
      "y": 7,
      "z": 3,
      "name": "Wood_Drywood_Planks"
    },
    {
      "x": -7,
      "y": 11,
      "z": 3,
      "name": "Wood_Drywood_Planks"
    },
    {
      "x": -7,
      "y": 3,
      "z": 4,
      "name": "Wood_Drywood_Planks"
    },
    {
      "x": -7,
      "y": 4,
      "z": 4,
      "name": "Wood_Drywood_Planks"
    },
    {
      "x": -7,
      "y": 5,
      "z": 4,
      "name": "Wood_Drywood_Planks"
    },
    {
      "x": -7,
      "y": 6,
      "z": 4,
      "name": "Wood_Drywood_Stairs",
      "rotation": 1
    },
    {
      "x": -7,
      "y": 11,
      "z": 4,
      "name": "Wood_Drywood_Planks"
    },
    {
      "x": -7,
      "y": 4,
      "z": 5,
      "name": "Wood_Drywood_Planks"
    },
    {
      "x": -7,
      "y": 5,
      "z": 5,
      "name": "Wood_Drywood_Planks"
    },
    {
      "x": -7,
      "y": 6,
      "z": 5,
      "name": "Wood_Drywood_Stairs",
      "rotation": 1
    },
    {
      "x": -7,
      "y": 11,
      "z": 5,
      "name": "Wood_Drywood_Planks"
    },
    {
      "x": -7,
      "y": 5,
      "z": 6,
      "name": "Wood_Drywood_Planks"
    },
    {
      "x": -7,
      "y": 6,
      "z": 6,
      "name": "Wood_Drywood_Planks"
    },
    {
      "x": -7,
      "y": 7,
      "z": 6,
      "name": "Wood_Drywood_Planks"
    },
    {
      "x": -7,
      "y": 11,
      "z": 6,
      "name": "Wood_Drywood_Planks"
    },
    {
      "x": -7,
      "y": 8,
      "z": 7,
      "name": "Wood_Drywood_Planks"
    },
    {
      "x": -7,
      "y": 11,
      "z": 7,
      "name": "Wood_Drywood_Planks"
    },
    {
      "x": -7,
      "y": 9,
      "z": 8,
      "name": "Wood_Drywood_Planks"
    },
    {
      "x": -7,
      "y": 10,
      "z": 8,
      "name": "Wood_Drywood_Planks"
    },
    {
      "x": -7,
      "y": 11,
      "z": 8,
      "name": "Wood_Drywood_Decorative"
    },
    {
      "x": -7,
      "y": 12,
      "z": 8,
      "name": "Wood_Drywood_Fence"
    },
    {
      "x": -6,
      "y": 8,
      "z": -6,
      "name": "Wood_Drywood_Planks"
    },
    {
      "x": -6,
      "y": 9,
      "z": -6,
      "name": "Wood_Drywood_Planks"
    },
    {
      "x": -6,
      "y": 10,
      "z": -6,
      "name": "Wood_Drywood_Planks"
    },
    {
      "x": -6,
      "y": 11,
      "z": -6,
      "name": "Wood_Drywood_Decorative"
    },
    {
      "x": -6,
      "y": 12,
      "z": -6,
      "name": "Wood_Drywood_Fence",
      "rotation": 2
    },
    {
      "x": -6,
      "y": 7,
      "z": -5,
      "name": "Wood_Drywood_Planks"
    },
    {
      "x": -6,
      "y": 8,
      "z": -5,
      "name": "Wood_Drywood_Planks"
    },
    {
      "x": -6,
      "y": 9,
      "z": -5,
      "name": "Wood_Drywood_Planks"
    },
    {
      "x": -6,
      "y": 10,
      "z": -5,
      "name": "Wood_Drywood_Planks"
    },
    {
      "x": -6,
      "y": 11,
      "z": -5,
      "name": "Wood_Drywood_Planks"
    },
    {
      "x": -6,
      "y": 4,
      "z": -4,
      "name": "Wood_Drywood_Planks"
    },
    {
      "x": -6,
      "y": 5,
      "z": -4,
      "name": "Wood_Drywood_Planks"
    },
    {
      "x": -6,
      "y": 6,
      "z": -4,
      "name": "Wood_Drywood_Planks"
    },
    {
      "x": -6,
      "y": 7,
      "z": -4,
      "name": "Wood_Drywood_Planks"
    },
    {
      "x": -6,
      "y": 8,
      "z": -4,
      "name": "Wood_Drywood_Planks"
    },
    {
      "x": -6,
      "y": 9,
      "z": -4,
      "name": "Wood_Drywood_Planks"
    },
    {
      "x": -6,
      "y": 10,
      "z": -4,
      "name": "Wood_Drywood_Planks"
    },
    {
      "x": -6,
      "y": 11,
      "z": -4,
      "name": "Wood_Drywood_Planks"
    },
    {
      "x": -6,
      "y": 3,
      "z": -3,
      "name": "Wood_Drywood_Planks"
    },
    {
      "x": -6,
      "y": 4,
      "z": -3,
      "name": "Wood_Drywood_Planks"
    },
    {
      "x": -6,
      "y": 5,
      "z": -3,
      "name": "Wood_Drywood_Stairs",
      "rotation": 1
    },
    {
      "x": -6,
      "y": 10,
      "z": -3,
      "name": "Wood_Drywood_Planks"
    },
    {
      "x": -6,
      "y": 11,
      "z": -3,
      "name": "Wood_Drywood_Planks"
    },
    {
      "x": -6,
      "y": 3,
      "z": -2,
      "name": "Wood_Drywood_Planks"
    },
    {
      "x": -6,
      "y": 4,
      "z": -2,
      "name": "Wood_Drywood_Planks"
    },
    {
      "x": -6,
      "y": 5,
      "z": -2,
      "name": "Wood_Drywood_Stairs",
      "rotation": 1
    },
    {
      "x": -6,
      "y": 10,
      "z": -2,
      "name": "Wood_Drywood_Planks"
    },
    {
      "x": -6,
      "y": 11,
      "z": -2,
      "name": "Wood_Drywood_Planks"
    },
    {
      "x": -6,
      "y": 3,
      "z": -1,
      "name": "Wood_Drywood_Planks"
    },
    {
      "x": -6,
      "y": 7,
      "z": -1,
      "name": "Wood_Drywood_Planks"
    },
    {
      "x": -6,
      "y": 8,
      "z": -1,
      "name": "Wood_Drywood_Planks"
    },
    {
      "x": -6,
      "y": 9,
      "z": -1,
      "name": "Wood_Drywood_Planks"
    },
    {
      "x": -6,
      "y": 10,
      "z": -1,
      "name": "Wood_Drywood_Planks"
    },
    {
      "x": -6,
      "y": 11,
      "z": -1,
      "name": "Wood_Drywood_Planks"
    },
    {
      "x": -6,
      "y": 2,
      "z": 0,
      "name": "Wood_Drywood_Planks"
    },
    {
      "x": -6,
      "y": 3,
      "z": 0,
      "name": "Wood_Drywood_Planks"
    },
    {
      "x": -6,
      "y": 7,
      "z": 0,
      "name": "Wood_Drywood_Planks"
    },
    {
      "x": -6,
      "y": 8,
      "z": 0,
      "name": "Wood_Drywood_Planks_Half"
    },
    {
      "x": -6,
      "y": 11,
      "z": 0,
      "name": "Wood_Drywood_Planks"
    },
    {
      "x": -6,
      "y": 2,
      "z": 1,
      "name": "Wood_Drywood_Planks"
    },
    {
      "x": -6,
      "y": 3,
      "z": 1,
      "name": "Wood_Drywood_Planks"
    },
    {
      "x": -6,
      "y": 8,
      "z": 1,
      "name": "Wood_Drywood_Planks_Half"
    },
    {
      "x": -6,
      "y": 11,
      "z": 1,
      "name": "Wood_Drywood_Planks"
    },
    {
      "x": -6,
      "y": 2,
      "z": 2,
      "name": "Wood_Drywood_Planks"
    },
    {
      "x": -6,
      "y": 3,
      "z": 2,
      "name": "Wood_Drywood_Planks"
    },
    {
      "x": -6,
      "y": 8,
      "z": 2,
      "name": "Wood_Drywood_Planks_Half"
    },
    {
      "x": -6,
      "y": 11,
      "z": 2,
      "name": "Wood_Drywood_Planks"
    },
    {
      "x": -6,
      "y": 3,
      "z": 3,
      "name": "Wood_Drywood_Planks"
    },
    {
      "x": -6,
      "y": 7,
      "z": 3,
      "name": "Wood_Drywood_Planks"
    },
    {
      "x": -6,
      "y": 8,
      "z": 3,
      "name": "Wood_Drywood_Planks"
    },
    {
      "x": -6,
      "y": 9,
      "z": 3,
      "name": "Wood_Drywood_Planks"
    },
    {
      "x": -6,
      "y": 10,
      "z": 3,
      "name": "Wood_Drywood_Planks"
    },
    {
      "x": -6,
      "y": 11,
      "z": 3,
      "name": "Wood_Drywood_Planks"
    },
    {
      "x": -6,
      "y": 3,
      "z": 4,
      "name": "Wood_Drywood_Planks"
    },
    {
      "x": -6,
      "y": 4,
      "z": 4,
      "name": "Wood_Drywood_Planks"
    },
    {
      "x": -6,
      "y": 5,
      "z": 4,
      "name": "Wood_Drywood_Stairs",
      "rotation": 1
    },
    {
      "x": -6,
      "y": 10,
      "z": 4,
      "name": "Wood_Drywood_Planks"
    },
    {
      "x": -6,
      "y": 11,
      "z": 4,
      "name": "Wood_Drywood_Planks"
    },
    {
      "x": -6,
      "y": 3,
      "z": 5,
      "name": "Wood_Drywood_Planks"
    },
    {
      "x": -6,
      "y": 4,
      "z": 5,
      "name": "Wood_Drywood_Planks"
    },
    {
      "x": -6,
      "y": 5,
      "z": 5,
      "name": "Wood_Drywood_Stairs",
      "rotation": 1
    },
    {
      "x": -6,
      "y": 10,
      "z": 5,
      "name": "Wood_Drywood_Planks"
    },
    {
      "x": -6,
      "y": 11,
      "z": 5,
      "name": "Wood_Drywood_Planks"
    },
    {
      "x": -6,
      "y": 4,
      "z": 6,
      "name": "Wood_Drywood_Planks"
    },
    {
      "x": -6,
      "y": 5,
      "z": 6,
      "name": "Wood_Drywood_Planks"
    },
    {
      "x": -6,
      "y": 6,
      "z": 6,
      "name": "Wood_Drywood_Planks"
    },
    {
      "x": -6,
      "y": 7,
      "z": 6,
      "name": "Wood_Drywood_Planks"
    },
    {
      "x": -6,
      "y": 8,
      "z": 6,
      "name": "Wood_Drywood_Planks"
    },
    {
      "x": -6,
      "y": 9,
      "z": 6,
      "name": "Wood_Drywood_Planks"
    },
    {
      "x": -6,
      "y": 10,
      "z": 6,
      "name": "Wood_Drywood_Planks"
    },
    {
      "x": -6,
      "y": 11,
      "z": 6,
      "name": "Wood_Drywood_Planks"
    },
    {
      "x": -6,
      "y": 7,
      "z": 7,
      "name": "Wood_Drywood_Planks"
    },
    {
      "x": -6,
      "y": 8,
      "z": 7,
      "name": "Wood_Drywood_Planks"
    },
    {
      "x": -6,
      "y": 9,
      "z": 7,
      "name": "Wood_Drywood_Planks"
    },
    {
      "x": -6,
      "y": 10,
      "z": 7,
      "name": "Wood_Drywood_Planks"
    },
    {
      "x": -6,
      "y": 11,
      "z": 7,
      "name": "Wood_Drywood_Planks"
    },
    {
      "x": -6,
      "y": 8,
      "z": 8,
      "name": "Wood_Drywood_Planks"
    },
    {
      "x": -6,
      "y": 9,
      "z": 8,
      "name": "Wood_Drywood_Planks"
    },
    {
      "x": -6,
      "y": 10,
      "z": 8,
      "name": "Wood_Drywood_Planks"
    },
    {
      "x": -6,
      "y": 11,
      "z": 8,
      "name": "Wood_Drywood_Decorative"
    },
    {
      "x": -6,
      "y": 12,
      "z": 8,
      "name": "Wood_Drywood_Fence"
    },
    {
      "x": -5,
      "y": 8,
      "z": -7,
      "name": "Wood_Drywood_Planks"
    },
    {
      "x": -5,
      "y": 9,
      "z": -7,
      "name": "Wood_Drywood_Decorative"
    },
    {
      "x": -5,
      "y": 10,
      "z": -7,
      "name": "Wood_Drywood_Fence",
      "rotation": 1
    },
    {
      "x": -5,
      "y": 7,
      "z": -6,
      "name": "Wood_Drywood_Planks"
    },
    {
      "x": -5,
      "y": 9,
      "z": -6,
      "name": "Wood_Drywood_Planks"
    },
    {
      "x": -5,
      "y": 7,
      "z": -5,
      "name": "Wood_Drywood_Planks"
    },
    {
      "x": -5,
      "y": 9,
      "z": -5,
      "name": "Wood_Drywood_Planks"
    },
    {
      "x": -5,
      "y": 10,
      "z": -5,
      "name": "Wood_Drywood_Planks"
    },
    {
      "x": -5,
      "y": 11,
      "z": -5,
      "name": "Wood_Drywood_Stairs",
      "rotation": 1
    },
    {
      "x": -5,
      "y": 9,
      "z": -4,
      "name": "Wood_Drywood_Planks"
    },
    {
      "x": -5,
      "y": 10,
      "z": -4,
      "name": "Wood_Drywood_Planks"
    },
    {
      "x": -5,
      "y": 11,
      "z": -4,
      "name": "Wood_Drywood_Stairs",
      "rotation": 1
    },
    {
      "x": -5,
      "y": 4,
      "z": -3,
      "name": "Wood_Drywood_Planks"
    },
    {
      "x": -5,
      "y": 9,
      "z": -3,
      "name": "Wood_Drywood_Planks"
    },
    {
      "x": -5,
      "y": 10,
      "z": -3,
      "name": "Wood_Drywood_Planks"
    },
    {
      "x": -5,
      "y": 11,
      "z": -3,
      "name": "Wood_Drywood_Stairs",
      "rotation": 1
    },
    {
      "x": -5,
      "y": 4,
      "z": -2,
      "name": "Wood_Drywood_Planks"
    },
    {
      "x": -5,
      "y": 9,
      "z": -2,
      "name": "Wood_Drywood_Planks"
    },
    {
      "x": -5,
      "y": 10,
      "z": -2,
      "name": "Wood_Drywood_Planks"
    },
    {
      "x": -5,
      "y": 11,
      "z": -2,
      "name": "Wood_Drywood_Stairs",
      "rotation": 1
    },
    {
      "x": -5,
      "y": 3,
      "z": -1,
      "name": "Wood_Drywood_Planks"
    },
    {
      "x": -5,
      "y": 4,
      "z": -1,
      "name": "Wood_Drywood_Stairs"
    },
    {
      "x": -5,
      "y": 8,
      "z": -1,
      "name": "Wood_Drywood_Planks"
    },
    {
      "x": -5,
      "y": 9,
      "z": -1,
      "name": "Wood_Drywood_Planks"
    },
    {
      "x": -5,
      "y": 10,
      "z": -1,
      "name": "Wood_Drywood_Planks"
    },
    {
      "x": -5,
      "y": 11,
      "z": -1,
      "name": "Wood_Drywood_Planks"
    },
    {
      "x": -5,
      "y": 12,
      "z": -1,
      "name": "Wood_Drywood_Fence",
      "rotation": 1
    },
    {
      "x": -5,
      "y": 3,
      "z": 0,
      "name": "Wood_Drywood_Planks"
    },
    {
      "x": -5,
      "y": 8,
      "z": 0,
      "name": "Wood_Drywood_Planks"
    },
    {
      "x": -5,
      "y": 11,
      "z": 0,
      "name": "Wood_Drywood_Planks_Half",
      "rotation": 8
    },
    {
      "x": -5,
      "y": 12,
      "z": 0,
      "name": "Wood_Drywood_Fence",
      "rotation": 1
    },
    {
      "x": -5,
      "y": 3,
      "z": 1,
      "name": "Wood_Drywood_Planks"
    },
    {
      "x": -5,
      "y": 8,
      "z": 1,
      "name": "Wood_Drywood_Planks"
    },
    {
      "x": -5,
      "y": 11,
      "z": 1,
      "name": "Wood_Drywood_Planks_Half",
      "rotation": 8
    },
    {
      "x": -5,
      "y": 12,
      "z": 1,
      "name": "Wood_Drywood_Fence",
      "rotation": 1
    },
    {
      "x": -5,
      "y": 3,
      "z": 2,
      "name": "Wood_Drywood_Planks"
    },
    {
      "x": -5,
      "y": 8,
      "z": 2,
      "name": "Wood_Drywood_Planks"
    },
    {
      "x": -5,
      "y": 11,
      "z": 2,
      "name": "Wood_Drywood_Planks_Half",
      "rotation": 8
    },
    {
      "x": -5,
      "y": 12,
      "z": 2,
      "name": "Wood_Drywood_Fence",
      "rotation": 1
    },
    {
      "x": -5,
      "y": 3,
      "z": 3,
      "name": "Wood_Drywood_Planks"
    },
    {
      "x": -5,
      "y": 4,
      "z": 3,
      "name": "Wood_Drywood_Stairs",
      "rotation": 2
    },
    {
      "x": -5,
      "y": 8,
      "z": 3,
      "name": "Wood_Drywood_Planks"
    },
    {
      "x": -5,
      "y": 9,
      "z": 3,
      "name": "Wood_Drywood_Planks"
    },
    {
      "x": -5,
      "y": 10,
      "z": 3,
      "name": "Wood_Drywood_Planks"
    },
    {
      "x": -5,
      "y": 11,
      "z": 3,
      "name": "Wood_Drywood_Planks"
    },
    {
      "x": -5,
      "y": 12,
      "z": 3,
      "name": "Wood_Drywood_Fence",
      "rotation": 1
    },
    {
      "x": -5,
      "y": 4,
      "z": 4,
      "name": "Wood_Drywood_Planks"
    },
    {
      "x": -5,
      "y": 9,
      "z": 4,
      "name": "Wood_Drywood_Planks"
    },
    {
      "x": -5,
      "y": 10,
      "z": 4,
      "name": "Wood_Drywood_Planks"
    },
    {
      "x": -5,
      "y": 11,
      "z": 4,
      "name": "Wood_Drywood_Stairs",
      "rotation": 1
    },
    {
      "x": -5,
      "y": 4,
      "z": 5,
      "name": "Wood_Drywood_Planks"
    },
    {
      "x": -5,
      "y": 9,
      "z": 5,
      "name": "Wood_Drywood_Planks"
    },
    {
      "x": -5,
      "y": 10,
      "z": 5,
      "name": "Wood_Drywood_Planks"
    },
    {
      "x": -5,
      "y": 11,
      "z": 5,
      "name": "Wood_Drywood_Stairs",
      "rotation": 1
    },
    {
      "x": -5,
      "y": 9,
      "z": 6,
      "name": "Wood_Drywood_Planks"
    },
    {
      "x": -5,
      "y": 10,
      "z": 6,
      "name": "Wood_Drywood_Planks"
    },
    {
      "x": -5,
      "y": 11,
      "z": 6,
      "name": "Wood_Drywood_Stairs",
      "rotation": 1
    },
    {
      "x": -5,
      "y": 7,
      "z": 7,
      "name": "Wood_Drywood_Planks"
    },
    {
      "x": -5,
      "y": 9,
      "z": 7,
      "name": "Wood_Drywood_Planks"
    },
    {
      "x": -5,
      "y": 10,
      "z": 7,
      "name": "Wood_Drywood_Planks"
    },
    {
      "x": -5,
      "y": 11,
      "z": 7,
      "name": "Wood_Drywood_Stairs",
      "rotation": 1
    },
    {
      "x": -5,
      "y": 7,
      "z": 8,
      "name": "Wood_Drywood_Planks"
    },
    {
      "x": -5,
      "y": 9,
      "z": 8,
      "name": "Wood_Drywood_Planks"
    },
    {
      "x": -5,
      "y": 8,
      "z": 9,
      "name": "Wood_Drywood_Planks"
    },
    {
      "x": -5,
      "y": 9,
      "z": 9,
      "name": "Wood_Drywood_Decorative"
    },
    {
      "x": -5,
      "y": 10,
      "z": 9,
      "name": "Wood_Drywood_Fence",
      "rotation": 2
    },
    {
      "x": -4,
      "y": 8,
      "z": -7,
      "name": "Wood_Drywood_Planks"
    },
    {
      "x": -4,
      "y": 9,
      "z": -7,
      "name": "Wood_Drywood_Decorative"
    },
    {
      "x": -4,
      "y": 10,
      "z": -7,
      "name": "Wood_Drywood_Fence",
      "rotation": 2
    },
    {
      "x": -4,
      "y": 9,
      "z": -6,
      "name": "Wood_Drywood_Planks"
    },
    {
      "x": -4,
      "y": 9,
      "z": -5,
      "name": "Wood_Drywood_Planks"
    },
    {
      "x": -4,
      "y": 10,
      "z": -5,
      "name": "Wood_Drywood_Stairs",
      "rotation": 1
    },
    {
      "x": -4,
      "y": 9,
      "z": -4,
      "name": "Wood_Drywood_Planks"
    },
    {
      "x": -4,
      "y": 10,
      "z": -4,
      "name": "Wood_Drywood_Stairs",
      "rotation": 1
    },
    {
      "x": -4,
      "y": 4,
      "z": -3,
      "name": "Wood_Drywood_Planks"
    },
    {
      "x": -4,
      "y": 9,
      "z": -3,
      "name": "Wood_Drywood_Planks"
    },
    {
      "x": -4,
      "y": 10,
      "z": -3,
      "name": "Wood_Drywood_Stairs",
      "rotation": 1
    },
    {
      "x": -4,
      "y": 4,
      "z": -2,
      "name": "Wood_Drywood_Planks"
    },
    {
      "x": -4,
      "y": 9,
      "z": -2,
      "name": "Wood_Drywood_Planks"
    },
    {
      "x": -4,
      "y": 10,
      "z": -2,
      "name": "Wood_Drywood_Stairs",
      "rotation": 1
    },
    {
      "x": -4,
      "y": 3,
      "z": -1,
      "name": "Wood_Drywood_Planks"
    },
    {
      "x": -4,
      "y": 4,
      "z": -1,
      "name": "Wood_Drywood_Stairs"
    },
    {
      "x": -4,
      "y": 8,
      "z": -1,
      "name": "Wood_Drywood_Planks"
    },
    {
      "x": -4,
      "y": 9,
      "z": -1,
      "name": "Wood_Drywood_Planks"
    },
    {
      "x": -4,
      "y": 10,
      "z": -1,
      "name": "Wood_Drywood_Planks"
    },
    {
      "x": -4,
      "y": 11,
      "z": -1,
      "name": "Wood_Drywood_Stairs",
      "rotation": 1
    },
    {
      "x": -4,
      "y": 3,
      "z": 0,
      "name": "Wood_Drywood_Planks"
    },
    {
      "x": -4,
      "y": 8,
      "z": 0,
      "name": "Wood_Drywood_Planks"
    },
    {
      "x": -4,
      "y": 9,
      "z": 0,
      "name": "Wood_Drywood_Planks_Half"
    },
    {
      "x": -4,
      "y": 3,
      "z": 1,
      "name": "Wood_Drywood_Planks"
    },
    {
      "x": -4,
      "y": 8,
      "z": 1,
      "name": "Wood_Drywood_Planks"
    },
    {
      "x": -4,
      "y": 9,
      "z": 1,
      "name": "Wood_Drywood_Planks_Half"
    },
    {
      "x": -4,
      "y": 3,
      "z": 2,
      "name": "Wood_Drywood_Planks"
    },
    {
      "x": -4,
      "y": 8,
      "z": 2,
      "name": "Wood_Drywood_Planks"
    },
    {
      "x": -4,
      "y": 9,
      "z": 2,
      "name": "Wood_Drywood_Planks_Half"
    },
    {
      "x": -4,
      "y": 3,
      "z": 3,
      "name": "Wood_Drywood_Planks"
    },
    {
      "x": -4,
      "y": 4,
      "z": 3,
      "name": "Wood_Drywood_Stairs",
      "rotation": 2
    },
    {
      "x": -4,
      "y": 8,
      "z": 3,
      "name": "Wood_Drywood_Planks"
    },
    {
      "x": -4,
      "y": 9,
      "z": 3,
      "name": "Wood_Drywood_Planks"
    },
    {
      "x": -4,
      "y": 10,
      "z": 3,
      "name": "Wood_Drywood_Planks"
    },
    {
      "x": -4,
      "y": 11,
      "z": 3,
      "name": "Wood_Drywood_Stairs",
      "rotation": 1
    },
    {
      "x": -4,
      "y": 4,
      "z": 4,
      "name": "Wood_Drywood_Planks"
    },
    {
      "x": -4,
      "y": 9,
      "z": 4,
      "name": "Wood_Drywood_Planks"
    },
    {
      "x": -4,
      "y": 10,
      "z": 4,
      "name": "Wood_Drywood_Stairs",
      "rotation": 1
    },
    {
      "x": -4,
      "y": 4,
      "z": 5,
      "name": "Wood_Drywood_Planks"
    },
    {
      "x": -4,
      "y": 9,
      "z": 5,
      "name": "Wood_Drywood_Planks"
    },
    {
      "x": -4,
      "y": 10,
      "z": 5,
      "name": "Wood_Drywood_Stairs",
      "rotation": 1
    },
    {
      "x": -4,
      "y": 9,
      "z": 6,
      "name": "Wood_Drywood_Planks"
    },
    {
      "x": -4,
      "y": 10,
      "z": 6,
      "name": "Wood_Drywood_Stairs",
      "rotation": 1
    },
    {
      "x": -4,
      "y": 9,
      "z": 7,
      "name": "Wood_Drywood_Planks"
    },
    {
      "x": -4,
      "y": 10,
      "z": 7,
      "name": "Wood_Drywood_Stairs",
      "rotation": 1
    },
    {
      "x": -4,
      "y": 9,
      "z": 8,
      "name": "Wood_Drywood_Planks"
    },
    {
      "x": -4,
      "y": 8,
      "z": 9,
      "name": "Wood_Drywood_Planks"
    },
    {
      "x": -4,
      "y": 9,
      "z": 9,
      "name": "Wood_Drywood_Decorative"
    },
    {
      "x": -4,
      "y": 10,
      "z": 9,
      "name": "Wood_Drywood_Fence"
    },
    {
      "x": -3,
      "y": 8,
      "z": -7,
      "name": "Wood_Drywood_Planks"
    },
    {
      "x": -3,
      "y": 9,
      "z": -7,
      "name": "Wood_Drywood_Decorative"
    },
    {
      "x": -3,
      "y": 10,
      "z": -7,
      "name": "Wood_Drywood_Fence",
      "rotation": 2
    },
    {
      "x": -3,
      "y": 9,
      "z": -6,
      "name": "Wood_Drywood_Planks"
    },
    {
      "x": -3,
      "y": 9,
      "z": -5,
      "name": "Wood_Drywood_Planks"
    },
    {
      "x": -3,
      "y": 9,
      "z": -4,
      "name": "Wood_Drywood_Planks"
    },
    {
      "x": -3,
      "y": 9,
      "z": -3,
      "name": "Wood_Drywood_Planks"
    },
    {
      "x": -3,
      "y": 9,
      "z": -2,
      "name": "Wood_Drywood_Planks"
    },
    {
      "x": -3,
      "y": 9,
      "z": -1,
      "name": "Wood_Drywood_Planks"
    },
    {
      "x": -3,
      "y": 3,
      "z": 0,
      "name": "Wood_Drywood_Stairs",
      "rotation": 1
    },
    {
      "x": -3,
      "y": 9,
      "z": 0,
      "name": "Wood_Drywood_Planks"
    },
    {
      "x": -3,
      "y": 3,
      "z": 1,
      "name": "Wood_Drywood_Stairs",
      "rotation": 1
    },
    {
      "x": -3,
      "y": 9,
      "z": 1,
      "name": "Wood_Drywood_Planks",
      "support": 15
    },
    {
      "x": -3,
      "y": 2,
      "z": 2,
      "name": "Wood_Drywood_Planks"
    },
    {
      "x": -3,
      "y": 3,
      "z": 2,
      "name": "Wood_Drywood_Stairs",
      "rotation": 1
    },
    {
      "x": -3,
      "y": 9,
      "z": 2,
      "name": "Wood_Drywood_Planks"
    },
    {
      "x": -3,
      "y": 9,
      "z": 3,
      "name": "Wood_Drywood_Planks"
    },
    {
      "x": -3,
      "y": 4,
      "z": 4,
      "name": "Wood_Drywood_Planks"
    },
    {
      "x": -3,
      "y": 5,
      "z": 4,
      "name": "Wood_Drywood_Stairs",
      "rotation": 3
    },
    {
      "x": -3,
      "y": 9,
      "z": 4,
      "name": "Wood_Drywood_Planks"
    },
    {
      "x": -3,
      "y": 4,
      "z": 5,
      "name": "Wood_Drywood_Planks"
    },
    {
      "x": -3,
      "y": 5,
      "z": 5,
      "name": "Wood_Drywood_Stairs",
      "rotation": 3
    },
    {
      "x": -3,
      "y": 9,
      "z": 5,
      "name": "Wood_Drywood_Planks"
    },
    {
      "x": -3,
      "y": 9,
      "z": 6,
      "name": "Wood_Drywood_Planks"
    },
    {
      "x": -3,
      "y": 9,
      "z": 7,
      "name": "Wood_Drywood_Planks"
    },
    {
      "x": -3,
      "y": 9,
      "z": 8,
      "name": "Wood_Drywood_Planks"
    },
    {
      "x": -3,
      "y": 8,
      "z": 9,
      "name": "Wood_Drywood_Planks"
    },
    {
      "x": -3,
      "y": 9,
      "z": 9,
      "name": "Wood_Drywood_Decorative"
    },
    {
      "x": -3,
      "y": 10,
      "z": 9,
      "name": "Wood_Drywood_Fence"
    },
    {
      "x": -2,
      "y": 8,
      "z": -7,
      "name": "Wood_Drywood_Planks"
    },
    {
      "x": -2,
      "y": 9,
      "z": -7,
      "name": "Wood_Drywood_Decorative"
    },
    {
      "x": -2,
      "y": 10,
      "z": -7,
      "name": "Wood_Drywood_Fence",
      "rotation": 2
    },
    {
      "x": -2,
      "y": 22,
      "z": -7,
      "name": "Wood_Dry_Trunk_Half",
      "rotation": 6
    },
    {
      "x": -2,
      "y": 9,
      "z": -6,
      "name": "Wood_Drywood_Planks"
    },
    {
      "x": -2,
      "y": 13,
      "z": -6,
      "name": "Wood_Dry_Trunk_Half",
      "rotation": 6
    },
    {
      "x": -2,
      "y": 20,
      "z": -6,
      "name": "Wood_Drywood_Beam"
    },
    {
      "x": -2,
      "y": 21,
      "z": -6,
      "name": "Wood_Drywood_Beam"
    },
    {
      "x": -2,
      "y": 22,
      "z": -6,
      "name": "Wood_Dry_Trunk",
      "support": 15,
      "rotation": 4
    },
    {
      "x": -2,
      "y": 9,
      "z": -5,
      "name": "Wood_Drywood_Planks"
    },
    {
      "x": -2,
      "y": 13,
      "z": -5,
      "name": "Wood_Dry_Trunk",
      "support": 15,
      "rotation": 4
    },
    {
      "x": -2,
      "y": 21,
      "z": -5,
      "name": "Cloth_Roof_Hide_Flap",
      "rotation": 1
    },
    {
      "x": -2,
      "y": 22,
      "z": -5,
      "name": "Wood_Dry_Trunk",
      "support": 15,
      "rotation": 4
    },
    {
      "x": -2,
      "y": 9,
      "z": -4,
      "name": "Wood_Drywood_Planks"
    },
    {
      "x": -2,
      "y": 13,
      "z": -4,
      "name": "Wood_Dry_Trunk",
      "support": 15,
      "rotation": 4
    },
    {
      "x": -2,
      "y": 14,
      "z": -4,
      "name": "Wood_Drywood_Beam"
    },
    {
      "x": -2,
      "y": 21,
      "z": -4,
      "name": "Cloth_Roof_Hide_Flap",
      "rotation": 1
    },
    {
      "x": -2,
      "y": 22,
      "z": -4,
      "name": "Wood_Dry_Trunk",
      "support": 15,
      "rotation": 4
    },
    {
      "x": -2,
      "y": 9,
      "z": -3,
      "name": "Wood_Drywood_Planks_Half"
    },
    {
      "x": -2,
      "y": 13,
      "z": -3,
      "name": "Wood_Dry_Trunk_Half",
      "rotation": 4
    },
    {
      "x": -2,
      "y": 22,
      "z": -3,
      "name": "Wood_Dry_Trunk",
      "support": 15,
      "rotation": 4
    },
    {
      "x": -2,
      "y": 9,
      "z": -2,
      "name": "Wood_Drywood_Planks_Half"
    },
    {
      "x": -2,
      "y": 13,
      "z": -2,
      "name": "Cloth_Roof_Hide_Flap",
      "rotation": 3
    },
    {
      "x": -2,
      "y": 22,
      "z": -2,
      "name": "Wood_Dry_Trunk_Half",
      "rotation": 4
    },
    {
      "x": -2,
      "y": 9,
      "z": -1,
      "name": "Wood_Drywood_Planks"
    },
    {
      "x": -2,
      "y": 9,
      "z": 0,
      "name": "Wood_Drywood_Planks"
    },
    {
      "x": -2,
      "y": 13,
      "z": 0,
      "name": "Cloth_Roof_Hide_Flap",
      "rotation": 3
    },
    {
      "x": -2,
      "y": 9,
      "z": 1,
      "name": "Wood_Drywood_Planks"
    },
    {
      "x": -2,
      "y": 12,
      "z": 1,
      "name": "Cloth_Roof_Hide_Flap",
      "rotation": 3
    },
    {
      "x": -2,
      "y": 13,
      "z": 1,
      "name": "Cloth_Roof_Hide_Vertical",
      "rotation": 3
    },
    {
      "x": -2,
      "y": 2,
      "z": 2,
      "name": "Wood_Drywood_Planks"
    },
    {
      "x": -2,
      "y": 9,
      "z": 2,
      "name": "Wood_Drywood_Planks"
    },
    {
      "x": -2,
      "y": 9,
      "z": 3,
      "name": "Wood_Drywood_Planks"
    },
    {
      "x": -2,
      "y": 13,
      "z": 3,
      "name": "Cloth_Roof_Hide_Flap",
      "rotation": 3
    },
    {
      "x": -2,
      "y": 5,
      "z": 4,
      "name": "Wood_Drywood_Planks"
    },
    {
      "x": -2,
      "y": 9,
      "z": 4,
      "name": "Wood_Drywood_Planks_Half"
    },
    {
      "x": -2,
      "y": 13,
      "z": 4,
      "name": "Cloth_Roof_Hide_Flap",
      "rotation": 3
    },
    {
      "x": -2,
      "y": 5,
      "z": 5,
      "name": "Wood_Drywood_Planks"
    },
    {
      "x": -2,
      "y": 9,
      "z": 5,
      "name": "Wood_Drywood_Planks_Half"
    },
    {
      "x": -2,
      "y": 12,
      "z": 5,
      "name": "Cloth_Roof_Hide_Flap",
      "rotation": 3
    },
    {
      "x": -2,
      "y": 13,
      "z": 5,
      "name": "Cloth_Roof_Hide_Vertical",
      "rotation": 3
    },
    {
      "x": -2,
      "y": 9,
      "z": 6,
      "name": "Wood_Drywood_Planks"
    },
    {
      "x": -2,
      "y": 9,
      "z": 7,
      "name": "Wood_Drywood_Planks"
    },
    {
      "x": -2,
      "y": 9,
      "z": 8,
      "name": "Wood_Drywood_Planks"
    },
    {
      "x": -2,
      "y": 8,
      "z": 9,
      "name": "Wood_Drywood_Planks"
    },
    {
      "x": -2,
      "y": 9,
      "z": 9,
      "name": "Wood_Drywood_Decorative"
    },
    {
      "x": -2,
      "y": 10,
      "z": 9,
      "name": "Wood_Drywood_Fence"
    },
    {
      "x": -1,
      "y": 8,
      "z": -7,
      "name": "Wood_Drywood_Planks"
    },
    {
      "x": -1,
      "y": 9,
      "z": -7,
      "name": "Wood_Drywood_Decorative"
    },
    {
      "x": -1,
      "y": 10,
      "z": -7,
      "name": "Wood_Drywood_Fence",
      "rotation": 2
    },
    {
      "x": -1,
      "y": 9,
      "z": -6,
      "name": "Wood_Drywood_Planks"
    },
    {
      "x": -1,
      "y": 9,
      "z": -5,
      "name": "Wood_Drywood_Planks"
    },
    {
      "x": -1,
      "y": 9,
      "z": -4,
      "name": "Wood_Drywood_Planks_Half"
    },
    {
      "x": -1,
      "y": 13,
      "z": -4,
      "name": "Wood_Dry_Trunk_Half",
      "rotation": 6
    },
    {
      "x": -1,
      "y": 9,
      "z": -3,
      "name": "Wood_Drywood_Planks_Half"
    },
    {
      "x": -1,
      "y": 13,
      "z": -3,
      "name": "Wood_Dry_Trunk",
      "support": 15,
      "rotation": 4
    },
    {
      "x": -1,
      "y": 22,
      "z": -3,
      "name": "Wood_Dry_Trunk_Half",
      "rotation": 6
    },
    {
      "x": -1,
      "y": 9,
      "z": -2,
      "name": "Wood_Drywood_Planks_Half"
    },
    {
      "x": -1,
      "y": 13,
      "z": -2,
      "name": "Wood_Dry_Trunk",
      "support": 15,
      "rotation": 4
    },
    {
      "x": -1,
      "y": 21,
      "z": -2,
      "name": "Cloth_Roof_Hide_Flap",
      "rotation": 3
    },
    {
      "x": -1,
      "y": 22,
      "z": -2,
      "name": "Wood_Dry_Trunk",
      "support": 15,
      "rotation": 4
    },
    {
      "x": -1,
      "y": 9,
      "z": -1,
      "name": "Wood_Drywood_Planks"
    },
    {
      "x": -1,
      "y": 13,
      "z": -1,
      "name": "Wood_Dry_Trunk",
      "support": 15,
      "rotation": 4
    },
    {
      "x": -1,
      "y": 14,
      "z": -1,
      "name": "Wood_Drywood_Beam"
    },
    {
      "x": -1,
      "y": 21,
      "z": -1,
      "name": "Wood_Drywood_Beam"
    },
    {
      "x": -1,
      "y": 22,
      "z": -1,
      "name": "Wood_Dry_Trunk",
      "support": 15,
      "rotation": 4
    },
    {
      "x": -1,
      "y": 9,
      "z": 0,
      "name": "Wood_Drywood_Planks"
    },
    {
      "x": -1,
      "y": 13,
      "z": 0,
      "name": "Wood_Dry_Trunk",
      "support": 15,
      "rotation": 4
    },
    {
      "x": -1,
      "y": 22,
      "z": 0,
      "name": "Wood_Dry_Trunk",
      "support": 15,
      "rotation": 4
    },
    {
      "x": -1,
      "y": 9,
      "z": 1,
      "name": "Wood_Drywood_Planks"
    },
    {
      "x": -1,
      "y": 12,
      "z": 1,
      "name": "Cloth_Roof_Hide_Flap",
      "rotation": 1
    },
    {
      "x": -1,
      "y": 13,
      "z": 1,
      "name": "Wood_Dry_Trunk",
      "support": 15,
      "rotation": 4
    },
    {
      "x": -1,
      "y": 21,
      "z": 1,
      "name": "Cloth_Roof_Hide_Flap",
      "rotation": 1
    },
    {
      "x": -1,
      "y": 22,
      "z": 1,
      "name": "Wood_Dry_Trunk",
      "support": 15,
      "rotation": 4
    },
    {
      "x": -1,
      "y": 9,
      "z": 2,
      "name": "Wood_Drywood_Planks"
    },
    {
      "x": -1,
      "y": 13,
      "z": 2,
      "name": "Wood_Dry_Trunk",
      "support": 15,
      "rotation": 4
    },
    {
      "x": -1,
      "y": 21,
      "z": 2,
      "name": "Cloth_Roof_Hide_Flap",
      "rotation": 1
    },
    {
      "x": -1,
      "y": 22,
      "z": 2,
      "name": "Wood_Dry_Trunk",
      "support": 15,
      "rotation": 4
    },
    {
      "x": -1,
      "y": 9,
      "z": 3,
      "name": "Wood_Drywood_Planks"
    },
    {
      "x": -1,
      "y": 13,
      "z": 3,
      "name": "Wood_Dry_Trunk",
      "support": 15,
      "rotation": 4
    },
    {
      "x": -1,
      "y": 14,
      "z": 3,
      "name": "Wood_Drywood_Beam"
    },
    {
      "x": -1,
      "y": 15,
      "z": 3,
      "name": "Wood_Drywood_Beam"
    },
    {
      "x": -1,
      "y": 22,
      "z": 3,
      "name": "Wood_Dry_Trunk",
      "support": 15,
      "rotation": 4
    },
    {
      "x": -1,
      "y": 9,
      "z": 4,
      "name": "Wood_Drywood_Planks_Half"
    },
    {
      "x": -1,
      "y": 12,
      "z": 4,
      "name": "Cloth_Roof_Hide_Flap",
      "rotation": 1
    },
    {
      "x": -1,
      "y": 13,
      "z": 4,
      "name": "Wood_Dry_Trunk",
      "support": 15,
      "rotation": 4
    },
    {
      "x": -1,
      "y": 22,
      "z": 4,
      "name": "Wood_Dry_Trunk",
      "support": 15,
      "rotation": 4
    },
    {
      "x": -1,
      "y": 9,
      "z": 5,
      "name": "Wood_Drywood_Planks_Half"
    },
    {
      "x": -1,
      "y": 13,
      "z": 5,
      "name": "Wood_Dry_Trunk",
      "support": 15,
      "rotation": 4
    },
    {
      "x": -1,
      "y": 14,
      "z": 5,
      "name": "Wood_Drywood_Beam"
    },
    {
      "x": -1,
      "y": 22,
      "z": 5,
      "name": "Wood_Dry_Trunk_Half",
      "rotation": 4
    },
    {
      "x": -1,
      "y": 9,
      "z": 6,
      "name": "Wood_Drywood_Planks_Half"
    },
    {
      "x": -1,
      "y": 13,
      "z": 6,
      "name": "Wood_Dry_Trunk_Half",
      "rotation": 4
    },
    {
      "x": -1,
      "y": 9,
      "z": 7,
      "name": "Wood_Drywood_Planks"
    },
    {
      "x": -1,
      "y": 9,
      "z": 8,
      "name": "Wood_Drywood_Planks"
    },
    {
      "x": -1,
      "y": 8,
      "z": 9,
      "name": "Wood_Drywood_Planks"
    },
    {
      "x": -1,
      "y": 9,
      "z": 9,
      "name": "Wood_Drywood_Decorative"
    },
    {
      "x": -1,
      "y": 10,
      "z": 9,
      "name": "Wood_Drywood_Fence"
    },
    {
      "x": 0,
      "y": 8,
      "z": -7,
      "name": "Wood_Drywood_Planks"
    },
    {
      "x": 0,
      "y": 9,
      "z": -7,
      "name": "Wood_Drywood_Decorative"
    },
    {
      "x": 0,
      "y": 10,
      "z": -7,
      "name": "Wood_Drywood_Fence",
      "rotation": 2
    },
    {
      "x": 0,
      "y": 9,
      "z": -6,
      "name": "Wood_Drywood_Planks"
    },
    {
      "x": 0,
      "y": 9,
      "z": -5,
      "name": "Wood_Drywood_Planks"
    },
    {
      "x": 0,
      "y": 9,
      "z": -4,
      "name": "Wood_Drywood_Planks_Half"
    },
    {
      "x": 0,
      "y": 9,
      "z": -3,
      "name": "Wood_Drywood_Planks_Half"
    },
    {
      "x": 0,
      "y": 9,
      "z": -2,
      "name": "Wood_Drywood_Planks_Half"
    },
    {
      "x": 0,
      "y": 9,
      "z": -1,
      "name": "Wood_Drywood_Planks"
    },
    {
      "x": 0,
      "y": 9,
      "z": 0,
      "name": "Wood_Drywood_Planks"
    },
    {
      "x": 0,
      "y": 9,
      "z": 1,
      "name": "Wood_Drywood_Planks"
    },
    {
      "x": 0,
      "y": 10,
      "z": 1,
      "name": "Wood_Dry_Trunk_Stairs",
      "rotation": 3
    },
    {
      "x": 0,
      "y": 11,
      "z": 1,
      "name": "Wood_Dry_Trunk_Half",
      "rotation": 7
    },
    {
      "x": 0,
      "y": 12,
      "z": 1,
      "name": "Wood_Dry_Trunk_Stairs",
      "rotation": 9
    },
    {
      "x": 0,
      "y": 13,
      "z": 1,
      "name": "Wood_Dry_Trunk_Stairs",
      "rotation": 3
    },
    {
      "x": 0,
      "y": 14,
      "z": 1,
      "name": "Wood_Dry_Trunk_Half",
      "rotation": 7
    },
    {
      "x": 0,
      "y": 21,
      "z": 1,
      "name": "Wood_Dry_Trunk_Stairs",
      "rotation": 9
    },
    {
      "x": 0,
      "y": 22,
      "z": 1,
      "name": "Wood_Dry_Trunk_Stairs",
      "rotation": 3
    },
    {
      "x": 0,
      "y": 9,
      "z": 2,
      "name": "Wood_Drywood_Planks"
    },
    {
      "x": 0,
      "y": 9,
      "z": 3,
      "name": "Wood_Drywood_Planks"
    },
    {
      "x": 0,
      "y": 9,
      "z": 4,
      "name": "Wood_Drywood_Planks_Half"
    },
    {
      "x": 0,
      "y": 22,
      "z": 4,
      "name": "Wood_Dry_Trunk_Half",
      "rotation": 6
    },
    {
      "x": 0,
      "y": 9,
      "z": 5,
      "name": "Wood_Drywood_Planks_Half"
    },
    {
      "x": 0,
      "y": 13,
      "z": 5,
      "name": "Wood_Dry_Trunk_Half",
      "rotation": 6
    },
    {
      "x": 0,
      "y": 22,
      "z": 5,
      "name": "Wood_Dry_Trunk",
      "support": 15,
      "rotation": 4
    },
    {
      "x": 0,
      "y": 9,
      "z": 6,
      "name": "Wood_Drywood_Planks_Half"
    },
    {
      "x": 0,
      "y": 13,
      "z": 6,
      "name": "Wood_Dry_Trunk",
      "support": 15,
      "rotation": 4
    },
    {
      "x": 0,
      "y": 21,
      "z": 6,
      "name": "Cloth_Roof_Hide_Flap",
      "rotation": 1
    },
    {
      "x": 0,
      "y": 22,
      "z": 6,
      "name": "Wood_Dry_Trunk",
      "support": 15,
      "rotation": 4
    },
    {
      "x": 0,
      "y": 9,
      "z": 7,
      "name": "Wood_Drywood_Planks"
    },
    {
      "x": 0,
      "y": 13,
      "z": 7,
      "name": "Wood_Dry_Trunk",
      "support": 15,
      "rotation": 4
    },
    {
      "x": 0,
      "y": 14,
      "z": 7,
      "name": "Wood_Drywood_Beam"
    },
    {
      "x": 0,
      "y": 20,
      "z": 7,
      "name": "Wood_Drywood_Beam"
    },
    {
      "x": 0,
      "y": 21,
      "z": 7,
      "name": "Wood_Drywood_Beam"
    },
    {
      "x": 0,
      "y": 22,
      "z": 7,
      "name": "Wood_Dry_Trunk",
      "support": 15,
      "rotation": 4
    },
    {
      "x": 0,
      "y": 9,
      "z": 8,
      "name": "Wood_Drywood_Planks"
    },
    {
      "x": 0,
      "y": 13,
      "z": 8,
      "name": "Wood_Dry_Trunk_Half",
      "rotation": 4
    },
    {
      "x": 0,
      "y": 22,
      "z": 8,
      "name": "Wood_Dry_Trunk",
      "support": 15,
      "rotation": 4
    },
    {
      "x": 0,
      "y": 8,
      "z": 9,
      "name": "Wood_Drywood_Planks"
    },
    {
      "x": 0,
      "y": 9,
      "z": 9,
