{
  "version": 8,
  "blockIdVersion": 11,
  "anchorX": 0,
  "anchorY": 1,
  "anchorZ": 0,
  "blocks": [
    {
      "x": -4,
      "y": 0,
      "z": -1,
      "name": "Rock_Marble"
    },
    {
      "x": -4,
      "y": 1,
      "z": -1,
      "name": "Rock_Crystal_White_Small"
    },
    {
      "x": -4,
      "y": 0,
      "z": 0,
      "name": "Rock_Marble"
    },
    {
      "x": -4,
      "y": 1,
      "z": 0,
      "name": "Rock_Marble"
    },
    {
      "x": -4,
      "y": 0,
      "z": 1,
      "name": "Rock_Marble"
    },
    {
      "x": -4,
      "y": 1,
      "z": 1,
      "name": "Rock_Marble"
    },
    {
      "x": -4,
      "y": 2,
      "z": 1,
      "name": "Plant_Coral_Bush_Dead"
    },
    {
      "x": -3,
      "y": 0,
      "z": -2,
      "name": "Rock_Marble"
    },
    {
      "x": -3,
      "y": 1,
      "z": -2,
      "name": "Rock_Marble"
    },
    {
      "x": -3,
      "y": 2,
      "z": -2,
      "name": "Plant_Coral_Model_Dead"
    },
    {
      "x": -3,
      "y": 0,
      "z": -1,
      "name": "Rock_Marble"
    },
    {
      "x": -3,
      "y": 1,
      "z": -1,
      "name": "Rock_Marble"
    },
    {
      "x": -3,
      "y": 2,
      "z": -1,
      "name": "Rock_Marble"
    },
    {
      "x": -3,
      "y": 3,
      "z": -1,
      "name": "Plant_Coral_Model_Dead6"
    },
    {
      "x": -3,
      "y": 0,
      "z": 0,
      "name": "Rock_Marble"
    },
    {
      "x": -3,
      "y": 1,
      "z": 0,
      "name": "Rock_Marble"
    },
    {
      "x": -3,
      "y": 2,
      "z": 0,
      "name": "Rock_Marble"
    },
    {
      "x": -3,
      "y": 3,
      "z": 0,
      "name": "Rock_Marble"
    },
    {
      "x": -3,
      "y": 4,
      "z": 0,
      "name": "Rock_Marble"
    },
    {
      "x": -3,
      "y": 5,
      "z": 0,
      "name": "Plant_Coral_Model_White"
    },
    {
      "x": -3,
      "y": 0,
      "z": 1,
      "name": "Rock_Marble"
    },
    {
      "x": -3,
      "y": 1,
      "z": 1,
      "name": "Rock_Marble"
    },
    {
      "x": -3,
      "y": 2,
      "z": 1,
      "name": "Rock_Marble"
    },
    {
      "x": -3,
      "y": 3,
      "z": 1,
      "name": "Rock_Marble"
    },
    {
      "x": -3,
      "y": 4,
      "z": 1,
      "name": "Rock_Marble"
    },
    {
      "x": -3,
      "y": 5,
      "z": 1,
      "name": "Plant_Coral_Bush_Dead2"
    },
    {
      "x": -3,
      "y": 0,
      "z": 2,
      "name": "Rock_Marble"
    },
    {
      "x": -3,
      "y": 1,
      "z": 2,
      "name": "Rock_Marble"
    },
    {
      "x": -3,
      "y": 2,
      "z": 2,
      "name": "Plant_Coral_Model_White"
    },
    {
      "x": -2,
      "y": 0,
      "z": -3,
      "name": "Rock_Marble"
    },
    {
      "x": -2,
      "y": 1,
      "z": -3,
      "name": "Rock_Marble"
    },
    {
      "x": -2,
      "y": 2,
      "z": -3,
      "name": "Rock_Marble"
    },
    {
      "x": -2,
      "y": 0,
      "z": -2,
      "name": "Rock_Marble"
    },
    {
      "x": -2,
      "y": 1,
      "z": -2,
      "name": "Rock_Marble"
    },
    {
      "x": -2,
      "y": 2,
      "z": -2,
      "name": "Rock_Marble"
    },
    {
      "x": -2,
      "y": 3,
      "z": -2,
      "name": "Rock_Marble"
    },
    {
      "x": -2,
      "y": 0,
      "z": -1,
      "name": "Rock_Marble"
    },
    {
      "x": -2,
      "y": 1,
      "z": -1,
      "name": "Rock_Marble"
    },
    {
      "x": -2,
      "y": 2,
      "z": -1,
      "name": "Rock_Marble"
    },
    {
      "x": -2,
      "y": 3,
      "z": -1,
      "name": "Rock_Marble"
    },
    {
      "x": -2,
      "y": 4,
      "z": -1,
      "name": "Plant_Coral_Model_Dead7"
    },
    {
      "x": -2,
      "y": 0,
      "z": 0,
      "name": "Rock_Marble"
    },
    {
      "x": -2,
      "y": 1,
      "z": 0,
      "name": "Rock_Marble"
    },
    {
      "x": -2,
      "y": 2,
      "z": 0,
      "name": "Rock_Marble"
    },
    {
      "x": -2,
      "y": 3,
      "z": 0,
      "name": "Rock_Marble"
    },
    {
      "x": -2,
      "y": 4,
      "z": 0,
      "name": "Rock_Marble"
    },
    {
      "x": -2,
      "y": 5,
      "z": 0,
      "name": "Rubble_Marble",
      "support": 15
    },
    {
      "x": -2,
      "y": 0,
      "z": 1,
      "name": "Rock_Marble"
    },
    {
      "x": -2,
      "y": 1,
      "z": 1,
      "name": "Rock_Marble"
    },
    {
      "x": -2,
      "y": 2,
      "z": 1,
      "name": "Rock_Marble"
    },
    {
      "x": -2,
      "y": 3,
      "z": 1,
      "name": "Rock_Marble"
    },
    {
      "x": -2,
      "y": 4,
      "z": 1,
      "name": "Rock_Marble"
    },
    {
      "x": -2,
      "y": 5,
      "z": 1,
      "name": "Rock_Marble"
    },
    {
      "x": -2,
      "y": 6,
      "z": 1,
      "name": "Rock_Marble"
    },
    {
      "x": -2,
      "y": 7,
      "z": 1,
      "name": "Rock_Marble"
    },
    {
      "x": -2,
      "y": 8,
      "z": 1,
      "name": "Plant_Coral_Model_Dead4"
    },
    {
      "x": -2,
      "y": 0,
      "z": 2,
      "name": "Rock_Marble"
    },
    {
      "x": -2,
      "y": 1,
      "z": 2,
      "name": "Rock_Marble"
    },
    {
      "x": -2,
      "y": 2,
      "z": 2,
      "name": "Rock_Marble"
    },
    {
      "x": -2,
      "y": 3,
      "z": 2,
      "name": "Rock_Crystal_White_Small"
    },
    {
      "x": -2,
      "y": 5,
      "z": 2,
      "name": "Rock_Crystal_White_Medium",
      "rotation": 8
    },
    {
      "x": -2,
      "y": 6,
      "z": 2,
      "name": "Rock_Marble"
    },
    {
      "x": -2,
      "y": 7,
      "z": 2,
      "name": "Rock_Marble"
    },
    {
      "x": -2,
      "y": 8,
      "z": 2,
      "name": "Rock_Marble"
    },
    {
      "x": -2,
      "y": 9,
      "z": 2,
      "name": "Rock_Marble"
    },
    {
      "x": -2,
      "y": 10,
      "z": 2,
      "name": "Rock_Marble"
    },
    {
      "x": -2,
      "y": 11,
      "z": 2,
      "name": "Rock_Marble"
    },
    {
      "x": -2,
      "y": 0,
      "z": 3,
      "name": "Rock_Marble"
    },
    {
      "x": -2,
      "y": 1,
      "z": 3,
      "name": "Rock_Marble"
    },
    {
      "x": -2,
      "y": 2,
      "z": 3,
      "name": "Rubble_Marble",
      "support": 15
    },
    {
      "x": -2,
      "y": 8,
      "z": 3,
      "name": "Rock_Marble"
    },
    {
      "x": -2,
      "y": 9,
      "z": 3,
      "name": "Rock_Marble"
    },
    {
      "x": -2,
      "y": 10,
      "z": 3,
      "name": "Rock_Marble"
    },
    {
      "x": -2,
      "y": 11,
      "z": 3,
      "name": "Rubble_Marble_Medium",
      "support": 15
    },
    {
      "x": -2,
      "y": 0,
      "z": 4,
      "name": "Plant_Coral_Bush_Dead2"
    },
    {
      "x": -1,
      "y": 0,
      "z": -4,
      "name": "Rock_Marble"
    },
    {
      "x": -1,
      "y": 1,
      "z": -4,
      "name": "Rock_Marble"
    },
    {
      "x": -1,
      "y": 2,
      "z": -4,
      "name": "Rock_Marble"
    },
    {
      "x": -1,
      "y": 3,
      "z": -4,
      "name": "Plant_Coral_Model_Dead3"
    },
    {
      "x": -1,
      "y": 0,
      "z": -3,
      "name": "Rock_Marble"
    },
    {
      "x": -1,
      "y": 1,
      "z": -3,
      "name": "Rock_Marble"
    },
    {
      "x": -1,
      "y": 2,
      "z": -3,
      "name": "Rock_Marble"
    },
    {
      "x": -1,
      "y": 3,
      "z": -3,
      "name": "Rock_Marble"
    },
    {
      "x": -1,
      "y": 4,
      "z": -3,
      "name": "Plant_Coral_Bush_Dead"
    },
    {
      "x": -1,
      "y": 0,
      "z": -2,
      "name": "Rock_Marble"
    },
    {
      "x": -1,
      "y": 1,
      "z": -2,
      "name": "Rock_Marble"
    },
    {
      "x": -1,
      "y": 2,
      "z": -2,
      "name": "Rock_Marble"
    },
    {
      "x": -1,
      "y": 3,
      "z": -2,
      "name": "Rock_Marble"
    },
    {
      "x": -1,
      "y": 4,
      "z": -2,
      "name": "Rock_Marble"
    },
    {
      "x": -1,
      "y": 5,
      "z": -2,
      "name": "Plant_Coral_Model_Dead7"
    },
    {
      "x": -1,
      "y": 0,
      "z": -1,
      "name": "Rock_Marble"
    },
    {
      "x": -1,
      "y": 1,
      "z": -1,
      "name": "Rock_Marble"
    },
    {
      "x": -1,
      "y": 2,
      "z": -1,
      "name": "Rock_Marble"
    },
    {
      "x": -1,
      "y": 3,
      "z": -1,
      "name": "Rock_Marble"
    },
    {
      "x": -1,
      "y": 4,
      "z": -1,
      "name": "Rock_Marble"
    },
    {
      "x": -1,
      "y": 5,
      "z": -1,
      "name": "Rubble_Marble_Medium",
      "support": 15
    },
    {
      "x": -1,
      "y": 0,
      "z": 0,
      "name": "Rock_Marble"
    },
    {
      "x": -1,
      "y": 1,
      "z": 0,
      "name": "Rock_Marble"
    },
    {
      "x": -1,
      "y": 2,
      "z": 0,
      "name": "Rock_Marble"
    },
    {
      "x": -1,
      "y": 3,
      "z": 0,
      "name": "Rock_Marble"
    },
    {
      "x": -1,
      "y": 4,
      "z": 0,
      "name": "Rock_Marble"
    },
    {
      "x": -1,
      "y": 5,
      "z": 0,
      "name": "Rock_Marble"
    },
    {
      "x": -1,
      "y": 6,
      "z": 0,
      "name": "Rock_Marble"
    },
    {
      "x": -1,
      "y": 7,
      "z": 0,
      "name": "Rubble_Marble",
      "support": 15
    },
    {
      "x": -1,
      "y": 13,
      "z": 0,
      "name": "Rock_Marble"
    },
    {
      "x": -1,
      "y": 14,
      "z": 0,
      "name": "Rubble_Marble_Medium",
      "support": 15
    },
    {
      "x": -1,
      "y": 0,
      "z": 1,
      "name": "Rock_Marble"
    },
    {
      "x": -1,
      "y": 1,
      "z": 1,
      "name": "Rock_Marble"
    },
    {
      "x": -1,
      "y": 2,
      "z": 1,
      "name": "Rock_Marble"
    },
    {
      "x": -1,
      "y": 3,
      "z": 1,
      "name": "Rock_Marble"
    },
    {
      "x": -1,
      "y": 4,
      "z": 1,
      "name": "Rock_Marble"
    },
    {
      "x": -1,
      "y": 5,
      "z": 1,
      "name": "Rock_Marble"
    },
    {
      "x": -1,
      "y": 6,
      "z": 1,
      "name": "Rock_Marble"
    },
    {
      "x": -1,
      "y": 7,
      "z": 1,
      "name": "Rock_Marble"
    },
    {
      "x": -1,
      "y": 8,
      "z": 1,
      "name": "Rock_Marble"
    },
    {
      "x": -1,
      "y": 9,
      "z": 1,
      "name": "Rubble_Marble",
      "support": 15
    },
    {
      "x": -1,
      "y": 13,
      "z": 1,
      "name": "Rock_Marble"
    },
    {
      "x": -1,
      "y": 0,
      "z": 2,
      "name": "Rock_Marble"
    },
    {
      "x": -1,
      "y": 1,
      "z": 2,
      "name": "Rock_Marble"
    },
    {
      "x": -1,
      "y": 2,
      "z": 2,
      "name": "Rock_Marble"
    },
    {
      "x": -1,
      "y": 3,
      "z": 2,
      "name": "Rock_Marble"
    },
    {
      "x": -1,
      "y": 4,
      "z": 2,
      "name": "Rock_Marble"
    },
    {
      "x": -1,
      "y": 5,
      "z": 2,
      "name": "Rock_Marble"
    },
    {
      "x": -1,
      "y": 6,
      "z": 2,
      "name": "Rock_Marble"
    },
    {
      "x": -1,
      "y": 7,
      "z": 2,
      "name": "Rock_Marble"
    },
    {
      "x": -1,
      "y": 8,
      "z": 2,
      "name": "Rock_Marble"
    },
    {
      "x": -1,
      "y": 9,
      "z": 2,
      "name": "Rock_Marble"
    },
    {
      "x": -1,
      "y": 10,
      "z": 2,
      "name": "Rock_Marble"
    },
    {
      "x": -1,
      "y": 11,
      "z": 2,
      "name": "Rock_Marble"
    },
    {
      "x": -1,
      "y": 12,
      "z": 2,
      "name": "Rock_Marble"
    },
    {
      "x": -1,
      "y": 13,
      "z": 2,
      "name": "Plant_Coral_Model_Dead4"
    },
    {
      "x": -1,
      "y": 0,
      "z": 3,
      "name": "Rock_Marble"
    },
    {
      "x": -1,
      "y": 1,
      "z": 3,
      "name": "Rock_Marble"
    },
    {
      "x": -1,
      "y": 2,
      "z": 3,
      "name": "Rock_Marble"
    },
    {
      "x": -1,
      "y": 3,
      "z": 3,
      "name": "Rubble_Marble",
      "support": 15
    },
    {
      "x": -1,
      "y": 7,
      "z": 3,
      "name": "Rock_Marble"
    },
    {
      "x": -1,
      "y": 8,
      "z": 3,
      "name": "Rock_Marble"
    },
    {
      "x": -1,
      "y": 9,
      "z": 3,
      "name": "Rock_Marble"
    },
    {
      "x": -1,
      "y": 10,
      "z": 3,
      "name": "Rock_Marble"
    },
    {
      "x": -1,
      "y": 0,
      "z": 4,
      "name": "Rock_Marble"
    },
    {
      "x": -1,
      "y": 1,
      "z": 4,
      "name": "Plant_Coral_Bush_White"
    },
    {
      "x": 0,
      "y": 0,
      "z": -4,
      "name": "Rock_Marble"
    },
    {
      "x": 0,
      "y": 1,
      "z": -4,
      "name": "Rock_Marble"
    },
    {
      "x": 0,
      "y": 2,
      "z": -4,
      "name": "Rock_Marble"
    },
    {
      "x": 0,
      "y": 0,
      "z": -3,
      "name": "Rock_Marble"
    },
    {
      "x": 0,
      "y": 1,
      "z": -3,
      "name": "Rock_Marble"
    },
    {
      "x": 0,
      "y": 2,
      "z": -3,
      "name": "Rock_Marble"
    },
    {
      "x": 0,
      "y": 3,
      "z": -3,
      "name": "Plant_Coral_Block_White"
    },
    {
      "x": 0,
      "y": 4,
      "z": -3,
      "name": "Plant_Coral_Block_White"
    },
    {
      "x": 0,
      "y": 5,
      "z": -3,
      "name": "Rock_Marble"
    },
    {
      "x": 0,
      "y": 6,
      "z": -3,
      "name": "Rubble_Marble_Medium",
      "support": 15
    },
    {
      "x": 0,
      "y": 8,
      "z": -3,
      "name": "Rock_Crystal_White_Medium",
      "rotation": 8
    },
    {
      "x": 0,
      "y": 9,
      "z": -3,
      "name": "Rock_Marble"
    },
    {
      "x": 0,
      "y": 10,
      "z": -3,
      "name": "Rock_Marble"
    },
    {
      "x": 0,
      "y": 11,
      "z": -3,
      "name": "Plant_Coral_Model_Dead7"
    },
    {
      "x": 0,
      "y": 0,
      "z": -2,
      "name": "Rock_Marble"
    },
    {
      "x": 0,
      "y": 1,
      "z": -2,
      "name": "Rock_Marble"
    },
    {
      "x": 0,
      "y": 2,
      "z": -2,
      "name": "Rock_Marble"
    },
    {
      "x": 0,
      "y": 3,
      "z": -2,
      "name": "Rock_Marble"
    },
    {
      "x": 0,
      "y": 4,
      "z": -2,
      "name": "Rock_Marble"
    },
    {
      "x": 0,
      "y": 5,
      "z": -2,
      "name": "Rock_Marble"
    },
    {
      "x": 0,
      "y": 6,
      "z": -2,
      "name": "Plant_Coral_Block_White"
    },
    {
      "x": 0,
      "y": 7,
      "z": -2,
      "name": "Plant_Coral_Block_White"
    },
    {
      "x": 0,
      "y": 8,
      "z": -2,
      "name": "Rock_Marble"
    },
    {
      "x": 0,
      "y": 9,
      "z": -2,
      "name": "Rubble_Marble_Medium",
      "support": 15
    },
    {
      "x": 0,
      "y": 11,
      "z": -2,
      "name": "Rock_Marble"
    },
    {
      "x": 0,
      "y": 12,
      "z": -2,
      "name": "Rock_Marble"
    },
    {
      "x": 0,
      "y": 13,
      "z": -2,
      "name": "Plant_Coral_Model_Dead6"
    },
    {
      "x": 0,
      "y": 0,
      "z": -1,
      "name": "Rock_Marble"
    },
    {
      "x": 0,
      "y": 1,
      "z": -1,
      "name": "Rock_Marble"
    },
    {
      "x": 0,
      "y": 2,
      "z": -1,
      "name": "Rock_Marble"
    },
    {
      "x": 0,
      "y": 3,
      "z": -1,
      "name": "Rock_Marble"
    },
    {
      "x": 0,
      "y": 4,
      "z": -1,
      "name": "Rock_Marble"
    },
    {
      "x": 0,
      "y": 5,
      "z": -1,
      "name": "Plant_Coral_Block_White"
    },
    {
      "x": 0,
      "y": 6,
      "z": -1,
      "name": "Plant_Coral_Block_White"
    },
    {
      "x": 0,
      "y": 7,
      "z": -1,
      "name": "Rock_Marble"
    },
    {
      "x": 0,
      "y": 8,
      "z": -1,
      "name": "Rubble_Marble_Medium",
      "support": 15
    },
    {
      "x": 0,
      "y": 12,
      "z": -1,
      "name": "Rock_Marble"
    },
    {
      "x": 0,
      "y": 13,
      "z": -1,
      "name": "Rock_Marble"
    },
    {
      "x": 0,
      "y": 14,
      "z": -1,
      "name": "Plant_Coral_Bush_Dead3"
    },
    {
      "x": 0,
      "y": 0,
      "z": 0,
      "name": "Rock_Marble"
    },
    {
      "x": 0,
      "y": 1,
      "z": 0,
      "name": "Rock_Marble"
    },
    {
      "x": 0,
      "y": 2,
      "z": 0,
      "name": "Rock_Marble"
    },
    {
      "x": 0,
      "y": 3,
      "z": 0,
      "name": "Rock_Marble"
    },
    {
      "x": 0,
      "y": 4,
      "z": 0,
      "name": "Rock_Marble"
    },
    {
      "x": 0,
      "y": 5,
      "z": 0,
      "name": "Rock_Marble"
    },
    {
      "x": 0,
      "y": 6,
      "z": 0,
      "name": "Rock_Marble"
    },
    {
      "x": 0,
      "y": 7,
      "z": 0,
      "name": "Rock_Crystal_White_Block"
    },
    {
      "x": 0,
      "y": 8,
      "z": 0,
      "name": "Rock_Crystal_White_Small"
    },
    {
      "x": 0,
      "y": 12,
      "z": 0,
      "name": "Rock_Crystal_White_Large",
      "rotation": 8
    },
    {
      "x": 0,
      "y": 13,
      "z": 0,
      "name": "Rock_Marble"
    },
    {
      "x": 0,
      "y": 14,
      "z": 0,
      "name": "Rubble_Marble",
      "support": 15
    },
    {
      "x": 0,
      "y": 0,
      "z": 1,
      "name": "Rock_Marble"
    },
    {
      "x": 0,
      "y": 1,
      "z": 1,
      "name": "Rock_Marble"
    },
    {
      "x": 0,
      "y": 2,
      "z": 1,
      "name": "Rock_Marble"
    },
    {
      "x": 0,
      "y": 3,
      "z": 1,
      "name": "Rock_Marble"
    },
    {
      "x": 0,
      "y": 4,
      "z": 1,
      "name": "Rock_Marble"
    },
    {
      "x": 0,
      "y": 5,
      "z": 1,
      "name": "Rock_Marble"
    },
    {
      "x": 0,
      "y": 6,
      "z": 1,
      "name": "Rock_Marble"
    },
    {
      "x": 0,
      "y": 7,
      "z": 1,
      "name": "Rock_Marble"
    },
    {
      "x": 0,
      "y": 8,
      "z": 1,
      "name": "Rubble_Marble_Medium",
      "support": 15
    },
    {
      "x": 0,
      "y": 12,
      "z": 1,
      "name": "Rock_Marble"
    },
    {
      "x": 0,
      "y": 13,
      "z": 1,
      "name": "Rubble_Marble",
      "support": 15
    },
    {
      "x": 0,
      "y": 0,
      "z": 2,
      "name": "Rock_Marble"
    },
    {
      "x": 0,
      "y": 1,
      "z": 2,
      "name": "Rock_Marble"
    },
    {
      "x": 0,
      "y": 2,
      "z": 2,
      "name": "Rock_Marble"
    },
    {
      "x": 0,
      "y": 3,
      "z": 2,
      "name": "Rock_Marble"
    },
    {
      "x": 0,
      "y": 4,
      "z": 2,
      "name": "Rock_Marble"
    },
    {
      "x": 0,
      "y": 5,
      "z": 2,
      "name": "Rock_Marble"
    },
    {
      "x": 0,
      "y": 6,
      "z": 2,
      "name": "Rock_Marble"
    },
    {
      "x": 0,
      "y": 7,
      "z": 2,
      "name": "Rock_Marble"
    },
    {
      "x": 0,
      "y": 8,
      "z": 2,
      "name": "Rock_Marble"
    },
    {
      "x": 0,
      "y": 9,
      "z": 2,
      "name": "Plant_Coral_Bush_Dead3"
    },
    {
      "x": 0,
      "y": 12,
      "z": 2,
      "name": "Rock_Marble"
    },
    {
      "x": 0,
      "y": 0,
      "z": 3,
      "name": "Rock_Marble"
    },
    {
      "x": 0,
      "y": 1,
      "z": 3,
      "name": "Rock_Marble"
    },
    {
      "x": 0,
      "y": 2,
      "z": 3,
      "name": "Rock_Marble"
    },
    {
      "x": 0,
      "y": 3,
      "z": 3,
      "name": "Rock_Marble"
    },
    {
      "x": 0,
      "y": 7,
      "z": 3,
      "name": "Rock_Marble"
    },
    {
      "x": 0,
      "y": 8,
      "z": 3,
      "name": "Rock_Marble"
    },
    {
      "x": 0,
      "y": 9,
      "z": 3,
      "name": "Rock_Marble"
    },
    {
      "x": 0,
      "y": 10,
      "z": 3,
      "name": "Plant_Coral_Model_Dead"
    },
    {
      "x": 0,
      "y": 0,
      "z": 4,
      "name": "Rock_Marble"
    },
    {
      "x": 0,
      "y": 1,
      "z": 4,
      "name": "Rock_Marble"
    },
    {
      "x": 1,
      "y": 0,
      "z": -4,
      "name": "Rock_Marble"
    },
    {
      "x": 1,
      "y": 1,
      "z": -4,
      "name": "Rock_Marble"
    },
    {
      "x": 1,
      "y": 2,
      "z": -4,
      "name": "Plant_Coral_Model_Dead7"
    },
    {
      "x": 1,
      "y": 0,
      "z": -3,
      "name": "Rock_Marble"
    },
    {
      "x": 1,
      "y": 1,
      "z": -3,
      "name": "Rock_Marble"
    },
    {
      "x": 1,
      "y": 2,
      "z": -3,
      "name": "Rock_Marble"
    },
    {
      "x": 1,
      "y": 3,
      "z": -3,
      "name": "Rock_Marble"
    },
    {
      "x": 1,
      "y": 4,
      "z": -3,
      "name": "Plant_Coral_Block_White"
    },
    {
      "x": 1,
      "y": 5,
      "z": -3,
      "name": "Plant_Coral_Block_White"
    },
    {
      "x": 1,
      "y": 8,
      "z": -3,
      "name": "Rock_Marble"
    },
    {
      "x": 1,
      "y": 9,
      "z": -3,
      "name": "Rock_Marble"
    },
    {
      "x": 1,
      "y": 10,
      "z": -3,
      "name": "Rock_Marble"
    },
    {
      "x": 1,
      "y": 11,
      "z": -3,
      "name": "Rock_Marble"
    },
    {
      "x": 1,
      "y": 12,
      "z": -3,
      "name": "Rubble_Marble",
      "support": 15
    },
    {
      "x": 1,
      "y": 0,
      "z": -2,
      "name": "Rock_Marble"
    },
    {
      "x": 1,
      "y": 1,
      "z": -2,
      "name": "Rock_Marble"
    },
    {
      "x": 1,
      "y": 2,
      "z": -2,
      "name": "Rock_Marble"
    },
    {
      "x": 1,
      "y": 3,
      "z": -2,
      "name": "Rock_Marble"
    },
    {
      "x": 1,
      "y": 4,
      "z": -2,
      "name": "Rock_Marble"
    },
    {
      "x": 1,
      "y": 5,
      "z": -2,
      "name": "Rock_Marble"
    },
    {
      "x": 1,
      "y": 6,
      "z": -2,
      "name": "Plant_Coral_Block_White"
    },
    {
      "x": 1,
      "y": 7,
      "z": -2,
      "name": "Plant_Coral_Block_White"
    },
    {
      "x": 1,
      "y": 8,
      "z": -2,
      "name": "Rock_Marble"
    },
    {
      "x": 1,
      "y": 9,
      "z": -2,
      "name": "Rock_Marble"
    },
    {
      "x": 1,
      "y": 10,
      "z": -2,
      "name": "Rock_Marble"
    },
    {
      "x": 1,
      "y": 11,
      "z": -2,
      "name": "Rock_Marble"
    },
    {
      "x": 1,
      "y": 12,
      "z": -2,
      "name": "Rock_Marble"
    },
    {
      "x": 1,
      "y": 0,
      "z": -1,
      "name": "Rock_Marble"
    },
    {
      "x": 1,
      "y": 1,
      "z": -1,
      "name": "Rock_Marble"
    },
    {
      "x": 1,
      "y": 2,
      "z": -1,
      "name": "Rock_Marble"
    },
    {
      "x": 1,
      "y": 3,
      "z": -1,
      "name": "Rock_Marble"
    },
    {
      "x": 1,
      "y": 4,
      "z": -1,
      "name": "Rock_Marble"
    },
    {
      "x": 1,
      "y": 5,
      "z": -1,
      "name": "Rock_Marble"
    },
    {
      "x": 1,
      "y": 6,
      "z": -1,
      "name": "Rock_Marble"
    },
    {
      "x": 1,
      "y": 7,
      "z": -1,
      "name": "Rock_Marble"
    },
    {
      "x": 1,
      "y": 8,
      "z": -1,
      "name": "Rock_Marble"
    },
    {
      "x": 1,
      "y": 9,
      "z": -1,
      "name": "Rubble_Marble",
      "support": 15
    },
    {
      "x": 1,
      "y": 11,
      "z": -1,
      "name": "Rock_Marble"
    },
    {
      "x": 1,
      "y": 12,
      "z": -1,
      "name": "Rock_Marble"
    },
    {
      "x": 1,
      "y": 13,
      "z": -1,
      "name": "Rubble_Marble",
      "support": 15
    },
    {
      "x": 1,
      "y": 0,
      "z": 0,
      "name": "Rock_Marble"
    },
    {
      "x": 1,
      "y": 1,
      "z": 0,
      "name": "Rock_Marble"
    },
    {
      "x": 1,
      "y": 2,
      "z": 0,
      "name": "Rock_Marble"
    },
    {
      "x": 1,
      "y": 3,
      "z": 0,
      "name": "Rock_Marble"
    },
    {
      "x": 1,
      "y": 4,
      "z": 0,
      "name": "Rock_Marble"
    },
    {
      "x": 1,
      "y": 5,
      "z": 0,
      "name": "Rock_Marble"
    },
    {
      "x": 1,
      "y": 6,
      "z": 0,
      "name": "Rock_Marble"
    },
    {
      "x": 1,
      "y": 7,
      "z": 0,
      "name": "Rock_Marble"
    },
    {
      "x": 1,
      "y": 8,
      "z": 0,
      "name": "Rubble_Marble_Medium",
      "support": 15
    },
    {
      "x": 1,
      "y": 0,
      "z": 1,
      "name": "Rock_Marble"
    },
    {
      "x": 1,
      "y": 1,
      "z": 1,
      "name": "Rock_Marble"
    },
    {
      "x": 1,
      "y": 2,
      "z": 1,
      "name": "Rock_Marble"
    },
    {
      "x": 1,
      "y": 3,
      "z": 1,
      "name": "Rock_Marble"
    },
    {
      "x": 1,
      "y": 4,
      "z": 1,
      "name": "Rock_Marble"
    },
    {
      "x": 1,
      "y": 5,
      "z": 1,
      "name": "Rock_Marble"
    },
    {
      "x": 1,
      "y": 6,
      "z": 1,
      "name": "Rock_Marble"
    },
    {
      "x": 1,
      "y": 7,
      "z": 1,
      "name": "Rubble_Marble_Medium",
      "support": 15
    },
    {
      "x": 1,
      "y": 0,
      "z": 2,
      "name": "Rock_Marble"
    },
    {
      "x": 1,
      "y": 1,
      "z": 2,
      "name": "Rock_Marble"
    },
    {
      "x": 1,
      "y": 2,
      "z": 2,
      "name": "Rock_Marble"
    },
    {
      "x": 1,
      "y": 3,
      "z": 2,
      "name": "Rock_Marble"
    },
    {
      "x": 1,
      "y": 4,
      "z": 2,
      "name": "Rock_Marble"
    },
    {
      "x": 1,
      "y": 5,
      "z": 2,
      "name": "Plant_Coral_Model_White"
    },
    {
      "x": 1,
      "y": 0,
      "z": 3,
      "name": "Rock_Marble"
    },
    {
      "x": 1,
      "y": 1,
      "z": 3,
      "name": "Rock_Marble"
    },
    {
      "x": 1,
      "y": 2,
      "z": 3,
      "name": "Rock_Marble"
    },
    {
      "x": 1,
      "y": 3,
      "z": 3,
      "name": "Rock_Marble"
    },
    {
      "x": 1,
      "y": 4,
      "z": 3,
      "name": "Plant_Coral_Model_Dead7"
    },
    {
      "x": 1,
      "y": 0,
      "z": 4,
      "name": "Rock_Marble"
    },
    {
      "x": 2,
      "y": 0,
      "z": -3,
      "name": "Rock_Marble"
    },
    {
      "x": 2,
      "y": 1,
      "z": -3,
      "name": "Rock_Marble"
    },
    {
      "x": 2,
      "y": 2,
      "z": -3,
      "name": "Rock_Marble"
    },
    {
      "x": 2,
      "y": 3,
      "z": -3,
      "name": "Rock_Marble"
    },
    {
      "x": 2,
      "y": 4,
      "z": -3,
      "name": "Rubble_Marble",
      "support": 15
    },
    {
      "x": 2,
      "y": 8,
      "z": -3,
      "name": "Rock_Marble"
    },
    {
      "x": 2,
      "y": 9,
      "z": -3,
      "name": "Rock_Marble"
    },
    {
      "x": 2,
      "y": 10,
      "z": -3,
      "name": "Rubble_Marble_Medium",
      "support": 15
    },
    {
      "x": 2,
      "y": 0,
      "z": -2,
      "name": "Rock_Marble"
    },
    {
      "x": 2,
      "y": 1,
      "z": -2,
      "name": "Rock_Marble"
    },
    {
      "x": 2,
      "y": 2,
      "z": -2,
      "name": "Rock_Marble"
    },
    {
      "x": 2,
      "y": 3,
      "z": -2,
      "name": "Rock_Marble"
    },
    {
      "x": 2,
      "y": 4,
      "z": -2,
      "name": "Rock_Marble"
    },
    {
      "x": 2,
      "y": 5,
      "z": -2,
      "name": "Rock_Marble"
    },
    {
      "x": 2,
      "y": 6,
      "z": -2,
      "name": "Plant_Coral_Model_Dead2"
    },
    {
      "x": 2,
      "y": 7,
      "z": -2,
      "name": "Rock_Marble"
    },
    {
      "x": 2,
      "y": 8,
      "z": -2,
      "name": "Rock_Marble"
    },
    {
      "x": 2,
      "y": 9,
      "z": -2,
      "name": "Rock_Marble"
    },
    {
      "x": 2,
      "y": 10,
      "z": -2,
      "name": "Rock_Marble"
    },
    {
      "x": 2,
      "y": 11,
      "z": -2,
      "name": "Rock_Marble"
    },
    {
      "x": 2,
      "y": 12,
      "z": -2,
      "name": "Plant_Coral_Bush_Dead"
    },
    {
      "x": 2,
      "y": 0,
      "z": -1,
      "name": "Rock_Marble"
    },
    {
      "x": 2,
      "y": 1,
      "z": -1,
      "name": "Rock_Marble"
    },
    {
      "x": 2,
      "y": 2,
      "z": -1,
      "name": "Rock_Marble"
    },
    {
      "x": 2,
      "y": 3,
      "z": -1,
      "name": "Rock_Marble"
    },
    {
      "x": 2,
      "y": 4,
      "z": -1,
      "name": "Rock_Marble"
    },
    {
      "x": 2,
      "y": 5,
      "z": -1,
      "name": "Rock_Marble"
    },
    {
      "x": 2,
      "y": 6,
      "z": -1,
      "name": "Rock_Marble"
    },
    {
      "x": 2,
      "y": 7,
      "z": -1,
      "name": "Rock_Marble"
    },
    {
      "x": 2,
      "y": 8,
      "z": -1,
      "name": "Rock_Marble"
    },
    {
      "x": 2,
      "y": 0,
      "z": 0,
      "name": "Rock_Marble"
    },
    {
      "x": 2,
      "y": 1,
      "z": 0,
      "name": "Rock_Marble"
    },
    {
      "x": 2,
      "y": 2,
      "z": 0,
      "name": "Rock_Marble"
    },
    {
      "x": 2,
      "y": 3,
      "z": 0,
      "name": "Rock_Marble"
    },
    {
      "x": 2,
      "y": 4,
      "z": 0,
      "name": "Rock_Marble"
    },
    {
      "x": 2,
      "y": 5,
      "z": 0,
      "name": "Rock_Marble"
    },
    {
      "x": 2,
      "y": 0,
      "z": 1,
      "name": "Rock_Marble"
    },
    {
      "x": 2,
      "y": 1,
      "z": 1,
      "name": "Rock_Marble"
    },
    {
      "x": 2,
      "y": 2,
      "z": 1,
      "name": "Rock_Marble"
    },
    {
      "x": 2,
      "y": 3,
      "z": 1,
      "name": "Rock_Marble"
    },
    {
      "x": 2,
      "y": 4,
      "z": 1,
      "name": "Plant_Coral_Block_White"
    },
    {
      "x": 2,
      "y": 5,
      "z": 1,
      "name": "Rock_Marble"
    },
    {
      "x": 2,
      "y": 6,
      "z": 1,
      "name": "Plant_Coral_Model_Dead"
    },
    {
      "x": 2,
      "y": 0,
      "z": 2,
      "name": "Rock_Marble"
    },
    {
      "x": 2,
      "y": 1,
      "z": 2,
      "name": "Rock_Marble"
    },
    {
      "x": 2,
      "y": 2,
      "z": 2,
      "name": "Plant_Coral_Block_White"
    },
    {
      "x": 2,
      "y": 3,
      "z": 2,
      "name": "Plant_Coral_Block_White"
    },
    {
      "x": 2,
      "y": 4,
      "z": 2,
      "name": "Plant_Coral_Bush_White"
    },
    {
      "x": 2,
      "y": 0,
      "z": 3,
      "name": "Rock_Marble"
    },
    {
      "x": 2,
      "y": 1,
      "z": 3,
      "name": "Plant_Coral_Bush_White"
    },
    {
      "x": 3,
      "y": 0,
      "z": -3,
      "name": "Rock_Marble"
    },
    {
      "x": 3,
      "y": 1,
      "z": -3,
      "name": "Plant_Coral_Model_Dead6"
    },
    {
      "x": 3,
      "y": 0,
      "z": -2,
      "name": "Plant_Coral_Block_White"
    },
    {
      "x": 3,
      "y": 1,
      "z": -2,
      "name": "Rock_Marble"
    },
    {
      "x": 3,
      "y": 2,
      "z": -2,
      "name": "Rock_Marble"
    },
    {
      "x": 3,
      "y": 3,
      "z": -2,
      "name": "Plant_Coral_Model_Dead2"
    },
    {
      "x": 3,
      "y": 0,
      "z": -1,
      "name": "Plant_Coral_Block_White"
    },
    {
      "x": 3,
      "y": 1,
      "z": -1,
      "name": "Plant_Coral_Block_White"
    },
    {
      "x": 3,
      "y": 2,
      "z": -1,
      "name": "Plant_Coral_Block_White"
    },
    {
      "x": 3,
      "y": 3,
      "z": -1,
      "name": "Rock_Marble"
    },
    {
      "x": 3,
      "y": 4,
      "z": -1,
      "name": "Rock_Marble"
    },
    {
      "x": 3,
      "y": 0,
      "z": 0,
      "name": "Rock_Marble"
    },
    {
      "x": 3,
      "y": 1,
      "z": 0,
      "name": "Plant_Coral_Block_White"
    },
    {
      "x": 3,
      "y": 2,
      "z": 0,
      "name": "Plant_Coral_Block_White"
    },
    {
      "x": 3,
      "y": 3,
      "z": 0,
      "name": "Rock_Marble"
    },
    {
      "x": 3,
      "y": 0,
      "z": 1,
      "name": "Rock_Marble"
    },
    {
      "x": 3,
      "y": 1,
      "z": 1,
      "name": "Rock_Marble"
    },
    {
      "x": 3,
      "y": 2,
      "z": 1,
      "name": "Rock_Marble"
    },
    {
      "x": 3,
      "y": 3,
      "z": 1,
      "name": "Rock_Marble"
    },
    {
      "x": 3,
      "y": 4,
      "z": 1,
      "name": "Rubble_Marble",
      "support": 15
    },
    {
      "x": 3,
      "y": 0,
      "z": 2,
      "name": "Rock_Marble"
    },
    {
      "x": 3,
      "y": 1,
      "z": 2,
      "name": "Rock_Marble"
    },
    {
      "x": 3,
      "y": 2,
      "z": 2,
      "name": "Plant_Coral_Bush_White"
    },
    {
      "x": 3,
      "y": 0,
      "z": 3,
      "name": "Plant_Coral_Bush_White"
    },
    {
      "x": 4,
      "y": 0,
      "z": 0,
      "name": "Rock_Marble"
    },
    {
      "x": 4,
      "y": 1,
      "z": 0,
      "name": "Rubble_Marble",
      "support": 15
    },
    {
      "x": 4,
      "y": 0,
      "z": 1,
      "name": "Rock_Marble"
    },
    {
      "x": 4,
      "y": 1,
      "z": 1,
      "name": "Rock_Marble"
    },
    {
      "x": 4,
      "y": 2,
      "z": 1,
      "name": "Plant_Coral_Model_Dead7",
      "rotation": 1
    },
    {
      "x": 5,
      "y": 0,
      "z": 1,
      "name": "Plant_Coral_Bush_Dead3"
    }
  ]
}