{
  "version": 8,
  "blockIdVersion": 11,
  "anchorX": 2,
  "anchorY": 1,
  "anchorZ": 0,
  "blocks": [
    {
      "x": -21,
      "y": 9,
      "z": -1,
      "name": "Wood_Drywood_Planks"
    },
    {
      "x": -21,
      "y": 10,
      "z": -1,
      "name": "Wood_Drywood_Decorative"
    },
    {
      "x": -21,
      "y": 11,
      "z": -1,
      "name": "*Wood_Drywood_Fence_State_Definitions_Corner",
      "rotation": 1
    },
    {
      "x": -21,
      "y": 9,
      "z": 0,
      "name": "Wood_Drywood_Planks"
    },
    {
      "x": -21,
      "y": 10,
      "z": 0,
      "name": "Wood_Drywood_Decorative"
    },
    {
      "x": -21,
      "y": 11,
      "z": 0,
      "name": "Wood_Drywood_Fence",
      "rotation": 3
    },
    {
      "x": -21,
      "y": 9,
      "z": 1,
      "name": "Wood_Drywood_Planks"
    },
    {
      "x": -21,
      "y": 10,
      "z": 1,
      "name": "Wood_Drywood_Decorative"
    },
    {
      "x": -21,
      "y": 11,
      "z": 1,
      "name": "*Wood_Drywood_Fence_State_Definitions_Corner",
      "rotation": 2
    },
    {
      "x": -20,
      "y": 9,
      "z": -2,
      "name": "Wood_Drywood_Planks"
    },
    {
      "x": -20,
      "y": 10,
      "z": -2,
      "name": "Wood_Drywood_Decorative"
    },
    {
      "x": -20,
      "y": 11,
      "z": -2,
      "name": "*Wood_Drywood_Fence_State_Definitions_Corner",
      "rotation": 1
    },
    {
      "x": -20,
      "y": 8,
      "z": -1,
      "name": "Wood_Drywood_Planks"
    },
    {
      "x": -20,
      "y": 9,
      "z": -1,
      "name": "Wood_Drywood_Planks"
    },
    {
      "x": -20,
      "y": 10,
      "z": -1,
      "name": "Wood_Drywood_Planks"
    },
    {
      "x": -20,
      "y": 11,
      "z": -1,
      "name": "*Wood_Drywood_Fence_State_Definitions_Corner",
      "rotation": 3
    },
    {
      "x": -20,
      "y": 7,
      "z": 0,
      "name": "Wood_Drywood_Planks"
    },
    {
      "x": -20,
      "y": 8,
      "z": 0,
      "name": "Wood_Drywood_Planks"
    },
    {
      "x": -20,
      "y": 9,
      "z": 0,
      "name": "Wood_Drywood_Planks"
    },
    {
      "x": -20,
      "y": 10,
      "z": 0,
      "name": "Wood_Drywood_Planks"
    },
    {
      "x": -20,
      "y": 8,
      "z": 1,
      "name": "Wood_Drywood_Planks"
    },
    {
      "x": -20,
      "y": 9,
      "z": 1,
      "name": "Wood_Drywood_Planks"
    },
    {
      "x": -20,
      "y": 10,
      "z": 1,
      "name": "Wood_Drywood_Planks"
    },
    {
      "x": -20,
      "y": 11,
      "z": 1,
      "name": "*Wood_Drywood_Fence_State_Definitions_Corner"
    },
    {
      "x": -20,
      "y": 9,
      "z": 2,
      "name": "Wood_Drywood_Planks"
    },
    {
      "x": -20,
      "y": 10,
      "z": 2,
      "name": "Wood_Drywood_Decorative"
    },
    {
      "x": -20,
      "y": 11,
      "z": 2,
      "name": "*Wood_Drywood_Fence_State_Definitions_Corner",
      "rotation": 2
    },
    {
      "x": -19,
      "y": 8,
      "z": -3,
      "name": "Wood_Drywood_Planks"
    },
    {
      "x": -19,
      "y": 9,
      "z": -3,
      "name": "Wood_Drywood_Planks"
    },
    {
      "x": -19,
      "y": 10,
      "z": -3,
      "name": "Wood_Drywood_Decorative"
    },
    {
      "x": -19,
      "y": 11,
      "z": -3,
      "name": "*Wood_Drywood_Fence_State_Definitions_Corner",
      "rotation": 1
    },
    {
      "x": -19,
      "y": 7,
      "z": -2,
      "name": "Wood_Drywood_Planks"
    },
    {
      "x": -19,
      "y": 8,
      "z": -2,
      "name": "Wood_Drywood_Planks"
    },
    {
      "x": -19,
      "y": 9,
      "z": -2,
      "name": "Wood_Drywood_Planks"
    },
    {
      "x": -19,
      "y": 10,
      "z": -2,
      "name": "Wood_Drywood_Planks"
    },
    {
      "x": -19,
      "y": 11,
      "z": -2,
      "name": "*Wood_Drywood_Fence_State_Definitions_Corner",
      "rotation": 3
    },
    {
      "x": -19,
      "y": 6,
      "z": -1,
      "name": "Wood_Drywood_Planks"
    },
    {
      "x": -19,
      "y": 7,
      "z": -1,
      "name": "Wood_Drywood_Planks"
    },
    {
      "x": -19,
      "y": 8,
      "z": -1,
      "name": "Wood_Drywood_Planks"
    },
    {
      "x": -19,
      "y": 9,
      "z": -1,
      "name": "Wood_Drywood_Planks"
    },
    {
      "x": -19,
      "y": 10,
      "z": -1,
      "name": "Wood_Drywood_Planks"
    },
    {
      "x": -19,
      "y": 6,
      "z": 0,
      "name": "Wood_Drywood_Planks"
    },
    {
      "x": -19,
      "y": 7,
      "z": 0,
      "name": "Wood_Drywood_Planks"
    },
    {
      "x": -19,
      "y": 8,
      "z": 0,
      "name": "Wood_Drywood_Planks"
    },
    {
      "x": -19,
      "y": 9,
      "z": 0,
      "name": "Wood_Drywood_Planks"
    },
    {
      "x": -19,
      "y": 10,
      "z": 0,
      "name": "Wood_Drywood_Planks"
    },
    {
      "x": -19,
      "y": 6,
      "z": 1,
      "name": "Wood_Drywood_Planks"
    },
    {
      "x": -19,
      "y": 7,
      "z": 1,
      "name": "Wood_Drywood_Planks"
    },
    {
      "x": -19,
      "y": 8,
      "z": 1,
      "name": "Wood_Drywood_Planks"
    },
    {
      "x": -19,
      "y": 9,
      "z": 1,
      "name": "Wood_Drywood_Planks"
    },
    {
      "x": -19,
      "y": 10,
      "z": 1,
      "name": "Wood_Drywood_Planks"
    },
    {
      "x": -19,
      "y": 7,
      "z": 2,
      "name": "Wood_Drywood_Planks"
    },
    {
      "x": -19,
      "y": 8,
      "z": 2,
      "name": "Wood_Drywood_Planks"
    },
    {
      "x": -19,
      "y": 9,
      "z": 2,
      "name": "Wood_Drywood_Planks"
    },
    {
      "x": -19,
      "y": 10,
      "z": 2,
      "name": "Wood_Drywood_Planks"
    },
    {
      "x": -19,
      "y": 11,
      "z": 2,
      "name": "*Wood_Drywood_Fence_State_Definitions_Corner"
    },
    {
      "x": -19,
      "y": 8,
      "z": 3,
      "name": "Wood_Drywood_Planks"
    },
    {
      "x": -19,
      "y": 9,
      "z": 3,
      "name": "Wood_Drywood_Planks"
    },
    {
      "x": -19,
      "y": 10,
      "z": 3,
      "name": "Wood_Drywood_Decorative"
    },
    {
      "x": -19,
      "y": 11,
      "z": 3,
      "name": "*Wood_Drywood_Fence_State_Definitions_Corner",
      "rotation": 2
    },
    {
      "x": -18,
      "y": 8,
      "z": -3,
      "name": "Wood_Drywood_Planks"
    },
    {
      "x": -18,
      "y": 9,
      "z": -3,
      "name": "Wood_Drywood_Planks"
    },
    {
      "x": -18,
      "y": 10,
      "z": -3,
      "name": "Wood_Drywood_Decorative"
    },
    {
      "x": -18,
      "y": 11,
      "z": -3,
      "name": "Wood_Drywood_Fence",
      "rotation": 2
    },
    {
      "x": -18,
      "y": 6,
      "z": -2,
      "name": "Wood_Drywood_Planks"
    },
    {
      "x": -18,
      "y": 7,
      "z": -2,
      "name": "Wood_Drywood_Planks"
    },
    {
      "x": -18,
      "y": 8,
      "z": -2,
      "name": "Wood_Drywood_Planks"
    },
    {
      "x": -18,
      "y": 9,
      "z": -2,
      "name": "Wood_Drywood_Planks"
    },
    {
      "x": -18,
      "y": 10,
      "z": -2,
      "name": "Wood_Drywood_Planks"
    },
    {
      "x": -18,
      "y": 5,
      "z": -1,
      "name": "Wood_Drywood_Planks"
    },
    {
      "x": -18,
      "y": 6,
      "z": -1,
      "name": "Wood_Drywood_Planks"
    },
    {
      "x": -18,
      "y": 7,
      "z": -1,
      "name": "Wood_Drywood_Planks"
    },
    {
      "x": -18,
      "y": 8,
      "z": -1,
      "name": "Wood_Drywood_Planks"
    },
    {
      "x": -18,
      "y": 9,
      "z": -1,
      "name": "Wood_Drywood_Planks"
    },
    {
      "x": -18,
      "y": 10,
      "z": -1,
      "name": "Wood_Drywood_Planks"
    },
    {
      "x": -18,
      "y": 5,
      "z": 0,
      "name": "Wood_Drywood_Planks"
    },
    {
      "x": -18,
      "y": 6,
      "z": 0,
      "name": "Wood_Drywood_Planks"
    },
    {
      "x": -18,
      "y": 7,
      "z": 0,
      "name": "Wood_Drywood_Planks"
    },
    {
      "x": -18,
      "y": 8,
      "z": 0,
      "name": "Wood_Drywood_Planks"
    },
    {
      "x": -18,
      "y": 9,
      "z": 0,
      "name": "Wood_Drywood_Planks"
    },
    {
      "x": -18,
      "y": 10,
      "z": 0,
      "name": "Wood_Drywood_Planks"
    },
    {
      "x": -18,
      "y": 5,
      "z": 1,
      "name": "Wood_Drywood_Planks"
    },
    {
      "x": -18,
      "y": 6,
      "z": 1,
      "name": "Wood_Drywood_Planks"
    },
    {
      "x": -18,
      "y": 7,
      "z": 1,
      "name": "Wood_Drywood_Planks"
    },
    {
      "x": -18,
      "y": 8,
      "z": 1,
      "name": "Wood_Drywood_Planks"
    },
    {
      "x": -18,
      "y": 9,
      "z": 1,
      "name": "Wood_Drywood_Planks"
    },
    {
      "x": -18,
      "y": 10,
      "z": 1,
      "name": "Wood_Drywood_Planks"
    },
    {
      "x": -18,
      "y": 6,
      "z": 2,
      "name": "Wood_Drywood_Planks"
    },
    {
      "x": -18,
      "y": 7,
      "z": 2,
      "name": "Wood_Drywood_Planks"
    },
    {
      "x": -18,
      "y": 8,
      "z": 2,
      "name": "Wood_Drywood_Planks"
    },
    {
      "x": -18,
      "y": 9,
      "z": 2,
      "name": "Wood_Drywood_Planks"
    },
    {
      "x": -18,
      "y": 10,
      "z": 2,
      "name": "Wood_Drywood_Planks"
    },
    {
      "x": -18,
      "y": 8,
      "z": 3,
      "name": "Wood_Drywood_Planks"
    },
    {
      "x": -18,
      "y": 9,
      "z": 3,
      "name": "Wood_Drywood_Planks"
    },
    {
      "x": -18,
      "y": 10,
      "z": 3,
      "name": "Wood_Drywood_Decorative"
    },
    {
      "x": -18,
      "y": 11,
      "z": 3,
      "name": "Wood_Drywood_Fence"
    },
    {
      "x": -17,
      "y": 8,
      "z": -4,
      "name": "Wood_Drywood_Planks"
    },
    {
      "x": -17,
      "y": 9,
      "z": -4,
      "name": "Wood_Drywood_Planks"
    },
    {
      "x": -17,
      "y": 10,
      "z": -4,
      "name": "Wood_Drywood_Decorative"
    },
    {
      "x": -17,
      "y": 11,
      "z": -4,
      "name": "*Wood_Drywood_Fence_State_Definitions_Corner",
      "rotation": 1
    },
    {
      "x": -17,
      "y": 7,
      "z": -3,
      "name": "Wood_Drywood_Planks"
    },
    {
      "x": -17,
      "y": 8,
      "z": -3,
      "name": "Wood_Drywood_Planks"
    },
    {
      "x": -17,
      "y": 9,
      "z": -3,
      "name": "Wood_Drywood_Planks"
    },
    {
      "x": -17,
      "y": 10,
      "z": -3,
      "name": "Wood_Drywood_Planks"
    },
    {
      "x": -17,
      "y": 11,
      "z": -3,
      "name": "*Wood_Drywood_Fence_State_Definitions_Corner",
      "rotation": 3
    },
    {
      "x": -17,
      "y": 6,
      "z": -2,
      "name": "Wood_Drywood_Planks"
    },
    {
      "x": -17,
      "y": 7,
      "z": -2,
      "name": "Wood_Drywood_Planks"
    },
    {
      "x": -17,
      "y": 8,
      "z": -2,
      "name": "Wood_Drywood_Planks"
    },
    {
      "x": -17,
      "y": 9,
      "z": -2,
      "name": "Wood_Drywood_Planks"
    },
    {
      "x": -17,
      "y": 10,
      "z": -2,
      "name": "Wood_Drywood_Planks"
    },
    {
      "x": -17,
      "y": 4,
      "z": -1,
      "name": "Wood_Drywood_Planks"
    },
    {
      "x": -17,
      "y": 5,
      "z": -1,
      "name": "Wood_Drywood_Planks"
    },
    {
      "x": -17,
      "y": 6,
      "z": -1,
      "name": "Wood_Drywood_Planks"
    },
    {
      "x": -17,
      "y": 7,
      "z": -1,
      "name": "Wood_Drywood_Stairs",
      "rotation": 1
    },
    {
      "x": -17,
      "y": 8,
      "z": -1,
      "name": "Wood_Drywood_Stairs",
      "rotation": 11
    },
    {
      "x": -17,
      "y": 9,
      "z": -1,
      "name": "Wood_Drywood_Planks"
    },
    {
      "x": -17,
      "y": 10,
      "z": -1,
      "name": "Wood_Drywood_Planks"
    },
    {
      "x": -17,
      "y": 3,
      "z": 0,
      "name": "Wood_Drywood_Planks"
    },
    {
      "x": -17,
      "y": 4,
      "z": 0,
      "name": "Wood_Drywood_Planks"
    },
    {
      "x": -17,
      "y": 5,
      "z": 0,
      "name": "Wood_Drywood_Planks"
    },
    {
      "x": -17,
      "y": 6,
      "z": 0,
      "name": "Wood_Drywood_Planks"
    },
    {
      "x": -17,
      "y": 7,
      "z": 0,
      "name": "Wood_Drywood_Stairs",
      "rotation": 1
    },
    {
      "x": -17,
      "y": 8,
      "z": 0,
      "name": "Wood_Drywood_Stairs",
      "rotation": 11
    },
    {
      "x": -17,
      "y": 9,
      "z": 0,
      "name": "Wood_Drywood_Planks"
    },
    {
      "x": -17,
      "y": 10,
      "z": 0,
      "name": "Wood_Drywood_Planks"
    },
    {
      "x": -17,
      "y": 4,
      "z": 1,
      "name": "Wood_Drywood_Planks"
    },
    {
      "x": -17,
      "y": 5,
      "z": 1,
      "name": "Wood_Drywood_Planks"
    },
    {
      "x": -17,
      "y": 6,
      "z": 1,
      "name": "Wood_Drywood_Planks"
    },
    {
      "x": -17,
      "y": 7,
      "z": 1,
      "name": "Wood_Drywood_Stairs",
      "rotation": 1
    },
    {
      "x": -17,
      "y": 8,
      "z": 1,
      "name": "Wood_Drywood_Stairs",
      "rotation": 11
    },
    {
      "x": -17,
      "y": 9,
      "z": 1,
      "name": "Wood_Drywood_Planks"
    },
    {
      "x": -17,
      "y": 10,
      "z": 1,
      "name": "Wood_Drywood_Planks"
    },
    {
      "x": -17,
      "y": 6,
      "z": 2,
      "name": "Wood_Drywood_Planks"
    },
    {
      "x": -17,
      "y": 7,
      "z": 2,
      "name": "Wood_Drywood_Planks"
    },
    {
      "x": -17,
      "y": 8,
      "z": 2,
      "name": "Wood_Drywood_Planks"
    },
    {
      "x": -17,
      "y": 9,
      "z": 2,
      "name": "Wood_Drywood_Planks"
    },
    {
      "x": -17,
      "y": 10,
      "z": 2,
      "name": "Wood_Drywood_Planks"
    },
    {
      "x": -17,
      "y": 7,
      "z": 3,
      "name": "Wood_Drywood_Planks"
    },
    {
      "x": -17,
      "y": 8,
      "z": 3,
      "name": "Wood_Drywood_Planks"
    },
    {
      "x": -17,
      "y": 9,
      "z": 3,
      "name": "Wood_Drywood_Planks"
    },
    {
      "x": -17,
      "y": 10,
      "z": 3,
      "name": "Wood_Drywood_Planks"
    },
    {
      "x": -17,
      "y": 11,
      "z": 3,
      "name": "*Wood_Drywood_Fence_State_Definitions_Corner"
    },
    {
      "x": -17,
      "y": 8,
      "z": 4,
      "name": "Wood_Drywood_Planks"
    },
    {
      "x": -17,
      "y": 9,
      "z": 4,
      "name": "Wood_Drywood_Planks"
    },
    {
      "x": -17,
      "y": 10,
      "z": 4,
      "name": "Wood_Drywood_Decorative"
    },
    {
      "x": -17,
      "y": 11,
      "z": 4,
      "name": "*Wood_Drywood_Fence_State_Definitions_Corner",
      "rotation": 2
    },
    {
      "x": -16,
      "y": 8,
      "z": -4,
      "name": "Wood_Drywood_Planks"
    },
    {
      "x": -16,
      "y": 9,
      "z": -4,
      "name": "Wood_Drywood_Planks"
    },
    {
      "x": -16,
      "y": 10,
      "z": -4,
      "name": "Wood_Drywood_Decorative"
    },
    {
      "x": -16,
      "y": 11,
      "z": -4,
      "name": "Wood_Drywood_Fence",
      "rotation": 2
    },
    {
      "x": -16,
      "y": 7,
      "z": -3,
      "name": "Wood_Drywood_Planks"
    },
    {
      "x": -16,
      "y": 8,
      "z": -3,
      "name": "Wood_Drywood_Planks"
    },
    {
      "x": -16,
      "y": 9,
      "z": -3,
      "name": "Wood_Drywood_Planks"
    },
    {
      "x": -16,
      "y": 10,
      "z": -3,
      "name": "Wood_Drywood_Planks"
    },
    {
      "x": -16,
      "y": 5,
      "z": -2,
      "name": "Wood_Drywood_Planks"
    },
    {
      "x": -16,
      "y": 6,
      "z": -2,
      "name": "Wood_Drywood_Planks"
    },
    {
      "x": -16,
      "y": 7,
      "z": -2,
      "name": "Wood_Drywood_Planks"
    },
    {
      "x": -16,
      "y": 8,
      "z": -2,
      "name": "Wood_Drywood_Planks"
    },
    {
      "x": -16,
      "y": 9,
      "z": -2,
      "name": "Wood_Drywood_Planks"
    },
    {
      "x": -16,
      "y": 10,
      "z": -2,
      "name": "Wood_Drywood_Planks"
    },
    {
      "x": -16,
      "y": 3,
      "z": -1,
      "name": "Wood_Drywood_Planks"
    },
    {
      "x": -16,
      "y": 4,
      "z": -1,
      "name": "Wood_Drywood_Planks"
    },
    {
      "x": -16,
      "y": 5,
      "z": -1,
      "name": "Wood_Drywood_Planks"
    },
    {
      "x": -16,
      "y": 6,
      "z": -1,
      "name": "Wood_Drywood_Planks"
    },
    {
      "x": -16,
      "y": 7,
      "z": -1,
      "name": "Wood_Drywood_Planks_Half"
    },
    {
      "x": -16,
      "y": 9,
      "z": -1,
      "name": "Wood_Drywood_Planks"
    },
    {
      "x": -16,
      "y": 10,
      "z": -1,
      "name": "Wood_Drywood_Planks"
    },
    {
      "x": -16,
      "y": 2,
      "z": 0,
      "name": "Wood_Drywood_Planks"
    },
    {
      "x": -16,
      "y": 3,
      "z": 0,
      "name": "Wood_Drywood_Planks"
    },
    {
      "x": -16,
      "y": 4,
      "z": 0,
      "name": "Wood_Drywood_Planks"
    },
    {
      "x": -16,
      "y": 5,
      "z": 0,
      "name": "Wood_Drywood_Planks"
    },
    {
      "x": -16,
      "y": 6,
      "z": 0,
      "name": "Wood_Drywood_Planks"
    },
    {
      "x": -16,
      "y": 7,
      "z": 0,
      "name": "Wood_Drywood_Planks_Half"
    },
    {
      "x": -16,
      "y": 9,
      "z": 0,
      "name": "Wood_Drywood_Planks"
    },
    {
      "x": -16,
      "y": 10,
      "z": 0,
      "name": "Wood_Drywood_Planks"
    },
    {
      "x": -16,
      "y": 3,
      "z": 1,
      "name": "Wood_Drywood_Planks"
    },
    {
      "x": -16,
      "y": 4,
      "z": 1,
      "name": "Wood_Drywood_Planks"
    },
    {
      "x": -16,
      "y": 5,
      "z": 1,
      "name": "Wood_Drywood_Planks"
    },
    {
      "x": -16,
      "y": 6,
      "z": 1,
      "name": "Wood_Drywood_Planks"
    },
    {
      "x": -16,
      "y": 7,
      "z": 1,
      "name": "Wood_Drywood_Planks_Half"
    },
    {
      "x": -16,
      "y": 9,
      "z": 1,
      "name": "Wood_Drywood_Planks"
    },
    {
      "x": -16,
      "y": 10,
      "z": 1,
      "name": "Wood_Drywood_Planks"
    },
    {
      "x": -16,
      "y": 5,
      "z": 2,
      "name": "Wood_Drywood_Planks"
    },
    {
      "x": -16,
      "y": 6,
      "z": 2,
      "name": "Wood_Drywood_Planks"
    },
    {
      "x": -16,
      "y": 7,
      "z": 2,
      "name": "Wood_Drywood_Planks"
    },
    {
      "x": -16,
      "y": 8,
      "z": 2,
      "name": "Wood_Drywood_Planks"
    },
    {
      "x": -16,
      "y": 9,
      "z": 2,
      "name": "Wood_Drywood_Planks"
    },
    {
      "x": -16,
      "y": 10,
      "z": 2,
      "name": "Wood_Drywood_Planks"
    },
    {
      "x": -16,
      "y": 7,
      "z": 3,
      "name": "Wood_Drywood_Planks"
    },
    {
      "x": -16,
      "y": 8,
      "z": 3,
      "name": "Wood_Drywood_Planks"
    },
    {
      "x": -16,
      "y": 9,
      "z": 3,
      "name": "Wood_Drywood_Planks"
    },
    {
      "x": -16,
      "y": 10,
      "z": 3,
      "name": "Wood_Drywood_Planks"
    },
    {
      "x": -16,
      "y": 8,
      "z": 4,
      "name": "Wood_Drywood_Planks"
    },
    {
      "x": -16,
      "y": 9,
      "z": 4,
      "name": "Wood_Drywood_Planks"
    },
    {
      "x": -16,
      "y": 10,
      "z": 4,
      "name": "Wood_Drywood_Decorative"
    },
    {
      "x": -16,
      "y": 11,
      "z": 4,
      "name": "Wood_Drywood_Fence"
    },
    {
      "x": -15,
      "y": 8,
      "z": -5,
      "name": "Wood_Drywood_Planks"
    },
    {
      "x": -15,
      "y": 9,
      "z": -5,
      "name": "Wood_Drywood_Planks"
    },
    {
      "x": -15,
      "y": 10,
      "z": -5,
      "name": "Wood_Drywood_Decorative"
    },
    {
      "x": -15,
      "y": 11,
      "z": -5,
      "name": "*Wood_Drywood_Fence_State_Definitions_Corner",
      "rotation": 1
    },
    {
      "x": -15,
      "y": 7,
      "z": -4,
      "name": "Wood_Drywood_Planks"
    },
    {
      "x": -15,
      "y": 8,
      "z": -4,
      "name": "Wood_Drywood_Planks"
    },
    {
      "x": -15,
      "y": 9,
      "z": -4,
      "name": "Wood_Drywood_Planks"
    },
    {
      "x": -15,
      "y": 10,
      "z": -4,
      "name": "Wood_Drywood_Planks"
    },
    {
      "x": -15,
      "y": 11,
      "z": -4,
      "name": "*Wood_Drywood_Fence_State_Definitions_Corner",
      "rotation": 3
    },
    {
      "x": -15,
      "y": 6,
      "z": -3,
      "name": "Wood_Drywood_Planks"
    },
    {
      "x": -15,
      "y": 7,
      "z": -3,
      "name": "Wood_Drywood_Planks"
    },
    {
      "x": -15,
      "y": 8,
      "z": -3,
      "name": "Wood_Drywood_Planks"
    },
    {
      "x": -15,
      "y": 9,
      "z": -3,
      "name": "Wood_Drywood_Planks"
    },
    {
      "x": -15,
      "y": 10,
      "z": -3,
      "name": "Wood_Drywood_Planks"
    },
    {
      "x": -15,
      "y": 4,
      "z": -2,
      "name": "Wood_Drywood_Planks"
    },
    {
      "x": -15,
      "y": 5,
      "z": -2,
      "name": "Wood_Drywood_Planks"
    },
    {
      "x": -15,
      "y": 6,
      "z": -2,
      "name": "Wood_Drywood_Planks"
    },
    {
      "x": -15,
      "y": 7,
      "z": -2,
      "name": "Wood_Drywood_Stairs",
      "rotation": 11
    },
    {
      "x": -15,
      "y": 8,
      "z": -2,
      "name": "Cloth_Roof_Leather_Flat"
    },
    {
      "x": -15,
      "y": 9,
      "z": -2,
      "name": "Wood_Drywood_Planks"
    },
    {
      "x": -15,
      "y": 10,
      "z": -2,
      "name": "Wood_Drywood_Planks"
    },
    {
      "x": -15,
      "y": 3,
      "z": -1,
      "name": "Wood_Drywood_Planks"
    },
    {
      "x": -15,
      "y": 4,
      "z": -1,
      "name": "Wood_Drywood_Planks"
    },
    {
      "x": -15,
      "y": 5,
      "z": -1,
      "name": "Wood_Drywood_Planks"
    },
    {
      "x": -15,
      "y": 6,
      "z": -1,
      "name": "Wood_Drywood_Planks"
    },
    {
      "x": -15,
      "y": 7,
      "z": -1,
      "name": "Cloth_Roof_Leather_Flap"
    },
    {
      "x": -15,
      "y": 9,
      "z": -1,
      "name": "Wood_Drywood_Planks_Half",
      "rotation": 8
    },
    {
      "x": -15,
      "y": 10,
      "z": -1,
      "name": "Wood_Drywood_Planks"
    },
    {
      "x": -15,
      "y": 2,
      "z": 0,
      "name": "Wood_Drywood_Planks"
    },
    {
      "x": -15,
      "y": 3,
      "z": 0,
      "name": "Wood_Drywood_Planks"
    },
    {
      "x": -15,
      "y": 4,
      "z": 0,
      "name": "Wood_Drywood_Planks"
    },
    {
      "x": -15,
      "y": 5,
      "z": 0,
      "name": "Wood_Drywood_Planks"
    },
    {
      "x": -15,
      "y": 6,
      "z": 0,
      "name": "Wood_Drywood_Planks"
    },
    {
      "x": -15,
      "y": 7,
      "z": 0,
      "name": "Wood_Drywood_Stairs",
      "rotation": 11
    },
    {
      "x": -15,
      "y": 9,
      "z": 0,
      "name": "Wood_Drywood_Planks_Half",
      "rotation": 8
    },
    {
      "x": -15,
      "y": 10,
      "z": 0,
      "name": "Wood_Drywood_Planks"
    },
    {
      "x": -15,
      "y": 3,
      "z": 1,
      "name": "Wood_Drywood_Planks"
    },
    {
      "x": -15,
      "y": 4,
      "z": 1,
      "name": "Wood_Drywood_Planks"
    },
    {
      "x": -15,
      "y": 5,
      "z": 1,
      "name": "Wood_Drywood_Planks"
    },
    {
      "x": -15,
      "y": 6,
      "z": 1,
      "name": "Wood_Drywood_Planks"
    },
    {
      "x": -15,
      "y": 9,
      "z": 1,
      "name": "Wood_Drywood_Planks_Half",
      "rotation": 8
    },
    {
      "x": -15,
      "y": 10,
      "z": 1,
      "name": "Wood_Drywood_Planks"
    },
    {
      "x": -15,
      "y": 4,
      "z": 2,
      "name": "Wood_Drywood_Planks"
    },
    {
      "x": -15,
      "y": 5,
      "z": 2,
      "name": "Wood_Drywood_Planks"
    },
    {
      "x": -15,
      "y": 6,
      "z": 2,
      "name": "Wood_Drywood_Planks"
    },
    {
      "x": -15,
      "y": 7,
      "z": 2,
      "name": "Wood_Drywood_Stairs",
      "rotation": 11
    },
    {
      "x": -15,
      "y": 8,
      "z": 2,
      "name": "Plant_Moss_Rug_Red",
      "support": 15
    },
    {
      "x": -15,
      "y": 9,
      "z": 2,
      "name": "Wood_Drywood_Planks"
    },
    {
      "x": -15,
      "y": 10,
      "z": 2,
      "name": "Wood_Drywood_Planks"
    },
    {
      "x": -15,
      "y": 6,
      "z": 3,
      "name": "Wood_Drywood_Planks"
    },
    {
      "x": -15,
      "y": 7,
      "z": 3,
      "name": "Wood_Drywood_Planks"
    },
    {
      "x": -15,
      "y": 8,
      "z": 3,
      "name": "Wood_Drywood_Planks"
    },
    {
      "x": -15,
      "y": 9,
      "z": 3,
      "name": "Wood_Drywood_Planks"
    },
    {
      "x": -15,
      "y": 10,
      "z": 3,
      "name": "Wood_Drywood_Planks"
    },
    {
      "x": -15,
      "y": 7,
      "z": 4,
      "name": "Wood_Drywood_Planks"
    },
    {
      "x": -15,
      "y": 8,
      "z": 4,
      "name": "Wood_Drywood_Planks"
    },
    {
      "x": -15,
      "y": 9,
      "z": 4,
      "name": "Wood_Drywood_Planks"
    },
    {
      "x": -15,
      "y": 10,
      "z": 4,
      "name": "Wood_Drywood_Planks"
    },
    {
      "x": -15,
      "y": 11,
      "z": 4,
      "name": "*Wood_Drywood_Fence_State_Definitions_Corner"
    },
    {
      "x": -15,
      "y": 8,
      "z": 5,
      "name": "Wood_Drywood_Planks"
    },
    {
      "x": -15,
      "y": 9,
      "z": 5,
      "name": "Wood_Drywood_Planks"
    },
    {
      "x": -15,
      "y": 10,
      "z": 5,
      "name": "Wood_Drywood_Decorative"
    },
    {
      "x": -15,
      "y": 11,
      "z": 5,
      "name": "*Wood_Drywood_Fence_State_Definitions_Corner",
      "rotation": 2
    },
    {
      "x": -14,
      "y": 8,
      "z": -5,
      "name": "Wood_Drywood_Planks"
    },
    {
      "x": -14,
      "y": 9,
      "z": -5,
      "name": "Wood_Drywood_Planks"
    },
    {
      "x": -14,
      "y": 10,
      "z": -5,
      "name": "Wood_Drywood_Decorative"
    },
    {
      "x": -14,
      "y": 11,
      "z": -5,
      "name": "Wood_Drywood_Fence",
      "rotation": 2
    },
    {
      "x": -14,
      "y": 7,
      "z": -4,
      "name": "Wood_Drywood_Planks"
    },
    {
      "x": -14,
      "y": 8,
      "z": -4,
      "name": "Wood_Drywood_Planks"
    },
    {
      "x": -14,
      "y": 9,
      "z": -4,
      "name": "Wood_Drywood_Planks"
    },
    {
      "x": -14,
      "y": 10,
      "z": -4,
      "name": "Wood_Drywood_Planks"
    },
    {
      "x": -14,
      "y": 5,
      "z": -3,
      "name": "Wood_Drywood_Planks"
    },
    {
      "x": -14,
      "y": 6,
      "z": -3,
      "name": "Wood_Drywood_Planks"
    },
    {
      "x": -14,
      "y": 7,
      "z": -3,
      "name": "Wood_Drywood_Planks"
    },
    {
      "x": -14,
      "y": 8,
      "z": -3,
      "name": "Wood_Drywood_Planks"
    },
    {
      "x": -14,
      "y": 9,
      "z": -3,
      "name": "Wood_Drywood_Planks"
    },
    {
      "x": -14,
      "y": 10,
      "z": -3,
      "name": "Wood_Drywood_Planks"
    },
    {
      "x": -14,
      "y": 4,
      "z": -2,
      "name": "Wood_Drywood_Planks"
    },
    {
      "x": -14,
      "y": 5,
      "z": -2,
      "name": "Wood_Drywood_Planks"
    },
    {
      "x": -14,
      "y": 6,
      "z": -2,
      "name": "Wood_Drywood_Planks"
    },
    {
      "x": -14,
      "y": 7,
      "z": -2,
      "name": "Wood_Drywood_Stairs",
      "rotation": 9
    },
    {
      "x": -14,
      "y": 9,
      "z": -2,
      "name": "Wood_Drywood_Planks_Half",
      "rotation": 8
    },
    {
      "x": -14,
      "y": 10,
      "z": -2,
      "name": "Wood_Drywood_Planks"
    },
    {
      "x": -14,
      "y": 3,
      "z": -1,
      "name": "Wood_Drywood_Planks"
    },
    {
      "x": -14,
      "y": 4,
      "z": -1,
      "name": "Wood_Drywood_Planks"
    },
    {
      "x": -14,
      "y": 5,
      "z": -1,
      "name": "Wood_Drywood_Planks"
    },
    {
      "x": -14,
      "y": 6,
      "z": -1,
      "name": "Wood_Drywood_Planks"
    },
    {
      "x": -14,
      "y": 9,
      "z": -1,
      "name": "Wood_Drywood_Planks_Half",
      "rotation": 8
    },
    {
      "x": -14,
      "y": 10,
      "z": -1,
      "name": "Wood_Drywood_Planks"
    },
    {
      "x": -14,
      "y": 2,
      "z": 0,
      "name": "Wood_Drywood_Planks"
    },
    {
      "x": -14,
      "y": 3,
      "z": 0,
      "name": "Wood_Drywood_Planks"
    },
    {
      "x": -14,
      "y": 4,
      "z": 0,
      "name": "Wood_Drywood_Planks"
    },
    {
      "x": -14,
      "y": 5,
      "z": 0,
      "name": "Wood_Drywood_Planks"
    },
    {
      "x": -14,
      "y": 6,
      "z": 0,
      "name": "Wood_Drywood_Planks"
    },
    {
      "x": -14,
      "y": 7,
      "z": 0,
      "name": "Wood_Drywood_Stairs",
      "rotation": 9
    },
    {
      "x": -14,
      "y": 8,
      "z": 0,
      "name": "Plant_Moss_Rug_Red",
      "support": 15
    },
    {
      "x": -14,
      "y": 9,
      "z": 0,
      "name": "Wood_Drywood_Planks_Half",
      "rotation": 8
    },
    {
      "x": -14,
      "y": 10,
      "z": 0,
      "name": "Wood_Drywood_Planks"
    },
    {
      "x": -14,
      "y": 3,
      "z": 1,
      "name": "Wood_Drywood_Planks"
    },
    {
      "x": -14,
      "y": 4,
      "z": 1,
      "name": "Wood_Drywood_Planks"
    },
    {
      "x": -14,
      "y": 5,
      "z": 1,
      "name": "Wood_Drywood_Planks"
    },
    {
      "x": -14,
      "y": 6,
      "z": 1,
      "name": "Wood_Drywood_Planks"
    },
    {
      "x": -14,
      "y": 7,
      "z": 1,
      "name": "Cloth_Roof_Leather_Flap",
      "rotation": 2
    },
    {
      "x": -14,
      "y": 9,
      "z": 1,
      "name": "Wood_Drywood_Planks_Half",
      "rotation": 8
    },
    {
      "x": -14,
      "y": 10,
      "z": 1,
      "name": "Wood_Drywood_Planks"
    },
    {
      "x": -14,
      "y": 4,
      "z": 2,
      "name": "Wood_Drywood_Planks"
    },
    {
      "x": -14,
      "y": 5,
      "z": 2,
      "name": "Wood_Drywood_Planks"
    },
    {
      "x": -14,
      "y": 6,
      "z": 2,
      "name": "Wood_Drywood_Planks"
    },
    {
      "x": -14,
      "y": 7,
      "z": 2,
      "name": "Wood_Drywood_Stairs",
      "rotation": 9
    },
    {
      "x": -14,
      "y": 8,
      "z": 2,
      "name": "Cloth_Roof_Leather_Flat"
    },
    {
      "x": -14,
      "y": 9,
      "z": 2,
      "name": "Wood_Drywood_Planks_Half",
      "rotation": 8
    },
    {
      "x": -14,
      "y": 10,
      "z": 2,
      "name": "Wood_Drywood_Planks"
    },
    {
      "x": -14,
      "y": 5,
      "z": 3,
      "name": "Wood_Drywood_Planks"
    },
    {
      "x": -14,
      "y": 6,
      "z": 3,
      "name": "Wood_Drywood_Planks"
    },
    {
      "x": -14,
      "y": 7,
      "z": 3,
      "name": "Wood_Drywood_Planks"
    },
    {
      "x": -14,
      "y": 8,
      "z": 3,
      "name": "Wood_Drywood_Planks"
    },
    {
      "x": -14,
      "y": 9,
      "z": 3,
      "name": "Wood_Drywood_Planks"
    },
    {
      "x": -14,
      "y": 10,
      "z": 3,
      "name": "Wood_Drywood_Planks"
    },
    {
      "x": -14,
      "y": 7,
      "z": 4,
      "name": "Wood_Drywood_Planks"
    },
    {
      "x": -14,
      "y": 8,
      "z": 4,
      "name": "Wood_Drywood_Planks"
    },
    {
      "x": -14,
      "y": 9,
      "z": 4,
      "name": "Wood_Drywood_Planks"
    },
    {
      "x": -14,
      "y": 10,
      "z": 4,
      "name": "Wood_Drywood_Planks"
    },
    {
      "x": -14,
      "y": 8,
      "z": 5,
      "name": "Wood_Drywood_Planks"
    },
    {
      "x": -14,
      "y": 9,
      "z": 5,
      "name": "Wood_Drywood_Planks"
    },
    {
      "x": -14,
      "y": 10,
      "z": 5,
      "name": "Wood_Drywood_Decorative"
    },
    {
      "x": -14,
      "y": 11,
      "z": 5,
      "name": "Wood_Drywood_Fence"
    },
    {
      "x": -13,
      "y": 8,
      "z": -6,
      "name": "Wood_Drywood_Planks"
    },
    {
      "x": -13,
      "y": 9,
      "z": -6,
      "name": "Wood_Drywood_Planks"
    },
    {
      "x": -13,
      "y": 10,
      "z": -6,
      "name": "Wood_Drywood_Decorative"
    },
    {
      "x": -13,
      "y": 11,
      "z": -6,
      "name": "*Wood_Drywood_Fence_State_Definitions_Corner",
      "rotation": 1
    },
    {
      "x": -13,
      "y": 7,
      "z": -5,
      "name": "Wood_Drywood_Planks"
    },
    {
      "x": -13,
      "y": 8,
      "z": -5,
      "name": "Wood_Drywood_Planks"
    },
    {
      "x": -13,
      "y": 9,
      "z": -5,
      "name": "Wood_Drywood_Planks"
    },
    {
      "x": -13,
      "y": 10,
      "z": -5,
      "name": "Wood_Drywood_Planks"
    },
    {
      "x": -13,
      "y": 11,
      "z": -5,
      "name": "*Wood_Drywood_Fence_State_Definitions_Corner",
      "rotation": 3
    },
    {
      "x": -13,
      "y": 6,
      "z": -4,
      "name": "Wood_Drywood_Planks"
    },
    {
      "x": -13,
      "y": 7,
      "z": -4,
      "name": "Wood_Drywood_Planks"
    },
    {
      "x": -13,
      "y": 8,
      "z": -4,
      "name": "Wood_Drywood_Planks"
    },
    {
      "x": -13,
      "y": 9,
      "z": -4,
      "name": "Wood_Drywood_Planks"
    },
    {
      "x": -13,
      "y": 10,
      "z": -4,
      "name": "Wood_Drywood_Planks"
    },
    {
      "x": -13,
      "y": 4,
      "z": -3,
      "name": "Wood_Drywood_Planks"
    },
    {
      "x": -13,
      "y": 5,
      "z": -3,
      "name": "Wood_Drywood_Planks"
    },
    {
      "x": -13,
      "y": 6,
      "z": -3,
      "name": "Wood_Drywood_Planks"
    },
    {
      "x": -13,
      "y": 7,
      "z": -3,
      "name": "Wood_Drywood_Stairs",
      "rotation": 1
    },
    {
      "x": -13,
      "y": 9,
      "z": -3,
      "name": "Wood_Drywood_Planks_Half",
      "rotation": 8
    },
    {
      "x": -13,
      "y": 10,
      "z": -3,
      "name": "Wood_Drywood_Planks"
    },
    {
      "x": -13,
      "y": 3,
      "z": -2,
      "name": "Wood_Drywood_Planks"
    },
    {
      "x": -13,
      "y": 4,
      "z": -2,
      "name": "Wood_Drywood_Planks"
    },
    {
      "x": -13,
      "y": 5,
      "z": -2,
      "name": "Wood_Drywood_Planks"
    },
    {
      "x": -13,
      "y": 6,
      "z": -2,
      "name": "Wood_Drywood_Planks"
    },
    {
      "x": -13,
      "y": 9,
      "z": -2,
      "name": "Wood_Drywood_Planks_Half",
      "rotation": 8
    },
    {
      "x": -13,
      "y": 10,
      "z": -2,
      "name": "Wood_Drywood_Planks"
    },
    {
      "x": -13,
      "y": 2,
      "z": -1,
      "name": "Wood_Drywood_Planks"
    },
    {
      "x": -13,
      "y": 3,
      "z": -1,
      "name": "Wood_Drywood_Planks"
    },
    {
      "x": -13,
      "y": 4,
      "z": -1,
      "name": "Wood_Drywood_Planks"
    },
    {
      "x": -13,
      "y": 5,
      "z": -1,
      "name": "Wood_Drywood_Planks"
    },
    {
      "x": -13,
      "y": 6,
      "z": -1,
      "name": "Wood_Drywood_Planks"
    },
    {
      "x": -13,
      "y": 7,
      "z": -1,
      "name": "Deco_Bone_Pile"
    },
    {
      "x": -13,
      "y": 9,
      "z": -1,
      "name": "Wood_Drywood_Planks_Half",
      "rotation": 8
    },
    {
      "x": -13,
      "y": 10,
      "z": -1,
      "name": "Wood_Drywood_Planks"
    },
    {
      "x": -13,
      "y": 2,
      "z": 0,
      "name": "Wood_Drywood_Planks"
    },
    {
      "x": -13,
      "y": 3,
      "z": 0,
      "name": "Wood_Drywood_Planks"
    },
    {
      "x": -13,
      "y": 4,
      "z": 0,
      "name": "Wood_Drywood_Planks"
    },
    {
      "x": -13,
      "y": 5,
      "z": 0,
      "name": "Wood_Drywood_Planks"
    },
    {
      "x": -13,
      "y": 6,
      "z": 0,
      "name": "Wood_Drywood_Planks"
    },
    {
      "x": -13,
      "y": 9,
      "z": 0,
      "name": "Wood_Drywood_Planks_Half",
      "rotation": 8
    },
    {
      "x": -13,
      "y": 10,
      "z": 0,
      "name": "Wood_Drywood_Planks"
    },
    {
      "x": -13,
      "y": 2,
      "z": 1,
      "name": "Wood_Drywood_Planks"
    },
    {
      "x": -13,
      "y": 3,
      "z": 1,
      "name": "Wood_Drywood_Planks"
    },
    {
      "x": -13,
      "y": 4,
      "z": 1,
      "name": "Wood_Drywood_Planks"
    },
    {
      "x": -13,
      "y": 5,
      "z": 1,
      "name": "Wood_Drywood_Planks"
    },
    {
      "x": -13,
      "y": 6,
      "z": 1,
      "name": "Wood_Drywood_Planks"
    },
    {
      "x": -13,
      "y": 9,
      "z": 1,
      "name": "Wood_Drywood_Planks_Half",
      "rotation": 8
    },
    {
      "x": -13,
      "y": 10,
      "z": 1,
      "name": "Wood_Drywood_Planks"
    },
    {
      "x": -13,
      "y": 3,
      "z": 2,
      "name": "Wood_Drywood_Planks"
    },
    {
      "x": -13,
      "y": 4,
      "z": 2,
      "name": "Wood_Drywood_Planks"
    },
    {
      "x": -13,
      "y": 5,
      "z": 2,
      "name": "Wood_Drywood_Planks"
    },
    {
      "x": -13,
      "y": 6,
      "z": 2,
      "name": "Wood_Drywood_Planks"
    },
    {
      "x": -13,
      "y": 7,
      "z": 2,
      "name": "Cloth_Roof_Leather_Flap",
      "rotation": 1
    },
    {
      "x": -13,
      "y": 9,
      "z": 2,
      "name": "Wood_Drywood_Planks_Half",
      "rotation": 8
    },
    {
      "x": -13,
      "y": 10,
      "z": 2,
      "name": "Wood_Drywood_Planks"
    },
    {
      "x": -13,
      "y": 4,
      "z": 3,
      "name": "Wood_Drywood_Planks"
    },
    {
      "x": -13,
      "y": 5,
      "z": 3,
      "name": "Wood_Drywood_Planks"
    },
    {
      "x": -13,
      "y": 6,
      "z": 3,
      "name": "Wood_Drywood_Planks"
    },
    {
      "x": -13,
      "y": 7,
      "z": 3,
      "name": "Wood_Drywood_Stairs",
      "rotation": 1
    },
    {
      "x": -13,
      "y": 9,
      "z": 3,
      "name": "Wood_Drywood_Planks_Half",
      "rotation": 8
    },
    {
      "x": -13,
      "y": 10,
      "z": 3,
      "name": "Wood_Drywood_Planks"
    },
    {
      "x": -13,
      "y": 6,
      "z": 4,
      "name": "Wood_Drywood_Planks"
    },
    {
      "x": -13,
      "y": 7,
      "z": 4,
      "name": "Wood_Drywood_Planks"
    },
    {
      "x": -13,
      "y": 8,
      "z": 4,
      "name": "Wood_Drywood_Planks"
    },
    {
      "x": -13,
      "y": 9,
      "z": 4,
      "name": "Wood_Drywood_Planks"
    },
    {
      "x": -13,
      "y": 10,
      "z": 4,
      "name": "Wood_Drywood_Planks"
    },
    {
      "x": -13,
      "y": 7,
      "z": 5,
      "name": "Wood_Drywood_Planks"
    },
    {
      "x": -13,
      "y": 8,
      "z": 5,
      "name": "Wood_Drywood_Planks"
    },
    {
      "x": -13,
      "y": 9,
      "z": 5,
      "name": "Wood_Drywood_Planks"
    },
    {
      "x": -13,
      "y": 10,
      "z": 5,
      "name": "Wood_Drywood_Planks"
    },
    {
      "x": -13,
      "y": 11,
      "z": 5,
      "name": "*Wood_Drywood_Fence_State_Definitions_Corner"
    },
    {
      "x": -13,
      "y": 8,
      "z": 6,
      "name": "Wood_Drywood_Planks"
    },
    {
      "x": -13,
      "y": 9,
      "z": 6,
      "name": "Wood_Drywood_Planks"
    },
    {
      "x": -13,
      "y": 10,
      "z": 6,
      "name": "Wood_Drywood_Decorative"
    },
    {
      "x": -13,
      "y": 11,
      "z": 6,
      "name": "*Wood_Drywood_Fence_State_Definitions_Corner",
      "rotation": 2
    },
    {
      "x": -12,
      "y": 8,
      "z": -6,
      "name": "Wood_Drywood_Planks"
    },
    {
      "x": -12,
      "y": 9,
      "z": -6,
      "name": "Wood_Drywood_Planks"
    },
    {
      "x": -12,
      "y": 10,
      "z": -6,
      "name": "Wood_Drywood_Decorative"
    },
    {
      "x": -12,
      "y": 11,
      "z": -6,
      "name": "Wood_Drywood_Fence",
      "rotation": 2
    },
    {
      "x": -12,
      "y": 7,
      "z": -5,
      "name": "Wood_Drywood_Planks"
    },
    {
      "x": -12,
      "y": 8,
      "z": -5,
      "name": "Wood_Drywood_Planks"
    },
    {
      "x": -12,
      "y": 9,
      "z": -5,
      "name": "Wood_Drywood_Planks"
    },
    {
      "x": -12,
      "y": 10,
      "z": -5,
      "name": "Wood_Drywood_Planks"
    },
    {
      "x": -12,
      "y": 5,
      "z": -4,
      "name": "Wood_Drywood_Planks"
    },
    {
      "x": -12,
      "y": 6,
      "z": -4,
      "name": "Wood_Drywood_Planks"
    },
    {
      "x": -12,
      "y": 7,
      "z": -4,
      "name": "Wood_Drywood_Planks"
    },
    {
      "x": -12,
      "y": 8,
      "z": -4,
      "name": "Wood_Drywood_Planks"
    },
    {
      "x": -12,
      "y": 9,
      "z": -4,
      "name": "Wood_Drywood_Planks"
    },
    {
      "x": -12,
      "y": 10,
      "z": -4,
      "name": "Wood_Drywood_Planks"
    },
    {
      "x": -12,
      "y": 4,
      "z": -3,
      "name": "Wood_Drywood_Planks"
    },
    {
      "x": -12,
      "y": 5,
      "z": -3,
      "name": "Wood_Drywood_Planks"
    },
    {
      "x": -12,
      "y": 6,
      "z": -3,
      "name": "Wood_Drywood_Planks"
    },
    {
      "x": -12,
      "y": 9,
      "z": -3,
      "name": "Wood_Drywood_Planks_Half",
      "rotation": 8
    },
    {
      "x": -12,
      "y": 10,
      "z": -3,
      "name": "Wood_Drywood_Planks"
    },
    {
      "x": -12,
      "y": 3,
      "z": -2,
      "name": "Wood_Drywood_Planks"
    },
    {
      "x": -12,
      "y": 4,
      "z": -2,
      "name": "Wood_Drywood_Planks"
    },
    {
      "x": -12,
      "y": 5,
      "z": -2,
      "name": "Wood_Drywood_Planks"
    },
    {
      "x": -12,
      "y": 6,
      "z": -2,
      "name": "Wood_Drywood_Planks"
    },
    {
      "x": -12,
      "y": 7,
      "z": -2,
      "name": "Wood_Drywood_Stairs",
      "rotation": 11
    },
    {
      "x": -12,
      "y": 9,
      "z": -2,
      "name": "Wood_Drywood_Planks_Half",
      "rotation": 8
    },
    {
      "x": -12,
      "y": 10,
      "z": -2,
      "name": "Wood_Drywood_Planks"
    },
    {
      "x": -12,
      "y": 2,
      "z": -1,
      "name": "Wood_Drywood_Planks"
    },
    {
      "x": -12,
      "y": 3,
      "z": -1,
      "name": "Wood_Drywood_Planks"
    },
    {
      "x": -12,
      "y": 4,
      "z": -1,
      "name": "Wood_Drywood_Stairs",
      "rotation": 1
    },
    {
      "x": -12,
      "y": 5,
      "z": -1,
      "name": "Wood_Drywood_Stairs",
      "rotation": 11
    },
    {
      "x": -12,
      "y": 6,
      "z": -1,
      "name": "Wood_Drywood_Planks"
    },
    {
      "x": -12,
      "y": 9,
      "z": -1,
      "name": "Wood_Drywood_Planks_Half",
      "rotation": 8
    },
    {
      "x": -12,
      "y": 10,
      "z": -1,
      "name": "Wood_Drywood_Planks"
    },
    {
      "x": -12,
      "y": 2,
      "z": 0,
      "name": "Wood_Drywood_Planks"
    },
    {
      "x": -12,
      "y": 3,
      "z": 0,
      "name": "Wood_Drywood_Planks"
    },
    {
      "x": -12,
      "y": 4,
      "z": 0,
      "name": "Wood_Drywood_Planks_Half",
      "rotation": 5
    },
    {
      "x": -12,
      "y": 5,
      "z": 0,
      "name": "Wood_Drywood_Planks_Half",
      "rotation": 5
    },
    {
      "x": -12,
      "y": 6,
      "z": 0,
      "name": "Wood_Drywood_Planks"
    },
    {
      "x": -12,
      "y": 7,
      "z": 0,
      "name": "Wood_Drywood_Stairs",
      "rotation": 11
    },
    {
      "x": -12,
      "y": 9,
      "z": 0,
      "name": "Wood_Drywood_Planks_Half",
      "rotation": 8
    },
    {
      "x": -12,
      "y": 10,
      "z": 0,
      "name": "Wood_Drywood_Planks"
    },
    {
      "x": -12,
      "y": 2,
      "z": 1,
      "name": "Wood_Drywood_Planks"
    },
    {
      "x": -12,
      "y": 3,
      "z": 1,
      "name": "Wood_Drywood_Planks"
    },
    {
      "x": -12,
      "y": 4,
      "z": 1,
      "name": "Wood_Drywood_Stairs",
      "rotation": 1
    },
    {
      "x": -12,
      "y": 5,
      "z": 1,
      "name": "Wood_Drywood_Stairs",
      "rotation": 11
    },
    {
      "x": -12,
      "y": 6,
      "z": 1,
      "name": "Wood_Drywood_Planks"
    },
    {
      "x": -12,
      "y": 9,
      "z": 1,
      "name": "Wood_Drywood_Planks_Half",
      "rotation": 8
    },
    {
      "x": -12,
      "y": 10,
      "z": 1,
      "name": "Wood_Drywood_Planks"
    },
    {
      "x": -12,
      "y": 3,
      "z": 2,
      "name": "Wood_Drywood_Planks"
    },
    {
      "x": -12,
      "y": 4,
      "z": 2,
      "name": "Wood_Drywood_Planks"
    },
    {
      "x": -12,
      "y": 5,
      "z": 2,
      "name": "Wood_Drywood_Planks"
    },
    {
      "x": -12,
      "y": 6,
      "z": 2,
      "name": "Wood_Drywood_Planks"
    },
    {
      "x": -12,
      "y": 7,
      "z": 2,
      "name": "Wood_Drywood_Stairs",
      "rotation": 11
    },
    {
      "x": -12,
      "y": 9,
      "z": 2,
      "name": "Wood_Drywood_Planks_Half",
      "rotation": 8
    },
    {
      "x": -12,
      "y": 10,
      "z": 2,
      "name": "Wood_Drywood_Planks"
    },
    {
      "x": -12,
      "y": 4,
      "z": 3,
      "name": "Wood_Drywood_Planks"
    },
    {
      "x": -12,
      "y": 5,
      "z": 3,
      "name": "Wood_Drywood_Planks"
    },
    {
      "x": -12,
      "y": 6,
      "z": 3,
      "name": "Wood_Drywood_Planks"
    },
    {
      "x": -12,
      "y": 9,
      "z": 3,
      "name": "Wood_Drywood_Planks_Half",
      "rotation": 8
    },
    {
      "x": -12,
      "y": 10,
      "z": 3,
      "name": "Wood_Drywood_Planks"
    },
    {
      "x": -12,
      "y": 5,
      "z": 4,
      "name": "Wood_Drywood_Planks"
    },
    {
      "x": -12,
      "y": 6,
      "z": 4,
      "name": "Wood_Drywood_Planks"
    },
    {
      "x": -12,
      "y": 7,
      "z": 4,
      "name": "Wood_Drywood_Planks"
    },
    {
      "x": -12,
      "y": 8,
      "z": 4,
      "name": "Wood_Drywood_Planks"
    },
    {
      "x": -12,
      "y": 9,
      "z": 4,
      "name": "Wood_Drywood_Planks"
    },
    {
      "x": -12,
      "y": 10,
      "z": 4,
      "name": "Wood_Drywood_Planks"
    },
    {
      "x": -12,
      "y": 7,
      "z": 5,
      "name": "Wood_Drywood_Planks"
    },
    {
      "x": -12,
      "y": 8,
      "z": 5,
      "name": "Wood_Drywood_Planks"
    },
    {
      "x": -12,
      "y": 9,
      "z": 5,
      "name": "Wood_Drywood_Planks"
    },
    {
      "x": -12,
      "y": 10,
      "z": 5,
      "name": "Wood_Drywood_Planks"
    },
    {
      "x": -12,
      "y": 8,
      "z": 6,
      "name": "Wood_Drywood_Planks"
    },
    {
      "x": -12,
      "y": 9,
      "z": 6,
      "name": "Wood_Drywood_Planks"
    },
    {
      "x": -12,
      "y": 10,
      "z": 6,
      "name": "Wood_Drywood_Decorative"
    },
    {
      "x": -12,
      "y": 11,
      "z": 6,
      "name": "Wood_Drywood_Fence"
    },
    {
      "x": -11,
      "y": 8,
      "z": -6,
      "name": "Wood_Drywood_Planks"
    },
    {
      "x": -11,
      "y": 9,
      "z": -6,
      "name": "Wood_Drywood_Planks"
    },
    {
      "x": -11,
      "y": 10,
      "z": -6,
      "name": "Wood_Drywood_Decorative"
    },
    {
      "x": -11,
      "y": 11,
      "z": -6,
      "name": "Wood_Drywood_Fence",
      "rotation": 2
    },
    {
      "x": -11,
      "y": 7,
      "z": -5,
      "name": "Wood_Drywood_Planks"
    },
    {
      "x": -11,
      "y": 8,
      "z": -5,
      "name": "Wood_Drywood_Planks"
    },
    {
      "x": -11,
      "y": 9,
      "z": -5,
      "name": "Wood_Drywood_Planks"
    },
    {
      "x": -11,
      "y": 10,
      "z": -5,
      "name": "Wood_Drywood_Planks"
    },
    {
      "x": -11,
      "y": 4,
      "z": -4,
      "name": "Wood_Drywood_Planks"
    },
    {
      "x": -11,
      "y": 5,
      "z": -4,
      "name": "Wood_Drywood_Planks"
    },
    {
      "x": -11,
      "y": 6,
      "z": -4,
      "name": "Wood_Drywood_Planks"
    },
    {
      "x": -11,
      "y": 7,
      "z": -4,
      "name": "Wood_Drywood_Planks"
    },
    {
      "x": -11,
      "y": 9,
      "z": -4,
      "name": "Wood_Drywood_Planks_Half",
      "rotation": 8
    },
    {
      "x": -11,
      "y": 10,
      "z": -4,
      "name": "Wood_Drywood_Planks"
    },
    {
      "x": -11,
      "y": 3,
      "z": -3,
      "name": "Wood_Drywood_Planks"
    },
    {
      "x": -11,
      "y": 4,
      "z": -3,
      "name": "Wood_Drywood_Planks"
    },
    {
      "x": -11,
      "y": 5,
      "z": -3,
      "name": "Wood_Drywood_Planks"
    },
    {
      "x": -11,
      "y": 6,
      "z": -3,
      "name": "Wood_Drywood_Planks"
    },
    {
      "x": -11,
      "y": 9,
      "z": -3,
      "name": "Wood_Drywood_Planks_Half",
      "rotation": 8
    },
    {
      "x": -11,
      "y": 10,
      "z": -3,
      "name": "Wood_Drywood_Planks"
    },
    {
      "x": -11,
      "y": 2,
      "z": -2,
      "name": "Wood_Drywood_Planks"
    },
    {
      "x": -11,
      "y": 3,
      "z": -2,
      "name": "Wood_Drywood_Planks"
    },
    {
      "x": -11,
      "y": 4,
      "z": -2,
      "name": "Wood_Drywood_Stairs"
    },
    {
      "x": -11,
      "y": 5,
      "z": -2,
      "name": "Wood_Drywood_Stairs",
      "rotation": 10
    },
    {
      "x": -11,
      "y": 6,
      "z": -2,
      "name": "Wood_Drywood_Planks"
    },
    {
      "x": -11,
      "y": 7,
      "z": -2,
      "name": "Wood_Drywood_Stairs",
      "rotation": 9
    },
    {
      "x": -11,
      "y": 8,
      "z": -2,
      "name": "Cloth_Roof_Leather_Flat"
    },
    {
      "x": -11,
      "y": 9,
      "z": -2,
      "name": "Wood_Drywood_Planks_Half",
      "rotation": 8
    },
    {
      "x": -11,
      "y": 10,
      "z": -2,
      "name": "Wood_Drywood_Planks"
    },
    {
      "x": -11,
      "y": 2,
      "z": -1,
      "name": "Wood_Drywood_Planks"
    },
    {
      "x": -11,
      "y": 3,
      "z": -1,
      "name": "Wood_Drywood_Planks"
    },
    {
      "x": -11,
      "y": 4,
      "z": -1,
      "name": "Deco_Trash_Pile_Small"
    },
    {
      "x": -11,
      "y": 6,
      "z": -1,
      "name": "Wood_Drywood_Planks"
    },
    {
      "x": -11,
      "y": 7,
      "z": -1,
      "name": "Cloth_Roof_Leather_Flap"
    },
    {
      "x": -11,
      "y": 9,
      "z": -1,
      "name": "Wood_Drywood_Planks_Half",
      "rotation": 8
    },
    {
      "x": -11,
      "y": 10,
      "z": -1,
      "name": "Wood_Drywood_Planks"
    },
    {
      "x": -11,
      "y": 2,
      "z": 0,
      "name": "Wood_Drywood_Planks"
    },
    {
      "x": -11,
      "y": 3,
      "z": 0,
      "name": "Wood_Drywood_Planks"
    },
    {
      "x": -11,
      "y": 6,
      "z": 0,
      "name": "Wood_Drywood_Planks"
    },
    {
      "x": -11,
      "y": 7,
      "z": 0,
      "name": "Wood_Drywood_Stairs",
      "rotation": 9
    },
    {
      "x": -11,
      "y": 8,
      "z": 0,
      "name": "Cloth_Roof_Leather_Flat"
    },
    {
      "x": -11,
      "y": 9,
      "z": 0,
      "name": "Wood_Drywood_Planks_Half",
      "rotation": 8
    },
    {
      "x": -11,
      "y": 10,
      "z": 0,
      "name": "Wood_Drywood_Planks"
    },
    {
      "x": -11,
      "y": 2,
      "z": 1,
      "name": "Wood_Drywood_Planks"
    },
    {
      "x": -11,
      "y": 3,
      "z": 1,
      "name": "Wood_Drywood_Planks"
    },
    {
      "x": -11,
      "y": 6,
      "z": 1,
      "name": "Wood_Drywood_Planks"
    },
    {
      "x": -11,
      "y": 9,
      "z": 1,
      "name": "Wood_Drywood_Planks_Half",
      "rotation": 8
    },
    {
      "x": -11,
      "y": 10,
      "z": 1,
      "name": "Wood_Drywood_Planks"
    },
    {
      "x": -11,
      "y": 2,
      "z": 2,
      "name": "Wood_Drywood_Planks"
    },
    {
      "x": -11,
      "y": 3,
      "z": 2,
      "name": "Wood_Drywood_Planks"
    },
    {
      "x": -11,
      "y": 4,
      "z": 2,
      "name": "Wood_Drywood_Stairs",
      "rotation": 2
    },
    {
      "x": -11,
      "y": 5,
      "z": 2,
      "name": "Wood_Drywood_Stairs",
      "rotation": 8
    },
    {
      "x": -11,
      "y": 6,
      "z": 2,
      "name": "Wood_Drywood_Planks"
    },
    {
      "x": -11,
      "y": 7,
      "z": 2,
      "name": "Wood_Drywood_Stairs",
      "rotation": 9
    },
    {
      "x": -11,
      "y": 8,
      "z": 2,
      "name": "Plant_Moss_Rug_Red",
      "support": 15
    },
    {
      "x": -11,
      "y": 9,
      "z": 2,
      "name": "Wood_Drywood_Planks_Half",
      "rotation": 8
    },
    {
      "x": -11,
      "y": 10,
      "z": 2,
      "name": "Wood_Drywood_Planks"
    },
    {
      "x": -11,
      "y": 3,
      "z": 3,
      "name": "Wood_Drywood_Planks"
    },
    {
      "x": -11,
      "y": 4,
      "z": 3,
      "name": "Wood_Drywood_Planks"
    },
    {
      "x": -11,
      "y": 5,
      "z": 3,
      "name": "Wood_Drywood_Planks"
    },
    {
      "x": -11,
      "y": 6,
      "z": 3,
      "name": "Wood_Drywood_Planks"
    },
    {
      "x": -11,
      "y": 9,
      "z": 3,
      "name": "Wood_Drywood_Planks_Half",
      "rotation": 8
    },
    {
      "x": -11,
      "y": 10,
      "z": 3,
      "name": "Wood_Drywood_Planks"
    },
    {
      "x": -11,
      "y": 4,
      "z": 4,
      "name": "Wood_Drywood_Planks"
    },
    {
      "x": -11,
      "y": 5,
      "z": 4,
      "name": "Wood_Drywood_Planks"
    },
    {
      "x": -11,
      "y": 6,
      "z": 4,
      "name": "Wood_Drywood_Planks"
    },
    {
      "x": -11,
      "y": 7,
      "z": 4,
      "name": "Wood_Drywood_Planks"
    },
    {
      "x": -11,
      "y": 9,
      "z": 4,
      "name": "Wood_Drywood_Planks_Half",
      "rotation": 8
    },
    {
      "x": -11,
      "y": 10,
      "z": 4,
      "name": "Wood_Drywood_Planks"
    },
    {
      "x": -11,
      "y": 7,
      "z": 5,
      "name": "Wood_Drywood_Planks"
    },
    {
      "x": -11,
      "y": 8,
      "z": 5,
      "name": "Wood_Drywood_Planks"
    },
    {
      "x": -11,
      "y": 9,
      "z": 5,
      "name": "Wood_Drywood_Planks"
    },
    {
      "x": -11,
      "y": 10,
      "z": 5,
      "name": "Wood_Drywood_Planks"
    },
    {
      "x": -11,
      "y": 8,
      "z": 6,
      "name": "Wood_Drywood_Planks"
    },
    {
      "x": -11,
      "y": 9,
      "z": 6,
      "name": "Wood_Drywood_Planks"
    },
    {
      "x": -11,
      "y": 10,
      "z": 6,
      "name": "Wood_Drywood_Decorative"
    },
    {
      "x": -11,
      "y": 11,
      "z": 6,
      "name": "Wood_Drywood_Fence"
    },
    {
      "x": -10,
      "y": 8,
      "z": -6,
      "name": "Wood_Drywood_Planks"
    },
    {
      "x": -10,
      "y": 9,
      "z": -6,
      "name": "Wood_Drywood_Planks"
    },
    {
      "x": -10,
      "y": 10,
      "z": -6,
      "name": "Wood_Drywood_Decorative"
    },
    {
      "x": -10,
      "y": 11,
      "z": -6,
      "name": "Wood_Drywood_Fence",
      "rotation": 2
    },
    {
      "x": -10,
      "y": 7,
      "z": -5,
      "name": "Wood_Drywood_Planks"
    },
    {
      "x": -10,
      "y": 8,
      "z": -5,
      "name": "Wood_Drywood_Planks"
    },
    {
      "x": -10,
      "y": 9,
      "z": -5,
      "name": "Wood_Drywood_Planks"
    },
    {
      "x": -10,
      "y": 10,
      "z": -5,
      "name": "Wood_Drywood_Planks"
    },
    {
      "x": -10,
      "y": 16,
      "z": -5,
      "name": "Wood_Dry_Trunk_Half",
      "rotation": 6
    },
    {
      "x": -10,
      "y": 4,
      "z": -4,
      "name": "Wood_Drywood_Planks"
    },
    {
      "x": -10,
      "y": 5,
      "z": -4,
      "name": "Wood_Drywood_Planks"
    },
    {
      "x": -10,
      "y": 6,
      "z": -4,
      "name": "Wood_Drywood_Planks"
    },
    {
      "x": -10,
      "y": 7,
      "z": -4,
      "name": "Wood_Drywood_Stairs",
      "rotation": 1
    },
    {
      "x": -10,
      "y": 9,
      "z": -4,
      "name": "Wood_Drywood_Planks_Half",
      "rotation": 8
    },
    {
      "x": -10,
      "y": 10,
      "z": -4,
      "name": "Wood_Drywood_Planks"
    },
    {
      "x": -10,
      "y": 14,
      "z": -4,
      "name": "Cloth_Roof_Hide_Flap",
      "support": 15,
      "rotation": 3
    },
    {
      "x": -10,
      "y": 15,
      "z": -4,
      "name": "Cloth_Roof_Hide_Vertical",
      "rotation": 3
    },
    {
      "x": -10,
      "y": 16,
      "z": -4,
      "name": "Wood_Dry_Trunk",
      "rotation": 4
    },
    {
      "x": -10,
      "y": 3,
      "z": -3,
      "name": "Wood_Drywood_Planks"
    },
    {
      "x": -10,
      "y": 4,
      "z": -3,
      "name": "Wood_Drywood_Planks"
    },
    {
      "x": -10,
      "y": 5,
      "z": -3,
      "name": "Wood_Drywood_Planks"
    },
    {
      "x": -10,
      "y": 6,
      "z": -3,
      "name": "Wood_Drywood_Planks"
    },
    {
      "x": -10,
      "y": 9,
      "z": -3,
      "name": "Wood_Drywood_Planks_Half",
      "rotation": 8
    },
    {
      "x": -10,
      "y": 10,
      "z": -3,
      "name": "Wood_Drywood_Planks"
    },
    {
      "x": -10,
      "y": 15,
      "z": -3,
      "name": "Cloth_Roof_Hide_Flap",
      "rotation": 3
    },
    {
      "x": -10,
      "y": 16,
      "z": -3,
      "name": "Wood_Dry_Trunk",
      "rotation": 4
    },
    {
      "x": -10,
      "y": 2,
      "z": -2,
      "name": "Wood_Drywood_Planks"
    },
    {
      "x": -10,
      "y": 3,
      "z": -2,
      "name": "Wood_Drywood_Planks"
    },
    {
      "x": -10,
      "y": 4,
      "z": -2,
      "name": "Wood_Drywood_Planks_Half",
      "rotation": 4
    },
    {
      "x": -10,
      "y": 5,
      "z": -2,
      "name": "Wood_Drywood_Planks_Half",
      "rotation": 4
    },
    {
      "x": -10,
      "y": 6,
      "z": -2,
      "name": "Wood_Drywood_Planks"
    },
    {
      "x": -10,
      "y": 7,
      "z": -2,
      "name": "Cloth_Roof_Leather_Flap",
      "rotation": 1
    },
    {
      "x": -10,
      "y": 9,
      "z": -2,
      "name": "Wood_Drywood_Planks_Half",
      "rotation": 8
    },
    {
      "x": -10,
      "y": 10,
      "z": -2,
      "name": "Wood_Drywood_Planks"
    },
    {
      "x": -10,
      "y": 15,
      "z": -2,
      "name": "Cloth_Roof_Hide_Flap",
      "rotation": 3
    },
    {
      "x": -10,
      "y": 16,
      "z": -2,
      "name": "Wood_Dry_Trunk_Half",
      "rotation": 4
    },
    {
      "x": -10,
      "y": 2,
      "z": -1,
      "name": "Wood_Drywood_Planks"
    },
    {
      "x": -10,
      "y": 3,
      "z": -1,
      "name": "Wood_Drywood_Planks"
    },
    {
      "x": -10,
      "y": 4,
      "z": -1,
      "name": "Deco_Trash_Pile_Large",
      "rotation": 1
    },
    {
      "x": -10,
      "y": 6,
      "z": -1,
      "name": "Wood_Drywood_Planks"
    },
    {
      "x": -10,
      "y": 9,
      "z": -1,
      "name": "Wood_Drywood_Planks_Half",
      "rotation": 8
    },
    {
      "x": -10,
      "y": 10,
      "z": -1,
      "name": "Wood_Drywood_Planks"
    },
    {
      "x": -10,
      "y": 1,
      "z": 0,
      "name": "Wood_Drywood_Planks"
    },
    {
      "x": -10,
      "y": 2,
      "z": 0,
      "name": "Wood_Drywood_Planks"
    },
    {
      "x": -10,
      "y": 3,
      "z": 0,
      "name": "Wood_Drywood_Planks"
    },
    {
      "x": -10,
      "y": 4,
      "z": 0,
      "name": "Deco_Trash_Pile_Small"
    },
    {
      "x": -10,
      "y": 6,
      "z": 0,
      "name": "Wood_Drywood_Planks"
    },
    {
      "x": -10,
      "y": 7,
      "z": 0,
      "name": "Cloth_Roof_Leather_Flap",
      "rotation": 1
    },
    {
      "x": -10,
      "y": 9,
      "z": 0,
      "name": "Wood_Drywood_Planks_Half",
      "rotation": 8
    },
    {
      "x": -10,
      "y": 10,
      "z": 0,
      "name": "Wood_Drywood_Planks"
    },
    {
      "x": -10,
      "y": 2,
      "z": 1,
      "name": "Wood_Drywood_Planks"
    },
    {
      "x": -10,
      "y": 3,
      "z": 1,
      "name": "Wood_Drywood_Planks"
    },
    {
      "x": -10,
      "y": 6,
      "z": 1,
      "name": "Wood_Drywood_Planks"
    },
    {
      "x": -10,
      "y": 9,
      "z": 1,
      "name": "Wood_Drywood_Planks_Half",
      "rotation": 8
    },
    {
      "x": -10,
      "y": 10,
      "z": 1,
      "name": "Wood_Drywood_Planks"
    },
    {
      "x": -10,
      "y": 2,
      "z": 2,
      "name": "Wood_Drywood_Planks"
    },
    {
      "x": -10,
      "y": 3,
      "z": 2,
      "name": "Wood_Drywood_Planks"
    },
    {
      "x": -10,
      "y": 4,
      "z": 2,
      "name": "Wood_Drywood_Planks_Half",
      "rotation": 6
    },
    {
      "x": -10,
      "y": 5,
      "z": 2,
      "name": "Wood_Drywood_Planks_Half",
      "rotation": 6
    },
    {
      "x": -10,
      "y": 6,
      "z": 2,
      "name": "Wood_Drywood_Planks"
    },
    {
      "x": -10,
      "y": 9,
      "z": 2,
      "name": "Wood_Drywood_Planks_Half",
      "rotation": 8
    },
    {
      "x": -10,
      "y": 10,
      "z": 2,
      "name": "Wood_Drywood_Planks"
    },
    {
      "x": -10,
      "y": 3,
      "z": 3,
      "name": "Wood_Drywood_Planks"
    },
    {
      "x": -10,
      "y": 4,
      "z": 3,
      "name": "Wood_Drywood_Planks"
    },
    {
      "x": -10,
      "y": 5,
      "z": 3,
      "name": "Wood_Drywood_Planks"
    },
    {
      "x": -10,
      "y": 6,
      "z": 3,
      "name": "Wood_Drywood_Planks"
    },
    {
      "x": -10,
      "y": 9,
      "z": 3,
      "name": "Wood_Drywood_Planks_Half",
      "rotation": 8
    },
    {
      "x": -10,
      "y": 10,
      "z": 3,
      "name": "Wood_Drywood_Planks"
    },
    {
      "x": -10,
      "y": 4,
      "z": 4,
      "name": "Wood_Drywood_Planks"
    },
    {
      "x": -10,
      "y": 5,
      "z": 4,
      "name": "Wood_Drywood_Planks"
    },
    {
      "x": -10,
      "y": 6,
      "z": 4,
      "name": "Wood_Drywood_Planks"
    },
    {
      "x": -10,
      "y": 7,
      "z": 4,
      "name": "Wood_Drywood_Stairs",
      "rotation": 1
    },
    {
      "x": -10,
      "y": 9,
      "z": 4,
      "name": "Wood_Drywood_Planks_Half",
      "rotation": 8
    },
    {
      "x": -10,
      "y": 10,
      "z": 4,
      "name": "Wood_Drywood_Planks"
    },
    {
      "x": -10,
      "y": 7,
      "z": 5,
      "name": "Wood_Drywood_Planks"
    },
    {
      "x": -10,
      "y": 8,
      "z": 5,
      "name": "Wood_Drywood_Planks"
    },
    {
      "x": -10,
      "y": 9,
      "z": 5,
      "name": "Wood_Drywood_Planks"
    },
    {
      "x": -10,
      "y": 10,
      "z": 5,
      "name": "Wood_Drywood_Planks"
    },
    {
      "x": -10,
      "y": 8,
      "z": 6,
      "name": "Wood_Drywood_Planks"
    },
    {
      "x": -10,
      "y": 9,
      "z": 6,
      "name": "Wood_Drywood_Planks"
    },
    {
      "x": -10,
      "y": 10,
      "z": 6,
      "name": "Wood_Drywood_Decorative"
    },
    {
      "x": -10,
      "y": 11,
      "z": 6,
      "name": "Wood_Drywood_Fence"
    },
    {
      "x": -9,
      "y": 8,
      "z": -7,
      "name": "Wood_Drywood_Planks"
    },
    {
      "x": -9,
      "y": 9,
      "z": -7,
      "name": "Wood_Drywood_Planks"
    },
    {
      "x": -9,
      "y": 10,
      "z": -7,
      "name": "Wood_Drywood_Decorative"
    },
    {
      "x": -9,
      "y": 11,
      "z": -7,
      "name": "*Wood_Drywood_Fence_State_Definitions_Corner",
      "rotation": 1
    },
    {
      "x": -9,
      "y": 7,
      "z": -6,
      "name": "Wood_Drywood_Planks"
    },
    {
      "x": -9,
      "y": 8,
      "z": -6,
      "name": "Wood_Drywood_Planks"
    },
    {
      "x": -9,
      "y": 9,
      "z": -6,
      "name": "Wood_Drywood_Planks"
    },
    {
      "x": -9,
      "y": 10,
      "z": -6,
      "name": "Wood_Drywood_Planks"
    },
    {
      "x": -9,
      "y": 11,
      "z": -6,
      "name": "*Wood_Drywood_Fence_State_Definitions_Corner",
      "rotation": 3
    },
    {
      "x": -9,
      "y": 6,
      "z": -5,
      "name": "Wood_Drywood_Planks"
    },
    {
      "x": -9,
      "y": 7,
      "z": -5,
      "name": "Wood_Drywood_Planks"
    },
    {
      "x": -9,
      "y": 8,
      "z": -5,
      "name": "Wood_Drywood_Planks"
    },
    {
      "x": -9,
      "y": 9,
      "z": -5,
      "name": "Wood_Drywood_Planks"
    },
    {
      "x": -9,
      "y": 10,
      "z": -5,
      "name": "Wood_Drywood_Planks"
    },
    {
      "x": -9,
      "y": 4,
      "z": -4,
      "name": "Wood_Drywood_Planks"
    },
    {
      "x": -9,
      "y": 5,
      "z": -4,
      "name": "Wood_Drywood_Planks"
    },
    {
      "x": -9,
      "y": 6,
      "z": -4,
      "name": "Wood_Drywood_Planks"
    },
    {
      "x": -9,
      "y": 9,
      "z": -4,
      "name": "Wood_Drywood_Planks_Half",
      "rotation": 8
    },
    {
      "x": -9,
      "y": 10,
      "z": -4,
      "name": "Wood_Drywood_Planks"
    },
    {
      "x": -9,
      "y": 3,
      "z": -3,
      "name": "Wood_Drywood_Planks"
    },
    {
      "x": -9,
      "y": 4,
      "z": -3,
      "name": "Wood_Drywood_Planks"
    },
    {
      "x": -9,
      "y": 5,
      "z": -3,
      "name": "Wood_Drywood_Planks"
    },
    {
      "x": -9,
      "y": 6,
      "z": -3,
      "name": "Wood_Drywood_Planks"
    },
    {
      "x": -9,
      "y": 9,
      "z": -3,
      "name": "Wood_Drywood_Planks_Half",
      "rotation": 8
    },
    {
      "x": -9,
      "y": 10,
      "z": -3,
      "name": "Wood_Drywood_Planks"
    },
    {
      "x": -9,
      "y": 17,
      "z": -3,
      "name": "Wood_Dry_Trunk_Half",
      "rotation": 6
    },
    {
      "x": -9,
      "y": 2,
      "z": -2,
      "name": "Wood_Drywood_Planks"
    },
    {
      "x": -9,
      "y": 3,
      "z": -2,
      "name": "Wood_Drywood_Planks"
    },
    {
      "x": -9,
      "y": 4,
      "z": -2,
      "name": "Wood_Drywood_Stairs"
    },
    {
      "x": -9,
      "y": 5,
      "z": -2,
      "name": "Wood_Drywood_Stairs",
      "rotation": 10
    },
    {
      "x": -9,
      "y": 6,
      "z": -2,
      "name": "Wood_Drywood_Planks"
    },
    {
      "x": -9,
      "y": 9,
      "z": -2,
      "name": "Wood_Drywood_Planks_Half",
      "rotation": 8
    },
    {
      "x": -9,
      "y": 10,
      "z": -2,
      "name": "Wood_Drywood_Planks"
    },
    {
      "x": -9,
      "y": 15,
      "z": -2,
      "name": "Cloth_Roof_Hide_Flap",
      "support": 15,
      "rotation": 1
    },
    {
      "x": -9,
      "y": 16,
      "z": -2,
      "name": "Cloth_Roof_Hide_Vertical",
      "rotation": 1
    },
    {
      "x": -9,
      "y": 17,
      "z": -2,
      "name": "Wood_Dry_Trunk",
      "rotation": 4
    },
    {
      "x": -9,
      "y": 2,
      "z": -1,
      "name": "Wood_Drywood_Planks"
    },
    {
      "x": -9,
      "y": 3,
      "z": -1,
      "name": "Wood_Drywood_Planks"
    },
    {
      "x": -9,
      "y": 4,
      "z": -1,
      "name": "Deco_Trash_Pile_Small"
    },
    {
      "x": -9,
      "y": 6,
      "z": -1,
      "name": "Wood_Drywood_Planks"
    },
    {
      "x": -9,
      "y": 9,
      "z": -1,
      "name": "Wood_Drywood_Planks_Half",
      "rotation": 8
    },
    {
      "x": -9,
      "y": 10,
      "z": -1,
      "name": "Wood_Drywood_Planks"
    },
    {
      "x": -9,
      "y": 16,
      "z": -1,
      "name": "Cloth_Roof_Hide_Flap",
      "rotation": 1
    },
    {
      "x": -9,
      "y": 17,
      "z": -1,
      "name": "Wood_Dry_Trunk",
      "rotation": 4
    },
    {
      "x": -9,
      "y": 1,
      "z": 0,
      "name": "Wood_Drywood_Planks"
    },
    {
      "x": -9,
      "y": 2,
      "z": 0,
      "name": "Wood_Drywood_Planks"
    },
    {
      "x": -9,
      "y": 3,
      "z": 0,
      "name": "Wood_Drywood_Planks"
    },
    {
      "x": -9,
      "y": 6,
      "z": 0,
      "name": "Wood_Drywood_Planks"
    },
    {
      "x": -9,
      "y": 9,
      "z": 0,
      "name": "Wood_Drywood_Planks_Half",
      "rotation": 8
    },
    {
      "x": -9,
      "y": 10,
      "z": 0,
      "name": "Wood_Drywood_Planks"
    },
    {
      "x": -9,
      "y": 11,
      "z": 0,
      "name": "Wood_Dry_Trunk_Half",
      "rotation": 7
    },
    {
      "x": -9,
      "y": 15,
      "z": 0,
      "name": "Cloth_Roof_Hide_Flap",
      "support": 15,
      "rotation": 1
    },
    {
      "x": -9,
      "y": 16,
      "z": 0,
      "name": "Cloth_Roof_Hide_Vertical",
      "rotation": 1
    },
    {
      "x": -9,
      "y": 17,
      "z": 0,
      "name": "Wood_Dry_Trunk",
      "rotation": 4
    },
    {
      "x": -9,
      "y": 2,
      "z": 1,
      "name": "Wood_Drywood_Planks"
    },
    {
      "x": -9,
      "y": 3,
      "z": 1,
      "name": "Wood_Drywood_Planks"
    },
    {
      "x": -9,
      "y": 6,
      "z": 1,
      "name": "Wood_Drywood_Planks"
    },
    {
      "x": -9,
      "y": 9,
      "z": 1,
      "name": "Wood_Drywood_Planks_Half",
      "rotation": 8
    },
    {
      "x": -9,
      "y": 10,
      "z": 1,
      "name": "Wood_Drywood_Planks"
    },
    {
      "x": -9,
      "y": 17,
      "z": 1,
      "name": "Wood_Dry_Trunk",
      "rotation": 4
    },
    {
      "x": -9,
      "y": 2,
      "z": 2,
      "name": "Wood_Drywood_Planks"
    },
    {
      "x": -9,
      "y": 3,
      "z": 2,
      "name": "Wood_Drywood_Planks"
    },
    {
      "x": -9,
      "y": 4,
      "z": 2,
      "name": "Wood_Drywood_Stairs",
      "rotation": 2
    },
    {
      "x": -9,
      "y": 5,
      "z": 2,
      "name": "Wood_Drywood_Stairs",
      "rotation": 8
    },
    {
      "x": -9,
      "y": 6,
      "z": 2,
      "name": "Wood_Drywood_Planks"
    },
    {
      "x": -9,
      "y": 9,
      "z": 2,
      "name": "Wood_Drywood_Planks_Half",
      "rotation": 8
    },
    {
      "x": -9,
      "y": 10,
      "z": 2,
      "name": "Wood_Drywood_Planks"
    },
    {
      "x": -9,
      "y": 16,
      "z": 2,
      "name": "Cloth_Roof_Hide_Flap",
      "rotation": 1
    },
    {
      "x": -9,
      "y": 17,
      "z": 2,
      "name": "Wood_Dry_Trunk",
      "rotation": 4
    },
    {
      "x": -9,
      "y": 3,
      "z": 3,
      "name": "Wood_Drywood_Planks"
    },
    {
      "x": -9,
      "y": 4,
      "z": 3,
      "name": "Wood_Drywood_Planks"
    },
    {
      "x": -9,
      "y": 5,
      "z": 3,
      "name": "Wood_Drywood_Planks"
    },
    {
      "x": -9,
      "y": 6,
      "z": 3,
      "name": "Wood_Drywood_Planks"
    },
    {
      "x": -9,
      "y": 9,
      "z": 3,
      "name": "Wood_Drywood_Planks_Half",
      "rotation": 8
    },
    {
      "x": -9,
      "y": 10,
      "z": 3,
      "name": "Wood_Drywood_Planks"
    },
    {
      "x": -9,
      "y": 16,
      "z": 3,
      "name": "Cloth_Roof_Hide_Flap",
      "rotation": 3
    },
    {
      "x": -9,
      "y": 17,
      "z": 3,
      "name": "Wood_Dry_Trunk_Half",
      "rotation": 4
    },
    {
      "x": -9,
      "y": 4,
      "z": 4,
      "name": "Wood_Drywood_Planks"
    },
    {
      "x": -9,
      "y": 5,
      "z": 4,
      "name": "Wood_Drywood_Planks"
    },
    {
      "x": -9,
      "y": 6,
      "z": 4,
      "name": "Wood_Drywood_Planks"
    },
    {
      "x": -9,
      "y": 9,
      "z": 4,
      "name": "Wood_Drywood_Planks_Half",
      "rotation": 8
    },
    {
      "x": -9,
      "y": 10,
      "z": 4,
      "name": "Wood_Drywood_Planks"
    },
    {
      "x": -9,
      "y": 6,
      "z": 5,
      "name": "Wood_Drywood_Planks"
    },
    {
      "x": -9,
      "y": 7,
      "z": 5,
      "name": "Wood_Drywood_Planks"
    },
    {
      "x": -9,
      "y": 8,
      "z": 5,
      "name": "Wood_Drywood_Planks"
    },
    {
      "x": -9,
      "y": 9,
      "z": 5,
      "name": "Wood_Drywood_Planks"
    },
    {
      "x": -9,
      "y": 10,
      "z": 5,
      "name": "Wood_Drywood_Planks"
    },
    {
      "x": -9,
      "y": 7,
      "z": 6,
      "name": "Wood_Drywood_Planks"
    },
    {
      "x": -9,
      "y": 8,
      "z": 6,
      "name": "Wood_Drywood_Planks"
    },
    {
      "x": -9,
      "y": 9,
      "z": 6,
      "name": "Wood_Drywood_Planks"
    },
    {
      "x": -9,
      "y": 10,
      "z": 6,
      "name": "Wood_Drywood_Planks"
    },
    {
      "x": -9,
      "y": 11,
      "z": 6,
      "name": "*Wood_Drywood_Fence_State_Definitions_Corner"
    },
    {
      "x": -9,
      "y": 8,
      "z": 7,
      "name": "Wood_Drywood_Planks"
    },
    {
      "x": -9,
      "y": 9,
      "z": 7,
      "name": "Wood_Drywood_Planks"
    },
    {
      "x": -9,
      "y": 10,
      "z": 7,
      "name": "Wood_Drywood_Decorative"
    },
    {
      "x": -9,
      "y": 11,
      "z": 7,
      "name": "*Wood_Drywood_Fence_State_Definitions_Corner",
      "rotation": 2
    },
    {
      "x": -8,
      "y": 8,
      "z": -7,
      "name": "Wood_Drywood_Planks"
    },
    {
      "x": -8,
      "y": 9,
      "z": -7,
      "name": "Wood_Drywood_Planks"
    },
    {
      "x": -8,
      "y": 10,
      "z": -7,
      "name": "Wood_Drywood_Decorative"
    },
    {
      "x": -8,
      "y": 11,
      "z": -7,
      "name": "Wood_Drywood_Fence",
      "rotation": 2
    },
    {
      "x": -8,
      "y": 7,
      "z": -6,
      "name": "Wood_Drywood_Planks"
    },
    {
      "x": -8,
      "y": 8,
      "z": -6,
      "name": "Wood_Drywood_Planks"
    },
    {
      "x": -8,
      "y": 9,
      "z": -6,
      "name": "Wood_Drywood_Planks"
    },
    {
      "x": -8,
      "y": 10,
      "z": -6,
      "name": "Wood_Drywood_Planks"
    },
    {
      "x": -8,
      "y": 5,
      "z": -5,
      "name": "Wood_Drywood_Planks"
    },
    {
      "x": -8,
      "y": 6,
      "z": -5,
      "name": "Wood_Drywood_Planks"
    },
    {
      "x": -8,
      "y": 7,
      "z": -5,
      "name": "Wood_Drywood_Stairs",
      "rotation": 1
    },
    {
      "x": -8,
      "y": 9,
      "z": -5,
      "name": "Wood_Drywood_Stairs",
      "rotation": 11
    },
    {
      "x": -8,
      "y": 10,
      "z": -5,
      "name": "Wood_Drywood_Planks"
    },
    {
      "x": -8,
      "y": 3,
      "z": -4,
      "name": "Wood_Drywood_Planks"
    },
    {
      "x": -8,
      "y": 4,
      "z": -4,
      "name": "Wood_Drywood_Planks"
    },
    {
      "x": -8,
      "y": 5,
      "z": -4,
      "name": "Wood_Drywood_Planks"
    },
    {
      "x": -8,
      "y": 6,
      "z": -4,
      "name": "Wood_Drywood_Planks"
    },
    {
      "x": -8,
      "y": 9,
      "z": -4,
      "name": "Wood_Drywood_Planks_Half",
      "rotation": 8
    },
    {
      "x": -8,
      "y": 10,
      "z": -4,
      "name": "Wood_Drywood_Planks"
    },
    {
      "x": -8,
      "y": 2,
      "z": -3,
      "name": "Wood_Drywood_Planks"
    },
    {
      "x": -8,
      "y": 3,
      "z": -3,
      "name": "Wood_Drywood_Planks"
    },
    {
      "x": -8,
      "y": 4,
      "z": -3,
      "name": "Wood_Drywood_Planks"
    },
    {
      "x": -8,
      "y": 5,
      "z": -3,
      "name": "Wood_Drywood_Planks"
    },
    {
      "x": -8,
      "y": 6,
      "z": -3,
      "name": "Wood_Drywood_Planks"
    },
    {
      "x": -8,
      "y": 9,
      "z": -3,
      "name": "Wood_Drywood_Planks_Half",
      "rotation": 8
    },
    {
      "x": -8,
      "y": 10,
      "z": -3,
      "name": "Wood_Drywood_Planks"
    },
    {
      "x": -8,
      "y": 2,
      "z": -2,
      "name": "Wood_Drywood_Planks"
    },
    {
      "x": -8,
      "y": 3,
      "z": -2,
      "name": "Wood_Dry_Trunk",
      "support": 15,
      "rotation": 4
    },
    {
      "x": -8,
      "y": 4,
      "z": -2,
      "name": "Wood_Drywood_Planks_Half",
      "rotation": 4
    },
    {
      "x": -8,
      "y": 5,
      "z": -2,
      "name": "Wood_Drywood_Planks_Half",
      "rotation": 4
    },
    {
      "x": -8,
      "y": 6,
      "z": -2,
      "name": "Wood_Drywood_Planks"
    },
    {
      "x": -8,
      "y": 9,
      "z": -2,
      "name": "Wood_Drywood_Planks_Half",
      "rotation": 8
    },
    {
      "x": -8,
      "y": 10,
      "z": -2,
      "name": "Wood_Drywood_Planks"
    },
    {
      "x": -8,
      "y": 2,
      "z": -1,
      "name": "Wood_Drywood_Planks"
    },
    {
      "x": -8,
      "y": 3,
      "z": -1,
      "name": "Wood_Dry_Trunk",
      "support": 15,
      "rotation": 4
    },
    {
      "x": -8,
      "y": 6,
      "z": -1,
      "name": "Wood_Drywood_Planks"
    },
    {
      "x": -8,
      "y": 9,
      "z": -1,
      "name": "Wood_Drywood_Planks_Half",
      "rotation": 8
    },
    {
      "x": -8,
      "y": 10,
      "z": -1,
      "name": "Wood_Drywood_Planks"
    },
    {
      "x": -8,
      "y": 11,
      "z": -1,
      "name": "Wood_Dry_Trunk_Half",
      "rotation": 6
    },
    {
      "x": -8,
      "y": 12,
      "z": -1,
      "name": "Furniture_Desert_Sign",
      "rotation": 3
    },
    {
      "x": -8,
      "y": 17,
      "z": -1,
      "name": "Wood_Dry_Trunk_Half",
      "rotation": 6
    },
    {
      "x": -8,
      "y": 1,
      "z": 0,
      "name": "Wood_Drywood_Planks"
    },
    {
      "x": -8,
      "y": 2,
      "z": 0,
      "name": "Wood_Dry_Trunk",
      "support": 15
    },
    {
      "x": -8,
      "y": 3,
      "z": 0,
      "name": "Wood_Dry_Trunk",
      "support": 15
    },
    {
      "x": -8,
      "y": 4,
      "z": 0,
      "name": "Wood_Dry_Trunk",
      "support": 15
    },
    {
      "x": -8,
      "y": 5,
      "z": 0,
      "name": "Wood_Dry_Trunk",
      "support": 15
    },
    {
      "x": -8,
      "y": 6,
      "z": 0,
      "name": "Wood_Dry_Trunk",
      "support": 15
    },
    {
      "x": -8,
      "y": 7,
      "z": 0,
      "name": "Wood_Dry_Trunk",
      "support": 15
    },
    {
      "x": -8,
      "y": 8,
      "z": 0,
      "name": "Wood_Dry_Trunk",
      "support": 15
    },
    {
      "x": -8,
      "y": 9,
      "z": 0,
      "name": "Wood_Dry_Trunk",
      "support": 15
    },
    {
      "x": -8,
      "y": 10,
      "z": 0,
      "name": "Wood_Dry_Trunk",
      "support": 15
    },
    {
      "x": -8,
      "y": 11,
      "z": 0,
      "name": "Wood_Dry_Trunk",
      "support": 15
    },
    {
      "x": -8,
      "y": 12,
      "z": 0,
      "name": "Wood_Dry_Trunk",
      "support": 15
    },
    {
      "x": -8,
      "y": 13,
      "z": 0,
      "name": "Wood_Dry_Trunk",
      "support": 15
    },
    {
      "x": -8,
      "y": 14,
      "z": 0,
      "name": "Wood_Dry_Trunk",
      "support": 15
    },
    {
      "x": -8,
      "y": 15,
      "z": 0,
      "name": "Wood_Dry_Trunk",
      "support": 15
    },
    {
      "x": -8,
      "y": 16,
      "z": 0,
      "name": "Wood_Dry_Trunk",
      "support": 15
    },
    {
      "x": -8,
      "y": 17,
      "z": 0,
      "name": "Wood_Dry_Trunk",
      "support": 15
    },
    {
      "x": -8,
      "y": 18,
      "z": 0,
      "name": "Wood_Dry_Trunk",
      "support": 15
    },
    {
      "x": -8,
      "y": 19,
      "z": 0,
      "name": "Wood_Dry_Trunk"
    },
    {
      "x": -8,
      "y": 20,
      "z": 0,
      "name": "Wood_Dry_Trunk"
    },
    {
      "x": -8,
      "y": 21,
      "z": 0,
      "name": "Wood_Dry_Trunk_Half"
    },
    {
      "x": -8,
      "y": 2,
      "z": 1,
      "name": "Wood_Drywood_Planks"
    },
    {
      "x": -8,
      "y": 3,
      "z": 1,
      "name": "Wood_Dry_Trunk",
      "support": 15,
      "rotation": 4
    },
    {
      "x": -8,
      "y": 6,
      "z": 1,
      "name": "Wood_Drywood_Planks"
    },
    {
      "x": -8,
      "y": 9,
      "z": 1,
      "name": "Wood_Drywood_Planks_Half",
      "rotation": 8
    },
    {
      "x": -8,
      "y": 10,
      "z": 1,
      "name": "Wood_Drywood_Planks"
    },
    {
      "x": -8,
      "y": 11,
      "z": 1,
      "name": "Wood_Dry_Trunk_Half",
      "rotation": 4
    },
    {
      "x": -8,
      "y": 12,
      "z": 1,
      "name": "Furniture_Desert_Sign",
      "rotation": 3
    },
    {
      "x": -8,
      "y": 17,
      "z": 1,
      "name": "Wood_Dry_Trunk_Half",
      "rotation": 4
    },
    {
      "x": -8,
      "y": 2,
      "z": 2,
      "name": "Wood_Drywood_Planks"
    },
    {
      "x": -8,
      "y": 3,
      "z": 2,
      "name": "Wood_Dry_Trunk",
      "support": 15,
      "rotation": 4
    },
    {
      "x": -8,
      "y": 4,
      "z": 2,
      "name": "Wood_Drywood_Planks_Half",
      "rotation": 6
    },
    {
      "x": -8,
      "y": 5,
      "z": 2,
      "name": "Wood_Drywood_Planks_Half",
      "rotation": 6
    },
    {
      "x": -8,
      "y": 6,
      "z": 2,
      "name": "Wood_Drywood_Planks"
    },
    {
      "x": -8,
      "y": 9,
      "z": 2,
      "name": "Wood_Drywood_Planks_Half",
      "rotation": 8
    },
    {
      "x": -8,
      "y": 10,
      "z": 2,
      "name": "Wood_Drywood_Planks"
    },
    {
      "x": -8,
      "y": 18,
      "z": 2,
      "name": "Wood_Dry_Trunk_Half",
      "rotation": 6
    },
    {
      "x": -8,
      "y": 2,
      "z": 3,
      "name": "Wood_Drywood_Planks"
    },
    {
      "x": -8,
      "y": 3,
      "z": 3,
      "name": "Wood_Drywood_Planks"
    },
    {
      "x": -8,
      "y": 4,
      "z": 3,
      "name": "Wood_Drywood_Planks"
    },
    {
      "x": -8,
      "y": 5,
      "z": 3,
      "name": "Wood_Drywood_Planks"
    },
    {
      "x": -8,
      "y": 6,
      "z": 3,
      "name": "Wood_Drywood_Planks"
    },
    {
      "x": -8,
      "y": 9,
      "z": 3,
      "name": "Wood_Drywood_Planks_Half",
      "rotation": 8
    },
    {
      "x": -8,
      "y": 10,
      "z": 3,
      "name": "Wood_Drywood_Planks"
    },
    {
      "x": -8,
      "y": 15,
      "z": 3,
      "name": "Cloth_Roof_Hide_Flap",
      "rotation": 1
    },
    {
      "x": -8,
      "y": 16,
      "z": 3,
      "name": "Cloth_Roof_Hide_Vertical",
      "support": 15,
      "rotation": 1
    },
    {
      "x": -8,
      "y": 17,
      "z": 3,
      "name": "Cloth_Roof_Hide_Vertical",
      "rotation": 1
    },
    {
      "x": -8,
      "y": 18,
      "z": 3,
      "name": "Wood_Dry_Trunk",
      "rotation": 4
    },
    {
      "x": -8,
      "y": 3,
      "z": 4,
      "name": "Wood_Drywood_Planks"
    },
    {
      "x": -8,
      "y": 4,
      "z": 4,
      "name": "Wood_Drywood_Planks"
    },
    {
      "x": -8,
      "y": 5,
      "z": 4,
      "name": "Wood_Drywood_Planks"
    },
    {
      "x": -8,
      "y": 6,
      "z": 4,
      "name": "Wood_Drywood_Planks"
    },
    {
      "x": -8,
      "y": 9,
      "z": 4,
      "name": "Wood_Drywood_Planks_Half",
      "rotation": 8
    },
    {
      "x": -8,
      "y": 10,
      "z": 4,
      "name": "Wood_Drywood_Planks"
    },
    {
      "x": -8,
      "y": 17,
      "z": 4,
      "name": "Cloth_Roof_Hide_Flap",
      "rotation": 1
    },
    {
      "x": -8,
      "y": 18,
      "z": 4,
      "name": "Wood_Dry_Trunk",
      "rotation": 4
    },
    {
      "x": -8,
      "y": 5,
      "z": 5,
      "name": "Wood_Drywood_Planks"
    },
    {
      "x": -8,
      "y": 6,
      "z": 5,
      "name": "Wood_Drywood_Planks"
    },
    {
      "x": -8,
      "y": 7,
      "z": 5,
      "name": "Wood_Drywood_Stairs",
      "rotation": 1
    },
    {
      "x": -8,
      "y": 9,
      "z": 5,
      "name": "Wood_Drywood_Stairs",
      "rotation": 11
    },
    {
      "x": -8,
      "y": 10,
      "z": 5,
      "name": "Wood_Drywood_Planks"
    },
    {
      "x": -8,
      "y": 18,
      "z": 5,
      "name": "Wood_Dry_Trunk_Half",
      "rotation": 4
    },
    {
      "x": -8,
      "y": 7,
      "z": 6,
      "name": "Wood_Drywood_Planks"
    },
    {
      "x": -8,
      "y": 8,
      "z": 6,
      "name": "Wood_Drywood_Planks"
    },
    {
      "x": -8,
      "y": 9,
      "z": 6,
      "name": "Wood_Drywood_Planks"
    },
    {
      "x": -8,
      "y": 10,
      "z": 6,
      "name": "Wood_Drywood_Planks"
    },
    {
      "x": -8,
      "y": 8,
      "z": 7,
      "name": "Wood_Drywood_Planks"
    },
    {
      "x": -8,
      "y": 9,
      "z": 7,
      "name": "Wood_Drywood_Planks"
    },
    {
      "x": -8,
      "y": 10,
      "z": 7,
      "name": "Wood_Drywood_Decorative"
    },
    {
      "x": -8,
      "y": 11,
      "z": 7,
      "name": "Wood_Drywood_Fence"
    },
    {
      "x": -7,
      "y": 8,
      "z": -7,
      "name": "Wood_Drywood_Planks"
    },
    {
      "x": -7,
      "y": 9,
      "z": -7,
      "name": "Wood_Drywood_Planks"
    },
    {
      "x": -7,
      "y": 10,
      "z": -7,
      "name": "Wood_Drywood_Decorative"
    },
    {
      "x": -7,
      "y": 11,
      "z": -7,
      "name": "Wood_Drywood_Fence",
      "rotation": 2
    },
    {
      "x": -7,
      "y": 6,
      "z": -6,
      "name": "Wood_Drywood_Planks"
    },
    {
      "x": -7,
      "y": 7,
      "z": -6,
      "name": "Wood_Drywood_Planks"
    },
    {
      "x": -7,
      "y": 8,
      "z": -6,
      "name": "Wood_Drywood_Planks"
    },
    {
      "x": -7,
      "y": 9,
      "z": -6,
      "name": "Wood_Drywood_Planks"
    },
    {
      "x": -7,
      "y": 10,
      "z": -6,
      "name": "Wood_Drywood_Planks"
    },
    {
      "x": -7,
      "y": 4,
      "z": -5,
      "name": "Wood_Drywood_Planks"
    },
    {
      "x": -7,
      "y": 5,
      "z": -5,
      "name": "Wood_Drywood_Planks"
    },
    {
      "x": -7,
      "y": 6,
      "z": -5,
      "name": "Wood_Drywood_Planks"
    },
    {
      "x": -7,
      "y": 9,
      "z": -5,
      "name": "Wood_Drywood_Planks_Half",
      "rotation": 8
    },
    {
      "x": -7,
      "y": 10,
      "z": -5,
      "name": "Wood_Drywood_Planks"
    },
    {
      "x": -7,
      "y": 3,
      "z": -4,
      "name": "Wood_Drywood_Planks"
    },
    {
      "x": -7,
      "y": 4,
      "z": -4,
      "name": "Wood_Drywood_Planks"
    },
    {
      "x": -7,
      "y": 5,
      "z": -4,
      "name": "Wood_Drywood_Planks"
    },
    {
      "x": -7,
      "y": 6,
      "z": -4,
      "name": "Wood_Drywood_Stairs",
      "rotation": 1
    },
    {
      "x": -7,
      "y": 9,
      "z": -4,
      "name": "Wood_Drywood_Planks_Half",
      "rotation": 8
    },
    {
      "x": -7,
      "y": 10,
      "z": -4,
      "name": "Wood_Drywood_Planks"
    },
    {
      "x": -7,
      "y": 2,
      "z": -3,
      "name": "Wood_Drywood_Planks"
    },
    {
      "x": -7,
      "y": 3,
      "z": -3,
      "name": "Wood_Drywood_Planks"
    },
    {
      "x": -7,
      "y": 4,
      "z": -3,
      "name": "Wood_Drywood_Planks"
    },
    {
      "x": -7,
      "y": 5,
      "z": -3,
      "name": "Wood_Drywood_Planks"
    },
    {
      "x": -7,
      "y": 6,
      "z": -3,
      "name": "Wood_Drywood_Stairs",
      "rotation": 1
    },
    {
      "x": -7,
      "y": 9,
      "z": -3,
      "name": "Wood_Drywood_Planks_Half",
      "rotation": 8
    },
    {
      "x": -7,
      "y": 10,
      "z": -3,
      "name": "Wood_Drywood_Planks"
    },
    {
      "x": -7,
      "y": 2,
      "z": -2,
      "name": "Wood_Drywood_Planks"
    },
    {
      "x": -7,
      "y": 3,
      "z": -2,
      "name": "Wood_Drywood_Planks"
    },
    {
      "x": -7,
      "y": 4,
      "z": -2,
      "name": "Wood_Drywood_Planks_Half",
      "rotation": 4
    },
    {
      "x": -7,
      "y": 5,
      "z": -2,
      "name": "Wood_Drywood_Planks_Half",
      "rotation": 4
    },
    {
      "x": -7,
      "y": 6,
      "z": -2,
      "name": "Wood_Drywood_Planks"
    },
    {
      "x": -7,
      "y": 9,
      "z": -2,
      "name": "Wood_Drywood_Planks_Half",
      "rotation": 8
    },
    {
      "x": -7,
      "y": 10,
      "z": -2,
      "name": "Wood_Drywood_Planks"
    },
    {
      "x": -7,
      "y": 1,
      "z": -1,
      "name": "Wood_Drywood_Planks"
    },
    {
      "x": -7,
      "y": 2,
      "z": -1,
      "name": "Wood_Drywood_Planks"
    },
    {
      "x": -7,
      "y": 3,
      "z": -1,
      "name": "Wood_Drywood_Planks"
    },
    {
      "x": -7,
      "y": 6,
      "z": -1,
      "name": "Wood_Drywood_Planks"
    },
    {
      "x": -7,
      "y": 9,
      "z": -1,
      "name": "Wood_Drywood_Planks_Half",
      "rotation": 8
    },
    {
      "x": -7,
      "y": 10,
      "z": -1,
      "name": "Wood_Drywood_Planks"
    },
    {
      "x": -7,
      "y": 1,
      "z": 0,
      "name": "Wood_Drywood_Planks"
    },
    {
      "x": -7,
      "y": 2,
      "z": 0,
      "name": "Wood_Drywood_Planks"
    },
    {
      "x": -7,
      "y": 3,
      "z": 0,
      "name": "Wood_Drywood_Planks"
    },
    {
      "x": -7,
      "y": 6,
      "z": 0,
      "name": "Wood_Drywood_Planks"
    },
    {
      "x": -7,
      "y": 9,
      "z": 0,
      "name": "Wood_Drywood_Planks_Half",
      "rotation": 8
    },
    {
      "x": -7,
      "y": 10,
      "z": 0,
      "name": "Wood_Drywood_Planks"
    },
    {
      "x": -7,
      "y": 11,
      "z": 0,
      "name": "Wood_Dry_Trunk_Half",
      "rotation": 5
    },
    {
      "x": -7,
      "y": 17,
      "z": 0,
      "name": "Wood_Dry_Trunk_Half",
      "rotation": 5
    },
    {
      "x": -7,
      "y": 1,
      "z": 1,
      "name": "Wood_Drywood_Planks"
    },
    {
      "x": -7,
      "y": 2,
      "z": 1,
      "name": "Wood_Drywood_Planks"
    },
    {
      "x": -7,
      "y": 3,
      "z": 1,
      "name": "Wood_Drywood_Planks"
    },
    {
      "x": -7,
      "y": 6,
      "z": 1,
      "name": "Wood_Drywood_Planks"
    },
    {
      "x": -7,
      "y": 9,
      "z": 1,
      "name": "Wood_Drywood_Planks_Half",
      "rotation": 8
    },
    {
      "x": -7,
      "y": 10,
      "z": 1,
      "name": "Wood_Drywood_Planks"
    },
    {
      "x": -7,
      "y": 2,
      "z": 2,
      "name": "Wood_Drywood_Planks"
    },
    {
      "x": -7,
      "y": 3,
      "z": 2,
      "name": "Wood_Drywood_Planks"
    },
    {
      "x": -7,
      "y": 4,
      "z": 2,
      "name": "Wood_Drywood_Planks_Half",
      "rotation": 6
    },
    {
      "x": -7,
      "y": 5,
      "z": 2,
      "name": "Wood_Drywood_Planks_Half",
      "rotation": 6
    },
    {
      "x": -7,
      "y": 6,
      "z": 2,
      "name": "Wood_Drywood_Planks"
    },
    {
      "x": -7,
      "y": 9,
      "z": 2,
      "name": "Wood_Drywood_Planks_Half",
      "rotation": 8
    },
    {
      "x": -7,
      "y": 10,
      "z": 2,
      "name": "Wood_Drywood_Planks"
    },
    {
      "x": -7,
      "y": 2,
      "z": 3,
      "name": "Wood_Drywood_Planks"
    },
    {
      "x": -7,
      "y": 3,
      "z": 3,
      "name": "Wood_Drywood_Planks"
    },
    {
      "x": -7,
      "y": 4,
      "z": 3,
      "name": "Wood_Drywood_Planks"
    },
    {
      "x": -7,
      "y": 5,
      "z": 3,
      "name": "Wood_Drywood_Planks"
    },
    {
      "x": -7,
      "y": 6,
      "z": 3,
      "name": "Wood_Drywood_Stairs",
      "rotation": 1
    },
    {
      "x": -7,
      "y": 9,
      "z": 3,
      "name": "Wood_Drywood_Planks_Half",
      "rotation": 8
    },
    {
      "x": -7,
      "y": 10,
      "z": 3,
      "name": "Wood_Drywood_Planks"
    },
    {
      "x": -7,
      "y": 3,
      "z": 4,
      "name": "Wood_Drywood_Planks"
    },
    {
      "x": -7,
      "y": 4,
      "z": 4,
      "name": "Wood_Drywood_Planks"
    },
    {
      "x": -7,
      "y": 5,
      "z": 4,
      "name": "Wood_Drywood_Planks"
    },
    {
      "x": -7,
      "y": 6,
      "z": 4,
      "name": "Wood_Drywood_Stairs",
      "rotation": 1
    },
    {
      "x": -7,
      "y": 9,
      "z": 4,
      "name": "Wood_Drywood_Planks_Half",
      "rotation": 8
    },
    {
      "x": -7,
      "y": 10,
      "z": 4,
      "name": "Wood_Drywood_Planks"
    },
    {
      "x": -7,
      "y": 4,
      "z": 5,
      "name": "Wood_Drywood_Planks"
    },
    {
      "x": -7,
      "y": 5,
      "z": 5,
      "name": "Wood_Drywood_Planks"
    },
    {
      "x": -7,
      "y": 6,
      "z": 5,
      "name": "Wood_Drywood_Planks"
    },
    {
      "x": -7,
      "y": 9,
      "z": 5,
      "name": "Wood_Drywood_Planks_Half",
      "rotation": 8
    },
    {
      "x": -7,
      "y": 10,
      "z": 5,
      "name": "Wood_Drywood_Planks"
    },
    {
      "x": -7,
      "y": 6,
      "z": 6,
      "name": "Wood_Drywood_Planks"
    },
    {
      "x": -7,
      "y": 7,
      "z": 6,
      "name": "Wood_Drywood_Planks"
    },
    {
      "x": -7,
      "y": 8,
      "z": 6,
      "name": "Wood_Drywood_Planks"
    },
    {
      "x": -7,
      "y": 9,
      "z": 6,
      "name": "Wood_Drywood_Planks"
    },
    {
      "x": -7,
      "y": 10,
      "z": 6,
      "name": "Wood_Drywood_Planks"
    },
    {
      "x": -7,
      "y": 8,
      "z": 7,
      "name": "Wood_Drywood_Planks"
    },
    {
      "x": -7,
      "y": 9,
      "z": 7,
      "name": "Wood_Drywood_Planks"
    },
    {
      "x": -7,
      "y": 10,
      "z": 7,
      "name": "Wood_Drywood_Decorative"
    },
    {
      "x": -7,
      "y": 11,
      "z": 7,
      "name": "Wood_Drywood_Fence"
    },
    {
      "x": -6,
      "y": 8,
      "z": -7,
      "name": "Wood_Drywood_Planks"
    },
    {
      "x": -6,
      "y": 9,
      "z": -7,
      "name": "Wood_Drywood_Planks"
    },
    {
      "x": -6,
      "y": 10,
      "z": -7,
      "name": "Wood_Drywood_Decorative"
    },
    {
      "x": -6,
      "y": 11,
      "z": -7,
      "name": "Wood_Drywood_Fence",
      "rotation": 2
    },
    {
      "x": -6,
      "y": 6,
      "z": -6,
      "name": "Wood_Drywood_Planks"
    },
    {
      "x": -6,
      "y": 7,
      "z": -6,
      "name": "Wood_Drywood_Planks"
    },
    {
      "x": -6,
      "y": 8,
      "z": -6,
      "name": "Wood_Drywood_Planks"
    },
    {
      "x": -6,
      "y": 9,
      "z": -6,
      "name": "Wood_Drywood_Planks"
    },
    {
      "x": -6,
      "y": 10,
      "z": -6,
      "name": "Wood_Drywood_Planks"
    },
    {
      "x": -6,
      "y": 4,
      "z": -5,
      "name": "Wood_Drywood_Planks"
    },
    {
      "x": -6,
      "y": 5,
      "z": -5,
      "name": "Wood_Drywood_Planks"
    },
    {
      "x": -6,
      "y": 6,
      "z": -5,
      "name": "Wood_Drywood_Planks"
    },
    {
      "x": -6,
      "y": 7,
      "z": -5,
      "name": "Wood_Drywood_Stairs",
      "rotation": 3
    },
    {
      "x": -6,
      "y": 8,
      "z": -5,
      "name": "Wood_Drywood_Planks_Half",
      "rotation": 7
    },
    {
      "x": -6,
      "y": 9,
      "z": -5,
      "name": "Wood_Drywood_Stairs",
      "rotation": 9
    },
    {
      "x": -6,
      "y": 10,
      "z": -5,
      "name": "Wood_Drywood_Planks"
    },
    {
      "x": -6,
      "y": 3,
      "z": -4,
      "name": "Wood_Drywood_Planks"
    },
    {
      "x": -6,
      "y": 4,
      "z": -4,
      "name": "Wood_Drywood_Planks"
    },
    {
      "x": -6,
      "y": 5,
      "z": -4,
      "name": "Wood_Drywood_Stairs",
      "rotation": 1
    },
    {
      "x": -6,
      "y": 9,
      "z": -4,
      "name": "Wood_Drywood_Planks_Half",
      "rotation": 8
    },
    {
      "x": -6,
      "y": 10,
      "z": -4,
      "name": "Wood_Drywood_Planks"
    },
    {
      "x": -6,
      "y": 2,
      "z": -3,
      "name": "Wood_Drywood_Planks"
    },
    {
      "x": -6,
      "y": 3,
      "z": -3,
      "name": "Wood_Drywood_Planks"
    },
    {
      "x": -6,
      "y": 4,
      "z": -3,
      "name": "Wood_Drywood_Planks"
    },
    {
      "x": -6,
      "y": 5,
      "z": -3,
      "name": "Wood_Drywood_Stairs",
      "rotation": 1
    },
    {
      "x": -6,
      "y": 9,
      "z": -3,
      "name": "Wood_Drywood_Planks_Half",
      "rotation": 8
    },
    {
      "x": -6,
      "y": 10,
      "z": -3,
      "name": "Wood_Drywood_Planks"
    },
    {
      "x": -6,
      "y": 2,
      "z": -2,
      "name": "Wood_Drywood_Planks"
    },
    {
      "x": -6,
      "y": 3,
      "z": -2,
      "name": "Wood_Drywood_Planks"
    },
    {
      "x": -6,
      "y": 4,
      "z": -2,
      "name": "Wood_Drywood_Planks_Half",
      "rotation": 4
    },
    {
      "x": -6,
      "y": 5,
      "z": -2,
      "name": "Wood_Drywood_Planks_Half",
      "rotation": 4
    },
    {
      "x": -6,
      "y": 6,
      "z": -2,
      "name": "Wood_Drywood_Planks"
    },
    {
      "x": -6,
      "y": 7,
      "z": -2,
      "name": "Wood_Drywood_Stairs",
      "rotation": 3
    },
    {
      "x": -6,
      "y": 9,
      "z": -2,
      "name": "Wood_Drywood_Planks_Half",
      "rotation": 8
    },
    {
      "x": -6,
      "y": 10,
      "z": -2,
      "name": "Wood_Drywood_Planks"
    },
    {
      "x": -6,
      "y": 1,
      "z": -1,
      "name": "Wood_Drywood_Planks"
    },
    {
      "x": -6,
      "y": 2,
      "z": -1,
      "name": "Wood_Drywood_Planks"
    },
    {
      "x": -6,
      "y": 3,
      "z": -1,
      "name": "Wood_Drywood_Stairs",
      "rotation": 1
    },
    {
      "x": -6,
      "y": 6,
      "z": -1,
      "name": "Wood_Drywood_Planks"
    },
    {
      "x": -6,
      "y": 9,
      "z": -1,
      "name": "Wood_Drywood_Planks_Half",
      "rotation": 8
    },
    {
      "x": -6,
      "y": 10,
      "z": -1,
      "name": "Wood_Drywood_Planks"
    },
    {
      "x": -6,
      "y": 1,
      "z": 0,
      "name": "Wood_Drywood_Planks"
    },
    {
      "x": -6,
      "y": 2,
      "z": 0,
      "name": "Wood_Drywood_Planks"
    },
    {
      "x": -6,
      "y": 3,
      "z": 0,
      "name": "Wood_Drywood_Planks"
    },
    {
      "x": -6,
      "y": 6,
      "z": 0,
      "name": "Wood_Drywood_Planks"
    },
    {
      "x": -6,
      "y": 9,
      "z": 0,
      "name": "Wood_Drywood_Planks_Half",
      "rotation": 8
    },
    {
      "x": -6,
      "y": 10,
      "z": 0,
      "name": "Wood_Drywood_Planks"
    },
    {
      "x": -6,
      "y": 1,
      "z": 1,
      "name": "Wood_Drywood_Planks"
    },
    {
      "x": -6,
      "y": 2,
      "z": 1,
      "name": "Wood_Drywood_Planks"
    },
    {
      "x": -6,
      "y": 3,
      "z": 1,
      "name": "Wood_Drywood_Stairs",
      "rotation": 1
    },
    {
      "x": -6,
      "y": 6,
      "z": 1,
      "name": "Wood_Drywood_Planks"
    },
    {
      "x": -6,
      "y": 9,
      "z": 1,
      "name": "Wood_Drywood_Planks_Half",
      "rotation": 8
    },
    {
      "x": -6,
      "y": 10,
      "z": 1,
      "name": "Wood_Drywood_Planks"
    },
    {
      "x": -6,
      "y": 2,
      "z": 2,
      "name": "Wood_Drywood_Planks"
    },
    {
      "x": -6,
      "y": 3,
      "z": 2,
      "name": "Wood_Drywood_Planks"
    },
    {
      "x": -6,
      "y": 4,
      "z": 2,
      "name": "Wood_Drywood_Planks_Half",
      "rotation": 6
    },
    {
      "x": -6,
      "y": 5,
      "z": 2,
      "name": "Wood_Drywood_Planks_Half",
      "rotation": 6
    },
    {
      "x": -6,
      "y": 6,
      "z": 2,
      "name": "Wood_Drywood_Planks"
    },
    {
      "x": -6,
      "y": 7,
      "z": 2,
      "name": "Wood_Drywood_Stairs",
      "rotation": 3
    },
    {
      "x": -6,
      "y": 9,
      "z": 2,
      "name": "Wood_Drywood_Planks_Half",
      "rotation": 8
    },
    {
      "x": -6,
      "y": 10,
      "z": 2,
      "name": "Wood_Drywood_Planks"
    },
    {
      "x": -6,
      "y": 2,
      "z": 3,
      "name": "Wood_Drywood_Planks"
    },
    {
      "x": -6,
      "y": 3,
      "z": 3,
      "name": "Wood_Drywood_Planks"
    },
    {
      "x": -6,
      "y": 4,
      "z": 3,
      "name": "Wood_Drywood_Planks"
    },
    {
      "x": -6,
      "y": 5,
      "z": 3,
      "name": "Wood_Drywood_Stairs",
      "rotation": 1
    },
    {
      "x": -6,
      "y": 9,
      "z": 3,
      "name": "Wood_Drywood_Planks_Half",
      "rotation": 8
    },
    {
      "x": -6,
      "y": 10,
      "z": 3,
      "name": "Wood_Drywood_Planks"
    },
    {
      "x": -6,
      "y": 3,
      "z": 4,
      "name": "Wood_Drywood_Planks"
    },
    {
      "x": -6,
      "y": 4,
      "z": 4,
      "name": "Wood_Drywood_Planks"
    },
    {
      "x": -6,
      "y": 5,
      "z": 4,
      "name": "Wood_Drywood_Stairs",
      "rotation": 1
    },
    {
      "x": -6,
      "y": 9,
      "z": 4,
      "name": "Wood_Drywood_Planks_Half",
      "rotation": 8
    },
    {
      "x": -6,
      "y": 10,
      "z": 4,
      "name": "Wood_Drywood_Planks"
    },
    {
      "x": -6,
      "y": 4,
      "z": 5,
      "name": "Wood_Drywood_Planks"
    },
    {
      "x": -6,
      "y": 5,
      "z": 5,
      "name": "Wood_Drywood_Planks"
    },
    {
      "x": -6,
      "y": 6,
      "z": 5,
      "name": "Wood_Drywood_Planks"
    },
    {
      "x": -6,
      "y": 7,
      "z": 5,
