{
  "version": 8,
  "blockIdVersion": 11,
  "anchorX": -9,
  "anchorY": 4,
  "anchorZ": 0,
  "blocks": [
    {
      "x": -9,
      "y": 5,
      "z": -8,
      "name": "Wood_Drywood_Planks"
    },
    {
      "x": -9,
      "y": 6,
      "z": -8,
      "name": "Wood_Drywood_Planks"
    },
    {
      "x": -9,
      "y": 7,
      "z": -8,
      "name": "Wood_Drywood_Planks"
    },
    {
      "x": -9,
      "y": 8,
      "z": -8,
      "name": "Wood_Drywood_Decorative"
    },
    {
      "x": -9,
      "y": 9,
      "z": -8,
      "name": "Wood_Drywood_Fence",
      "rotation": 2
    },
    {
      "x": -9,
      "y": 3,
      "z": -7,
      "name": "Wood_Drywood_Planks"
    },
    {
      "x": -9,
      "y": 4,
      "z": -7,
      "name": "Wood_Drywood_Planks"
    },
    {
      "x": -9,
      "y": 7,
      "z": -7,
      "name": "Wood_Drywood_Planks"
    },
    {
      "x": -9,
      "y": 8,
      "z": -7,
      "name": "Wood_Drywood_Planks"
    },
    {
      "x": -9,
      "y": 2,
      "z": -6,
      "name": "Wood_Drywood_Planks"
    },
    {
      "x": -9,
      "y": 4,
      "z": -6,
      "name": "Wood_Drywood_Stairs",
      "rotation": 10
    },
    {
      "x": -9,
      "y": 8,
      "z": -6,
      "name": "Wood_Drywood_Planks"
    },
    {
      "x": -9,
      "y": 1,
      "z": -5,
      "name": "Wood_Drywood_Planks"
    },
    {
      "x": -9,
      "y": 4,
      "z": -5,
      "name": "Wood_Drywood_Stairs",
      "rotation": 8
    },
    {
      "x": -9,
      "y": 8,
      "z": -5,
      "name": "Wood_Drywood_Planks_Half",
      "rotation": 2
    },
    {
      "x": -9,
      "y": 1,
      "z": -4,
      "name": "Wood_Drywood_Planks"
    },
    {
      "x": -9,
      "y": 4,
      "z": -4,
      "name": "Wood_Drywood_Planks"
    },
    {
      "x": -9,
      "y": 0,
      "z": -3,
      "name": "Wood_Drywood_Planks"
    },
    {
      "x": -9,
      "y": 1,
      "z": -3,
      "name": "Wood_Drywood_Planks"
    },
    {
      "x": -9,
      "y": 4,
      "z": -3,
      "name": "Wood_Drywood_Planks"
    },
    {
      "x": -9,
      "y": 8,
      "z": -3,
      "name": "Wood_Drywood_Planks_Half",
      "rotation": 2
    },
    {
      "x": -9,
      "y": 0,
      "z": -2,
      "name": "Wood_Drywood_Planks"
    },
    {
      "x": -9,
      "y": 1,
      "z": -2,
      "name": "Wood_Drywood_Planks"
    },
    {
      "x": -9,
      "y": 4,
      "z": -2,
      "name": "Wood_Drywood_Stairs",
      "rotation": 10
    },
    {
      "x": -9,
      "y": 8,
      "z": -2,
      "name": "Wood_Drywood_Planks"
    },
    {
      "x": -9,
      "y": 0,
      "z": -1,
      "name": "Wood_Drywood_Planks"
    },
    {
      "x": -9,
      "y": 1,
      "z": -1,
      "name": "Wood_Drywood_Planks"
    },
    {
      "x": -9,
      "y": 4,
      "z": -1,
      "name": "Wood_Drywood_Planks_Half",
      "rotation": 8
    },
    {
      "x": -9,
      "y": 8,
      "z": -1,
      "name": "Wood_Drywood_Planks"
    },
    {
      "x": -9,
      "y": 0,
      "z": 0,
      "name": "Wood_Drywood_Planks"
    },
    {
      "x": -9,
      "y": 1,
      "z": 0,
      "name": "Wood_Drywood_Planks"
    },
    {
      "x": -9,
      "y": 4,
      "z": 0,
      "name": "Wood_Drywood_Planks_Half",
      "rotation": 8
    },
    {
      "x": -9,
      "y": 5,
      "z": 0,
      "name": "Wood_Drywood_Fence"
    },
    {
      "x": -9,
      "y": 6,
      "z": 0,
      "name": "Wood_Drywood_Fence"
    },
    {
      "x": -9,
      "y": 8,
      "z": 0,
      "name": "Wood_Drywood_Planks",
      "support": 15
    },
    {
      "x": -9,
      "y": 0,
      "z": 1,
      "name": "Wood_Drywood_Planks"
    },
    {
      "x": -9,
      "y": 1,
      "z": 1,
      "name": "Wood_Drywood_Planks"
    },
    {
      "x": -9,
      "y": 4,
      "z": 1,
      "name": "Wood_Drywood_Planks_Half",
      "rotation": 8
    },
    {
      "x": -9,
      "y": 8,
      "z": 1,
      "name": "Wood_Drywood_Planks"
    },
    {
      "x": -9,
      "y": 0,
      "z": 2,
      "name": "Wood_Drywood_Planks"
    },
    {
      "x": -9,
      "y": 1,
      "z": 2,
      "name": "Wood_Drywood_Planks"
    },
    {
      "x": -9,
      "y": 4,
      "z": 2,
      "name": "Wood_Drywood_Stairs",
      "rotation": 8
    },
    {
      "x": -9,
      "y": 8,
      "z": 2,
      "name": "Wood_Drywood_Planks"
    },
    {
      "x": -9,
      "y": 0,
      "z": 3,
      "name": "Wood_Drywood_Planks"
    },
    {
      "x": -9,
      "y": 1,
      "z": 3,
      "name": "Wood_Drywood_Planks"
    },
    {
      "x": -9,
      "y": 4,
      "z": 3,
      "name": "Wood_Drywood_Planks"
    },
    {
      "x": -9,
      "y": 1,
      "z": 4,
      "name": "Wood_Drywood_Planks"
    },
    {
      "x": -9,
      "y": 4,
      "z": 4,
      "name": "Wood_Drywood_Planks"
    },
    {
      "x": -9,
      "y": 1,
      "z": 5,
      "name": "Wood_Drywood_Planks"
    },
    {
      "x": -9,
      "y": 4,
      "z": 5,
      "name": "Wood_Drywood_Stairs",
      "rotation": 10
    },
    {
      "x": -9,
      "y": 8,
      "z": 5,
      "name": "Wood_Drywood_Planks_Half"
    },
    {
      "x": -9,
      "y": 2,
      "z": 6,
      "name": "Wood_Drywood_Planks"
    },
    {
      "x": -9,
      "y": 4,
      "z": 6,
      "name": "Wood_Drywood_Stairs",
      "rotation": 8
    },
    {
      "x": -9,
      "y": 8,
      "z": 6,
      "name": "Wood_Drywood_Planks"
    },
    {
      "x": -9,
      "y": 3,
      "z": 7,
      "name": "Wood_Drywood_Planks"
    },
    {
      "x": -9,
      "y": 4,
      "z": 7,
      "name": "Wood_Drywood_Planks"
    },
    {
      "x": -9,
      "y": 7,
      "z": 7,
      "name": "Wood_Drywood_Planks"
    },
    {
      "x": -9,
      "y": 8,
      "z": 7,
      "name": "Wood_Drywood_Planks"
    },
    {
      "x": -9,
      "y": 5,
      "z": 8,
      "name": "Wood_Drywood_Planks"
    },
    {
      "x": -9,
      "y": 6,
      "z": 8,
      "name": "Wood_Drywood_Planks"
    },
    {
      "x": -9,
      "y": 7,
      "z": 8,
      "name": "Wood_Drywood_Planks"
    },
    {
      "x": -9,
      "y": 8,
      "z": 8,
      "name": "Wood_Drywood_Decorative"
    },
    {
      "x": -9,
      "y": 9,
      "z": 8,
      "name": "Wood_Drywood_Fence"
    },
    {
      "x": -8,
      "y": 5,
      "z": -8,
      "name": "Wood_Drywood_Planks"
    },
    {
      "x": -8,
      "y": 6,
      "z": -8,
      "name": "Wood_Drywood_Planks"
    },
    {
      "x": -8,
      "y": 7,
      "z": -8,
      "name": "Wood_Drywood_Planks"
    },
    {
      "x": -8,
      "y": 8,
      "z": -8,
      "name": "Wood_Drywood_Decorative"
    },
    {
      "x": -8,
      "y": 9,
      "z": -8,
      "name": "Wood_Drywood_Fence",
      "rotation": 2
    },
    {
      "x": -8,
      "y": 3,
      "z": -7,
      "name": "Wood_Drywood_Planks"
    },
    {
      "x": -8,
      "y": 4,
      "z": -7,
      "name": "Wood_Drywood_Planks"
    },
    {
      "x": -8,
      "y": 5,
      "z": -7,
      "name": "Wood_Drywood_Stairs",
      "rotation": 3
    },
    {
      "x": -8,
      "y": 6,
      "z": -7,
      "name": "Wood_Drywood_Stairs",
      "rotation": 9
    },
    {
      "x": -8,
      "y": 7,
      "z": -7,
      "name": "Wood_Drywood_Planks"
    },
    {
      "x": -8,
      "y": 8,
      "z": -7,
      "name": "Wood_Drywood_Planks"
    },
    {
      "x": -8,
      "y": 2,
      "z": -6,
      "name": "Wood_Drywood_Planks"
    },
    {
      "x": -8,
      "y": 4,
      "z": -6,
      "name": "Wood_Drywood_Stairs",
      "rotation": 10
    },
    {
      "x": -8,
      "y": 8,
      "z": -6,
      "name": "Wood_Drywood_Planks"
    },
    {
      "x": -8,
      "y": 1,
      "z": -5,
      "name": "Wood_Drywood_Planks"
    },
    {
      "x": -8,
      "y": 4,
      "z": -5,
      "name": "Wood_Drywood_Stairs",
      "rotation": 8
    },
    {
      "x": -8,
      "y": 8,
      "z": -5,
      "name": "Wood_Drywood_Planks"
    },
    {
      "x": -8,
      "y": 1,
      "z": -4,
      "name": "Wood_Drywood_Planks"
    },
    {
      "x": -8,
      "y": 4,
      "z": -4,
      "name": "Wood_Drywood_Planks"
    },
    {
      "x": -8,
      "y": 0,
      "z": -3,
      "name": "Wood_Drywood_Planks"
    },
    {
      "x": -8,
      "y": 1,
      "z": -3,
      "name": "Wood_Drywood_Stairs"
    },
    {
      "x": -8,
      "y": 4,
      "z": -3,
      "name": "Wood_Drywood_Planks"
    },
    {
      "x": -8,
      "y": 0,
      "z": -2,
      "name": "Wood_Drywood_Planks"
    },
    {
      "x": -8,
      "y": 1,
      "z": -2,
      "name": "Wood_Drywood_Planks"
    },
    {
      "x": -8,
      "y": 4,
      "z": -2,
      "name": "Wood_Drywood_Stairs",
      "rotation": 10
    },
    {
      "x": -8,
      "y": 8,
      "z": -2,
      "name": "Wood_Drywood_Planks"
    },
    {
      "x": -8,
      "y": 0,
      "z": -1,
      "name": "Wood_Drywood_Planks"
    },
    {
      "x": -8,
      "y": 1,
      "z": -1,
      "name": "Wood_Drywood_Planks"
    },
    {
      "x": -8,
      "y": 4,
      "z": -1,
      "name": "Wood_Drywood_Planks_Half",
      "rotation": 8
    },
    {
      "x": -8,
      "y": 8,
      "z": -1,
      "name": "Wood_Drywood_Planks"
    },
    {
      "x": -8,
      "y": 0,
      "z": 0,
      "name": "Wood_Drywood_Planks"
    },
    {
      "x": -8,
      "y": 1,
      "z": 0,
      "name": "Wood_Drywood_Planks"
    },
    {
      "x": -8,
      "y": 4,
      "z": 0,
      "name": "Wood_Drywood_Planks_Half",
      "rotation": 8
    },
    {
      "x": -8,
      "y": 6,
      "z": 0,
      "name": "Wood_Drywood_Fence"
    },
    {
      "x": -8,
      "y": 7,
      "z": 0,
      "name": "Wood_Drywood_Fence"
    },
    {
      "x": -8,
      "y": 8,
      "z": 0,
      "name": "Wood_Drywood_Planks",
      "support": 15
    },
    {
      "x": -8,
      "y": 0,
      "z": 1,
      "name": "Wood_Drywood_Planks"
    },
    {
      "x": -8,
      "y": 1,
      "z": 1,
      "name": "Wood_Drywood_Planks"
    },
    {
      "x": -8,
      "y": 4,
      "z": 1,
      "name": "Wood_Drywood_Planks_Half",
      "rotation": 8
    },
    {
      "x": -8,
      "y": 8,
      "z": 1,
      "name": "Wood_Drywood_Planks"
    },
    {
      "x": -8,
      "y": 0,
      "z": 2,
      "name": "Wood_Drywood_Planks"
    },
    {
      "x": -8,
      "y": 1,
      "z": 2,
      "name": "Wood_Drywood_Planks"
    },
    {
      "x": -8,
      "y": 4,
      "z": 2,
      "name": "Wood_Drywood_Stairs",
      "rotation": 8
    },
    {
      "x": -8,
      "y": 8,
      "z": 2,
      "name": "Wood_Drywood_Planks"
    },
    {
      "x": -8,
      "y": 0,
      "z": 3,
      "name": "Wood_Drywood_Planks"
    },
    {
      "x": -8,
      "y": 1,
      "z": 3,
      "name": "Wood_Drywood_Stairs",
      "rotation": 2
    },
    {
      "x": -8,
      "y": 4,
      "z": 3,
      "name": "Wood_Drywood_Planks"
    },
    {
      "x": -8,
      "y": 1,
      "z": 4,
      "name": "Wood_Drywood_Planks"
    },
    {
      "x": -8,
      "y": 4,
      "z": 4,
      "name": "Wood_Drywood_Planks"
    },
    {
      "x": -8,
      "y": 1,
      "z": 5,
      "name": "Wood_Drywood_Planks"
    },
    {
      "x": -8,
      "y": 4,
      "z": 5,
      "name": "Wood_Drywood_Stairs",
      "rotation": 10
    },
    {
      "x": -8,
      "y": 8,
      "z": 5,
      "name": "Wood_Drywood_Planks"
    },
    {
      "x": -8,
      "y": 2,
      "z": 6,
      "name": "Wood_Drywood_Planks"
    },
    {
      "x": -8,
      "y": 4,
      "z": 6,
      "name": "Wood_Drywood_Stairs",
      "rotation": 8
    },
    {
      "x": -8,
      "y": 8,
      "z": 6,
      "name": "Wood_Drywood_Planks"
    },
    {
      "x": -8,
      "y": 3,
      "z": 7,
      "name": "Wood_Drywood_Planks"
    },
    {
      "x": -8,
      "y": 4,
      "z": 7,
      "name": "Wood_Drywood_Planks"
    },
    {
      "x": -8,
      "y": 5,
      "z": 7,
      "name": "Wood_Drywood_Stairs",
      "rotation": 3
    },
    {
      "x": -8,
      "y": 6,
      "z": 7,
      "name": "Wood_Drywood_Stairs",
      "rotation": 9
    },
    {
      "x": -8,
      "y": 7,
      "z": 7,
      "name": "Wood_Drywood_Planks"
    },
    {
      "x": -8,
      "y": 8,
      "z": 7,
      "name": "Wood_Drywood_Planks"
    },
    {
      "x": -8,
      "y": 5,
      "z": 8,
      "name": "Wood_Drywood_Planks"
    },
    {
      "x": -8,
      "y": 6,
      "z": 8,
      "name": "Wood_Drywood_Planks"
    },
    {
      "x": -8,
      "y": 7,
      "z": 8,
      "name": "Wood_Drywood_Planks"
    },
    {
      "x": -8,
      "y": 8,
      "z": 8,
      "name": "Wood_Drywood_Decorative"
    },
    {
      "x": -8,
      "y": 9,
      "z": 8,
      "name": "Wood_Drywood_Fence"
    },
    {
      "x": -7,
      "y": 5,
      "z": -8,
      "name": "Wood_Drywood_Planks"
    },
    {
      "x": -7,
      "y": 6,
      "z": -8,
      "name": "Wood_Drywood_Planks"
    },
    {
      "x": -7,
      "y": 7,
      "z": -8,
      "name": "Wood_Drywood_Planks"
    },
    {
      "x": -7,
      "y": 8,
      "z": -8,
      "name": "Wood_Drywood_Decorative"
    },
    {
      "x": -7,
      "y": 9,
      "z": -8,
      "name": "Wood_Drywood_Fence",
      "rotation": 2
    },
    {
      "x": -7,
      "y": 3,
      "z": -7,
      "name": "Wood_Drywood_Planks"
    },
    {
      "x": -7,
      "y": 4,
      "z": -7,
      "name": "Wood_Drywood_Planks"
    },
    {
      "x": -7,
      "y": 5,
      "z": -7,
      "name": "Wood_Dry_Trunk",
      "support": 15
    },
    {
      "x": -7,
      "y": 6,
      "z": -7,
      "name": "Wood_Dry_Trunk",
      "support": 15
    },
    {
      "x": -7,
      "y": 7,
      "z": -7,
      "name": "Wood_Dry_Trunk",
      "support": 15
    },
    {
      "x": -7,
      "y": 8,
      "z": -7,
      "name": "Wood_Drywood_Planks"
    },
    {
      "x": -7,
      "y": 2,
      "z": -6,
      "name": "Wood_Drywood_Planks"
    },
    {
      "x": -7,
      "y": 3,
      "z": -6,
      "name": "Wood_Dry_Trunk",
      "support": 15
    },
    {
      "x": -7,
      "y": 4,
      "z": -6,
      "name": "Wood_Dry_Trunk_Full",
      "support": 15
    },
    {
      "x": -7,
      "y": 5,
      "z": -6,
      "name": "Wood_Drywood_Planks_Half"
    },
    {
      "x": -7,
      "y": 7,
      "z": -6,
      "name": "Wood_Dry_Trunk_Stairs",
      "rotation": 10
    },
    {
      "x": -7,
      "y": 8,
      "z": -6,
      "name": "Wood_Drywood_Planks"
    },
    {
      "x": -7,
      "y": 1,
      "z": -5,
      "name": "Wood_Drywood_Planks"
    },
    {
      "x": -7,
      "y": 2,
      "z": -5,
      "name": "Wood_Dry_Trunk",
      "support": 15,
      "rotation": 4
    },
    {
      "x": -7,
      "y": 3,
      "z": -5,
      "name": "Wood_Drywood_Fence",
      "rotation": 3
    },
    {
      "x": -7,
      "y": 4,
      "z": -5,
      "name": "Wood_Drywood_Planks"
    },
    {
      "x": -7,
      "y": 8,
      "z": -5,
      "name": "Wood_Drywood_Planks"
    },
    {
      "x": -7,
      "y": 1,
      "z": -4,
      "name": "Wood_Drywood_Planks"
    },
    {
      "x": -7,
      "y": 2,
      "z": -4,
      "name": "Wood_Dry_Trunk_Full",
      "support": 15,
      "rotation": 4
    },
    {
      "x": -7,
      "y": 3,
      "z": -4,
      "name": "Wood_Drywood_Fence",
      "rotation": 3
    },
    {
      "x": -7,
      "y": 4,
      "z": -4,
      "name": "Wood_Drywood_Planks"
    },
    {
      "x": -7,
      "y": 8,
      "z": -4,
      "name": "Wood_Drywood_Planks"
    },
    {
      "x": -7,
      "y": 0,
      "z": -3,
      "name": "Wood_Drywood_Planks"
    },
    {
      "x": -7,
      "y": 1,
      "z": -3,
      "name": "Wood_Dry_Trunk",
      "support": 15,
      "rotation": 4
    },
    {
      "x": -7,
      "y": 2,
      "z": -3,
      "name": "Wood_Dry_Trunk_Stairs"
    },
    {
      "x": -7,
      "y": 4,
      "z": -3,
      "name": "Wood_Drywood_Planks"
    },
    {
      "x": -7,
      "y": 8,
      "z": -3,
      "name": "Wood_Drywood_Planks"
    },
    {
      "x": -7,
      "y": 0,
      "z": -2,
      "name": "Wood_Drywood_Planks"
    },
    {
      "x": -7,
      "y": 1,
      "z": -2,
      "name": "Wood_Dry_Trunk",
      "support": 15,
      "rotation": 4
    },
    {
      "x": -7,
      "y": 4,
      "z": -2,
      "name": "Wood_Drywood_Planks"
    },
    {
      "x": -7,
      "y": 8,
      "z": -2,
      "name": "Wood_Drywood_Planks"
    },
    {
      "x": -7,
      "y": 0,
      "z": -1,
      "name": "Wood_Drywood_Planks"
    },
    {
      "x": -7,
      "y": 1,
      "z": -1,
      "name": "Wood_Dry_Trunk",
      "support": 15,
      "rotation": 4
    },
    {
      "x": -7,
      "y": 2,
      "z": -1,
      "name": "Wood_Dry_Trunk_Stairs",
      "rotation": 2
    },
    {
      "x": -7,
      "y": 4,
      "z": -1,
      "name": "Wood_Drywood_Stairs",
      "rotation": 10
    },
    {
      "x": -7,
      "y": 7,
      "z": -1,
      "name": "Wood_Dry_Trunk_Stairs",
      "rotation": 8
    },
    {
      "x": -7,
      "y": 8,
      "z": -1,
      "name": "Wood_Drywood_Planks"
    },
    {
      "x": -7,
      "y": 0,
      "z": 0,
      "name": "Wood_Drywood_Planks"
    },
    {
      "x": -7,
      "y": 1,
      "z": 0,
      "name": "Wood_Dry_Trunk",
      "support": 15
    },
    {
      "x": -7,
      "y": 2,
      "z": 0,
      "name": "Wood_Dry_Trunk",
      "support": 15
    },
    {
      "x": -7,
      "y": 3,
      "z": 0,
      "name": "Wood_Dry_Trunk",
      "support": 15
    },
    {
      "x": -7,
      "y": 4,
      "z": 0,
      "name": "Wood_Dry_Trunk",
      "support": 15
    },
    {
      "x": -7,
      "y": 5,
      "z": 0,
      "name": "Wood_Dry_Trunk",
      "support": 15
    },
    {
      "x": -7,
      "y": 6,
      "z": 0,
      "name": "Wood_Dry_Trunk",
      "support": 15
    },
    {
      "x": -7,
      "y": 7,
      "z": 0,
      "name": "Wood_Dry_Trunk",
      "support": 15
    },
    {
      "x": -7,
      "y": 8,
      "z": 0,
      "name": "Wood_Drywood_Planks",
      "support": 15
    },
    {
      "x": -7,
      "y": 0,
      "z": 1,
      "name": "Wood_Drywood_Planks"
    },
    {
      "x": -7,
      "y": 1,
      "z": 1,
      "name": "Wood_Dry_Trunk",
      "support": 15,
      "rotation": 4
    },
    {
      "x": -7,
      "y": 2,
      "z": 1,
      "name": "Wood_Dry_Trunk_Stairs"
    },
    {
      "x": -7,
      "y": 4,
      "z": 1,
      "name": "Wood_Drywood_Stairs",
      "rotation": 8
    },
    {
      "x": -7,
      "y": 7,
      "z": 1,
      "name": "Wood_Dry_Trunk_Stairs",
      "rotation": 10
    },
    {
      "x": -7,
      "y": 8,
      "z": 1,
      "name": "Wood_Drywood_Planks"
    },
    {
      "x": -7,
      "y": 0,
      "z": 2,
      "name": "Wood_Drywood_Planks"
    },
    {
      "x": -7,
      "y": 1,
      "z": 2,
      "name": "Wood_Dry_Trunk",
      "support": 15,
      "rotation": 4
    },
    {
      "x": -7,
      "y": 4,
      "z": 2,
      "name": "Wood_Drywood_Planks"
    },
    {
      "x": -7,
      "y": 8,
      "z": 2,
      "name": "Wood_Drywood_Planks"
    },
    {
      "x": -7,
      "y": 0,
      "z": 3,
      "name": "Wood_Drywood_Planks"
    },
    {
      "x": -7,
      "y": 1,
      "z": 3,
      "name": "Wood_Dry_Trunk",
      "support": 15,
      "rotation": 4
    },
    {
      "x": -7,
      "y": 2,
      "z": 3,
      "name": "Wood_Dry_Trunk_Stairs",
      "rotation": 2
    },
    {
      "x": -7,
      "y": 4,
      "z": 3,
      "name": "Wood_Drywood_Planks"
    },
    {
      "x": -7,
      "y": 8,
      "z": 3,
      "name": "Wood_Drywood_Planks"
    },
    {
      "x": -7,
      "y": 1,
      "z": 4,
      "name": "Wood_Drywood_Planks"
    },
    {
      "x": -7,
      "y": 2,
      "z": 4,
      "name": "Wood_Dry_Trunk_Full",
      "support": 15,
      "rotation": 4
    },
    {
      "x": -7,
      "y": 3,
      "z": 4,
      "name": "Wood_Drywood_Fence",
      "rotation": 3
    },
    {
      "x": -7,
      "y": 4,
      "z": 4,
      "name": "Wood_Drywood_Planks"
    },
    {
      "x": -7,
      "y": 8,
      "z": 4,
      "name": "Wood_Drywood_Planks"
    },
    {
      "x": -7,
      "y": 1,
      "z": 5,
      "name": "Wood_Drywood_Planks"
    },
    {
      "x": -7,
      "y": 2,
      "z": 5,
      "name": "Wood_Dry_Trunk",
      "support": 15,
      "rotation": 4
    },
    {
      "x": -7,
      "y": 3,
      "z": 5,
      "name": "Wood_Drywood_Fence",
      "rotation": 3
    },
    {
      "x": -7,
      "y": 4,
      "z": 5,
      "name": "Wood_Drywood_Planks"
    },
    {
      "x": -7,
      "y": 8,
      "z": 5,
      "name": "Wood_Drywood_Planks"
    },
    {
      "x": -7,
      "y": 2,
      "z": 6,
      "name": "Wood_Drywood_Planks"
    },
    {
      "x": -7,
      "y": 3,
      "z": 6,
      "name": "Wood_Dry_Trunk",
      "support": 15
    },
    {
      "x": -7,
      "y": 4,
      "z": 6,
      "name": "Wood_Dry_Trunk_Full",
      "support": 15
    },
    {
      "x": -7,
      "y": 5,
      "z": 6,
      "name": "Wood_Drywood_Planks_Half"
    },
    {
      "x": -7,
      "y": 7,
      "z": 6,
      "name": "Wood_Dry_Trunk_Stairs",
      "rotation": 8
    },
    {
      "x": -7,
      "y": 3,
      "z": 7,
      "name": "Wood_Drywood_Planks"
    },
    {
      "x": -7,
      "y": 4,
      "z": 7,
      "name": "Wood_Drywood_Planks"
    },
    {
      "x": -7,
      "y": 5,
      "z": 7,
      "name": "Wood_Dry_Trunk",
      "support": 15
    },
    {
      "x": -7,
      "y": 6,
      "z": 7,
      "name": "Wood_Dry_Trunk",
      "support": 15
    },
    {
      "x": -7,
      "y": 5,
      "z": 8,
      "name": "Wood_Drywood_Planks"
    },
    {
      "x": -7,
      "y": 6,
      "z": 8,
      "name": "Wood_Drywood_Planks"
    },
    {
      "x": -7,
      "y": 7,
      "z": 8,
      "name": "Wood_Drywood_Planks"
    },
    {
      "x": -6,
      "y": 5,
      "z": -8,
      "name": "Wood_Drywood_Planks"
    },
    {
      "x": -6,
      "y": 6,
      "z": -8,
      "name": "Wood_Drywood_Planks"
    },
    {
      "x": -6,
      "y": 7,
      "z": -8,
      "name": "Wood_Drywood_Planks"
    },
    {
      "x": -6,
      "y": 8,
      "z": -8,
      "name": "Wood_Drywood_Decorative"
    },
    {
      "x": -6,
      "y": 9,
      "z": -8,
      "name": "Wood_Drywood_Fence",
      "rotation": 2
    },
    {
      "x": -6,
      "y": 3,
      "z": -7,
      "name": "Wood_Drywood_Planks"
    },
    {
      "x": -6,
      "y": 4,
      "z": -7,
      "name": "Wood_Drywood_Planks"
    },
    {
      "x": -6,
      "y": 5,
      "z": -7,
      "name": "Wood_Drywood_Stairs",
      "rotation": 1
    },
    {
      "x": -6,
      "y": 6,
      "z": -7,
      "name": "Wood_Drywood_Stairs",
      "rotation": 11
    },
    {
      "x": -6,
      "y": 7,
      "z": -7,
      "name": "Wood_Drywood_Planks"
    },
    {
      "x": -6,
      "y": 8,
      "z": -7,
      "name": "Wood_Drywood_Planks"
    },
    {
      "x": -6,
      "y": 2,
      "z": -6,
      "name": "Wood_Drywood_Planks"
    },
    {
      "x": -6,
      "y": 4,
      "z": -6,
      "name": "Wood_Drywood_Stairs",
      "rotation": 10
    },
    {
      "x": -6,
      "y": 8,
      "z": -6,
      "name": "Wood_Drywood_Planks"
    },
    {
      "x": -6,
      "y": 1,
      "z": -5,
      "name": "Wood_Drywood_Planks"
    },
    {
      "x": -6,
      "y": 2,
      "z": -5,
      "name": "Wood_Drywood_Stairs",
      "rotation": 10
    },
    {
      "x": -6,
      "y": 4,
      "z": -5,
      "name": "Wood_Drywood_Stairs",
      "rotation": 8
    },
    {
      "x": -6,
      "y": 8,
      "z": -5,
      "name": "Wood_Drywood_Planks"
    },
    {
      "x": -6,
      "y": 1,
      "z": -4,
      "name": "Wood_Drywood_Planks"
    },
    {
      "x": -6,
      "y": 4,
      "z": -4,
      "name": "Wood_Drywood_Planks"
    },
    {
      "x": -6,
      "y": 8,
      "z": -4,
      "name": "Wood_Drywood_Planks"
    },
    {
      "x": -6,
      "y": 0,
      "z": -3,
      "name": "Wood_Drywood_Planks"
    },
    {
      "x": -6,
      "y": 1,
      "z": -3,
      "name": "Wood_Drywood_Stairs"
    },
    {
      "x": -6,
      "y": 4,
      "z": -3,
      "name": "Wood_Drywood_Planks"
    },
    {
      "x": -6,
      "y": 8,
      "z": -3,
      "name": "Wood_Drywood_Planks"
    },
    {
      "x": -6,
      "y": 0,
      "z": -2,
      "name": "Wood_Drywood_Planks"
    },
    {
      "x": -6,
      "y": 1,
      "z": -2,
      "name": "Wood_Drywood_Planks"
    },
    {
      "x": -6,
      "y": 4,
      "z": -2,
      "name": "Wood_Drywood_Stairs",
      "rotation": 10
    },
    {
      "x": -6,
      "y": 8,
      "z": -2,
      "name": "Wood_Drywood_Planks"
    },
    {
      "x": -6,
      "y": 0,
      "z": -1,
      "name": "Wood_Drywood_Planks"
    },
    {
      "x": -6,
      "y": 1,
      "z": -1,
      "name": "Wood_Drywood_Planks"
    },
    {
      "x": -6,
      "y": 4,
      "z": -1,
      "name": "Wood_Drywood_Planks_Half",
      "rotation": 8
    },
    {
      "x": -6,
      "y": 8,
      "z": -1,
      "name": "Wood_Drywood_Planks"
    },
    {
      "x": -6,
      "y": 0,
      "z": 0,
      "name": "Wood_Drywood_Planks"
    },
    {
      "x": -6,
      "y": 1,
      "z": 0,
      "name": "Wood_Drywood_Planks"
    },
    {
      "x": -6,
      "y": 4,
      "z": 0,
      "name": "Wood_Drywood_Planks_Half",
      "rotation": 8
    },
    {
      "x": -6,
      "y": 5,
      "z": 0,
      "name": "Wood_Drywood_Fence"
    },
    {
      "x": -6,
      "y": 6,
      "z": 0,
      "name": "Wood_Drywood_Fence"
    },
    {
      "x": -6,
      "y": 7,
      "z": 0,
      "name": "Wood_Drywood_Fence"
    },
    {
      "x": -6,
      "y": 8,
      "z": 0,
      "name": "Wood_Drywood_Planks",
      "support": 15
    },
    {
      "x": -6,
      "y": 0,
      "z": 1,
      "name": "Wood_Drywood_Planks"
    },
    {
      "x": -6,
      "y": 1,
      "z": 1,
      "name": "Wood_Drywood_Planks"
    },
    {
      "x": -6,
      "y": 4,
      "z": 1,
      "name": "Wood_Drywood_Planks_Half",
      "rotation": 8
    },
    {
      "x": -6,
      "y": 8,
      "z": 1,
      "name": "Wood_Drywood_Planks"
    },
    {
      "x": -6,
      "y": 0,
      "z": 2,
      "name": "Wood_Drywood_Planks"
    },
    {
      "x": -6,
      "y": 1,
      "z": 2,
      "name": "Wood_Drywood_Planks"
    },
    {
      "x": -6,
      "y": 4,
      "z": 2,
      "name": "Wood_Drywood_Stairs",
      "rotation": 8
    },
    {
      "x": -6,
      "y": 8,
      "z": 2,
      "name": "Wood_Drywood_Planks"
    },
    {
      "x": -6,
      "y": 0,
      "z": 3,
      "name": "Wood_Drywood_Planks"
    },
    {
      "x": -6,
      "y": 1,
      "z": 3,
      "name": "Wood_Drywood_Stairs",
      "rotation": 2
    },
    {
      "x": -6,
      "y": 4,
      "z": 3,
      "name": "Wood_Drywood_Planks"
    },
    {
      "x": -6,
      "y": 8,
      "z": 3,
      "name": "Wood_Drywood_Planks"
    },
    {
      "x": -6,
      "y": 1,
      "z": 4,
      "name": "Wood_Drywood_Planks"
    },
    {
      "x": -6,
      "y": 4,
      "z": 4,
      "name": "Wood_Drywood_Planks"
    },
    {
      "x": -6,
      "y": 8,
      "z": 4,
      "name": "Wood_Drywood_Planks"
    },
    {
      "x": -6,
      "y": 1,
      "z": 5,
      "name": "Wood_Drywood_Planks"
    },
    {
      "x": -6,
      "y": 2,
      "z": 5,
      "name": "Wood_Drywood_Stairs",
      "rotation": 8
    },
    {
      "x": -6,
      "y": 4,
      "z": 5,
      "name": "Wood_Drywood_Stairs",
      "rotation": 10
    },
    {
      "x": -6,
      "y": 2,
      "z": 6,
      "name": "Wood_Drywood_Planks"
    },
    {
      "x": -6,
      "y": 4,
      "z": 6,
      "name": "Wood_Drywood_Stairs",
      "rotation": 8
    },
    {
      "x": -6,
      "y": 3,
      "z": 7,
      "name": "Wood_Drywood_Planks"
    },
    {
      "x": -6,
      "y": 4,
      "z": 7,
      "name": "Wood_Drywood_Planks"
    },
    {
      "x": -6,
      "y": 5,
      "z": 7,
      "name": "Wood_Drywood_Stairs",
      "rotation": 1
    },
    {
      "x": -6,
      "y": 5,
      "z": 8,
      "name": "Wood_Drywood_Planks"
    },
    {
      "x": -5,
      "y": 5,
      "z": -8,
      "name": "Wood_Drywood_Planks"
    },
    {
      "x": -5,
      "y": 6,
      "z": -8,
      "name": "Wood_Drywood_Planks"
    },
    {
      "x": -5,
      "y": 7,
      "z": -8,
      "name": "Wood_Drywood_Planks"
    },
    {
      "x": -5,
      "y": 8,
      "z": -8,
      "name": "Wood_Drywood_Decorative"
    },
    {
      "x": -5,
      "y": 9,
      "z": -8,
      "name": "*Wood_Drywood_Fence_State_Definitions_Corner"
    },
    {
      "x": -5,
      "y": 3,
      "z": -7,
      "name": "Wood_Drywood_Planks"
    },
    {
      "x": -5,
      "y": 5,
      "z": -7,
      "name": "Wood_Drywood_Planks"
    },
    {
      "x": -5,
      "y": 6,
      "z": -7,
      "name": "Wood_Drywood_Planks"
    },
    {
      "x": -5,
      "y": 7,
      "z": -7,
      "name": "Wood_Drywood_Planks"
    },
    {
      "x": -5,
      "y": 8,
      "z": -7,
      "name": "Wood_Drywood_Planks"
    },
    {
      "x": -5,
      "y": 9,
      "z": -7,
      "name": "*Wood_Drywood_Fence_State_Definitions_Corner",
      "rotation": 2
    },
    {
      "x": -5,
      "y": 2,
      "z": -6,
      "name": "Wood_Drywood_Planks"
    },
    {
      "x": -5,
      "y": 7,
      "z": -6,
      "name": "Wood_Drywood_Stairs",
      "rotation": 9
    },
    {
      "x": -5,
      "y": 8,
      "z": -6,
      "name": "Wood_Drywood_Planks"
    },
    {
      "x": -5,
      "y": 1,
      "z": -5,
      "name": "Wood_Drywood_Planks"
    },
    {
      "x": -5,
      "y": 2,
      "z": -5,
      "name": "Wood_Drywood_Stairs",
      "rotation": 10
    },
    {
      "x": -5,
      "y": 8,
      "z": -5,
      "name": "Wood_Drywood_Planks"
    },
    {
      "x": -5,
      "y": 1,
      "z": -4,
      "name": "Wood_Drywood_Planks"
    },
    {
      "x": -5,
      "y": 8,
      "z": -4,
      "name": "Wood_Drywood_Planks"
    },
    {
      "x": -5,
      "y": 0,
      "z": -3,
      "name": "Wood_Drywood_Planks"
    },
    {
      "x": -5,
      "y": 1,
      "z": -3,
      "name": "Wood_Drywood_Planks"
    },
    {
      "x": -5,
      "y": 8,
      "z": -3,
      "name": "Wood_Drywood_Planks"
    },
    {
      "x": -5,
      "y": 0,
      "z": -2,
      "name": "Wood_Drywood_Planks"
    },
    {
      "x": -5,
      "y": 1,
      "z": -2,
      "name": "Wood_Drywood_Planks"
    },
    {
      "x": -5,
      "y": 8,
      "z": -2,
      "name": "Wood_Drywood_Planks"
    },
    {
      "x": -5,
      "y": 0,
      "z": -1,
      "name": "Wood_Drywood_Planks"
    },
    {
      "x": -5,
      "y": 1,
      "z": -1,
      "name": "Wood_Drywood_Planks"
    },
    {
      "x": -5,
      "y": 4,
      "z": -1,
      "name": "Wood_Drywood_Planks_Half",
      "rotation": 8
    },
    {
      "x": -5,
      "y": 8,
      "z": -1,
      "name": "Wood_Drywood_Planks"
    },
    {
      "x": -5,
      "y": 0,
      "z": 0,
      "name": "Wood_Drywood_Planks"
    },
    {
      "x": -5,
      "y": 1,
      "z": 0,
      "name": "Wood_Drywood_Planks"
    },
    {
      "x": -5,
      "y": 7,
      "z": 0,
      "name": "Wood_Drywood_Fence"
    },
    {
      "x": -5,
      "y": 8,
      "z": 0,
      "name": "Wood_Drywood_Planks",
      "support": 15
    },
    {
      "x": -5,
      "y": 0,
      "z": 1,
      "name": "Wood_Drywood_Planks"
    },
    {
      "x": -5,
      "y": 1,
      "z": 1,
      "name": "Wood_Drywood_Planks"
    },
    {
      "x": -5,
      "y": 4,
      "z": 1,
      "name": "Wood_Drywood_Planks_Half",
      "rotation": 8
    },
    {
      "x": -5,
      "y": 8,
      "z": 1,
      "name": "Wood_Drywood_Planks"
    },
    {
      "x": -5,
      "y": 0,
      "z": 2,
      "name": "Wood_Drywood_Planks"
    },
    {
      "x": -5,
      "y": 1,
      "z": 2,
      "name": "Wood_Drywood_Planks"
    },
    {
      "x": -5,
      "y": 4,
      "z": 2,
      "name": "Wood_Drywood_Stairs",
      "rotation": 8
    },
    {
      "x": -5,
      "y": 8,
      "z": 2,
      "name": "Wood_Drywood_Planks"
    },
    {
      "x": -5,
      "y": 0,
      "z": 3,
      "name": "Wood_Drywood_Planks"
    },
    {
      "x": -5,
      "y": 1,
      "z": 3,
      "name": "Wood_Drywood_Planks"
    },
    {
      "x": -5,
      "y": 4,
      "z": 3,
      "name": "Wood_Drywood_Planks"
    },
    {
      "x": -5,
      "y": 8,
      "z": 3,
      "name": "Wood_Drywood_Planks"
    },
    {
      "x": -5,
      "y": 1,
      "z": 4,
      "name": "Wood_Drywood_Planks"
    },
    {
      "x": -5,
      "y": 4,
      "z": 4,
      "name": "Wood_Drywood_Planks"
    },
    {
      "x": -5,
      "y": 8,
      "z": 4,
      "name": "Wood_Drywood_Planks"
    },
    {
      "x": -5,
      "y": 1,
      "z": 5,
      "name": "Wood_Drywood_Planks"
    },
    {
      "x": -5,
      "y": 2,
      "z": 5,
      "name": "Wood_Drywood_Stairs",
      "rotation": 8
    },
    {
      "x": -5,
      "y": 4,
      "z": 5,
      "name": "Wood_Drywood_Stairs",
      "rotation": 10
    },
    {
      "x": -5,
      "y": 2,
      "z": 6,
      "name": "Wood_Drywood_Planks"
    },
    {
      "x": -5,
      "y": 3,
      "z": 6,
      "name": "Deco_Trash_Pile_Small",
      "rotation": 2
    },
    {
      "x": -5,
      "y": 4,
      "z": 6,
      "name": "Wood_Drywood_Stairs",
      "rotation": 8
    },
    {
      "x": -5,
      "y": 3,
      "z": 7,
      "name": "Wood_Drywood_Planks"
    },
    {
      "x": -5,
      "y": 4,
      "z": 7,
      "name": "Wood_Drywood_Planks"
    },
    {
      "x": -4,
      "y": 6,
      "z": -7,
      "name": "Wood_Drywood_Planks"
    },
    {
      "x": -4,
      "y": 7,
      "z": -7,
      "name": "Wood_Drywood_Planks"
    },
    {
      "x": -4,
      "y": 8,
      "z": -7,
      "name": "Wood_Drywood_Decorative"
    },
    {
      "x": -4,
      "y": 9,
      "z": -7,
      "name": "Wood_Drywood_Fence",
      "rotation": 2
    },
    {
      "x": -4,
      "y": 7,
      "z": -6,
      "name": "Wood_Drywood_Planks"
    },
    {
      "x": -4,
      "y": 8,
      "z": -6,
      "name": "Wood_Drywood_Planks"
    },
    {
      "x": -4,
      "y": 1,
      "z": -5,
      "name": "Wood_Drywood_Planks"
    },
    {
      "x": -4,
      "y": 2,
      "z": -5,
      "name": "Wood_Drywood_Planks"
    },
    {
      "x": -4,
      "y": 8,
      "z": -5,
      "name": "Wood_Drywood_Planks"
    },
    {
      "x": -4,
      "y": 1,
      "z": -4,
      "name": "Wood_Drywood_Planks"
    },
    {
      "x": -4,
      "y": 0,
      "z": -3,
      "name": "Wood_Drywood_Planks"
    },
    {
      "x": -4,
      "y": 1,
      "z": -3,
      "name": "Wood_Drywood_Stairs"
    },
    {
      "x": -4,
      "y": 0,
      "z": -2,
      "name": "Wood_Drywood_Planks"
    },
    {
      "x": -4,
      "y": 1,
      "z": -2,
      "name": "Wood_Drywood_Planks"
    },
    {
      "x": -4,
      "y": 8,
      "z": -2,
      "name": "Wood_Drywood_Planks"
    },
    {
      "x": -4,
      "y": 0,
      "z": -1,
      "name": "Wood_Drywood_Planks"
    },
    {
      "x": -4,
      "y": 1,
      "z": -1,
      "name": "Wood_Drywood_Planks"
    },
    {
      "x": -4,
      "y": 8,
      "z": -1,
      "name": "Wood_Drywood_Planks"
    },
    {
      "x": -4,
      "y": 0,
      "z": 0,
      "name": "Wood_Drywood_Planks"
    },
    {
      "x": -4,
      "y": 1,
      "z": 0,
      "name": "Wood_Drywood_Planks"
    },
    {
      "x": -4,
      "y": 8,
      "z": 0,
      "name": "Wood_Drywood_Planks",
      "support": 15
    },
    {
      "x": -4,
      "y": 0,
      "z": 1,
      "name": "Wood_Drywood_Planks"
    },
    {
      "x": -4,
      "y": 1,
      "z": 1,
      "name": "Wood_Drywood_Planks"
    },
    {
      "x": -4,
      "y": 8,
      "z": 1,
      "name": "Wood_Drywood_Planks"
    },
    {
      "x": -4,
      "y": 0,
      "z": 2,
      "name": "Wood_Drywood_Planks"
    },
    {
      "x": -4,
      "y": 1,
      "z": 2,
      "name": "Wood_Drywood_Planks"
    },
    {
      "x": -4,
      "y": 4,
      "z": 2,
      "name": "Wood_Drywood_Stairs",
      "rotation": 8
    },
    {
      "x": -4,
      "y": 8,
      "z": 2,
      "name": "Wood_Drywood_Planks"
    },
    {
      "x": -4,
      "y": 0,
      "z": 3,
      "name": "Wood_Drywood_Planks"
    },
    {
      "x": -4,
      "y": 1,
      "z": 3,
      "name": "Wood_Drywood_Stairs",
      "rotation": 2
    },
    {
      "x": -4,
      "y": 4,
      "z": 3,
      "name": "Wood_Drywood_Planks"
    },
    {
      "x": -4,
      "y": 8,
      "z": 3,
      "name": "Wood_Drywood_Planks"
    },
    {
      "x": -4,
      "y": 1,
      "z": 4,
      "name": "Wood_Drywood_Planks"
    },
    {
      "x": -4,
      "y": 2,
      "z": 4,
      "name": "Deco_Trash_Pile_Small",
      "rotation": 2
    },
    {
      "x": -4,
      "y": 4,
      "z": 4,
      "name": "Wood_Drywood_Planks"
    },
    {
      "x": -4,
      "y": 1,
      "z": 5,
      "name": "Wood_Drywood_Planks"
    },
    {
      "x": -4,
      "y": 2,
      "z": 5,
      "name": "Wood_Drywood_Planks"
    },
    {
      "x": -4,
      "y": 4,
      "z": 5,
      "name": "Wood_Drywood_Stairs",
      "rotation": 10
    },
    {
      "x": -4,
      "y": 2,
      "z": 6,
      "name": "Wood_Drywood_Planks"
    },
    {
      "x": -4,
      "y": 3,
      "z": 6,
      "name": "Deco_Trash_Pile_Small",
      "rotation": 2
    },
    {
      "x": -4,
      "y": 4,
      "z": 6,
      "name": "Wood_Drywood_Stairs",
      "rotation": 8
    },
    {
      "x": -4,
      "y": 3,
      "z": 7,
      "name": "Wood_Drywood_Planks"
    },
    {
      "x": -3,
      "y": 7,
      "z": -7,
      "name": "Wood_Drywood_Planks"
    },
    {
      "x": -3,
      "y": 8,
      "z": -7,
      "name": "Wood_Drywood_Decorative"
    },
    {
      "x": -3,
      "y": 9,
      "z": -7,
      "name": "Wood_Drywood_Fence",
      "rotation": 2
    },
    {
      "x": -3,
      "y": 7,
      "z": -6,
      "name": "Wood_Dry_Trunk",
      "support": 15
    },
    {
      "x": -3,
      "y": 8,
      "z": -6,
      "name": "Wood_Drywood_Planks"
    },
    {
      "x": -3,
      "y": 1,
      "z": -5,
      "name": "Wood_Drywood_Planks"
    },
    {
      "x": -3,
      "y": 7,
      "z": -5,
      "name": "Wood_Dry_Trunk_Stairs",
      "rotation": 10
    },
    {
      "x": -3,
      "y": 8,
      "z": -5,
      "name": "Wood_Drywood_Planks"
    },
    {
      "x": -3,
      "y": 1,
      "z": -4,
      "name": "Wood_Drywood_Planks"
    },
    {
      "x": -3,
      "y": 8,
      "z": -4,
      "name": "Wood_Drywood_Planks"
    },
    {
      "x": -3,
      "y": 0,
      "z": -3,
      "name": "Wood_Drywood_Planks"
    },
    {
      "x": -3,
      "y": 1,
      "z": -3,
      "name": "Wood_Dry_Trunk",
      "support": 15,
      "rotation": 4
    },
    {
      "x": -3,
      "y": 0,
      "z": -2,
      "name": "Wood_Drywood_Planks"
    },
    {
      "x": -3,
      "y": 1,
      "z": -2,
      "name": "Wood_Dry_Trunk",
      "support": 15,
      "rotation": 4
    },
    {
      "x": -3,
      "y": 0,
      "z": -1,
      "name": "Wood_Drywood_Planks"
    },
    {
      "x": -3,
      "y": 1,
      "z": -1,
      "name": "Wood_Dry_Trunk",
      "support": 15,
      "rotation": 4
    },
    {
      "x": -3,
      "y": 2,
      "z": -1,
      "name": "Wood_Dry_Trunk_Stairs",
      "rotation": 2
    },
    {
      "x": -3,
      "y": 0,
      "z": 0,
      "name": "Wood_Drywood_Planks"
    },
    {
      "x": -3,
      "y": 1,
      "z": 0,
      "name": "Wood_Dry_Trunk",
      "support": 15
    },
    {
      "x": -3,
      "y": 2,
      "z": 0,
      "name": "Wood_Dry_Trunk",
      "support": 15
    },
    {
      "x": -3,
      "y": 8,
      "z": 0,
      "name": "Wood_Drywood_Planks",
      "support": 15
    },
    {
      "x": -3,
      "y": 0,
      "z": 1,
      "name": "Wood_Drywood_Planks"
    },
    {
      "x": -3,
      "y": 1,
      "z": 1,
      "name": "Wood_Dry_Trunk",
      "support": 15,
      "rotation": 4
    },
    {
      "x": -3,
      "y": 2,
      "z": 1,
      "name": "Wood_Dry_Trunk_Stairs"
    },
    {
      "x": -3,
      "y": 8,
      "z": 1,
      "name": "Wood_Drywood_Planks"
    },
    {
      "x": -3,
      "y": 0,
      "z": 2,
      "name": "Wood_Drywood_Planks"
    },
    {
      "x": -3,
      "y": 1,
      "z": 2,
      "name": "Wood_Dry_Trunk",
      "support": 15,
      "rotation": 4
    },
    {
      "x": -3,
      "y": 8,
      "z": 2,
      "name": "Wood_Drywood_Planks"
    },
    {
      "x": -3,
      "y": 0,
      "z": 3,
      "name": "Wood_Drywood_Planks"
    },
    {
      "x": -3,
      "y": 1,
      "z": 3,
      "name": "Wood_Dry_Trunk",
      "support": 15,
      "rotation": 4
    },
    {
      "x": -3,
      "y": 2,
      "z": 3,
      "name": "Wood_Dry_Trunk_Stairs",
      "rotation": 2
    },
    {
      "x": -3,
      "y": 4,
      "z": 3,
      "name": "Wood_Drywood_Planks"
    },
    {
      "x": -3,
      "y": 8,
      "z": 3,
      "name": "Wood_Drywood_Planks"
    },
    {
      "x": -3,
      "y": 1,
      "z": 4,
      "name": "Wood_Drywood_Planks"
    },
    {
      "x": -3,
      "y": 2,
      "z": 4,
      "name": "Wood_Dry_Trunk_Full",
      "support": 15,
      "rotation": 4
    },
    {
      "x": -3,
      "y": 3,
      "z": 4,
      "name": "Wood_Drywood_Fence",
      "rotation": 3
    },
    {
      "x": -3,
      "y": 4,
      "z": 4,
      "name": "Wood_Drywood_Planks"
    },
    {
      "x": -3,
      "y": 1,
      "z": 5,
      "name": "Wood_Drywood_Planks"
    },
    {
      "x": -3,
      "y": 2,
      "z": 5,
      "name": "Wood_Dry_Trunk",
      "support": 15,
      "rotation": 4
    },
    {
      "x": -3,
      "y": 3,
      "z": 5,
      "name": "Wood_Dry_Trunk_Full",
      "support": 15
    },
    {
      "x": -3,
      "y": 4,
      "z": 5,
      "name": "Wood_Drywood_Planks"
    },
    {
      "x": -3,
      "y": 2,
      "z": 6,
      "name": "Wood_Drywood_Planks"
    },
    {
      "x": -3,
      "y": 3,
      "z": 6,
      "name": "Wood_Drywood_Planks"
    },
    {
      "x": -2,
      "y": 6,
      "z": -7,
      "name": "Wood_Drywood_Planks"
    },
    {
      "x": -2,
      "y": 7,
      "z": -7,
      "name": "Wood_Drywood_Planks"
    },
    {
      "x": -2,
      "y": 8,
      "z": -7,
      "name": "Wood_Drywood_Decorative"
    },
    {
      "x": -2,
      "y": 9,
      "z": -7,
      "name": "Wood_Drywood_Fence",
      "rotation": 2
    },
    {
      "x": -2,
      "y": 7,
      "z": -6,
      "name": "Wood_Drywood_Planks"
    },
    {
      "x": -2,
      "y": 8,
      "z": -6,
      "name": "Wood_Drywood_Planks"
    },
    {
      "x": -2,
      "y": 1,
      "z": -5,
      "name": "Wood_Drywood_Planks"
    },
    {
      "x": -2,
      "y": 2,
      "z": -5,
      "name": "Wood_Drywood_Planks"
    },
    {
      "x": -2,
      "y": 8,
      "z": -5,
      "name": "Wood_Drywood_Planks"
    },
    {
      "x": -2,
      "y": 1,
      "z": -4,
      "name": "Wood_Drywood_Planks"
    },
    {
      "x": -2,
      "y": 8,
      "z": -4,
      "name": "Wood_Drywood_Planks"
    },
    {
      "x": -2,
      "y": 0,
      "z": -3,
      "name": "Wood_Drywood_Planks"
    },
    {
      "x": -2,
      "y": 1,
      "z": -3,
      "name": "Wood_Drywood_Stairs"
    },
    {
      "x": -2,
      "y": 8,
      "z": -3,
      "name": "Wood_Drywood_Planks"
    },
    {
      "x": -2,
      "y": 9,
      "z": -3,
      "name": "Wood_Drywood_Planks"
    },
    {
      "x": -2,
      "y": 10,
      "z": -3,
      "name": "Wood_Drywood_Stairs",
      "rotation": 3
    },
    {
      "x": -2,
      "y": 0,
      "z": -2,
      "name": "Wood_Drywood_Planks"
    },
    {
      "x": -2,
      "y": 1,
      "z": -2,
      "name": "Wood_Drywood_Planks"
    },
    {
      "x": -2,
      "y": 8,
      "z": -2,
      "name": "Wood_Drywood_Planks"
    },
    {
      "x": -2,
      "y": 9,
      "z": -2,
      "name": "Wood_Drywood_Stairs",
      "rotation": 3
    },
    {
      "x": -2,
      "y": 0,
      "z": -1,
      "name": "Wood_Drywood_Planks"
    },
    {
      "x": -2,
      "y": 1,
      "z": -1,
      "name": "Wood_Drywood_Planks"
    },
    {
      "x": -2,
      "y": 8,
      "z": -1,
      "name": "Wood_Drywood_Planks"
    },
    {
      "x": -2,
      "y": 9,
      "z": -1,
      "name": "Wood_Drywood_Stairs",
      "rotation": 3
    },
    {
      "x": -2,
      "y": 0,
      "z": 0,
      "name": "Wood_Drywood_Planks"
    },
    {
      "x": -2,
      "y": 1,
      "z": 0,
      "name": "Wood_Drywood_Planks"
    },
    {
      "x": -2,
      "y": 8,
      "z": 0,
      "name": "Wood_Drywood_Planks",
      "support": 15
    },
    {
      "x": -2,
      "y": 9,
      "z": 0,
      "name": "Wood_Drywood_Stairs",
      "rotation": 3
    },
    {
      "x": -2,
      "y": 0,
      "z": 1,
      "name": "Wood_Drywood_Planks"
    },
    {
      "x": -2,
      "y": 1,
      "z": 1,
      "name": "Wood_Drywood_Planks"
    },
    {
      "x": -2,
      "y": 8,
      "z": 1,
      "name": "Wood_Drywood_Planks"
    },
    {
      "x": -2,
      "y": 9,
      "z": 1,
      "name": "Wood_Drywood_Stairs",
      "rotation": 3
    },
    {
      "x": -2,
      "y": 0,
      "z": 2,
      "name": "Wood_Drywood_Planks"
    },
    {
      "x": -2,
      "y": 1,
      "z": 2,
      "name": "Wood_Drywood_Planks"
    },
    {
      "x": -2,
      "y": 0,
      "z": 3,
      "name": "Wood_Drywood_Planks"
    },
    {
      "x": -2,
      "y": 1,
      "z": 3,
      "name": "Wood_Drywood_Stairs",
      "rotation": 2
    },
    {
      "x": -2,
      "y": 1,
      "z": 4,
      "name": "Wood_Drywood_Planks"
    },
    {
      "x": -2,
      "y": 2,
      "z": 4,
      "name": "Deco_Treasure_Pile_Small",
      "rotation": 2
    },
    {
      "x": -2,
      "y": 4,
      "z": 4,
      "name": "Wood_Drywood_Planks"
    },
    {
      "x": -2,
      "y": 1,
      "z": 5,
      "name": "Wood_Drywood_Planks"
    },
    {
      "x": -2,
      "y": 2,
      "z": 5,
      "name": "Wood_Drywood_Planks"
    },
    {
      "x": -2,
      "y": 4,
      "z": 5,
      "name": "Wood_Drywood_Stairs",
      "rotation": 8
    },
    {
      "x": -2,
      "y": 2,
      "z": 6,
      "name": "Wood_Drywood_Planks"
    },
    {
      "x": -2,
      "y": 3,
      "z": 6,
      "name": "Wood_Drywood_Planks"
    },
    {
      "x": -1,
      "y": 5,
      "z": -7,
      "name": "Wood_Drywood_Planks"
    },
    {
      "x": -1,
      "y": 6,
      "z": -7,
      "name": "Wood_Drywood_Planks"
    },
    {
      "x": -1,
      "y": 7,
      "z": -7,
      "name": "Wood_Drywood_Planks"
    },
    {
      "x": -1,
      "y": 8,
      "z": -7,
      "name": "Wood_Drywood_Decorative"
    },
    {
      "x": -1,
      "y": 9,
      "z": -7,
      "name": "Wood_Drywood_Fence",
      "rotation": 2
    },
    {
      "x": -1,
      "y": 2,
      "z": -6,
      "name": "Wood_Drywood_Planks"
    },
    {
      "x": -1,
      "y": 6,
      "z": -6,
      "name": "Wood_Drywood_Planks"
    },
    {
      "x": -1,
      "y": 7,
      "z": -6,
      "name": "Wood_Drywood_Planks"
    },
    {
      "x": -1,
      "y": 8,
      "z": -6,
      "name": "Wood_Drywood_Planks"
    },
    {
      "x": -1,
      "y": 1,
      "z": -5,
      "name": "Wood_Drywood_Planks"
    },
    {
      "x": -1,
      "y": 2,
      "z": -5,
      "name": "Wood_Drywood_Planks"
    },
    {
      "x": -1,
      "y": 7,
      "z": -5,
      "name": "Wood_Drywood_Stairs",
      "rotation": 9
    },
    {
      "x": -1,
      "y": 8,
      "z": -5,
      "name": "Wood_Drywood_Planks"
    },
    {
      "x": -1,
      "y": 1,
      "z": -4,
      "name": "Wood_Drywood_Planks"
    },
    {
      "x": -1,
      "y": 8,
      "z": -4,
      "name": "Wood_Drywood_Planks"
    },
    {
      "x": -1,
      "y": 0,
      "z": -3,
      "name": "Wood_Drywood_Planks"
    },
    {
      "x": -1,
      "y": 1,
      "z": -3,
      "name": "Wood_Drywood_Planks"
    },
    {
      "x": -1,
      "y": 8,
      "z": -3,
      "name": "Wood_Drywood_Planks"
    },
    {
      "x": -1,
      "y": 9,
      "z": -3,
      "name": "Wood_Drywood_Planks"
    },
    {
      "x": -1,
      "y": 10,
      "z": -3,
      "name": "Wood_Drywood_Planks"
    },
    {
      "x": -1,
      "y": 11,
      "z": -3,
      "name": "Wood_Drywood_Stairs",
      "rotation": 3
    },
    {
      "x": -1,
      "y": 0,
      "z": -2,
      "name": "Wood_Drywood_Planks"
    },
    {
      "x": -1,
      "y": 1,
      "z": -2,
      "name": "Wood_Drywood_Planks"
    },
    {
      "x": -1,
      "y": 8,
      "z": -2,
      "name": "Wood_Drywood_Planks"
    },
    {
      "x": -1,
      "y": 9,
      "z": -2,
      "name": "Wood_Drywood_Planks"
    },
    {
      "x": -1,
      "y": 10,
      "z": -2,
      "name": "Wood_Drywood_Stairs",
      "rotation": 3
    },
    {
      "x": -1,
      "y": 0,
      "z": -1,
      "name": "Wood_Drywood_Planks"
    },
    {
      "x": -1,
      "y": 1,
      "z": -1,
      "name": "Wood_Drywood_Planks"
    },
    {
      "x": -1,
      "y": 4,
      "z": -1,
      "name": "Wood_Drywood_Planks_Half",
      "rotation": 8
    },
    {
      "x": -1,
      "y": 8,
      "z": -1,
      "name": "Wood_Drywood_Planks"
    },
    {
      "x": -1,
      "y": 9,
      "z": -1,
      "name": "Wood_Drywood_Planks"
    },
    {
      "x": -1,
      "y": 10,
      "z": -1,
      "name": "Wood_Drywood_Stairs",
      "rotation": 3
    },
    {
      "x": -1,
      "y": 0,
      "z": 0,
      "name": "Wood_Drywood_Planks"
    },
    {
      "x": -1,
      "y": 1,
      "z": 0,
      "name": "Wood_Drywood_Planks"
    },
    {
      "x": -1,
      "y": 7,
      "z": 0,
      "name": "Wood_Drywood_Fence"
    },
    {
      "x": -1,
      "y": 8,
      "z": 0,
      "name": "Wood_Drywood_Planks",
      "support": 15
    },
    {
      "x": -1,
      "y": 9,
      "z": 0,
      "name": "Wood_Drywood_Planks"
    },
    {
      "x": -1,
      "y": 10,
      "z": 0,
      "name": "Wood_Drywood_Stairs",
      "rotation": 3
    },
    {
      "x": -1,
      "y": 0,
      "z": 1,
      "name": "Wood_Drywood_Planks"
    },
    {
      "x": -1,
      "y": 1,
      "z": 1,
      "name": "Wood_Drywood_Planks"
    },
    {
      "x": -1,
      "y": 4,
      "z": 1,
      "name": "Wood_Drywood_Planks_Half",
      "rotation": 8
    },
    {
      "x": -1,
      "y": 9,
      "z": 1,
      "name": "Wood_Drywood_Planks"
    },
    {
      "x": -1,
      "y": 10,
      "z": 1,
      "name": "Wood_Drywood_Stairs",
      "rotation": 3
    },
    {
      "x": -1,
      "y": 0,
      "z": 2,
      "name": "Wood_Drywood_Planks"
    },
    {
      "x": -1,
      "y": 1,
      "z": 2,
      "name": "Wood_Drywood_Planks"
    },
    {
      "x": -1,
      "y": 4,
      "z": 2,
      "name": "Wood_Drywood_Stairs",
      "rotation": 8
    },
    {
      "x": -1,
      "y": 0,
      "z": 3,
      "name": "Wood_Drywood_Planks"
    },
    {
      "x": -1,
      "y": 1,
      "z": 3,
      "name": "Wood_Drywood_Planks"
    },
    {
      "x": -1,
      "y": 4,
      "z": 3,
      "name": "Wood_Drywood_Planks"
    },
    {
      "x": -1,
      "y": 1,
      "z": 4,
      "name": "Wood_Drywood_Planks"
    },
    {
      "x": -1,
      "y": 4,
      "z": 4,
      "name": "Wood_Drywood_Planks"
    },
    {
      "x": -1,
      "y": 1,
      "z": 5,
      "name": "Wood_Drywood_Planks"
    },
    {
      "x": -1,
      "y": 2,
      "z": 5,
      "name": "Wood_Drywood_Planks"
    },
    {
      "x": -1,
      "y": 4,
      "z": 5,
      "name": "Wood_Drywood_Stairs",
      "rotation": 8
    },
    {
      "x": -1,
      "y": 2,
      "z": 6,
      "name": "Wood_Drywood_Planks"
    },
    {
      "x": -1,
      "y": 3,
      "z": 6,
      "name": "Wood_Drywood_Planks"
    },
    {
      "x": 0,
      "y": 4,
      "z": -7,
      "name": "Wood_Drywood_Planks"
    },
    {
      "x": 0,
      "y": 5,
      "z": -7,
      "name": "Wood_Drywood_Planks"
    },
    {
      "x": 0,
      "y": 6,
      "z": -7,
      "name": "Wood_Drywood_Planks"
    },
    {
      "x": 0,
      "y": 7,
      "z": -7,
      "name": "Wood_Drywood_Planks"
    },
    {
      "x": 0,
      "y": 8,
      "z": -7,
      "name": "Wood_Drywood_Decorative"
    },
    {
      "x": 0,
      "y": 9,
      "z": -7,
      "name": "*Wood_Drywood_Fence_State_Definitions_Corner"
    },
    {
      "x": 0,
      "y": 2,
      "z": -6,
      "name": "Wood_Drywood_Planks"
    },
    {
      "x": 0,
      "y": 3,
      "z": -6,
      "name": "Wood_Drywood_Planks"
    },
    {
      "x": 0,
      "y": 4,
      "z": -6,
      "name": "Wood_Drywood_Planks"
    },
    {
      "x": 0,
      "y": 5,
      "z": -6,
      "name": "Wood_Drywood_Planks"
    },
    {
      "x": 0,
      "y": 6,
      "z": -6,
      "name": "Wood_Drywood_Planks"
    },
    {
      "x": 0,
      "y": 7,
      "z": -6,
      "name": "Wood_Drywood_Planks"
    },
    {
      "x": 0,
      "y": 8,
      "z": -6,
      "name": "Wood_Drywood_Planks"
    },
    {
      "x": 0,
      "y": 9,
      "z": -6,
      "name": "*Wood_Drywood_Fence_State_Definitions_Corner",
      "rotation": 2
    },
    {
      "x": 0,
      "y": 1,
      "z": -5,
      "name": "Wood_Drywood_Planks"
    },
    {
      "x": 0,
      "y": 2,
      "z": -5,
      "name": "Wood_Drywood_Planks"
    },
    {
      "x": 0,
      "y": 3,
      "z": -5,
      "name": "Deco_Trash_Pile_Small"
    },
    {
      "x": 0,
      "y": 4,
      "z": -5,
      "name": "Wood_Drywood_Stairs",
      "rotation": 10
    },
    {
      "x": 0,
      "y": 5,
      "z": -5,
      "name": "Wood_Drywood_Stairs",
      "rotation": 3
    },
    {
      "x": 0,
      "y": 6,
      "z": -5,
      "name": "Wood_Drywood_Stairs",
      "rotation": 9
    },
    {
      "x": 0,
      "y": 7,
      "z": -5,
      "name": "Wood_Drywood_Planks"
    },
    {
      "x": 0,
      "y": 8,
      "z": -5,
      "name": "Wood_Drywood_Planks"
    },
    {
      "x": 0,
      "y": 1,
      "z": -4,
      "name": "Wood_Drywood_Planks"
    },
    {
      "x": 0,
      "y": 4,
      "z": -4,
      "name": "Wood_Drywood_Planks"
    },
    {
      "x": 0,
      "y": 8,
      "z": -4,
      "name": "Wood_Drywood_Planks"
    },
    {
      "x": 0,
      "y": 0,
      "z": -3,
      "name": "Wood_Drywood_Planks"
    },
    {
      "x": 0,
      "y": 1,
      "z": -3,
      "name": "Wood_Drywood_Stairs"
    },
    {
      "x": 0,
      "y": 4,
      "z": -3,
      "name": "Wood_Drywood_Planks"
    },
    {
      "x": 0,
      "y": 8,
      "z": -3,
      "name": "Wood_Drywood_Planks"
    },
    {
      "x": 0,
      "y": 9,
      "z": -3,
      "name": "Wood_Drywood_Planks"
    },
    {
      "x": 0,
      "y": 10,
      "z": -3,
      "name": "Wood_Drywood_Planks"
    },
    {
      "x": 0,
      "y": 11,
      "z": -3,
      "name": "Wood_Drywood_Planks"
    },
    {
      "x": 0,
      "y": 12,
      "z": -3,
      "name": "Wood_Drywood_Stairs",
      "rotation": 3
    },
    {
      "x": 0,
      "y": 0,
      "z": -2,
      "name": "Wood_Drywood_Planks"
    },
    {
      "x": 0,
      "y": 1,
      "z": -2,
      "name": "Wood_Drywood_Planks"
    },
    {
      "x": 0,
      "y": 4,
      "z": -2,
      "name": "Wood_Drywood_Stairs",
      "rotation": 10
    },
    {
      "x": 0,
      "y": 8,
      "z": -2,
      "name": "Wood_Drywood_Planks"
    },
    {
      "x": 0,
      "y": 9,
      "z": -2,
      "name": "Wood_Drywood_Planks"
    },
    {
      "x": 0,
      "y": 10,
      "z": -2,
      "name": "Wood_Drywood_Planks"
    },
    {
      "x": 0,
      "y": 11,
      "z": -2,
      "name": "Wood_Drywood_Stairs",
      "rotation": 3
    },
    {
      "x": 0,
      "y": 0,
      "z": -1,
      "name": "Wood_Drywood_Planks"
    },
    {
      "x": 0,
      "y": 1,
      "z": -1,
      "name": "Wood_Drywood_Planks"
    },
    {
      "x": 0,
      "y": 4,
      "z": -1,
      "name": "Wood_Drywood_Planks_Half",
      "rotation": 8
    },
    {
      "x": 0,
      "y": 8,
      "z": -1,
      "name": "Wood_Drywood_Planks"
    },
    {
      "x": 0,
      "y": 9,
      "z": -1,
      "name": "Wood_Drywood_Planks"
    },
    {
      "x": 0,
      "y": 10,
      "z": -1,
      "name": "Wood_Drywood_Planks"
    },
    {
      "x": 0,
      "y": 11,
      "z": -1,
      "name": "Wood_Drywood_Stairs",
      "rotation": 3
    },
    {
      "x": 0,
      "y": 0,
      "z": 0,
      "name": "Wood_Drywood_Planks"
    },
    {
      "x": 0,
      "y": 1,
      "z": 0,
      "name": "Wood_Drywood_Planks"
    },
    {
      "x": 0,
      "y": 4,
      "z": 0,
      "name": "Wood_Drywood_Planks_Half",
      "rotation": 8
    },
    {
      "x": 0,
      "y": 5,
      "z": 0,
      "name": "Wood_Drywood_Fence"
    },
    {
      "x": 0,
      "y": 6,
      "z": 0,
      "name": "Wood_Drywood_Fence"
    },
    {
      "x": 0,
      "y": 7,
      "z": 0,
      "name": "Wood_Drywood_Fence"
    },
    {
      "x": 0,
      "y": 8,
      "z": 0,
      "name": "Wood_Drywood_Planks",
      "support": 15
    },
    {
      "x": 0,
      "y": 9,
      "z": 0,
      "name": "Wood_Drywood_Planks"
    },
    {
      "x": 0,
      "y": 10,
      "z": 0,
      "name": "Wood_Drywood_Planks"
    },
    {
      "x": 0,
      "y": 11,
      "z": 0,
      "name": "Wood_Drywood_Stairs",
      "rotation": 3
    },
    {
      "x": 0,
      "y": 0,
      "z": 1,
      "name": "Wood_Drywood_Planks"
    },
    {
      "x": 0,
      "y": 1,
      "z": 1,
      "name": "Wood_Drywood_Planks"
    },
    {
      "x": 0,
      "y": 4,
      "z": 1,
      "name": "Wood_Drywood_Planks_Half",
      "rotation": 8
    },
    {
      "x": 0,
      "y": 8,
      "z": 1,
      "name": "Wood_Drywood_Planks"
    },
    {
      "x": 0,
      "y": 9,
      "z": 1,
      "name": "Wood_Drywood_Planks"
    },
    {
      "x": 0,
      "y": 10,
      "z": 1,
      "name": "Wood_Drywood_Planks"
    },
    {
      "x": 0,
      "y": 11,
      "z": 1,
      "name": "Wood_Drywood_Stairs",
      "rotation": 3
    },
    {
      "x": 0,
      "y": 0,
      "z": 2,
      "name": "Wood_Drywood_Planks"
    },
    {
      "x": 0,
      "y": 1,
      "z": 2,
      "name": "Wood_Drywood_Planks"
    },
    {
      "x": 0,
      "y": 2,
      "z": 2,
      "name": "Deco_Bone_Pile"
    },
    {
      "x": 0,
      "y": 4,
      "z": 2,
      "name": "Wood_Drywood_Stairs",
      "rotation": 8
    },
    {
      "x": 0,
      "y": 9,
      "z": 2,
      "name": "Wood_Drywood_Planks"
    },
    {
      "x": 0,
      "y": 10,
      "z": 2,
      "name": "Wood_Drywood_Planks"
    },
    {
      "x": 0,
      "y": 11,
      "z": 2,
      "name": "Wood_Drywood_Stairs",
      "rotation": 3
    },
    {
      "x": 0,
      "y": 0,
      "z": 3,
      "name": "Wood_Drywood_Planks"
    },
    {
      "x": 0,
      "y": 1,
      "z": 3,
      "name": "Wood_Drywood_Stairs",
      "rotation": 2
    },
    {
      "x": 0,
      "y": 4,
      "z": 3,
      "name": "Wood_Drywood_Planks"
    },
    {
      "x": 0,
      "y": 11,
      "z": 3,
      "name": "Wood_Drywood_Planks"
    },
    {
      "x": 0,
      "y": 12,
      "z": 3,
      "name": "Wood_Drywood_Stairs",
      "rotation": 3
    },
    {
      "x": 0,
      "y": 1,
      "z": 4,
      "name": "Wood_Drywood_Planks"
    },
    {
      "x": 0,
      "y": 4,
      "z": 4,
      "name": "Wood_Drywood_Planks"
    },
    {
      "x": 0,
      "y": 1,
      "z": 5,
      "name": "Wood_Drywood_Planks"
    },
    {
      "x": 0,
      "y": 2,
      "z": 5,
      "name": "Wood_Drywood_Planks"
    },
    {
      "x": 0,
      "y": 4,
      "z": 5,
      "name": "Wood_Drywood_Stairs",
      "rotation": 8
    },
    {
      "x": 0,
      "y": 5,
      "z": 5,
      "name": "Wood_Drywood_Stairs",
      "rotation": 3
    },
    {
      "x": 0,
      "y": 2,
      "z": 6,
      "name": "Wood_Drywood_Planks"
    },
    {
      "x": 0,
      "y": 3,
      "z": 6,
      "name": "Wood_Drywood_Planks"
    },
    {
      "x": 0,
      "y": 4,
      "z": 6,
      "name": "Wood_Drywood_Planks"
    },
    {
      "x": 1,
      "y": 3,
      "z": -6,
      "name": "Wood_Drywood_Planks"
    },
    {
      "x": 1,
      "y": 4,
      "z": -6,
      "name": "Wood_Drywood_Planks"
    },
    {
      "x": 1,
      "y": 5,
      "z": -6,
      "name": "Wood_Drywood_Planks"
    },
    {
      "x": 1,
      "y": 6,
      "z": -6,
      "name": "Wood_Drywood_Planks"
    },
    {
      "x": 1,
      "y": 7,
      "z": -6,
      "name": "Wood_Drywood_Planks"
    },
    {
      "x": 1,
      "y": 8,
      "z": -6,
      "name": "Wood_Drywood_Decorative"
    },
    {
      "x": 1,
      "y": 9,
      "z": -6,
      "name": "Wood_Drywood_Fence",
      "rotation": 2
    },
    {
      "x": 1,
      "y": 2,
      "z": -5,
      "name": "Wood_Drywood_Planks"
    },
    {
      "x": 1,
      "y": 3,
      "z": -5,
      "name": "Wood_Dry_Trunk",
      "support": 15
    },
    {
      "x": 1,
      "y": 4,
      "z": -5,
      "name": "Wood_Dry_Trunk",
      "support": 15
    },
    {
      "x": 1,
      "y": 5,
      "z": -5,
      "name": "Wood_Dry_Trunk",
      "support": 15
    },
    {
      "x": 1,
      "y": 6,
      "z": -5,
      "name": "Wood_Dry_Trunk",
      "support": 15
    },
    {
      "x": 1,
      "y": 7,
      "z": -5,
      "name": "Wood_Dry_Trunk",
      "support": 15
    },
    {
      "x": 1,
      "y": 8,
      "z": -5,
      "name": "Wood_Drywood_Planks"
    },
    {
      "x": 1,
      "y": 1,
      "z": -4,
      "name": "Wood_Drywood_Planks"
    },
    {
      "x": 1,
      "y": 2,
      "z": -4,
      "name": "Wood_Dry_Trunk_Full",
      "support": 15
    },
    {
      "x": 1,
      "y": 3,
      "z": -4,
      "name": "Wood_Drywood_Fence",
      "rotation": 3
    },
    {
      "x": 1,
      "y": 4,
      "z": -4,
      "name": "Wood_Drywood_Planks"
    },
    {
      "x": 1,
      "y": 7,
      "z": -4,
      "name": "Wood_Dry_Trunk_Stairs",
      "rotation": 10
    },
    {
      "x": 1,
      "y": 8,
      "z": -4,
      "name": "Wood_Drywood_Planks"
    },
    {
      "x": 1,
      "y": 9,
      "z": -4,
      "name": "Wood_Dry_Trunk",
      "support": 15
    },
    {
      "x": 1,
      "y": 10,
      "z": -4,
      "name": "Wood_Dry_Trunk",
      "support": 15
    },
    {
      "x": 1,
      "y": 11,
      "z": -4,
      "name": "Wood_Drywood_Decorative"
    },
    {
      "x": 1,
      "y": 12,
      "z": -4,
      "name": "Wood_Drywood_Planks"
    },
    {
      "x": 1,
      "y": 13,
      "z": -4,
      "name": "Wood_Drywood_Fence",
      "rotation": 2
    },
    {
      "x": 1,
      "y": 0,
      "z": -3,
      "name": "Wood_Drywood_Planks"
    },
    {
      "x": 1,
      "y": 1,
      "z": -3,
      "name": "Wood_Dry_Trunk",
      "support": 15,
      "rotation": 4
    },
    {
      "x": 1,
      "y": 2,
      "z": -3,
      "name": "Wood_Dry_Trunk_Stairs"
    },
    {
      "x": 1,
      "y": 4,
      "z": -3,
      "name": "Wood_Drywood_Planks"
    },
    {
      "x": 1,
      "y": 8,
      "z": -3,
      "name": "Wood_Drywood_Planks"
    },
    {
      "x": 1,
      "y": 9,
      "z": -3,
      "name": "Wood_Drywood_Planks"
    },
    {
      "x": 1,
      "y": 10,
      "z": -3,
      "name": "Wood_Drywood_Planks"
    },
    {
      "x": 1,
      "y": 11,
      "z": -3,
      "name": "Wood_Drywood_Decorative"
    },
    {
      "x": 1,
      "y": 12,
      "z": -3,
      "name": "Wood_Drywood_Planks"
    },
    {
      "x": 1,
      "y": 0,
      "z": -2,
      "name": "Wood_Drywood_Planks"
    },
    {
      "x": 1,
      "y": 1,
      "z": -2,
      "name": "Wood_Dry_Trunk",
      "support": 15,
      "rotation": 4
    },
    {
      "x": 1,
      "y": 4,
      "z": -2,
      "name": "Wood_Drywood_Planks"
    },
    {
      "x": 1,
      "y": 8,
      "z": -2,
      "name": "Wood_Drywood_Planks"
    },
    {
      "x": 1,
      "y": 9,
      "z": -2,
      "name": "Wood_Drywood_Planks"
    },
    {
      "x": 1,
      "y": 10,
      "z": -2,
      "name": "Wood_Drywood_Planks"
    },
    {
      "x": 1,
      "y": 11,
      "z": -2,
      "name": "Wood_Drywood_Decorative"
    },
    {
      "x": 1,
      "y": 12,
      "z": -2,
      "name": "Wood_Drywood_Stairs",
      "rotation": 3
    },
    {
      "x": 1,
      "y": 0,
      "z": -1,
      "name": "Wood_Drywood_Planks"
    },
    {
      "x": 1,
      "y": 1,
      "z": -1,
      "name": "Wood_Dry_Trunk",
      "support": 15,
      "rotation": 4
    },
    {
      "x": 1,
      "y": 2,
      "z": -1,
      "name": "Wood_Dry_Trunk_Stairs",
      "rotation": 2
    },
    {
      "x": 1,
      "y": 4,
      "z": -1,
      "name": "Wood_Drywood_Stairs",
      "rotation": 10
    },
    {
      "x": 1,
      "y": 7,
      "z": -1,
      "name": "Wood_Dry_Trunk_Stairs",
      "rotation": 8
    },
    {
      "x": 1,
      "y": 8,
      "z": -1,
      "name": "Wood_Drywood_Planks"
    },
    {
      "x": 1,
      "y": 9,
      "z": -1,
      "name": "Wood_Drywood_Planks"
    },
    {
      "x": 1,
      "y": 10,
      "z": -1,
      "name": "Wood_Drywood_Planks"
    },
    {
      "x": 1,
      "y": 11,
      "z": -1,
      "name": "Wood_Drywood_Decorative"
    },
    {
      "x": 1,
      "y": 12,
      "z": -1,
      "name": "Wood_Drywood_Stairs",
      "rotation": 3
    },
    {
      "x": 1,
      "y": 0,
      "z": 0,
      "name": "Wood_Drywood_Planks"
    },
    {
      "x": 1,
      "y": 1,
      "z": 0,
      "name": "Wood_Dry_Trunk",
      "support": 15
    },
    {
      "x": 1,
      "y": 2,
      "z": 0,
      "name": "Wood_Dry_Trunk",
      "support": 15
    },
    {
      "x": 1,
      "y": 3,
      "z": 0,
      "name": "Wood_Dry_Trunk",
      "support": 15
    },
    {
      "x": 1,
      "y": 4,
      "z": 0,
      "name": "Wood_Dry_Trunk",
      "support": 15
    },
    {
      "x": 1,
      "y": 5,
      "z": 0,
      "name": "Wood_Dry_Trunk",
      "support": 15
    },
    {
      "x": 1,
      "y": 6,
      "z": 0,
      "name": "Wood_Dry_Trunk",
      "support": 15
    },
    {
      "x": 1,
      "y": 7,
      "z": 0,
      "name": "Wood_Dry_Trunk",
      "support": 15
    },
    {
      "x": 1,
      "y": 8,
      "z": 0,
      "name": "Wood_Drywood_Planks",
      "support": 15
    },
    {
      "x": 1,
      "y": 9,
      "z": 0,
      "name": "Wood_Drywood_Planks"
    },
    {
      "x": 1,
      "y": 10,
      "z": 0,
      "name": "Wood_Drywood_Planks"
    },
    {
      "x": 1,
      "y": 11,
      "z": 0,
      "name": "Wood_Drywood_Decorative"
    },
    {
      "x": 1,
      "y": 12,
      "z": 0,
      "name": "Wood_Drywood_Stairs",
      "rotation": 3
    },
    {
      "x": 1,
      "y": 0,
      "z": 1,
      "name": "Wood_Drywood_Planks"
    },
    {
      "x": 1,
      "y": 1,
      "z": 1,
      "name": "Wood_Dry_Trunk",
      "support": 15,
      "rotation": 4
    },
    {
      "x": 1,
      "y": 2,
      "z": 1,
      "name": "Wood_Dry_Trunk_Stairs"
    },
    {
      "x": 1,
      "y": 4,
      "z": 1,
      "name": "Wood_Drywood_Stairs",
      "rotation": 8
    },
    {
      "x": 1,
      "y": 7,
      "z": 1,
      "name": "Wood_Dry_Trunk_Stairs",
      "rotation": 10
    },
    {
      "x": 1,
      "y": 8,
      "z": 1,
      "name": "Wood_Drywood_Planks"
    },
    {
      "x": 1,
      "y": 9,
      "z": 1,
      "name": "Wood_Drywood_Planks"
    },
    {
      "x": 1,
      "y": 10,
      "z": 1,
      "name": "Wood_Drywood_Planks"
    },
    {
      "x": 1,
      "y": 11,
      "z": 1,
      "name": "Wood_Drywood_Decorative"
    },
    {
      "x": 1,
      "y": 12,
      "z": 1,
      "name": "Wood_Drywood_Stairs",
      "rotation": 3
    },
    {
      "x": 1,
      "y": 0,
      "z": 2,
      "name": "Wood_Drywood_Planks"
    },
    {
      "x": 1,
      "y": 1,
      "z": 2,
      "name": "Wood_Dry_Trunk",
      "support": 15,
      "rotation": 4
    },
    {
      "x": 1,
      "y": 4,
      "z": 2,
      "name": "Wood_Drywood_Planks"
    },
    {
      "x": 1,
      "y": 10,
      "z": 2,
      "name": "Wood_Drywood_Planks"
    },
    {
      "x": 1,
      "y": 11,
      "z": 2,
      "name": "Wood_Drywood_Decorative"
    },
    {
      "x": 1,
      "y": 12,
      "z": 2,
      "name": "Wood_Drywood_Stairs",
      "rotation": 3
    },
    {
      "x": 1,
      "y": 0,
      "z": 3,
      "name": "Wood_Drywood_Planks"
    },
    {
      "x": 1,
      "y": 1,
      "z": 3,
      "name": "Wood_Dry_Trunk",
      "support": 15,
      "rotation": 4
    },
    {
      "x": 1,
      "y": 2,
      "z": 3,
      "name": "Wood_Dry_Trunk_Stairs",
      "rotation": 2
    },
    {
      "x": 1,
      "y": 4,
      "z": 3,
      "name": "Wood_Drywood_Planks"
    },
    {
      "x": 1,
      "y": 11,
      "z": 3,
      "name": "Wood_Drywood_Decorative"
    },
    {
      "x": 1,
      "y": 12,
      "z": 3,
      "name": "Wood_Drywood_Planks"
    },
    {
      "x": 1,
      "y": 1,
      "z": 4,
      "name": "Wood_Drywood_Planks"
    },
    {
      "x": 1,
      "y": 2,
      "z": 4,
      "name": "Wood_Dry_Trunk_Full",
      "support": 15
    },
    {
      "x": 1,
      "y": 3,
      "z": 4,
      "name": "Wood_Drywood_Fence",
      "rotation": 3
    },
    {
      "x": 1,
      "y": 4,
      "z": 4,
      "name": "Wood_Drywood_Planks"
    },
    {
      "x": 1,
      "y": 11,
      "z": 4,
      "name": "Wood_Drywood_Decorative"
    },
    {
      "x": 1,
      "y": 12,
      "z": 4,
      "name": "Wood_Drywood_Planks"
    },
    {
      "x": 1,
      "y": 13,
      "z": 4,
      "name": "Wood_Drywood_Fence",
      "rotation": 2
    },
    {
      "x": 1,
      "y": 2,
      "z": 5,
      "name": "Wood_Drywood_Planks"
    },
    {
      "x": 1,
      "y": 3,
      "z": 5,
      "name": "Wood_Dry_Trunk",
      "support": 15
    },
    {
      "x": 1,
      "y": 4,
      "z": 5,
      "name": "Wood_Dry_Trunk",
      "support": 15
    },
    {
      "x": 1,
      "y": 5,
      "z": 5,
      "name": "Wood_Dry_Trunk",
      "support": 15
    },
    {
      "x": 1,
      "y": 3,
      "z": 6,
      "name": "Wood_Drywood_Planks"
    },
    {
      "x": 1,
      "y": 4,
      "z": 6,
      "name": "Wood_Drywood_Planks"
    },
    {
      "x": 2,
      "y": 4,
      "z": -6,
      "name": "Wood_Drywood_Planks"
    },
    {
      "x": 2,
      "y": 5,
      "z": -6,
      "name": "Wood_Drywood_Planks"
    },
    {
      "x": 2,
      "y": 6,
      "z": -6,
      "name": "Wood_Drywood_Planks"
    },
    {
      "x": 2,
      "y": 7,
      "z": -6,
      "name": "Wood_Drywood_Planks"
    },
    {
      "x": 2,
      "y": 8,
      "z": -6,
      "name": "Wood_Drywood_Decorative"
    },
    {
      "x": 2,
      "y": 9,
      "z": -6,
      "name": "Wood_Drywood_Fence",
      "rotation": 2
    },
    {
      "x": 2,
      "y": 2,
      "z": -5,
      "name": "Wood_Drywood_Planks"
    },
    {
      "x": 2,
      "y": 3,
      "z": -5,
      "name": "Wood_Drywood_Planks"
    },
    {
      "x": 2,
      "y": 4,
      "z": -5,
      "name": "Wood_Drywood_Planks"
    },
    {
      "x": 2,
      "y": 5,
      "z": -5,
      "name": "Wood_Drywood_Stairs",
      "rotation": 1
    },
    {
      "x": 2,
      "y": 6,
      "z": -5,
      "name": "Wood_Drywood_Stairs",
      "rotation": 11
    },
    {
      "x": 2,
      "y": 7,
      "z": -5,
      "name": "Wood_Drywood_Planks"
    },
    {
      "x": 2,
      "y": 8,
      "z": -5,
      "name": "Wood_Drywood_Planks"
    },
    {
      "x": 2,
      "y": 1,
      "z": -4,
      "name": "Wood_Drywood_Planks"
    },
    {
      "x": 2,
      "y": 2,
      "z": -4,
      "name": "Wood_Drywood_Planks"
    },
    {
      "x": 2,
      "y": 4,
      "z": -4,
      "name": "Wood_Drywood_Planks"
    },
    {
      "x": 2,
      "y": 8,
      "z": -4,
      "name": "Wood_Drywood_Planks"
    },
    {
      "x": 2,
      "y": 9,
      "z": -4,
      "name": "*Furniture_Desert_Door_State_Definitions_CloseDoorIn"
    },
    {
      "x": 2,
      "y": 10,
      "z": -4,
      "name": "*Furniture_Desert_Door_State_Definitions_CloseDoorIn",
      "filler": 1024
    },
    {
      "x": 2,
      "y": 11,
      "z": -4,
      "name": "Wood_Drywood_Decorative"
    },
    {
      "x": 2,
      "y": 12,
      "z": -4,
      "name": "Wood_Drywood_Planks"
    },
    {
      "x": 2,
      "y": 13,
      "z": -4,
      "name": "Wood_Drywood_Fence",
      "rotation": 2
    },
    {
      "x": 2,
      "y": 1,
      "z": -3,
      "name": "Wood_Drywood_Planks"
    },
    {
      "x": 2,
      "y": 4,
      "z": -3,
      "name": "Wood_Drywood_Planks"
    },
    {
      "x": 2,
      "y": 8,
      "z": -3,
      "name": "Wood_Drywood_Planks"
    },
    {
      "x": 2,
      "y": 11,
      "z": -3,
      "name": "Wood_Drywood_Planks"
    },
    {
      "x": 2,
      "y": 12,
      "z": -3,
      "name": "Wood_Drywood_Planks"
    },
    {
      "x": 2,
      "y": 0,
      "z": -2,
      "name": "Wood_Drywood_Planks"
    },
    {
      "x": 2,
      "y": 1,
      "z": -2,
      "name": "Wood_Drywood_Planks"
    },
    {
      "x": 2,
      "y": 4,
      "z": -2,
      "name": "Wood_Drywood_Stairs",
      "rotation": 10
    },
    {
      "x": 2,
      "y": 8,
      "z": -2,
      "name": "Wood_Drywood_Planks"
    },
    {
      "x": 2,
      "y": 11,
      "z": -2,
      "name": "Wood_Drywood_Planks"
    },
    {
      "x": 2,
      "y": 12,
      "z": -2,
      "name": "Wood_Drywood_Planks"
    },
    {
      "x": 2,
      "y": 0,
      "z": -1,
      "name": "Wood_Drywood_Planks"
    },
    {
      "x": 2,
      "y": 1,
      "z": -1,
      "name": "Wood_Drywood_Planks"
    },
    {
      "x": 2,
      "y": 4,
      "z": -1,
      "name": "Wood_Drywood_Planks_Half",
      "rotation": 8
    },
    {
      "x": 2,
      "y": 8,
      "z": -1,
      "name": "Wood_Drywood_Planks"
    },
    {
      "x": 2,
      "y": 12,
      "z": -1,
      "name": "Wood_Drywood_Planks"
    },
    {
      "x": 2,
      "y": 0,
      "z": 0,
      "name": "Wood_Drywood_Planks"
    },
    {
      "x": 2,
      "y": 1,
      "z": 0,
      "name": "Wood_Drywood_Planks"
    },
    {
      "x": 2,
      "y": 4,
      "z": 0,
      "name": "Wood_Drywood_Planks_Half",
      "rotation": 8
    },
    {
      "x": 2,
      "y": 8,
      "z": 0,
      "name": "Wood_Drywood_Planks",
      "support": 15
    },
    {
      "x": 2,
      "y": 12,
      "z": 0,
      "name": "Wood_Drywood_Planks"
    },
    {
      "x": 2,
      "y": 0,
      "z": 1,
      "name": "Wood_Drywood_Planks"
    },
    {
      "x": 2,
      "y": 1,
      "z": 1,
      "name": "Wood_Drywood_Planks"
    },
    {
      "x": 2,
      "y": 4,
      "z": 1,
      "name": "Wood_Drywood_Planks_Half",
      "rotation": 8
    },
    {
      "x": 2,
      "y": 8,
      "z": 1,
      "name": "Wood_Drywood_Planks"
    },
    {
      "x": 2,
      "y": 12,
      "z": 1,
      "name": "Wood_Drywood_Planks"
    },
    {
      "x": 2,
      "y": 0,
      "z": 2,
      "name": "Wood_Drywood_Planks"
    },
    {
      "x": 2,
      "y": 1,
      "z": 2,
      "name": "Wood_Drywood_Planks"
    },
    {
      "x": 2,
      "y": 4,
      "z": 2,
      "name": "Wood_Drywood_Stairs",
      "rotation": 8
    },
    {
      "x": 2,
      "y": 11,
      "z": 2,
      "name": "Wood_Drywood_Planks"
    },
    {
      "x": 2,
      "y": 12,
      "z": 2,
      "name": "Wood_Drywood_Planks"
    },
    {
      "x": 2,
      "y": 1,
      "z": 3,
      "name": "Wood_Drywood_Planks"
    },
    {
      "x": 2,
      "y": 4,
      "z": 3,
      "name": "Wood_Drywood_Planks"
    },
    {
      "x": 2,
      "y": 11,
      "z": 3,
      "name": "Wood_Drywood_Planks"
    },
    {
      "x": 2,
      "y": 12,
      "z": 3,
      "name": "Wood_Drywood_Planks"
    },
    {
      "x": 2,
      "y": 1,
      "z": 4,
      "name": "Wood_Drywood_Planks"
    },
    {
      "x": 2,
      "y": 2,
      "z": 4,
      "name": "Wood_Drywood_Planks"
    },
    {
      "x": 2,
      "y": 4,
      "z": 4,
      "name": "Wood_Drywood_Planks"
    },
    {
      "x": 2,
      "y": 11,
      "z": 4,
      "name": "Wood_Drywood_Decorative"
    },
    {
      "x": 2,
      "y": 12,
      "z": 4,
      "name": "Wood_Drywood_Planks"
    },
    {
      "x": 2,
      "y": 13,
      "z": 4,
      "name": "Wood_Drywood_Fence",
      "rotation": 2
    },
    {
      "x": 2,
      "y": 2,
      "z": 5,
      "name": "Wood_Drywood_Planks"
    },
    {
      "x": 2,
      "y": 3,
      "z": 5,
      "name": "Wood_Drywood_Planks"
    },
    {
      "x": 2,
      "y": 4,
      "z": 5,
      "name": "Wood_Drywood_Planks"
    },
    {
      "x": 2,
      "y": 5,
      "z": 5,
      "name": "Wood_Drywood_Stairs",
      "rotation": 1
    },
    {
      "x": 2,
      "y": 6,
      "z": 5,
      "name": "Wood_Drywood_Stairs",
      "rotation": 11
    },
    {
      "x": 2,
      "y": 4,
      "z": 6,
      "name": "Wood_Drywood_Planks"
    },
    {
      "x": 2,
      "y": 5,
      "z": 6,
      "name": "Wood_Drywood_Planks"
    },
    {
      "x": 3,
      "y": 4,
      "z": -6,
      "name": "Wood_Drywood_Planks"
    },
    {
      "x": 3,
      "y": 5,
      "z": -6,
      "name": "Wood_Drywood_Planks"
    },
    {
      "x": 3,
      "y": 6,
      "z": -6,
      "name": "Wood_Drywood_Planks"
    },
    {
      "x": 3,
      "y": 7,
      "z": -6,
      "name": "Wood_Drywood_Planks"
    },
    {
      "x": 3,
      "y": 8,
      "z": -6,
      "name": "Wood_Drywood_Decorative"
    },
    {
      "x": 3,
      "y": 9,
      "z": -6,
      "name": "Wood_Drywood_Fence",
      "rotation": 2
    },
    {
      "x": 3,
      "y": 2,
      "z": -5,
      "name": "Wood_Drywood_Planks"
    },
    {
      "x": 3,
      "y": 3,
      "z": -5,
      "name": "Wood_Drywood_Planks"
    },
    {
      "x": 3,
      "y": 4,
      "z": -5,
      "name": "Wood_Drywood_Planks"
    },
    {
      "x": 3,
      "y": 7,
      "z": -5,
      "name": "Wood_Drywood_Planks"
    },
    {
      "x": 3,
      "y": 8,
      "z": -5,
      "name": "Wood_Drywood_Planks"
    },
    {
      "x": 3,
      "y": 1,
      "z": -4,
      "name": "Wood_Drywood_Planks"
    },
    {
      "x": 3,
      "y": 2,
      "z": -4,
      "name": "Wood_Drywood_Planks"
    },
    {
      "x": 3,
      "y": 3,
      "z": -4,
      "name": "Deco_Trash_Pile_Small"
    },
    {
      "x": 3,
      "y": 4,
      "z": -4,
      "name": "Wood_Drywood_Planks"
    },
    {
      "x": 3,
      "y": 8,
      "z": -4,
      "name": "Wood_Drywood_Planks"
    },
    {
      "x": 3,
      "y": 9,
      "z": -4,
      "name": "*Furniture_Desert_Door_State_Definitions_CloseDoorOut",
      "rotation": 2
    },
    {
      "x": 3,
      "y": 10,
      "z": -4,
      "name": "*Furniture_Desert_Door_State_Definitions_CloseDoorOut",
      "filler": 1024,
      "rotation": 2
    },
    {
      "x": 3,
      "y": 11,
      "z": -4,
      "name": "Wood_Drywood_Decorative"
    },
    {
      "x": 3,
      "y": 12,
      "z": -4,
      "name": "Wood_Drywood_Planks"
    },
    {
      "x": 3,
      "y": 13,
      "z": -4,
      "name": "Wood_Drywood_Fence",
      "rotation": 2
    },
    {
      "x": 3,
      "y": 14,
      "z": -4,
      "name": "Wood_Drywood_Fence",
      "rotation": 2
    },
    {
      "x": 3,
      "y": 1,
      "z": -3,
      "name": "Wood_Drywood_Planks"
    },
    {
      "x": 3,
      "y": 4,
      "z": -3,
      "name": "Wood_Drywood_Planks"
    },
    {
      "x": 3,
      "y": 8,
      "z": -3,
      "name": "Wood_Drywood_Planks"
    },
    {
      "x": 3,
      "y": 11,
      "z": -3,
      "name": "Wood_Drywood_Planks"
    },
    {
      "x": 3,
      "y": 12,
      "z": -3,
      "name": "Wood_Drywood_Planks"
    },
    {
      "x": 3,
      "y": 0,
      "z": -2,
      "name": "Wood_Drywood_Planks"
    },
    {
      "x": 3,
      "y": 1,
      "z": -2,
      "name": "Wood_Drywood_Planks"
    },
    {
      "x": 3,
      "y": 4,
      "z": -2,
      "name": "Wood_Drywood_Stairs",
      "rotation": 10
    },
    {
      "x": 3,
      "y": 8,
      "z": -2,
      "name": "Wood_Drywood_Planks"
    },
    {
      "x": 3,
      "y": 11,
      "z": -2,
      "name": "Wood_Drywood_Planks"
    },
    {
      "x": 3,
      "y": 12,
      "z": -2,
      "name": "Wood_Drywood_Planks"
    },
    {
      "x": 3,
      "y": 0,
      "z": -1,
      "name": "Wood_Drywood_Planks"
    },
    {
      "x": 3,
      "y": 1,
      "z": -1,
      "name": "Wood_Drywood_Planks"
    },
    {
      "x": 3,
      "y": 4,
      "z": -1,
      "name": "Wood_Drywood_Planks_Half",
      "rotation": 8
    },
    {
      "x": 3,
      "y": 8,
      "z": -1,
      "name": "Wood_Drywood_Planks"
    },
    {
      "x": 3,
      "y": 12,
      "z": -1,
      "name": "Wood_Drywood_Planks"
    },
    {
      "x": 3,
      "y": 0,
      "z": 0,
      "name": "Wood_Drywood_Planks"
    },
    {
      "x": 3,
      "y": 1,
      "z": 0,
      "name": "Wood_Drywood_Planks"
    },
    {
      "x": 3,
      "y": 4,
      "z": 0,
      "name": "Wood_Drywood_Planks_Half",
      "rotation": 8
    },
    {
      "x": 3,
      "y": 8,
      "z": 0,
      "name": "Wood_Drywood_Planks",
      "support": 15
    },
    {
      "x": 3,
      "y": 12,
      "z": 0,
      "name": "Wood_Drywood_Planks"
    },
    {
      "x": 3,
      "y": 0,
      "z": 1,
      "name": "Wood_Drywood_Planks"
    },
    {
      "x": 3,
      "y": 1,
      "z": 1,
      "name": "Wood_Drywood_Planks"
    },
    {
      "x": 3,
      "y": 4,
      "z": 1,
      "name": "Wood_Drywood_Planks_Half",
      "rotation": 8
    },
    {
      "x": 3,
      "y": 8,
      "z": 1,
      "name": "Wood_Drywood_Planks"
    },
    {
      "x": 3,
      "y": 12,
      "z": 1,
      "name": "Wood_Drywood_Planks"
    },
    {
      "x": 3,
      "y": 0,
      "z": 2,
      "name": "Wood_Drywood_Planks"
    },
    {
      "x": 3,
      "y": 1,
      "z": 2,
      "name": "Wood_Drywood_Planks"
    },
    {
      "x": 3,
      "y": 2,
      "z": 2,
      "name": "Deco_Treasure_Pile_Small",
      "rotation": 3
    },
    {
      "x": 3,
      "y": 4,
      "z": 2,
      "name": "Wood_Drywood_Stairs",
      "rotation": 8
    },
    {
      "x": 3,
      "y": 8,
      "z": 2,
      "name": "Wood_Drywood_Planks"
    },
    {
      "x": 3,
      "y": 11,
      "z": 2,
      "name": "Wood_Drywood_Planks"
    },
    {
      "x": 3,
      "y": 12,
      "z": 2,
      "name": "Wood_Drywood_Planks"
    },
    {
      "x": 3,
      "y": 1,
      "z": 3,
      "name": "Wood_Drywood_Planks"
    },
    {
      "x": 3,
      "y": 2,
      "z": 3,
      "name": "Deco_Treasure_Pile_Small",
      "rotation": 2
    },
    {
      "x": 3,
      "y": 4,
      "z": 3,
      "name": "Wood_Drywood_Planks"
    },
    {
      "x": 3,
      "y": 11,
      "z": 3,
      "name": "Wood_Drywood_Planks"
    },
    {
      "x": 3,
      "y": 12,
      "z": 3,
      "name": "Wood_Drywood_Planks"
    },
    {
      "x": 3,
      "y": 1,
      "z": 4,
      "name": "Wood_Drywood_Planks"
    },
    {
      "x": 3,
      "y": 2,
      "z": 4,
      "name": "Wood_Drywood_Planks"
    },
    {
      "x": 3,
      "y": 4,
      "z": 4,
      "name": "Wood_Drywood_Planks"
    },
    {
      "x": 3,
      "y": 11,
      "z": 4,
      "name": "Wood_Drywood_Decorative"
    },
    {
      "x": 3,
      "y": 12,
      "z": 4,
      "name": "Wood_Drywood_Planks"
    },
    {
      "x": 3,
      "y": 13,
      "z": 4,
      "name": "Wood_Drywood_Fence",
      "rotation": 2
    },
    {
      "x": 3,
      "y": 14,
      "z": 4,
      "name": "Wood_Drywood_Fence",
      "rotation": 2
    },
    {
      "x": 3,
      "y": 2,
      "z": 5,
      "name": "Wood_Drywood_Planks"
    },
    {
      "x": 3,
      "y": 3,
      "z": 5,
      "name": "Wood_Drywood_Planks"
    },
    {
      "x": 3,
      "y": 4,
      "z": 5,
      "name": "Wood_Drywood_Planks"
    },
    {
      "x": 3,
      "y": 7,
      "z": 5,
      "name": "Wood_Drywood_Planks"
    },
    {
      "x": 3,
      "y": 4,
      "z": 6,
      "name": "Wood_Drywood_Planks"
    },
    {
      "x": 3,
      "y": 5,
      "z": 6,
      "name": "Wood_Drywood_Planks"
    },
    {
      "x": 3,
      "y": 6,
      "z": 6,
      "name": "Wood_Drywood_Planks"
    },
    {
      "x": 3,
      "y": 7,
      "z": 6,
      "name": "Wood_Drywood_Planks"
    },
    {
      "x": 4,
      "y": 5,
      "z": -6,
      "name": "Wood_Drywood_Planks"
    },
    {
      "x": 4,
      "y": 6,
      "z": -6,
      "name": "Wood_Drywood_Planks"
    },
    {
      "x": 4,
      "y": 7,
      "z": -6,
      "name": "Wood_Drywood_Planks"
    },
    {
      "x": 4,
      "y": 8,
      "z": -6,
      "name": "Wood_Drywood_Decorative"
    },
    {
      "x": 4,
      "y": 9,
      "z": -6,
      "name": "*Wood_Drywood_Fence_State_Definitions_Corner"
    },
    {
      "x": 4,
      "y": 4,
      "z": -5,
      "name": "Wood_Drywood_Planks"
    },
    {
      "x": 4,
      "y": 5,
      "z": -5,
      "name": "Wood_Drywood_Planks"
    },
    {
      "x": 4,
      "y": 6,
      "z": -5,
      "name": "Wood_Drywood_Planks"
    },
    {
      "x": 4,
      "y": 7,
      "z": -5,
      "name": "Wood_Drywood_Planks"
    },
    {
      "x": 4,
      "y": 8,
      "z": -5,
      "name": "Wood_Drywood_Planks"
    },
    {
      "x": 4,
      "y": 9,
      "z": -5,
      "name": "*Wood_Drywood_Fence_State_Definitions_Corner",
      "rotation": 2
    },
    {
      "x": 4,
      "y": 2,
      "z": -4,
      "name": "Wood_Drywood_Planks"
    },
    {
      "x": 4,
      "y": 3,
      "z": -4,
      "name": "Wood_Drywood_Planks"
    },
    {
      "x": 4,
      "y": 4,
      "z": -4,
      "name": "Wood_Drywood_Planks"
    },
    {
      "x": 4,
      "y": 5,
      "z": -4,
      "name": "Wood_Drywood_Stairs",
      "rotation": 3
    },
    {
      "x": 4,
      "y": 6,
      "z": -4,
      "name": "Wood_Drywood_Stairs",
      "rotation": 9
    },
    {
      "x": 4,
      "y": 7,
      "z": -4,
      "name": "Wood_Drywood_Planks"
    },
    {
      "x": 4,
      "y": 8,
      "z": -4,
      "name": "Wood_Drywood_Planks"
    },
    {
      "x": 4,
      "y": 9,
      "z": -4,
      "name": "Wood_Drywood_Planks"
    },
    {
      "x": 4,
      "y": 10,
      "z": -4,
      "name": "Wood_Drywood_Planks"
    },
    {
      "x": 4,
      "y": 11,
      "z": -4,
      "name": "Wood_Drywood_Planks"
    },
    {
      "x": 4,
      "y": 12,
      "z": -4,
      "name": "Wood_Drywood_Decorative"
    },
    {
      "x": 4,
      "y": 13,
      "z": -4,
      "name": "Wood_Drywood_Planks"
    },
    {
      "x": 4,
      "y": 14,
      "z": -4,
      "name": "Wood_Drywood_Fence",
      "rotation": 2
    },
    {
      "x": 4,
      "y": 19,
      "z": -4,
      "name": "Wood_Dry_Trunk_Half",
      "rotation": 6
    },
    {
      "x": 4,
      "y": 1,
      "z": -3,
      "name": "Wood_Drywood_Planks"
    },
    {
      "x": 4,
      "y": 2,
      "z": -3,
      "name": "Wood_Drywood_Planks"
    },
    {
      "x": 4,
      "y": 3,
      "z": -3,
      "name": "Wood_Drywood_Planks"
    },
    {
      "x": 4,
      "y": 4,
      "z": -3,
      "name": "Wood_Drywood_Planks"
    },
    {
      "x": 4,
      "y": 8,
      "z": -3,
      "name": "Wood_Drywood_Planks"
    },
    {
      "x": 4,
      "y": 11,
      "z": -3,
      "name": "Wood_Drywood_Planks"
    },
    {
      "x": 4,
      "y": 12,
      "z": -3,
      "name": "Wood_Drywood_Planks"
    },
    {
      "x": 4,
      "y": 13,
      "z": -3,
      "name": "Wood_Drywood_Planks_Half"
    },
    {
      "x": 4,
      "y": 18,
      "z": -3,
      "name": "Cloth_Roof_Hide_Flap",
      "rotation": 1
    },
    {
      "x": 4,
      "y": 19,
      "z": -3,
      "name": "Wood_Dry_Trunk",
      "support": 15,
      "rotation": 4
    },
    {
      "x": 4,
      "y": 1,
      "z": -2,
      "name": "Wood_Drywood_Planks"
    },
    {
      "x": 4,
      "y": 2,
      "z": -2,
      "name": "Wood_Drywood_Stairs"
    },
    {
      "x": 4,
      "y": 4,
      "z": -2,
      "name": "Wood_Drywood_Stairs",
      "rotation": 10
    },
    {
      "x": 4,
      "y": 8,
      "z": -2,
      "name": "Wood_Drywood_Planks"
    },
    {
      "x": 4,
      "y": 11,
      "z": -2,
      "name": "Wood_Drywood_Planks"
    },
    {
      "x": 4,
      "y": 12,
      "z": -2,
      "name": "Wood_Drywood_Planks"
    },
    {
      "x": 4,
      "y": 18,
      "z": -2,
      "name": "Cloth_Roof_Hide_Flap",
      "rotation": 3
    },
    {
      "x": 4,
      "y": 19,
      "z": -2,
      "name": "Wood_Dry_Trunk",
      "support": 15,
      "rotation": 4
    },
    {
      "x": 4,
      "y": 0,
      "z": -1,
      "name": "Wood_Drywood_Planks"
    },
    {
      "x": 4,
      "y": 1,
      "z": -1,
      "name": "Wood_Drywood_Planks"
    },
    {
      "x": 4,
      "y": 2,
      "z": -1,
      "name": "Deco_Bone_Pile"
    },
    {
      "x": 4,
      "y": 4,
      "z": -1,
      "name": "Wood_Drywood_Planks_Half",
      "rotation": 8
    },
    {
      "x": 4,
      "y": 8,
      "z": -1,
      "name": "Wood_Drywood_Planks"
    },
    {
      "x": 4,
      "y": 12,
      "z": -1,
      "name": "Wood_Drywood_Planks"
    },
    {
      "x": 4,
      "y": 19,
      "z": -1,
      "name": "Wood_Dry_Trunk_Half",
      "rotation": 4
    },
    {
      "x": 4,
      "y": 0,
      "z": 0,
      "name": "Wood_Drywood_Planks"
    },
    {
      "x": 4,
      "y": 1,
      "z": 0,
      "name": "Wood_Drywood_Planks"
    },
    {
      "x": 4,
      "y": 4,
      "z": 0,
      "name": "Wood_Drywood_Planks_Half",
      "rotation": 8
    },
    {
      "x": 4,
      "y": 8,
      "z": 0,
      "name": "Wood_Drywood_Planks",
      "support": 15
    },
    {
      "x": 4,
      "y": 12,
      "z": 0,
      "name": "Wood_Drywood_Planks"
    },
    {
      "x": 4,
      "y": 13,
      "z": 0,
      "name": "Wood_Dry_Trunk_Half",
      "rotation": 7
    },
    {
      "x": 4,
      "y": 0,
      "z": 1,
      "name": "Wood_Drywood_Planks"
    },
    {
      "x": 4,
      "y": 1,
      "z": 1,
      "name": "Wood_Drywood_Planks"
    },
    {
      "x": 4,
      "y": 4,
      "z": 1,
      "name": "Wood_Drywood_Planks_Half",
      "rotation": 8
    },
    {
      "x": 4,
      "y": 8,
      "z": 1,
      "name": "Wood_Drywood_Planks"
    },
    {
      "x": 4,
      "y": 12,
      "z": 1,
      "name": "Wood_Drywood_Planks"
    },
    {
      "x": 4,
      "y": 1,
      "z": 2,
      "name": "Wood_Drywood_Planks"
    },
    {
      "x": 4,
      "y": 2,
      "z": 2,
      "name": "Wood_Drywood_Stairs",
      "rotation": 2
    },
    {
      "x": 4,
      "y": 4,
      "z": 2,
      "name": "Wood_Drywood_Stairs",
      "rotation": 8
    },
    {
      "x": 4,
      "y": 8,
      "z": 2,
      "name": "Wood_Drywood_Planks"
    },
    {
      "x": 4,
      "y": 11,
      "z": 2,
      "name": "Wood_Drywood_Planks"
    },
    {
      "x": 4,
      "y": 12,
      "z": 2,
      "name": "Wood_Drywood_Planks"
    },
    {
      "x": 4,
      "y": 1,
      "z": 3,
      "name": "Wood_Drywood_Planks"
    },
    {
      "x": 4,
      "y": 2,
      "z": 3,
      "name": "Wood_Drywood_Planks"
    },
    {
      "x": 4,
      "y": 3,
      "z": 3,
      "name": "Wood_Drywood_Planks"
    },
    {
      "x": 4,
      "y": 4,
      "z": 3,
      "name": "Wood_Drywood_Planks"
    },
    {
      "x": 4,
      "y": 8,
      "z": 3,
      "name": "Wood_Drywood_Planks"
    },
    {
      "x": 4,
      "y": 11,
      "z": 3,
      "name": "Wood_Drywood_Planks"
    },
    {
      "x": 4,
      "y": 12,
      "z": 3,
      "name": "Wood_Drywood_Planks"
    },
    {
      "x": 4,
      "y": 13,
      "z": 3,
      "name": "Wood_Drywood_Planks_Half"
    },
    {
      "x": 4,
      "y": 2,
      "z": 4,
      "name": "Wood_Drywood_Planks"
    },
    {
      "x": 4,
      "y": 3,
      "z": 4,
      "name": "Wood_Drywood_Planks"
    },
    {
      "x": 4,
      "y": 4,
      "z": 4,
      "name": "Wood_Drywood_Planks"
    },
    {
      "x": 4,
      "y": 5,
      "z": 4,
      "name": "Wood_Drywood_Stairs",
      "rotation": 3
    },
    {
      "x": 4,
      "y": 6,
      "z": 4,
      "name": "Wood_Drywood_Stairs",
      "rotation": 9
    },
    {
      "x": 4,
      "y": 7,
      "z": 4,
      "name": "Wood_Drywood_Planks"
    },
    {
      "x": 4,
      "y": 8,
      "z": 4,
      "name": "Wood_Drywood_Planks"
    },
    {
      "x": 4,
      "y": 9,
      "z": 4,
      "name": "Wood_Drywood_Planks"
    },
    {
      "x": 4,
      "y": 10,
      "z": 4,
      "name": "Wood_Drywood_Planks"
    },
    {
      "x": 4,
      "y": 11,
      "z": 4,
      "name": "Wood_Drywood_Planks"
    },
    {
      "x": 4,
      "y": 12,
      "z": 4,
      "name": "Wood_Drywood_Decorative"
    },
    {
      "x": 4,
      "y": 13,
      "z": 4,
      "name": "Wood_Drywood_Planks"
    },
    {
      "x": 4,
      "y": 14,
      "z": 4,
      "name": "Wood_Drywood_Fence",
      "rotation": 2
    },
    {
      "x": 4,
      "y": 4,
      "z": 5,
      "name": "Wood_Drywood_Planks"
    },
    {
      "x": 4,
      "y": 5,
      "z": 5,
      "name": "Wood_Drywood_Planks"
    },
    {
      "x": 4,
      "y": 6,
      "z": 5,
      "name": "Wood_Drywood_Planks"
    },
    {
      "x": 4,
      "y": 7,
      "z": 5,
      "name": "Wood_Drywood_Planks"
    },
    {
      "x": 4,
      "y": 8,
      "z": 5,
      "name": "Wood_Drywood_Planks"
    },
    {
      "x": 4,
      "y": 9,
      "z": 5,
      "name": "*Wood_Drywood_Fence_State_Definitions_Corner",
      "rotation": 1
    },
    {
      "x": 4,
      "y": 5,
      "z": 6,
      "name": "Wood_Drywood_Planks"
    },
    {
      "x": 4,
      "y": 6,
      "z": 6,
      "name": "Wood_Drywood_Planks"
    },
    {
      "x": 4,
      "y": 7,
      "z": 6,
      "name": "Wood_Drywood_Planks"
    },
    {
      "x": 4,
      "y": 8,
      "z": 6,
      "name": "Wood_Drywood_Decorative"
    },
    {
      "x": 4,
      "y": 9,
      "z": 6,
      "name": "*Wood_Drywood_Fence_State_Definitions_Corner",
      "rotation": 3
    },
    {
      "x": 5,
      "y": 4,
      "z": -5,
      "name": "Wood_Drywood_Planks"
    },
    {
      "x": 5,
      "y": 5,
      "z": -5,
      "name": "Wood_Drywood_Planks"
    },
    {
      "x": 5,
      "y": 6,
      "z": -5,
      "name": "Wood_Drywood_Planks"
    },
    {
      "x": 5,
      "y": 7,
      "z": -5,
      "name": "Wood_Drywood_Planks"
    },
    {
      "x": 5,
      "y": 8,
      "z": -5,
      "name": "Wood_Drywood_Decorative"
    },
    {
      "x": 5,
      "y": 9,
      "z": -5,
      "name": "Wood_Drywood_Fence",
      "rotation": 2
    },
    {
      "x": 5,
      "y": 2,
      "z": -4,
      "name": "Wood_Drywood_Planks"
    },
    {
      "x": 5,
      "y": 3,
      "z": -4,
      "name": "Wood_Drywood_Planks"
    },
    {
      "x": 5,
      "y": 4,
      "z": -4,
      "name": "Wood_Dry_Trunk",
      "support": 15
    },
    {
      "x": 5,
      "y": 5,
      "z": -4,
      "name": "Wood_Dry_Trunk",
      "support": 15
    },
    {
      "x": 5,
      "y": 6,
      "z": -4,
      "name": "Wood_Dry_Trunk",
      "support": 15
    },
    {
      "x": 5,
      "y": 7,
      "z": -4,
      "name": "Wood_Dry_Trunk",
      "support": 15
    },
    {
      "x": 5,
      "y": 8,
      "z": -4,
      "name": "Wood_Drywood_Planks"
    },
    {
      "x": 5,
      "y": 9,
      "z": -4,
      "name": "Wood_Drywood_Planks"
    },
    {
      "x": 5,
      "y": 10,
      "z": -4,
      "name": "Wood_Drywood_Planks"
    },
    {
      "x": 5,
      "y": 11,
      "z": -4,
      "name": "Wood_Drywood_Planks"
    },
    {
      "x": 5,
      "y": 12,
      "z": -4,
      "name": "Wood_Drywood_Decorative"
    },
    {
      "x": 5,
      "y": 13,
      "z": -4,
      "name": "Wood_Drywood_Planks"
    },
    {
      "x": 5,
      "y": 14,
      "z": -4,
      "name": "Wood_Drywood_Fence",
      "rotation": 2
    },
    {
      "x": 5,
      "y": 1,
      "z": -3,
      "name": "Wood_Drywood_Planks"
    },
    {
      "x": 5,
      "y": 2,
      "z": -3,
      "name": "Wood_Dry_Trunk",
      "support": 15,
      "rotation": 4
    },
    {
      "x": 5,
      "y": 3,
      "z": -3,
      "name": "Wood_Dry_Trunk_Full",
      "support": 15,
      "rotation": 4
    },
    {
      "x": 5,
      "y": 4,
      "z": -3,
      "name": "Wood_Drywood_Planks"
    },
    {
      "x": 5,
      "y": 5,
      "z": -3,
      "name": "Wood_Drywood_Stairs"
    },
    {
      "x": 5,
      "y": 6,
      "z": -3,
      "name": "Wood_Drywood_Stairs",
      "rotation": 10
    },
    {
      "x": 5,
      "y": 7,
      "z": -3,
      "name": "Wood_Drywood_Planks"
    },
    {
      "x": 5,
      "y": 8,
      "z": -3,
      "name": "Wood_Drywood_Planks"
    },
    {
      "x": 5,
      "y": 9,
      "z": -3,
      "name": "Deco_Treasure_Pile_Small"
    },
    {
      "x": 5,
      "y": 11,
      "z": -3,
      "name": "Wood_Drywood_Planks"
    },
    {
      "x": 5,
      "y": 12,
      "z": -3,
      "name": "Wood_Drywood_Planks"
    },
    {
      "x": 5,
      "y": 13,
      "z": -3,
      "name": "Wood_Drywood_Planks_Half"
    },
    {
      "x": 5,
      "y": 1,
      "z": -2,
      "name": "Wood_Drywood_Planks"
    },
    {
      "x": 5,
      "y": 2,
      "z": -2,
      "name": "Wood_Dry_Trunk_Full",
      "support": 15,
      "rotation": 4
    },
    {
      "x": 5,
      "y": 4,
      "z": -2,
      "name": "Wood_Drywood_Planks"
    },
    {
      "x": 5,
      "y": 7,
      "z": -2,
      "name": "Wood_Drywood_Planks"
    },
    {
      "x": 5,
      "y": 8,
      "z": -2,
      "name": "Wood_Drywood_Planks"
    },
    {
      "x": 5,
      "y": 11,
      "z": -2,
      "name": "Wood_Drywood_Planks"
    },
    {
      "x": 5,
      "y": 12,
      "z": -2,
      "name": "Wood_Drywood_Planks"
    },
    {
      "x": 5,
      "y": 13,
      "z": -2,
      "name": "Wood_Drywood_Planks_Half"
    },
    {
      "x": 5,
      "y": 19,
      "z": -2,
      "name": "Wood_Dry_Trunk_Half",
      "rotation": 6
    },
    {
      "x": 5,
      "y": 0,
      "z": -1,
      "name": "Wood_Drywood_Planks"
    },
    {
      "x": 5,
      "y": 1,
      "z": -1,
      "name": "Wood_Dry_Trunk",
      "support": 15,
      "rotation": 4
    },
    {
      "x": 5,
      "y": 2,
      "z": -1,
      "name": "Wood_Dry_Trunk_Stairs"
    },
    {
      "x": 5,
      "y": 4,
      "z": -1,
      "name": "Wood_Drywood_Stairs",
      "rotation": 10
    },
    {
      "x": 5,
      "y": 5,
      "z": -1,
      "name": "Wood_Drywood_Stairs",
      "rotation": 2
    },
    {
      "x": 5,
      "y": 6,
      "z": -1,
      "name": "Wood_Drywood_Stairs",
      "rotation": 8
    },
    {
      "x": 5,
      "y": 7,
      "z": -1,
      "name": "Wood_Drywood_Planks"
    },
    {
      "x": 5,
      "y": 8,
      "z": -1,
      "name": "Wood_Drywood_Planks"
    },
    {
      "x": 5,
      "y": 12,
      "z": -1,
      "name": "Wood_Drywood_Planks"
    },
    {
      "x": 5,
      "y": 13,
      "z": -1,
      "name": "Wood_Dry_Trunk_Half",
      "rotation": 6
    },
    {
      "x": 5,
      "y": 15,
      "z": -1,
      "name": "Furniture_Desert_Sign",
      "rotation": 1
    },
    {
      "x": 5,
      "y": 18,
      "z": -1,
      "name": "Cloth_Roof_Hide_Flap",
      "rotation": 1
    },
    {
      "x": 5,
      "y": 19,
      "z": -1,
      "name": "Wood_Dry_Trunk",
      "support": 15,
      "rotation": 4
    },
    {
      "x": 5,
      "y": 0,
      "z": 0,
      "name": "Wood_Drywood_Planks"
    },
    {
      "x": 5,
      "y": 1,
      "z": 0,
      "name": "Wood_Dry_Trunk",
      "support": 15
    },
    {
      "x": 5,
      "y": 2,
      "z": 0,
      "name": "Wood_Dry_Trunk",
      "support": 15
    },
    {
      "x": 5,
      "y": 3,
      "z": 0,
      "name": "Wood_Dry_Trunk",
      "support": 15
    },
    {
      "x": 5,
