{
  "version": 8,
  "blockIdVersion": 11,
  "anchorX": 0,
  "anchorY": 1,
  "anchorZ": 1,
  "blocks": [
    {
      "x": -7,
      "y": 2,
      "z": 2,
      "name": "Plant_Coral_Bush_Dead3"
    },
    {
      "x": -6,
      "y": 2,
      "z": -2,
      "name": "Plant_Coral_Bush_White"
    },
    {
      "x": -6,
      "y": 2,
      "z": -1,
      "name": "Rock_Marble"
    },
    {
      "x": -6,
      "y": 3,
      "z": -1,
      "name": "Plant_Coral_Model_Dead3"
    },
    {
      "x": -6,
      "y": 2,
      "z": 0,
      "name": "Rock_Marble"
    },
    {
      "x": -6,
      "y": 3,
      "z": 0,
      "name": "Plant_Coral_Model_White"
    },
    {
      "x": -6,
      "y": 2,
      "z": 1,
      "name": "Rock_Marble"
    },
    {
      "x": -6,
      "y": 2,
      "z": 2,
      "name": "Rock_Marble"
    },
    {
      "x": -6,
      "y": 2,
      "z": 3,
      "name": "Plant_Coral_Bush_White"
    },
    {
      "x": -5,
      "y": 1,
      "z": -2,
      "name": "Rock_Marble"
    },
    {
      "x": -5,
      "y": 2,
      "z": -2,
      "name": "Rock_Marble"
    },
    {
      "x": -5,
      "y": 1,
      "z": -1,
      "name": "Rock_Marble"
    },
    {
      "x": -5,
      "y": 2,
      "z": -1,
      "name": "Rock_Marble"
    },
    {
      "x": -5,
      "y": 3,
      "z": -1,
      "name": "Rock_Marble"
    },
    {
      "x": -5,
      "y": 4,
      "z": -1,
      "name": "Plant_Moss_Rug_Red",
      "support": 15
    },
    {
      "x": -5,
      "y": 1,
      "z": 0,
      "name": "Rock_Marble"
    },
    {
      "x": -5,
      "y": 2,
      "z": 0,
      "name": "Rock_Marble"
    },
    {
      "x": -5,
      "y": 3,
      "z": 0,
      "name": "Rock_Marble"
    },
    {
      "x": -5,
      "y": 4,
      "z": 0,
      "name": "Plant_Moss_Rug_Red",
      "support": 15
    },
    {
      "x": -5,
      "y": 1,
      "z": 1,
      "name": "Rock_Marble"
    },
    {
      "x": -5,
      "y": 2,
      "z": 1,
      "name": "Rock_Marble"
    },
    {
      "x": -5,
      "y": 3,
      "z": 1,
      "name": "Rock_Marble"
    },
    {
      "x": -5,
      "y": 4,
      "z": 1,
      "name": "Plant_Moss_Short_Red",
      "support": 15
    },
    {
      "x": -5,
      "y": 1,
      "z": 2,
      "name": "Rock_Marble"
    },
    {
      "x": -5,
      "y": 2,
      "z": 2,
      "name": "Rock_Marble"
    },
    {
      "x": -5,
      "y": 3,
      "z": 2,
      "name": "Rock_Marble"
    },
    {
      "x": -5,
      "y": 4,
      "z": 2,
      "name": "Plant_Coral_Model_Dead2"
    },
    {
      "x": -5,
      "y": 2,
      "z": 3,
      "name": "Rock_Marble"
    },
    {
      "x": -5,
      "y": 3,
      "z": 3,
      "name": "Rock_Marble"
    },
    {
      "x": -5,
      "y": 4,
      "z": 3,
      "name": "Plant_Moss_Rug_Red",
      "support": 15
    },
    {
      "x": -4,
      "y": 2,
      "z": -4,
      "name": "Rock_Crystal_White_Small",
      "rotation": 6
    },
    {
      "x": -4,
      "y": 1,
      "z": -3,
      "name": "Rock_Marble"
    },
    {
      "x": -4,
      "y": 2,
      "z": -3,
      "name": "Rock_Marble"
    },
    {
      "x": -4,
      "y": 1,
      "z": -2,
      "name": "Rock_Marble"
    },
    {
      "x": -4,
      "y": 2,
      "z": -2,
      "name": "Rock_Marble"
    },
    {
      "x": -4,
      "y": 3,
      "z": -2,
      "name": "Rock_Marble"
    },
    {
      "x": -4,
      "y": 4,
      "z": -2,
      "name": "Rubble_Marble",
      "support": 15
    },
    {
      "x": -4,
      "y": 1,
      "z": -1,
      "name": "Rock_Marble"
    },
    {
      "x": -4,
      "y": 2,
      "z": -1,
      "name": "Rock_Marble"
    },
    {
      "x": -4,
      "y": 3,
      "z": -1,
      "name": "Plant_Moss_Block_Red",
      "support": 15
    },
    {
      "x": -4,
      "y": 1,
      "z": 0,
      "name": "Rock_Marble"
    },
    {
      "x": -4,
      "y": 2,
      "z": 0,
      "name": "Rock_Marble"
    },
    {
      "x": -4,
      "y": 3,
      "z": 0,
      "name": "Plant_Moss_Block_Red",
      "support": 15
    },
    {
      "x": -4,
      "y": 1,
      "z": 1,
      "name": "Rock_Marble"
    },
    {
      "x": -4,
      "y": 2,
      "z": 1,
      "name": "Rock_Marble"
    },
    {
      "x": -4,
      "y": 3,
      "z": 1,
      "name": "Plant_Coral_Block_White"
    },
    {
      "x": -4,
      "y": 4,
      "z": 1,
      "name": "Plant_Coral_Model_White"
    },
    {
      "x": -4,
      "y": 1,
      "z": 2,
      "name": "Rock_Marble"
    },
    {
      "x": -4,
      "y": 2,
      "z": 2,
      "name": "Rock_Marble"
    },
    {
      "x": -4,
      "y": 3,
      "z": 2,
      "name": "Rock_Marble"
    },
    {
      "x": -4,
      "y": 1,
      "z": 3,
      "name": "Rock_Marble"
    },
    {
      "x": -4,
      "y": 2,
      "z": 3,
      "name": "Rock_Marble"
    },
    {
      "x": -4,
      "y": 3,
      "z": 3,
      "name": "Rock_Marble"
    },
    {
      "x": -4,
      "y": 4,
      "z": 3,
      "name": "Plant_Moss_Short_Red",
      "support": 15
    },
    {
      "x": -4,
      "y": 1,
      "z": 4,
      "name": "Rock_Marble"
    },
    {
      "x": -4,
      "y": 2,
      "z": 4,
      "name": "Rock_Crystal_White_Block"
    },
    {
      "x": -4,
      "y": 3,
      "z": 4,
      "name": "Rock_Crystal_White_Small"
    },
    {
      "x": -3,
      "y": 2,
      "z": -4,
      "name": "Rock_Marble"
    },
    {
      "x": -3,
      "y": 3,
      "z": -4,
      "name": "Rubble_Marble",
      "support": 15
    },
    {
      "x": -3,
      "y": 1,
      "z": -3,
      "name": "Rock_Marble"
    },
    {
      "x": -3,
      "y": 2,
      "z": -3,
      "name": "Rock_Marble"
    },
    {
      "x": -3,
      "y": 3,
      "z": -3,
      "name": "Plant_Coral_Bush_Dead2"
    },
    {
      "x": -3,
      "y": 1,
      "z": -2,
      "name": "Rock_Marble"
    },
    {
      "x": -3,
      "y": 2,
      "z": -2,
      "name": "Rock_Marble"
    },
    {
      "x": -3,
      "y": 3,
      "z": -2,
      "name": "Rock_Marble"
    },
    {
      "x": -3,
      "y": 4,
      "z": -2,
      "name": "Plant_Moss_Short_Red",
      "support": 15
    },
    {
      "x": -3,
      "y": 1,
      "z": -1,
      "name": "Rock_Marble"
    },
    {
      "x": -3,
      "y": 2,
      "z": -1,
      "name": "Rock_Marble"
    },
    {
      "x": -3,
      "y": 3,
      "z": -1,
      "name": "Plant_Coral_Block_White"
    },
    {
      "x": -3,
      "y": 4,
      "z": -1,
      "name": "Plant_Coral_Model_White"
    },
    {
      "x": -3,
      "y": 0,
      "z": 0,
      "name": "Rock_Marble"
    },
    {
      "x": -3,
      "y": 1,
      "z": 0,
      "name": "Rock_Marble"
    },
    {
      "x": -3,
      "y": 2,
      "z": 0,
      "name": "Rock_Marble"
    },
    {
      "x": -3,
      "y": 3,
      "z": 0,
      "name": "Rock_Marble"
    },
    {
      "x": -3,
      "y": 4,
      "z": 0,
      "name": "Plant_Coral_Model_Dead6"
    },
    {
      "x": -3,
      "y": 0,
      "z": 1,
      "name": "Rock_Marble"
    },
    {
      "x": -3,
      "y": 1,
      "z": 1,
      "name": "Rock_Marble"
    },
    {
      "x": -3,
      "y": 2,
      "z": 1,
      "name": "Rock_Marble"
    },
    {
      "x": -3,
      "y": 3,
      "z": 1,
      "name": "Rock_Marble"
    },
    {
      "x": -3,
      "y": 4,
      "z": 1,
      "name": "Plant_Moss_Block_Red",
      "support": 15
    },
    {
      "x": -3,
      "y": 0,
      "z": 2,
      "name": "Rock_Marble"
    },
    {
      "x": -3,
      "y": 1,
      "z": 2,
      "name": "Rock_Marble"
    },
    {
      "x": -3,
      "y": 2,
      "z": 2,
      "name": "Rock_Marble"
    },
    {
      "x": -3,
      "y": 3,
      "z": 2,
      "name": "Rock_Marble"
    },
    {
      "x": -3,
      "y": 4,
      "z": 2,
      "name": "Rock_Marble"
    },
    {
      "x": -3,
      "y": 5,
      "z": 2,
      "name": "Plant_Moss_Rug_Red",
      "support": 15
    },
    {
      "x": -3,
      "y": 0,
      "z": 3,
      "name": "Rock_Crystal_White_Medium",
      "rotation": 8
    },
    {
      "x": -3,
      "y": 1,
      "z": 3,
      "name": "Rock_Marble"
    },
    {
      "x": -3,
      "y": 2,
      "z": 3,
      "name": "Rock_Marble"
    },
    {
      "x": -3,
      "y": 3,
      "z": 3,
      "name": "Rock_Marble"
    },
    {
      "x": -3,
      "y": 1,
      "z": 4,
      "name": "Rock_Marble"
    },
    {
      "x": -3,
      "y": 2,
      "z": 4,
      "name": "Rock_Marble"
    },
    {
      "x": -3,
      "y": 3,
      "z": 4,
      "name": "Rock_Marble"
    },
    {
      "x": -3,
      "y": 4,
      "z": 4,
      "name": "Plant_Coral_Model_Dead6"
    },
    {
      "x": -3,
      "y": 2,
      "z": 5,
      "name": "Plant_Coral_Bush_Dead2"
    },
    {
      "x": -2,
      "y": 1,
      "z": -4,
      "name": "Rock_Marble"
    },
    {
      "x": -2,
      "y": 2,
      "z": -4,
      "name": "Rock_Marble"
    },
    {
      "x": -2,
      "y": 3,
      "z": -4,
      "name": "Rock_Crystal_White_Small",
      "rotation": 7
    },
    {
      "x": -2,
      "y": 1,
      "z": -3,
      "name": "Rock_Marble"
    },
    {
      "x": -2,
      "y": 2,
      "z": -3,
      "name": "Rock_Marble"
    },
    {
      "x": -2,
      "y": 3,
      "z": -3,
      "name": "Rock_Marble"
    },
    {
      "x": -2,
      "y": 4,
      "z": -3,
      "name": "Rubble_Marble_Medium",
      "support": 15
    },
    {
      "x": -2,
      "y": 0,
      "z": -2,
      "name": "Rock_Marble"
    },
    {
      "x": -2,
      "y": 1,
      "z": -2,
      "name": "Rock_Marble"
    },
    {
      "x": -2,
      "y": 2,
      "z": -2,
      "name": "Rock_Marble"
    },
    {
      "x": -2,
      "y": 3,
      "z": -2,
      "name": "Plant_Coral_Block_White"
    },
    {
      "x": -2,
      "y": 0,
      "z": -1,
      "name": "Rock_Marble"
    },
    {
      "x": -2,
      "y": 1,
      "z": -1,
      "name": "Rock_Marble"
    },
    {
      "x": -2,
      "y": 2,
      "z": -1,
      "name": "Rock_Marble"
    },
    {
      "x": -2,
      "y": 3,
      "z": -1,
      "name": "Plant_Coral_Block_White"
    },
    {
      "x": -2,
      "y": 0,
      "z": 0,
      "name": "Rock_Marble"
    },
    {
      "x": -2,
      "y": 1,
      "z": 0,
      "name": "Rock_Marble"
    },
    {
      "x": -2,
      "y": 2,
      "z": 0,
      "name": "Rock_Marble"
    },
    {
      "x": -2,
      "y": 3,
      "z": 0,
      "name": "Rock_Marble"
    },
    {
      "x": -2,
      "y": 4,
      "z": 0,
      "name": "Plant_Moss_Block_Red",
      "support": 15
    },
    {
      "x": -2,
      "y": 5,
      "z": 0,
      "name": "Plant_Moss_Rug_Red",
      "support": 15
    },
    {
      "x": -2,
      "y": 0,
      "z": 1,
      "name": "Rock_Marble"
    },
    {
      "x": -2,
      "y": 1,
      "z": 1,
      "name": "Rock_Marble"
    },
    {
      "x": -2,
      "y": 2,
      "z": 1,
      "name": "Rock_Marble"
    },
    {
      "x": -2,
      "y": 3,
      "z": 1,
      "name": "Rock_Marble"
    },
    {
      "x": -2,
      "y": 4,
      "z": 1,
      "name": "Plant_Moss_Block_Red",
      "support": 15
    },
    {
      "x": -2,
      "y": 5,
      "z": 1,
      "name": "Plant_Moss_Short_Red",
      "support": 15
    },
    {
      "x": -2,
      "y": 0,
      "z": 2,
      "name": "Rock_Marble"
    },
    {
      "x": -2,
      "y": 1,
      "z": 2,
      "name": "Rock_Marble"
    },
    {
      "x": -2,
      "y": 2,
      "z": 2,
      "name": "Rock_Marble"
    },
    {
      "x": -2,
      "y": 3,
      "z": 2,
      "name": "Rock_Marble"
    },
    {
      "x": -2,
      "y": 4,
      "z": 2,
      "name": "Rock_Marble"
    },
    {
      "x": -2,
      "y": 5,
      "z": 2,
      "name": "Plant_Coral_Bush_Dead2"
    },
    {
      "x": -2,
      "y": 0,
      "z": 3,
      "name": "Rock_Crystal_White_Block"
    },
    {
      "x": -2,
      "y": 1,
      "z": 3,
      "name": "Rock_Marble"
    },
    {
      "x": -2,
      "y": 2,
      "z": 3,
      "name": "Rock_Marble"
    },
    {
      "x": -2,
      "y": 3,
      "z": 3,
      "name": "Rock_Marble"
    },
    {
      "x": -2,
      "y": 4,
      "z": 3,
      "name": "Rock_Marble"
    },
    {
      "x": -2,
      "y": 0,
      "z": 4,
      "name": "Rock_Crystal_White_Small",
      "rotation": 4
    },
    {
      "x": -2,
      "y": 1,
      "z": 4,
      "name": "Rock_Marble"
    },
    {
      "x": -2,
      "y": 2,
      "z": 4,
      "name": "Rock_Marble"
    },
    {
      "x": -2,
      "y": 3,
      "z": 4,
      "name": "Rock_Marble"
    },
    {
      "x": -2,
      "y": 4,
      "z": 4,
      "name": "Rubble_Marble_Medium",
      "support": 15
    },
    {
      "x": -2,
      "y": 1,
      "z": 5,
      "name": "Rock_Marble"
    },
    {
      "x": -2,
      "y": 2,
      "z": 5,
      "name": "Rock_Marble"
    },
    {
      "x": -2,
      "y": 3,
      "z": 5,
      "name": "Rock_Marble"
    },
    {
      "x": -2,
      "y": 1,
      "z": 6,
      "name": "Rock_Marble"
    },
    {
      "x": -2,
      "y": 2,
      "z": 6,
      "name": "Rock_Marble"
    },
    {
      "x": -2,
      "y": 3,
      "z": 6,
      "name": "Plant_Coral_Bush_Dead"
    },
    {
      "x": -1,
      "y": 3,
      "z": -5,
      "name": "Rock_Marble"
    },
    {
      "x": -1,
      "y": 1,
      "z": -4,
      "name": "Rock_Marble"
    },
    {
      "x": -1,
      "y": 2,
      "z": -4,
      "name": "Rock_Marble"
    },
    {
      "x": -1,
      "y": 3,
      "z": -4,
      "name": "Rock_Crystal_White_Block"
    },
    {
      "x": -1,
      "y": 4,
      "z": -4,
      "name": "Rock_Crystal_White_Medium"
    },
    {
      "x": -1,
      "y": 0,
      "z": -3,
      "name": "Rock_Marble"
    },
    {
      "x": -1,
      "y": 1,
      "z": -3,
      "name": "Rock_Marble"
    },
    {
      "x": -1,
      "y": 2,
      "z": -3,
      "name": "Rock_Marble"
    },
    {
      "x": -1,
      "y": 3,
      "z": -3,
      "name": "Rock_Marble"
    },
    {
      "x": -1,
      "y": 0,
      "z": -2,
      "name": "Rock_Marble"
    },
    {
      "x": -1,
      "y": 1,
      "z": -2,
      "name": "Rock_Marble"
    },
    {
      "x": -1,
      "y": 2,
      "z": -2,
      "name": "Rock_Marble"
    },
    {
      "x": -1,
      "y": 3,
      "z": -2,
      "name": "Rock_Marble"
    },
    {
      "x": -1,
      "y": 4,
      "z": -2,
      "name": "Rock_Marble"
    },
    {
      "x": -1,
      "y": 5,
      "z": -2,
      "name": "Plant_Moss_Rug_Red",
      "support": 15
    },
    {
      "x": -1,
      "y": 0,
      "z": -1,
      "name": "Rock_Marble"
    },
    {
      "x": -1,
      "y": 1,
      "z": -1,
      "name": "Rock_Marble"
    },
    {
      "x": -1,
      "y": 2,
      "z": -1,
      "name": "Rock_Marble"
    },
    {
      "x": -1,
      "y": 3,
      "z": -1,
      "name": "Rock_Marble"
    },
    {
      "x": -1,
      "y": 4,
      "z": -1,
      "name": "Plant_Moss_Block_Red",
      "support": 15
    },
    {
      "x": -1,
      "y": 5,
      "z": -1,
      "name": "Plant_Coral_Model_Dead7"
    },
    {
      "x": -1,
      "y": 0,
      "z": 0,
      "name": "Rock_Marble"
    },
    {
      "x": -1,
      "y": 1,
      "z": 0,
      "name": "Rock_Marble"
    },
    {
      "x": -1,
      "y": 2,
      "z": 0,
      "name": "Rock_Marble"
    },
    {
      "x": -1,
      "y": 3,
      "z": 0,
      "name": "Rock_Marble"
    },
    {
      "x": -1,
      "y": 4,
      "z": 0,
      "name": "Plant_Moss_Block_Red",
      "support": 15
    },
    {
      "x": -1,
      "y": 0,
      "z": 1,
      "name": "Rock_Marble"
    },
    {
      "x": -1,
      "y": 1,
      "z": 1,
      "name": "Rock_Marble"
    },
    {
      "x": -1,
      "y": 2,
      "z": 1,
      "name": "Rock_Marble"
    },
    {
      "x": -1,
      "y": 3,
      "z": 1,
      "name": "Rock_Marble"
    },
    {
      "x": -1,
      "y": 4,
      "z": 1,
      "name": "Plant_Moss_Block_Red",
      "support": 15
    },
    {
      "x": -1,
      "y": 5,
      "z": 1,
      "name": "Plant_Moss_Red",
      "support": 15
    },
    {
      "x": -1,
      "y": 0,
      "z": 2,
      "name": "Rock_Marble"
    },
    {
      "x": -1,
      "y": 1,
      "z": 2,
      "name": "Rock_Marble"
    },
    {
      "x": -1,
      "y": 2,
      "z": 2,
      "name": "Rock_Marble"
    },
    {
      "x": -1,
      "y": 3,
      "z": 2,
      "name": "Rock_Marble"
    },
    {
      "x": -1,
      "y": 4,
      "z": 2,
      "name": "Plant_Moss_Block_Red",
      "support": 15
    },
    {
      "x": -1,
      "y": 0,
      "z": 3,
      "name": "Rock_Marble"
    },
    {
      "x": -1,
      "y": 1,
      "z": 3,
      "name": "Rock_Marble"
    },
    {
      "x": -1,
      "y": 2,
      "z": 3,
      "name": "Rock_Marble"
    },
    {
      "x": -1,
      "y": 3,
      "z": 3,
      "name": "Rock_Marble"
    },
    {
      "x": -1,
      "y": 4,
      "z": 3,
      "name": "Plant_Moss_Block_Red",
      "support": 15
    },
    {
      "x": -1,
      "y": 5,
      "z": 3,
      "name": "Plant_Moss_Red",
      "support": 15
    },
    {
      "x": -1,
      "y": 0,
      "z": 4,
      "name": "Rock_Marble"
    },
    {
      "x": -1,
      "y": 1,
      "z": 4,
      "name": "Rock_Marble"
    },
    {
      "x": -1,
      "y": 2,
      "z": 4,
      "name": "Rock_Marble"
    },
    {
      "x": -1,
      "y": 3,
      "z": 4,
      "name": "Rock_Marble"
    },
    {
      "x": -1,
      "y": 4,
      "z": 4,
      "name": "Rock_Marble"
    },
    {
      "x": -1,
      "y": 5,
      "z": 4,
      "name": "Plant_Moss_Rug_Red",
      "support": 15
    },
    {
      "x": -1,
      "y": 1,
      "z": 5,
      "name": "Rock_Marble"
    },
    {
      "x": -1,
      "y": 2,
      "z": 5,
      "name": "Rock_Marble"
    },
    {
      "x": -1,
      "y": 3,
      "z": 5,
      "name": "Rock_Marble"
    },
    {
      "x": -1,
      "y": 4,
      "z": 5,
      "name": "Rubble_Marble_Medium",
      "support": 15
    },
    {
      "x": -1,
      "y": 1,
      "z": 6,
      "name": "Rock_Marble"
    },
    {
      "x": -1,
      "y": 2,
      "z": 6,
      "name": "Rock_Marble"
    },
    {
      "x": -1,
      "y": 3,
      "z": 6,
      "name": "Rock_Marble"
    },
    {
      "x": -1,
      "y": 2,
      "z": 7,
      "name": "Plant_Coral_Bush_Dead2"
    },
    {
      "x": 0,
      "y": 2,
      "z": -6,
      "name": "Plant_Coral_Bush_Dead"
    },
    {
      "x": 0,
      "y": 2,
      "z": -5,
      "name": "Rock_Marble"
    },
    {
      "x": 0,
      "y": 3,
      "z": -5,
      "name": "Rock_Marble"
    },
    {
      "x": 0,
      "y": 4,
      "z": -5,
      "name": "Rubble_Marble",
      "support": 15
    },
    {
      "x": 0,
      "y": 1,
      "z": -4,
      "name": "Rock_Marble"
    },
    {
      "x": 0,
      "y": 2,
      "z": -4,
      "name": "Rock_Marble"
    },
    {
      "x": 0,
      "y": 3,
      "z": -4,
      "name": "Rock_Marble"
    },
    {
      "x": 0,
      "y": 0,
      "z": -3,
      "name": "Rock_Marble"
    },
    {
      "x": 0,
      "y": 1,
      "z": -3,
      "name": "Rock_Marble"
    },
    {
      "x": 0,
      "y": 2,
      "z": -3,
      "name": "Rock_Marble"
    },
    {
      "x": 0,
      "y": 3,
      "z": -3,
      "name": "Rock_Marble"
    },
    {
      "x": 0,
      "y": 4,
      "z": -3,
      "name": "Rubble_Marble_Medium",
      "support": 15
    },
    {
      "x": 0,
      "y": 0,
      "z": -2,
      "name": "Rock_Marble"
    },
    {
      "x": 0,
      "y": 1,
      "z": -2,
      "name": "Rock_Marble"
    },
    {
      "x": 0,
      "y": 2,
      "z": -2,
      "name": "Rock_Marble"
    },
    {
      "x": 0,
      "y": 3,
      "z": -2,
      "name": "Rock_Marble"
    },
    {
      "x": 0,
      "y": 4,
      "z": -2,
      "name": "Rock_Marble"
    },
    {
      "x": 0,
      "y": 0,
      "z": -1,
      "name": "Rock_Marble"
    },
    {
      "x": 0,
      "y": 1,
      "z": -1,
      "name": "Rock_Marble"
    },
    {
      "x": 0,
      "y": 2,
      "z": -1,
      "name": "Rock_Marble"
    },
    {
      "x": 0,
      "y": 3,
      "z": -1,
      "name": "Rock_Marble"
    },
    {
      "x": 0,
      "y": 4,
      "z": -1,
      "name": "Plant_Moss_Block_Red",
      "support": 15
    },
    {
      "x": 0,
      "y": 0,
      "z": 0,
      "name": "Rock_Marble"
    },
    {
      "x": 0,
      "y": 1,
      "z": 0,
      "name": "Rock_Marble"
    },
    {
      "x": 0,
      "y": 2,
      "z": 0,
      "name": "Rock_Marble"
    },
    {
      "x": 0,
      "y": 3,
      "z": 0,
      "name": "Rock_Marble"
    },
    {
      "x": 0,
      "y": 4,
      "z": 0,
      "name": "Plant_Moss_Block_Red",
      "support": 15
    },
    {
      "x": 0,
      "y": 5,
      "z": 0,
      "name": "Plant_Moss_Red",
      "support": 15
    },
    {
      "x": 0,
      "y": 0,
      "z": 1,
      "name": "Rock_Marble"
    },
    {
      "x": 0,
      "y": 1,
      "z": 1,
      "name": "Rock_Marble"
    },
    {
      "x": 0,
      "y": 2,
      "z": 1,
      "name": "Rock_Marble"
    },
    {
      "x": 0,
      "y": 3,
      "z": 1,
      "name": "Rock_Marble"
    },
    {
      "x": 0,
      "y": 4,
      "z": 1,
      "name": "Plant_Moss_Block_Red",
      "support": 15
    },
    {
      "x": 0,
      "y": 5,
      "z": 1,
      "name": "Rubble_Marble_Medium",
      "support": 15
    },
    {
      "x": 0,
      "y": 0,
      "z": 2,
      "name": "Rock_Marble"
    },
    {
      "x": 0,
      "y": 1,
      "z": 2,
      "name": "Rock_Marble"
    },
    {
      "x": 0,
      "y": 2,
      "z": 2,
      "name": "Rock_Marble"
    },
    {
      "x": 0,
      "y": 3,
      "z": 2,
      "name": "Rock_Marble"
    },
    {
      "x": 0,
      "y": 4,
      "z": 2,
      "name": "Plant_Moss_Block_Red",
      "support": 15
    },
    {
      "x": 0,
      "y": 0,
      "z": 3,
      "name": "Rock_Marble"
    },
    {
      "x": 0,
      "y": 1,
      "z": 3,
      "name": "Rock_Marble"
    },
    {
      "x": 0,
      "y": 2,
      "z": 3,
      "name": "Rock_Marble"
    },
    {
      "x": 0,
      "y": 3,
      "z": 3,
      "name": "Rock_Marble"
    },
    {
      "x": 0,
      "y": 4,
      "z": 3,
      "name": "Rock_Marble"
    },
    {
      "x": 0,
      "y": 5,
      "z": 3,
      "name": "Plant_Coral_Model_White"
    },
    {
      "x": 0,
      "y": 0,
      "z": 4,
      "name": "Rock_Marble"
    },
    {
      "x": 0,
      "y": 1,
      "z": 4,
      "name": "Rock_Marble"
    },
    {
      "x": 0,
      "y": 2,
      "z": 4,
      "name": "Rock_Marble"
    },
    {
      "x": 0,
      "y": 3,
      "z": 4,
      "name": "Rock_Marble"
    },
    {
      "x": 0,
      "y": 4,
      "z": 4,
      "name": "Rock_Marble"
    },
    {
      "x": 0,
      "y": 0,
      "z": 5,
      "name": "Rock_Marble"
    },
    {
      "x": 0,
      "y": 1,
      "z": 5,
      "name": "Rock_Marble"
    },
    {
      "x": 0,
      "y": 2,
      "z": 5,
      "name": "Rock_Marble"
    },
    {
      "x": 0,
      "y": 3,
      "z": 5,
      "name": "Rock_Marble"
    },
    {
      "x": 0,
      "y": 4,
      "z": 5,
      "name": "Plant_Coral_Model_White"
    },
    {
      "x": 0,
      "y": 1,
      "z": 6,
      "name": "Rock_Marble"
    },
    {
      "x": 0,
      "y": 2,
      "z": 6,
      "name": "Rock_Marble"
    },
    {
      "x": 0,
      "y": 3,
      "z": 6,
      "name": "Rock_Marble"
    },
    {
      "x": 0,
      "y": 4,
      "z": 6,
      "name": "Plant_Moss_Short_Red",
      "support": 15
    },
    {
      "x": 0,
      "y": 2,
      "z": 7,
      "name": "Rock_Marble"
    },
    {
      "x": 0,
      "y": 3,
      "z": 7,
      "name": "Plant_Moss_Rug_Red",
      "support": 15
    },
    {
      "x": 1,
      "y": 2,
      "z": -5,
      "name": "Rock_Marble"
    },
    {
      "x": 1,
      "y": 3,
      "z": -5,
      "name": "Plant_Coral_Bush_White"
    },
    {
      "x": 1,
      "y": 1,
      "z": -4,
      "name": "Rock_Marble"
    },
    {
      "x": 1,
      "y": 2,
      "z": -4,
      "name": "Rock_Marble"
    },
    {
      "x": 1,
      "y": 3,
      "z": -4,
      "name": "Rock_Marble"
    },
    {
      "x": 1,
      "y": 1,
      "z": -3,
      "name": "Rock_Marble"
    },
    {
      "x": 1,
      "y": 2,
      "z": -3,
      "name": "Rock_Marble"
    },
    {
      "x": 1,
      "y": 3,
      "z": -3,
      "name": "Rock_Marble"
    },
    {
      "x": 1,
      "y": 4,
      "z": -3,
      "name": "Plant_Coral_Model_White"
    },
    {
      "x": 1,
      "y": 0,
      "z": -2,
      "name": "Rock_Marble"
    },
    {
      "x": 1,
      "y": 1,
      "z": -2,
      "name": "Rock_Marble"
    },
    {
      "x": 1,
      "y": 2,
      "z": -2,
      "name": "Rock_Marble"
    },
    {
      "x": 1,
      "y": 3,
      "z": -2,
      "name": "Rock_Marble"
    },
    {
      "x": 1,
      "y": 4,
      "z": -2,
      "name": "Rock_Marble"
    },
    {
      "x": 1,
      "y": 5,
      "z": -2,
      "name": "Plant_Moss_Short_Red",
      "support": 15
    },
    {
      "x": 1,
      "y": 0,
      "z": -1,
      "name": "Rock_Marble"
    },
    {
      "x": 1,
      "y": 1,
      "z": -1,
      "name": "Rock_Marble"
    },
    {
      "x": 1,
      "y": 2,
      "z": -1,
      "name": "Rock_Marble"
    },
    {
      "x": 1,
      "y": 3,
      "z": -1,
      "name": "Rock_Marble"
    },
    {
      "x": 1,
      "y": 4,
      "z": -1,
      "name": "Rock_Marble"
    },
    {
      "x": 1,
      "y": 5,
      "z": -1,
      "name": "Plant_Coral_Model_White"
    },
    {
      "x": 1,
      "y": 0,
      "z": 0,
      "name": "Rock_Marble"
    },
    {
      "x": 1,
      "y": 1,
      "z": 0,
      "name": "Rock_Marble"
    },
    {
      "x": 1,
      "y": 2,
      "z": 0,
      "name": "Rock_Marble"
    },
    {
      "x": 1,
      "y": 3,
      "z": 0,
      "name": "Rock_Marble"
    },
    {
      "x": 1,
      "y": 4,
      "z": 0,
      "name": "Plant_Moss_Block_Red",
      "support": 15
    },
    {
      "x": 1,
      "y": 0,
      "z": 1,
      "name": "Rock_Marble"
    },
    {
      "x": 1,
      "y": 1,
      "z": 1,
      "name": "Rock_Marble"
    },
    {
      "x": 1,
      "y": 2,
      "z": 1,
      "name": "Rock_Marble"
    },
    {
      "x": 1,
      "y": 3,
      "z": 1,
      "name": "Rock_Marble"
    },
    {
      "x": 1,
      "y": 4,
      "z": 1,
      "name": "Plant_Moss_Block_Red",
      "support": 15
    },
    {
      "x": 1,
      "y": 5,
      "z": 1,
      "name": "Plant_Moss_Red",
      "support": 15
    },
    {
      "x": 1,
      "y": 0,
      "z": 2,
      "name": "Rock_Marble"
    },
    {
      "x": 1,
      "y": 1,
      "z": 2,
      "name": "Rock_Marble"
    },
    {
      "x": 1,
      "y": 2,
      "z": 2,
      "name": "Rock_Marble"
    },
    {
      "x": 1,
      "y": 3,
      "z": 2,
      "name": "Rock_Marble"
    },
    {
      "x": 1,
      "y": 4,
      "z": 2,
      "name": "Rock_Marble"
    },
    {
      "x": 1,
      "y": 5,
      "z": 2,
      "name": "Plant_Moss_Short_Red",
      "support": 15
    },
    {
      "x": 1,
      "y": 0,
      "z": 3,
      "name": "Rock_Marble"
    },
    {
      "x": 1,
      "y": 1,
      "z": 3,
      "name": "Rock_Marble"
    },
    {
      "x": 1,
      "y": 2,
      "z": 3,
      "name": "Rock_Marble"
    },
    {
      "x": 1,
      "y": 3,
      "z": 3,
      "name": "Rock_Marble"
    },
    {
      "x": 1,
      "y": 4,
      "z": 3,
      "name": "Plant_Coral_Block_White"
    },
    {
      "x": 1,
      "y": 5,
      "z": 3,
      "name": "Plant_Moss_Rug_Red",
      "support": 15
    },
    {
      "x": 1,
      "y": 0,
      "z": 4,
      "name": "Rock_Marble"
    },
    {
      "x": 1,
      "y": 1,
      "z": 4,
      "name": "Rock_Marble"
    },
    {
      "x": 1,
      "y": 2,
      "z": 4,
      "name": "Rock_Marble"
    },
    {
      "x": 1,
      "y": 3,
      "z": 4,
      "name": "Plant_Coral_Block_White"
    },
    {
      "x": 1,
      "y": 0,
      "z": 5,
      "name": "Rock_Marble"
    },
    {
      "x": 1,
      "y": 1,
      "z": 5,
      "name": "Rock_Marble"
    },
    {
      "x": 1,
      "y": 2,
      "z": 5,
      "name": "Rock_Marble"
    },
    {
      "x": 1,
      "y": 3,
      "z": 5,
      "name": "Rock_Marble"
    },
    {
      "x": 1,
      "y": 4,
      "z": 5,
      "name": "Plant_Coral_Model_Dead3"
    },
    {
      "x": 1,
      "y": 1,
      "z": 6,
      "name": "Rock_Marble"
    },
    {
      "x": 1,
      "y": 2,
      "z": 6,
      "name": "Rock_Marble"
    },
    {
      "x": 1,
      "y": 3,
      "z": 6,
      "name": "Rock_Marble"
    },
    {
      "x": 1,
      "y": 2,
      "z": 7,
      "name": "Rock_Marble"
    },
    {
      "x": 1,
      "y": 3,
      "z": 7,
      "name": "Plant_Moss_Rug_Red",
      "support": 15
    },
    {
      "x": 2,
      "y": 2,
      "z": -5,
      "name": "Rock_Crystal_White_Small",
      "rotation": 5
    },
    {
      "x": 2,
      "y": 1,
      "z": -4,
      "name": "Rock_Marble"
    },
    {
      "x": 2,
      "y": 2,
      "z": -4,
      "name": "Rock_Marble"
    },
    {
      "x": 2,
      "y": 3,
      "z": -4,
      "name": "Rock_Marble"
    },
    {
      "x": 2,
      "y": 1,
      "z": -3,
      "name": "Rock_Marble"
    },
    {
      "x": 2,
      "y": 2,
      "z": -3,
      "name": "Rock_Marble"
    },
    {
      "x": 2,
      "y": 3,
      "z": -3,
      "name": "Rock_Marble"
    },
    {
      "x": 2,
      "y": 4,
      "z": -3,
      "name": "Plant_Coral_Bush_Dead"
    },
    {
      "x": 2,
      "y": 1,
      "z": -2,
      "name": "Rock_Marble"
    },
    {
      "x": 2,
      "y": 2,
      "z": -2,
      "name": "Rock_Marble"
    },
    {
      "x": 2,
      "y": 3,
      "z": -2,
      "name": "Rock_Marble"
    },
    {
      "x": 2,
      "y": 0,
      "z": -1,
      "name": "Rock_Marble"
    },
    {
      "x": 2,
      "y": 1,
      "z": -1,
      "name": "Rock_Marble"
    },
    {
      "x": 2,
      "y": 2,
      "z": -1,
      "name": "Rock_Marble"
    },
    {
      "x": 2,
      "y": 3,
      "z": -1,
      "name": "Rock_Marble"
    },
    {
      "x": 2,
      "y": 4,
      "z": -1,
      "name": "Rock_Marble"
    },
    {
      "x": 2,
      "y": 0,
      "z": 0,
      "name": "Rock_Marble"
    },
    {
      "x": 2,
      "y": 1,
      "z": 0,
      "name": "Rock_Marble"
    },
    {
      "x": 2,
      "y": 2,
      "z": 0,
      "name": "Rock_Marble"
    },
    {
      "x": 2,
      "y": 3,
      "z": 0,
      "name": "Rock_Marble"
    },
    {
      "x": 2,
      "y": 4,
      "z": 0,
      "name": "Rock_Marble"
    },
    {
      "x": 2,
      "y": 5,
      "z": 0,
      "name": "Plant_Moss_Short_Red",
      "support": 15
    },
    {
      "x": 2,
      "y": 0,
      "z": 1,
      "name": "Rock_Marble"
    },
    {
      "x": 2,
      "y": 1,
      "z": 1,
      "name": "Rock_Marble"
    },
    {
      "x": 2,
      "y": 2,
      "z": 1,
      "name": "Rock_Marble"
    },
    {
      "x": 2,
      "y": 3,
      "z": 1,
      "name": "Rock_Marble"
    },
    {
      "x": 2,
      "y": 4,
      "z": 1,
      "name": "Rock_Marble"
    },
    {
      "x": 2,
      "y": 0,
      "z": 2,
      "name": "Rock_Marble"
    },
    {
      "x": 2,
      "y": 1,
      "z": 2,
      "name": "Rock_Marble"
    },
    {
      "x": 2,
      "y": 2,
      "z": 2,
      "name": "Rock_Marble"
    },
    {
      "x": 2,
      "y": 3,
      "z": 2,
      "name": "Rock_Marble"
    },
    {
      "x": 2,
      "y": 0,
      "z": 3,
      "name": "Rock_Marble"
    },
    {
      "x": 2,
      "y": 1,
      "z": 3,
      "name": "Rock_Marble"
    },
    {
      "x": 2,
      "y": 2,
      "z": 3,
      "name": "Plant_Coral_Block_White"
    },
    {
      "x": 2,
      "y": 3,
      "z": 3,
      "name": "Plant_Coral_Block_White"
    },
    {
      "x": 2,
      "y": 4,
      "z": 3,
      "name": "Plant_Moss_Short_Red",
      "support": 15
    },
    {
      "x": 2,
      "y": 0,
      "z": 4,
      "name": "Rock_Marble"
    },
    {
      "x": 2,
      "y": 1,
      "z": 4,
      "name": "Rock_Marble"
    },
    {
      "x": 2,
      "y": 2,
      "z": 4,
      "name": "Plant_Coral_Block_White"
    },
    {
      "x": 2,
      "y": 3,
      "z": 4,
      "name": "Plant_Moss_Block_Red",
      "support": 15
    },
    {
      "x": 2,
      "y": 4,
      "z": 4,
      "name": "Plant_Moss_Rug_Red",
      "support": 15
    },
    {
      "x": 2,
      "y": 0,
      "z": 5,
      "name": "Rock_Marble"
    },
    {
      "x": 2,
      "y": 1,
      "z": 5,
      "name": "Rock_Marble"
    },
    {
      "x": 2,
      "y": 2,
      "z": 5,
      "name": "Rock_Marble"
    },
    {
      "x": 2,
      "y": 3,
      "z": 5,
      "name": "Plant_Moss_Block_Red",
      "support": 15
    },
    {
      "x": 2,
      "y": 4,
      "z": 5,
      "name": "Plant_Moss_Red",
      "support": 15
    },
    {
      "x": 2,
      "y": 1,
      "z": 6,
      "name": "Rock_Marble"
    },
    {
      "x": 2,
      "y": 2,
      "z": 6,
      "name": "Rock_Marble"
    },
    {
      "x": 2,
      "y": 3,
      "z": 6,
      "name": "Rock_Marble"
    },
    {
      "x": 2,
      "y": 4,
      "z": 6,
      "name": "Plant_Coral_Bush_Dead2"
    },
    {
      "x": 2,
      "y": 2,
      "z": 7,
      "name": "Rock_Marble"
    },
    {
      "x": 3,
      "y": 1,
      "z": -4,
      "name": "Rock_Marble"
    },
    {
      "x": 3,
      "y": 2,
      "z": -4,
      "name": "Plant_Coral_Bush_Dead3"
    },
    {
      "x": 3,
      "y": 1,
      "z": -3,
      "name": "Rock_Marble"
    },
    {
      "x": 3,
      "y": 2,
      "z": -3,
      "name": "Rock_Marble"
    },
    {
      "x": 3,
      "y": 3,
      "z": -3,
      "name": "Rock_Marble"
    },
    {
      "x": 3,
      "y": 1,
      "z": -2,
      "name": "Rock_Marble"
    },
    {
      "x": 3,
      "y": 2,
      "z": -2,
      "name": "Rock_Marble"
    },
    {
      "x": 3,
      "y": 3,
      "z": -2,
      "name": "Rock_Marble"
    },
    {
      "x": 3,
      "y": 4,
      "z": -2,
      "name": "Plant_Coral_Model_Dead6"
    },
    {
      "x": 3,
      "y": 1,
      "z": -1,
      "name": "Rock_Marble"
    },
    {
      "x": 3,
      "y": 2,
      "z": -1,
      "name": "Rock_Marble"
    },
    {
      "x": 3,
      "y": 3,
      "z": -1,
      "name": "Rock_Marble"
    },
    {
      "x": 3,
      "y": 4,
      "z": -1,
      "name": "Plant_Coral_Model_Dead6"
    },
    {
      "x": 3,
      "y": 0,
      "z": 0,
      "name": "Rock_Marble"
    },
    {
      "x": 3,
      "y": 1,
      "z": 0,
      "name": "Rock_Marble"
    },
    {
      "x": 3,
      "y": 2,
      "z": 0,
      "name": "Rock_Marble"
    },
    {
      "x": 3,
      "y": 3,
      "z": 0,
      "name": "Rock_Marble"
    },
    {
      "x": 3,
      "y": 4,
      "z": 0,
      "name": "Rock_Marble"
    },
    {
      "x": 3,
      "y": 0,
      "z": 1,
      "name": "Rock_Marble"
    },
    {
      "x": 3,
      "y": 1,
      "z": 1,
      "name": "Rock_Marble"
    },
    {
      "x": 3,
      "y": 2,
      "z": 1,
      "name": "Rock_Marble"
    },
    {
      "x": 3,
      "y": 3,
      "z": 1,
      "name": "Rock_Marble"
    },
    {
      "x": 3,
      "y": 0,
      "z": 2,
      "name": "Rock_Marble"
    },
    {
      "x": 3,
      "y": 1,
      "z": 2,
      "name": "Rock_Marble"
    },
    {
      "x": 3,
      "y": 2,
      "z": 2,
      "name": "Rock_Marble"
    },
    {
      "x": 3,
      "y": 3,
      "z": 2,
      "name": "Rock_Marble"
    },
    {
      "x": 3,
      "y": 0,
      "z": 3,
      "name": "Rock_Marble"
    },
    {
      "x": 3,
      "y": 1,
      "z": 3,
      "name": "Rock_Marble"
    },
    {
      "x": 3,
      "y": 2,
      "z": 3,
      "name": "Rock_Marble"
    },
    {
      "x": 3,
      "y": 3,
      "z": 3,
      "name": "Plant_Coral_Block_White"
    },
    {
      "x": 3,
      "y": 4,
      "z": 3,
      "name": "Plant_Coral_Bush_White"
    },
    {
      "x": 3,
      "y": 0,
      "z": 4,
      "name": "Rock_Crystal_White_Small",
      "rotation": 8
    },
    {
      "x": 3,
      "y": 1,
      "z": 4,
      "name": "Rock_Marble"
    },
    {
      "x": 3,
      "y": 2,
      "z": 4,
      "name": "Plant_Coral_Block_White"
    },
    {
      "x": 3,
      "y": 3,
      "z": 4,
      "name": "Plant_Moss_Block_Red",
      "support": 15
    },
    {
      "x": 3,
      "y": 1,
      "z": 5,
      "name": "Rock_Marble"
    },
    {
      "x": 3,
      "y": 2,
      "z": 5,
      "name": "Rock_Marble"
    },
    {
      "x": 3,
      "y": 3,
      "z": 5,
      "name": "Plant_Moss_Block_Red",
      "support": 15
    },
    {
      "x": 3,
      "y": 1,
      "z": 6,
      "name": "Rock_Marble"
    },
    {
      "x": 3,
      "y": 2,
      "z": 6,
      "name": "Rock_Marble"
    },
    {
      "x": 3,
      "y": 3,
      "z": 6,
      "name": "Rock_Marble"
    },
    {
      "x": 3,
      "y": 4,
      "z": 6,
      "name": "Plant_Coral_Model_Dead7"
    },
    {
      "x": 4,
      "y": 1,
      "z": -3,
      "name": "Rock_Marble"
    },
    {
      "x": 4,
      "y": 2,
      "z": -3,
      "name": "Rock_Marble"
    },
    {
      "x": 4,
      "y": 1,
      "z": -2,
      "name": "Rock_Marble"
    },
    {
      "x": 4,
      "y": 2,
      "z": -2,
      "name": "Rock_Marble"
    },
    {
      "x": 4,
      "y": 3,
      "z": -2,
      "name": "Plant_Moss_Block_Red",
      "support": 15
    },
    {
      "x": 4,
      "y": 4,
      "z": -2,
      "name": "Plant_Moss_Rug_Red",
      "support": 15
    },
    {
      "x": 4,
      "y": 1,
      "z": -1,
      "name": "Rock_Marble"
    },
    {
      "x": 4,
      "y": 2,
      "z": -1,
      "name": "Rock_Marble"
    },
    {
      "x": 4,
      "y": 3,
      "z": -1,
      "name": "Rock_Marble"
    },
    {
      "x": 4,
      "y": 1,
      "z": 0,
      "name": "Rock_Marble"
    },
    {
      "x": 4,
      "y": 2,
      "z": 0,
      "name": "Rock_Marble"
    },
    {
      "x": 4,
      "y": 3,
      "z": 0,
      "name": "Rock_Marble"
    },
    {
      "x": 4,
      "y": 1,
      "z": 1,
      "name": "Rock_Marble"
    },
    {
      "x": 4,
      "y": 2,
      "z": 1,
      "name": "Rock_Marble"
    },
    {
      "x": 4,
      "y": 3,
      "z": 1,
      "name": "Rock_Crystal_White_Block"
    },
    {
      "x": 4,
      "y": 4,
      "z": 1,
      "name": "Rock_Crystal_White_Large"
    },
    {
      "x": 4,
      "y": 1,
      "z": 2,
      "name": "Rock_Marble"
    },
    {
      "x": 4,
      "y": 2,
      "z": 2,
      "name": "Rock_Marble"
    },
    {
      "x": 4,
      "y": 3,
      "z": 2,
      "name": "Rock_Marble"
    },
    {
      "x": 4,
      "y": 1,
      "z": 3,
      "name": "Rock_Marble"
    },
    {
      "x": 4,
      "y": 2,
      "z": 3,
      "name": "Rock_Marble"
    },
    {
      "x": 4,
      "y": 3,
      "z": 3,
      "name": "Rock_Marble"
    },
    {
      "x": 4,
      "y": 4,
      "z": 3,
      "name": "Rubble_Marble",
      "support": 15
    },
    {
      "x": 4,
      "y": 1,
      "z": 4,
      "name": "Rock_Marble"
    },
    {
      "x": 4,
      "y": 2,
      "z": 4,
      "name": "Rock_Marble"
    },
    {
      "x": 4,
      "y": 3,
      "z": 4,
      "name": "Rock_Marble"
    },
    {
      "x": 4,
      "y": 4,
      "z": 4,
      "name": "Plant_Moss_Short_Red",
      "support": 15
    },
    {
      "x": 4,
      "y": 1,
      "z": 5,
      "name": "Rock_Marble"
    },
    {
      "x": 4,
      "y": 2,
      "z": 5,
      "name": "Rock_Marble"
    },
    {
      "x": 4,
      "y": 3,
      "z": 5,
      "name": "Rock_Marble"
    },
    {
      "x": 4,
      "y": 4,
      "z": 5,
      "name": "Plant_Moss_Rug_Red",
      "support": 15
    },
    {
      "x": 4,
      "y": 2,
      "z": 6,
      "name": "Rock_Marble"
    },
    {
      "x": 5,
      "y": 2,
      "z": -3,
      "name": "Rock_Marble"
    },
    {
      "x": 5,
      "y": 3,
      "z": -3,
      "name": "Plant_Moss_Rug_Red",
      "support": 15
    },
    {
      "x": 5,
      "y": 1,
      "z": -2,
      "name": "Rock_Marble"
    },
    {
      "x": 5,
      "y": 2,
      "z": -2,
      "name": "Rock_Marble"
    },
    {
      "x": 5,
      "y": 3,
      "z": -2,
      "name": "Rubble_Marble_Medium",
      "support": 15
    },
    {
      "x": 5,
      "y": 1,
      "z": -1,
      "name": "Rock_Marble"
    },
    {
      "x": 5,
      "y": 2,
      "z": -1,
      "name": "Rock_Marble"
    },
    {
      "x": 5,
      "y": 3,
      "z": -1,
      "name": "Rock_Marble"
    },
    {
      "x": 5,
      "y": 4,
      "z": -1,
      "name": "Plant_Coral_Model_Dead2"
    },
    {
      "x": 5,
      "y": 1,
      "z": 0,
      "name": "Rock_Marble"
    },
    {
      "x": 5,
      "y": 2,
      "z": 0,
      "name": "Rock_Marble"
    },
    {
      "x": 5,
      "y": 3,
      "z": 0,
      "name": "Rock_Marble"
    },
    {
      "x": 5,
      "y": 1,
      "z": 1,
      "name": "Rock_Marble"
    },
    {
      "x": 5,
      "y": 2,
      "z": 1,
      "name": "Rock_Marble"
    },
    {
      "x": 5,
      "y": 3,
      "z": 1,
      "name": "Rock_Marble"
    },
    {
      "x": 5,
      "y": 1,
      "z": 2,
      "name": "Rock_Marble"
    },
    {
      "x": 5,
      "y": 2,
      "z": 2,
      "name": "Rock_Marble"
    },
    {
      "x": 5,
      "y": 3,
      "z": 2,
      "name": "Rock_Marble"
    },
    {
      "x": 5,
      "y": 1,
      "z": 3,
      "name": "Rock_Marble"
    },
    {
      "x": 5,
      "y": 2,
      "z": 3,
      "name": "Rock_Marble"
    },
    {
      "x": 5,
      "y": 3,
      "z": 3,
      "name": "Rock_Marble"
    },
    {
      "x": 5,
      "y": 1,
      "z": 4,
      "name": "Rock_Marble"
    },
    {
      "x": 5,
      "y": 2,
      "z": 4,
      "name": "Rock_Marble"
    },
    {
      "x": 5,
      "y": 3,
      "z": 4,
      "name": "Rock_Marble"
    },
    {
      "x": 5,
      "y": 2,
      "z": 5,
      "name": "Rock_Marble"
    },
    {
      "x": 5,
      "y": 3,
      "z": 5,
      "name": "Plant_Coral_Bush_White"
    },
    {
      "x": 6,
      "y": 2,
      "z": -1,
      "name": "Rock_Marble"
    },
    {
      "x": 6,
      "y": 2,
      "z": 0,
      "name": "Rock_Marble"
    },
    {
      "x": 6,
      "y": 2,
      "z": 1,
      "name": "Rock_Marble"
    },
    {
      "x": 6,
      "y": 3,
      "z": 1,
      "name": "Rubble_Marble",
      "support": 15
    },
    {
      "x": 6,
      "y": 2,
      "z": 2,
      "name": "Rock_Marble"
    },
    {
      "x": 6,
      "y": 2,
      "z": 3,
      "name": "Rock_Marble"
    },
    {
      "x": 6,
      "y": 2,
      "z": 4,
      "name": "Plant_Coral_Bush_White"
    },
    {
      "x": 7,
      "y": 2,
      "z": 0,
      "name": "Plant_Coral_Bush_White"
    },
    {
      "x": 7,
      "y": 2,
      "z": 1,
      "name": "Plant_Coral_Bush_Dead"
    }
  ]
}